{"recv_ts": 1785928837.7012475, "raw": "[{\"market\": \"0xc68886d74e55e7bd083e4ca4266e1e53290758453dafccf33f5cf42c01e24bdf\", \"asset_id\": \"106505604131689189035613585021100506257761833815835754918231574384092554469378\", \"timestamp\": \"1785928826192\", \"hash\": \"59a2b1cf65aeb8f3630b291d193ecfc06c2030ad\", \"bids\": [{\"price\": \"0.001\", \"size\": \"369.8\"}, {\"price\": \"0.002\", \"size\": \"265.44\"}], \"asks\": [{\"price\": \"0.999\", \"size\": \"1149.01\"}, {\"price\": \"0.998\", \"size\": \"532.19\"}, {\"price\": \"0.997\", \"size\": \"1013.32\"}, {\"price\": \"0.996\", \"size\": \"16.92\"}, {\"price\": \"0.99\", \"size\": \"2120\"}, {\"price\": \"0.989\", \"size\": \"6.83\"}, {\"price\": \"0.98\", \"size\": \"2110\"}, {\"price\": \"0.979\", \"size\": \"5.77\"}, {\"price\": \"0.977\", \"size\": \"30\"}, {\"price\": \"0.97\", \"size\": \"1010\"}, {\"price\": \"0.96\", \"size\": \"1100\"}, {\"price\": \"0.959\", \"size\": \"6.74\"}, {\"price\": \"0.95\", \"size\": \"1010\"}, {\"price\": \"0.94\", \"size\": \"1016.66\"}, {\"price\": \"0.93\", \"size\": \"1000\"}, {\"price\": \"0.92\", \"size\": \"1012.5\"}, {\"price\": \"0.91\", \"size\": \"1000\"}, {\"price\": \"0.9\", \"size\": \"1010\"}, {\"price\": \"0.899\", \"size\": \"35.01\"}, {\"price\": \"0.88\", \"size\": \"8.33\"}, {\"price\": \"0.86\", \"size\": \"7.14\"}, {\"price\": \"0.84\", \"size\": \"6.25\"}, {\"price\": \"0.82\", \"size\": \"5.55\"}, {\"price\": \"0.8\", \"size\": \"5\"}, {\"price\": \"0.78\", \"size\": \"9.09\"}, {\"price\": \"0.76\", \"size\": \"8.33\"}, {\"price\": \"0.75\", \"size\": \"16\"}, {\"price\": \"0.749\", \"size\": \"5.24\"}, {\"price\": \"0.74\", \"size\": \"7.69\"}, {\"price\": \"0.72\", \"size\": \"7.14\"}, {\"price\": \"0.7\", \"size\": \"16.66\"}, {\"price\": \"0.68\", \"size\": \"6.25\"}, {\"price\": \"0.66\", \"size\": \"5.88\"}, {\"price\": \"0.64\", \"size\": \"5.55\"}, {\"price\": \"0.62\", \"size\": \"5.26\"}, {\"price\": \"0.6\", \"size\": \"15\"}, {\"price\": \"0.58\", \"size\": \"7.14\"}, {\"price\": \"0.56\", \"size\": \"6.81\"}, {\"price\": \"0.54\", \"size\": \"6.52\"}, {\"price\": \"0.52\", \"size\": \"6.25\"}, {\"price\": \"0.46\", \"size\": \"30\"}, {\"price\": \"0.37\", \"size\": \"5\"}, {\"price\": \"0.358\", \"size\": \"1431\"}, {\"price\": \"0.357\", \"size\": \"400\"}, {\"price\": \"0.2\", \"size\": \"91\"}, {\"price\": \"0.199\", \"size\": \"25\"}, {\"price\": \"0.187\", \"size\": \"30\"}, {\"price\": \"0.186\", \"size\": \"150\"}, {\"price\": \"0.14\", \"size\": \"26.16\"}, {\"price\": \"0.139\", \"size\": \"95\"}, {\"price\": \"0.106\", \"size\": \"46.41\"}, {\"price\": \"0.1\", \"size\": \"7\"}, {\"price\": \"0.09\", \"size\": \"230\"}, {\"price\": \"0.085\", \"size\": \"32.51\"}, {\"price\": \"0.083\", \"size\": \"5\"}, {\"price\": \"0.082\", \"size\": \"10\"}, {\"price\": \"0.07\", \"size\": \"200\"}, {\"price\": \"0.051\", \"size\": \"5\"}, {\"price\": \"0.05\", \"size\": \"275\"}, {\"price\": \"0.049\", \"size\": \"5\"}, {\"price\": \"0.04\", \"size\": \"32\"}, {\"price\": \"0.02\", \"size\": \"20\"}, {\"price\": \"0.019\", \"size\": \"50\"}, {\"price\": \"0.01\", \"size\": \"210.19\"}, {\"price\": \"0.009\", \"size\": \"5.01\"}, {\"price\": \"0.008\", \"size\": \"6\"}], \"tick_size\": \"0.001\", \"event_type\": \"book\", \"last_trade_price\": \"0.002\"}, {\"market\": \"0xe04f850ac80c98023bc726e4dd62f29febf5a2f759e235fc6c09e0db3b8f6f7e\", \"asset_id\": \"34077951133156412447098700623753690844252758976334606468375660852372809737079\", \"timestamp\": \"1785928829116\", \"hash\": \"794c82c7a5496cad4c044d8bc95c0fb33a299e3e\", \"bids\": [{\"price\": \"0.01\", \"size\": \"2654.05\"}, {\"price\": \"0.02\", \"size\": \"2134.39\"}, {\"price\": \"0.03\", \"size\": \"1018.39\"}, {\"price\": \"0.04\", \"size\": \"1125\"}, {\"price\": \"0.05\", \"size\": \"1011.2\"}, {\"price\": \"0.06\", \"size\": \"1016.67\"}, {\"price\": \"0.07\", \"size\": \"1000\"}, {\"price\": \"0.08\", \"size\": \"1017.91\"}, {\"price\": \"0.09\", \"size\": \"1000\"}, {\"price\": \"0.1\", \"size\": \"1010\"}, {\"price\": \"0.11\", \"size\": \"280\"}, {\"price\": \"0.12\", \"size\": \"8.33\"}, {\"price\": \"0.13\", \"size\": \"6.94\"}, {\"price\": \"0.14\", \"size\": \"7.14\"}, {\"price\": \"0.16\", \"size\": \"6.25\"}, {\"price\": \"0.18\", \"size\": \"5.56\"}, {\"price\": \"0.25\", \"size\": \"16\"}, {\"price\": \"0.26\", \"size\": \"6.49\"}, {\"price\": \"0.3\", \"size\": \"1185\"}, {\"price\": \"0.31\", \"size\": \"1591\"}, {\"price\": \"0.32\", \"size\": \"60\"}, {\"price\": \"0.4\", \"size\": \"10\"}, {\"price\": \"0.42\", \"size\": \"25\"}, {\"price\": \"0.43\", \"size\": \"400\"}, {\"price\": \"0.55\", \"size\": \"32\"}, {\"price\": \"0.56\", \"size\": \"100\"}, {\"price\": \"0.58\", \"size\": \"44\"}, {\"price\": \"0.59\", \"size\": \"7\"}, {\"price\": \"0.6\", \"size\": \"50\"}, {\"price\": \"0.63\", \"size\": \"175.84\"}, {\"price\": \"0.64\", \"size\": \"184.95\"}, {\"price\": \"0.65\", \"size\": \"127.05\"}, {\"price\": \"0.66\", \"size\": \"60\"}, {\"price\": \"0.67\", \"size\": \"599.5\"}, {\"price\": \"0.68\", \"size\": \"71\"}], \"asks\": [{\"price\": \"0.99\", \"size\": \"182.4\"}, {\"price\": \"0.98\", \"size\": \"18\"}, {\"price\": \"0.97\", \"size\": \"93\"}, {\"price\": \"0.96\", \"size\": \"30\"}, {\"price\": \"0.95\", \"size\": \"35.76\"}, {\"price\": \"0.94\", \"size\": \"10\"}, {\"price\": \"0.92\", \"size\": \"320\"}, {\"price\": \"0.91\", \"size\": \"1314\"}, {\"price\": \"0.89\", \"size\": \"30\"}, {\"price\": \"0.88\", \"size\": \"116.66\"}, {\"price\": \"0.85\", \"size\": \"53.33\"}, {\"price\": \"0.84\", \"size\": \"1433\"}, {\"price\": \"0.83\", \"size\": \"47.05\"}, {\"price\": \"0.82\", \"size\": \"35\"}, {\"price\": \"0.81\", \"size\": \"5\"}, {\"price\": \"0.79\", \"size\": \"5\"}, {\"price\": \"0.78\", \"size\": \"67\"}, {\"price\": \"0.72\", \"size\": \"180\"}, {\"price\": \"0.71\", \"size\": \"26.99\"}, {\"price\": \"0.7\", \"size\": \"709.17\"}, {\"price\": \"0.69\", \"size\": \"128.08\"}], \"tick_size\": \"0.01\", \"event_type\": \"book\", \"last_trade_price\": \"0.690\"}, {\"market\": \"0xe5a22f95367cb020b47dee1863c3fad66cea905dc81d814600da5aa2a4f6cf01\", \"asset_id\": \"34841150850380066874990789772436638726591319494768387870563958302928351740196\", \"timestamp\": \"1785928829865\", \"hash\": \"a9a9c1dba7fcfb233b19da5f2b7642496944bead\", \"bids\": [{\"price\": \"0.001\", \"size\": \"128.86\"}, {\"price\": \"0.002\", \"size\": \"45.81\"}, {\"price\": \"0.01\", \"size\": \"2170\"}, {\"price\": \"0.011\", \"size\": \"6.83\"}, {\"price\": \"0.02\", \"size\": \"160\"}, {\"price\": \"0.021\", \"size\": \"5.81\"}, {\"price\": \"0.03\", \"size\": \"10\"}, {\"price\": \"0.04\", \"size\": \"125\"}, {\"price\": \"0.041\", \"size\": \"6.55\"}, {\"price\": \"0.05\", \"size\": \"10\"}, {\"price\": \"0.06\", \"size\": \"33.33\"}, {\"price\": \"0.08\", \"size\": \"25\"}, {\"price\": \"0.1\", \"size\": \"20\"}, {\"price\": \"0.101\", \"size\": \"5.01\"}, {\"price\": \"0.11\", \"size\": \"186.36\"}, {\"price\": \"0.12\", \"size\": \"16.66\"}, {\"price\": \"0.14\", \"size\": \"14.28\"}, {\"price\": \"0.16\", \"size\": \"12.5\"}, {\"price\": \"0.18\", \"size\": \"11.11\"}, {\"price\": \"0.2\", \"size\": \"125\"}, {\"price\": \"0.21\", \"size\": \"97.61\"}, {\"price\": \"0.22\", \"size\": \"9.09\"}, {\"price\": \"0.24\", \"size\": \"8.33\"}, {\"price\": \"0.25\", \"size\": \"16\"}, {\"price\": \"0.251\", \"size\": \"5.27\"}, {\"price\": \"0.26\", \"size\": \"7.69\"}, {\"price\": \"0.28\", \"size\": \"7.14\"}, {\"price\": \"0.3\", \"size\": \"6.66\"}, {\"price\": \"0.31\", \"size\": \"66.12\"}, {\"price\": \"0.32\", \"size\": \"6.25\"}, {\"price\": \"0.34\", \"size\": \"5.88\"}, {\"price\": \"0.36\", \"size\": \"5.55\"}, {\"price\": \"0.38\", \"size\": \"5.26\"}, {\"price\": \"0.4\", \"size\": \"15\"}, {\"price\": \"0.41\", \"size\": \"50\"}, {\"price\": \"0.42\", \"size\": \"7.14\"}, {\"price\": \"0.44\", \"size\": \"6.81\"}, {\"price\": \"0.46\", \"size\": \"6.52\"}, {\"price\": \"0.48\", \"size\": \"6.25\"}, {\"price\": \"0.51\", \"size\": \"40.19\"}, {\"price\": \"0.511\", \"size\": \"25\"}, {\"price\": \"0.61\", \"size\": \"33.6\"}, {\"price\": \"0.65\", \"size\": \"5\"}, {\"price\": \"0.71\", \"size\": \"28.87\"}, {\"price\": \"0.729\", \"size\": \"2205\"}, {\"price\": \"0.73\", \"size\": \"30\"}, {\"price\": \"0.731\", \"size\": \"400\"}, {\"price\": \"0.8\", \"size\": \"78.62\"}, {\"price\": \"0.81\", \"size\": \"25.3\"}, {\"price\": \"0.82\", \"size\": \"25\"}, {\"price\": \"0.83\", \"size\": \"24.69\"}, {\"price\": \"0.84\", \"size\": \"24.4\"}, {\"price\": \"0.85\", \"size\": \"94.11\"}, {\"price\": \"0.86\", \"size\": \"23.83\"}, {\"price\": \"0.87\", \"size\": \"73.56\"}, {\"price\": \"0.88\", \"size\": \"23.29\"}, {\"price\": \"0.881\", \"size\": \"100\"}, {\"price\": \"0.89\", \"size\": \"23.03\"}, {\"price\": \"0.9\", \"size\": \"99.77\"}, {\"price\": \"0.91\", \"size\": \"472.52\"}, {\"price\": \"0.913\", \"size\": \"40\"}, {\"price\": \"0.92\", \"size\": \"72.28\"}, {\"price\": \"0.93\", \"size\": \"522.04\"}, {\"price\": \"0.931\", \"size\": \"50\"}, {\"price\": \"0.94\", \"size\": \"71.8\"}, {\"price\": \"0.943\", \"size\": \"78\"}, {\"price\": \"0.95\", \"size\": \"546.57\"}, {\"price\": \"0.951\", \"size\": \"65\"}, {\"price\": \"0.955\", \"size\": \"50\"}, {\"price\": \"0.96\", \"size\": \"503.35\"}, {\"price\": \"0.965\", \"size\": \"50\"}, {\"price\": \"0.966\", \"size\": \"23\"}, {\"price\": \"0.97\", \"size\": \"471.13\"}, {\"price\": \"0.971\", \"size\": \"30\"}, {\"price\": \"0.972\", \"size\": \"5\"}, {\"price\": \"0.973\", \"size\": \"41\"}, {\"price\": \"0.974\", \"size\": \"35\"}, {\"price\": \"0.975\", \"size\": \"92.02\"}, {\"price\": \"0.98\", \"size\": \"641.91\"}, {\"price\": \"0.985\", \"size\": \"470.81\"}, {\"price\": \"0.987\", \"size\": \"40\"}, {\"price\": \"0.99\", \"size\": \"541.7\"}, {\"price\": \"0.994\", \"size\": \"330\"}, {\"price\": \"0.995\", \"size\": \"345.13\"}, {\"price\": \"0.996\", \"size\": \"402.2\"}], \"asks\": [{\"price\": \"0.999\", \"size\": \"321.46\"}], \"tick_size\": \"0.001\", \"event_type\": \"book\", \"last_trade_price\": \"0.001\"}, {\"market\": \"0x2d3c367f4e2769b4d374835db9aa4f94e9eb1aa82f6120f1db34d98c6531b58b\", \"asset_id\": \"108122432812817305376268557669897379262458681647837813260920631546161187075193\", \"timestamp\": \"1785928818182\", \"hash\": \"2fdc8ce01d9205a671ef8cff67513e551305c063\", \"bids\": [{\"price\": \"0.001\", \"size\": \"128.51\"}, {\"price\": \"0.002\", \"size\": \"44.28\"}, {\"price\": \"0.01\", \"size\": \"3270\"}, {\"price\": \"0.011\", \"size\": \"9.09\"}, {\"price\": \"0.02\", \"size\": \"10\"}, {\"price\": \"0.021\", \"size\": \"5.63\"}, {\"price\": \"0.03\", \"size\": \"10\"}, {\"price\": \"0.04\", \"size\": \"75\"}, {\"price\": \"0.041\", \"size\": \"18.89\"}, {\"price\": \"0.11\", \"size\": \"295.45\"}, {\"price\": \"0.111\", \"size\": \"25\"}, {\"price\": \"0.21\", \"size\": \"154.76\"}, {\"price\": \"0.25\", \"size\": \"16\"}, {\"price\": \"0.251\", \"size\": \"5.2\"}, {\"price\": \"0.31\", \"size\": \"104.83\"}, {\"price\": \"0.4\", \"size\": \"10\"}, {\"price\": \"0.41\", \"size\": \"79.26\"}, {\"price\": \"0.51\", \"size\": \"63.72\"}, {\"price\": \"0.511\", \"size\": \"30\"}, {\"price\": \"0.61\", \"size\": \"53.27\"}, {\"price\": \"0.65\", \"size\": \"5\"}, {\"price\": \"0.71\", \"size\": \"45.77\"}, {\"price\": \"0.711\", \"size\": \"400\"}, {\"price\": \"0.75\", \"size\": \"20\"}, {\"price\": \"0.753\", \"size\": \"2126\"}, {\"price\": \"0.8\", \"size\": \"103.62\"}, {\"price\": \"0.81\", \"size\": \"40.12\"}, {\"price\": \"0.82\", \"size\": \"39.63\"}, {\"price\": \"0.83\", \"size\": \"39.15\"}, {\"price\": \"0.84\", \"size\": \"38.69\"}, {\"price\": \"0.85\", \"size\": \"108.23\"}, {\"price\": \"0.851\", \"size\": \"100\"}, {\"price\": \"0.86\", \"size\": \"37.79\"}, {\"price\": \"0.87\", \"size\": \"37.35\"}, {\"price\": \"0.88\", \"size\": \"36.93\"}, {\"price\": \"0.89\", \"size\": \"36.51\"}, {\"price\": \"0.9\", \"size\": \"43.11\"}, {\"price\": \"0.903\", \"size\": \"52.05\"}, {\"price\": \"0.91\", \"size\": \"435.71\"}, {\"price\": \"0.911\", \"size\": \"50\"}, {\"price\": \"0.92\", \"size\": \"35.32\"}, {\"price\": \"0.93\", \"size\": \"484.94\"}, {\"price\": \"0.933\", \"size\": \"24.05\"}, {\"price\": \"0.934\", \"size\": \"60\"}, {\"price\": \"0.94\", \"size\": \"34.57\"}, {\"price\": \"0.95\", \"size\": \"554.21\"}, {\"price\": \"0.96\", \"size\": \"540.85\"}, {\"price\": \"0.961\", \"size\": \"40\"}, {\"price\": \"0.97\", \"size\": \"433.5\"}, {\"price\": \"0.975\", \"size\": \"113.33\"}, {\"price\": \"0.978\", \"size\": \"40\"}, {\"price\": \"0.98\", \"size\": \"523.16\"}, {\"price\": \"0.985\", \"size\": \"482.99\"}, {\"price\": \"0.99\", \"size\": \"564.12\"}, {\"price\": \"0.994\", \"size\": \"590\"}, {\"price\": \"0.995\", \"size\": \"370\"}, {\"price\": \"0.997\", \"size\": \"40.98\"}, {\"price\": \"0.999\", \"size\": \"54.01\"}], \"asks\": [], \"tick_size\": \"0.001\", \"event_type\": \"book\", \"last_trade_price\": \"0.001\"}]", "trimmed": true}
{"recv_ts": 1785928837.7476535, "raw": "[{\"market\": \"0x91286ed87966da3ebae768f8a9729eb41f32f6801b577a9a4edddb77398d705b\", \"asset_id\": \"59376663278123869553062175306724268131684018080636196666962715551936405823313\", \"timestamp\": \"1785928833758\", \"hash\": \"631fdc1e72136a27a916da8970106d14eedce12d\", \"bids\": [], \"asks\": [{\"price\": \"0.999\", \"size\": \"130.58\"}, {\"price\": \"0.998\", \"size\": \"50.62\"}, {\"price\": \"0.99\", \"size\": \"120\"}, {\"price\": \"0.989\", \"size\": \"7.69\"}, {\"price\": \"0.98\", \"size\": \"110\"}, {\"price\": \"0.979\", \"size\": \"844\"}, {\"price\": \"0.977\", \"size\": \"808.02\"}, {\"price\": \"0.976\", \"size\": \"30\"}, {\"price\": \"0.97\", \"size\": \"20\"}, {\"price\": \"0.96\", \"size\": \"125\"}, {\"price\": \"0.95\", \"size\": \"20\"}, {\"price\": \"0.94\", \"size\": \"33.33\"}, {\"price\": \"0.92\", \"size\": \"25\"}, {\"price\": \"0.9\", \"size\": \"20\"}, {\"price\": \"0.899\", \"size\": \"5.98\"}, {\"price\": \"0.88\", \"size\": \"16.66\"}, {\"price\": \"0.86\", \"size\": \"114.28\"}, {\"price\": \"0.85\", \"size\": \"5\"}, {\"price\": \"0.84\", \"size\": \"12.5\"}, {\"price\": \"0.82\", \"size\": \"11.11\"}, {\"price\": \"0.8\", \"size\": \"5\"}, {\"price\": \"0.78\", \"size\": \"9.09\"}, {\"price\": \"0.76\", \"size\": \"8.33\"}, {\"price\": \"0.75\", \"size\": \"16\"}, {\"price\": \"0.74\", \"size\": \"7.69\"}, {\"price\": \"0.739\", \"size\": \"5.55\"}, {\"price\": \"0.72\", \"size\": \"7.14\"}, {\"price\": \"0.7\", \"size\": \"21.66\"}, {\"price\": \"0.68\", \"size\": \"6.25\"}, {\"price\": \"0.66\", \"size\": \"5.88\"}, {\"price\": \"0.64\", \"size\": \"5.55\"}, {\"price\": \"0.62\", \"size\": \"5.26\"}, {\"price\": \"0.6\", \"size\": \"5\"}, {\"price\": \"0.58\", \"size\": \"7.14\"}, {\"price\": \"0.579\", \"size\": \"50\"}, {\"price\": \"0.56\", \"size\": \"6.81\"}, {\"price\": \"0.54\", \"size\": \"6.52\"}, {\"price\": \"0.52\", \"size\": \"6.25\"}, {\"price\": \"0.5\", \"size\": \"5\"}, {\"price\": \"0.499\", \"size\": \"30\"}, {\"price\": \"0.3\", \"size\": \"5\"}, {\"price\": \"0.29\", \"size\": \"5\"}, {\"price\": \"0.289\", \"size\": \"30\"}, {\"price\": \"0.28\", \"size\": \"5\"}, {\"price\": \"0.27\", \"size\": \"5\"}, {\"price\": \"0.26\", \"size\": \"5\"}, {\"price\": \"0.25\", \"size\": \"5\"}, {\"price\": \"0.24\", \"size\": \"5\"}, {\"price\": \"0.23\", \"size\": \"5\"}, {\"price\": \"0.22\", \"size\": \"5\"}, {\"price\": \"0.21\", \"size\": \"5\"}, {\"price\": \"0.2\", \"size\": \"5\"}, {\"price\": \"0.19\", \"size\": \"5\"}, {\"price\": \"0.18\", \"size\": \"5\"}, {\"price\": \"0.179\", \"size\": \"10\"}, {\"price\": \"0.17\", \"size\": \"5\"}, {\"price\": \"0.16\", \"size\": \"5\"}, {\"price\": \"0.15\", \"size\": \"5\"}, {\"price\": \"0.14\", \"size\": \"5\"}, {\"price\": \"0.13\", \"size\": \"5\"}, {\"price\": \"0.12\", \"size\": \"5\"}, {\"price\": \"0.11\", \"size\": \"5\"}, {\"price\": \"0.1\", \"size\": \"12\"}, {\"price\": \"0.099\", \"size\": \"20\"}, {\"price\": \"0.09\", \"size\": \"5\"}, {\"price\": \"0.08\", \"size\": \"5\"}, {\"price\": \"0.07\", \"size\": \"55\"}, {\"price\": \"0.06\", \"size\": \"5\"}, {\"price\": \"0.059\", \"size\": \"20\"}, {\"price\": \"0.052\", \"size\": \"50\"}, {\"price\": \"0.05\", \"size\": \"37\"}, {\"price\": \"0.045\", \"size\": \"5.23\"}, {\"price\": \"0.04\", \"size\": \"5\"}, {\"price\": \"0.03\", \"size\": \"80\"}, {\"price\": \"0.022\", \"size\": \"37\"}, {\"price\": \"0.021\", \"size\": \"21.81\"}, {\"price\": \"0.02\", \"size\": \"25\"}, {\"price\": \"0.01\", \"size\": \"254\"}, {\"price\": \"0.009\", \"size\": \"20\"}, {\"price\": \"0.008\", \"size\": \"10\"}, {\"price\": \"0.007\", \"size\": \"10\"}, {\"price\": \"0.006\", \"size\": \"470\"}, {\"price\": \"0.005\", \"size\": \"1160.25\"}, {\"price\": \"0.004\", \"size\": \"2585\"}, {\"price\": \"0.003\", \"size\": \"2848.64\"}, {\"price\": \"0.002\", \"size\": \"9529\"}, {\"price\": \"0.001\", \"size\": \"12095.12\"}], \"tick_size\": \"0.001\", \"event_type\": \"book\", \"last_trade_price\": \"0.999\"}, {\"market\": \"0x60ed024338c838465f21e12a97bc3f27c47b2f7599cfc4136b91d98a12126f0a\", \"asset_id\": \"103377957279313196998820480104073254380203148020388430532733800464621320447909\", \"timestamp\": \"1785928817785\", \"hash\": \"444af72801f6ad01fc3415f0930ddba98ff9e3c9\", \"bids\": [], \"asks\": [{\"price\": \"0.999\", \"size\": \"123.92\"}, {\"price\": \"0.998\", \"size\": \"35.79\"}, {\"price\": \"0.99\", \"size\": \"220\"}, {\"price\": \"0.98\", \"size\": \"10\"}, {\"price\": \"0.979\", \"size\": \"804\"}, {\"price\": \"0.978\", \"size\": \"30\"}, {\"price\": \"0.977\", \"size\": \"800\"}, {\"price\": \"0.976\", \"size\": \"7.95\"}, {\"price\": \"0.97\", \"size\": \"43\"}, {\"price\": \"0.95\", \"size\": \"10\"}, {\"price\": \"0.94\", \"size\": \"105\"}, {\"price\": \"0.934\", \"size\": \"30\"}, {\"price\": \"0.933\", \"size\": \"18.91\"}, {\"price\": \"0.2\", \"size\": \"7\"}, {\"price\": \"0.16\", \"size\": \"5\"}, {\"price\": \"0.14\", \"size\": \"6\"}, {\"price\": \"0.08\", \"size\": \"6\"}, {\"price\": \"0.07\", \"size\": \"150\"}, {\"price\": \"0.069\", \"size\": \"30\"}, {\"price\": \"0.068\", \"size\": \"7\"}, {\"price\": \"0.02\", \"size\": \"20\"}, {\"price\": \"0.019\", \"size\": \"40\"}, {\"price\": \"0.01\", \"size\": \"218\"}, {\"price\": \"0.009\", \"size\": \"140\"}, {\"price\": \"0.008\", \"size\": \"70\"}, {\"price\": \"0.007\", \"size\": \"27.11\"}, {\"price\": \"0.006\", \"size\": \"99.99\"}, {\"price\": \"0.004\", \"size\": \"7.67\"}, {\"price\": \"0.002\", \"size\": \"10.4\"}, {\"price\": \"0.001\", \"size\": \"18.37\"}], \"tick_size\": \"0.001\", \"event_type\": \"book\", \"last_trade_price\": \"0.001\"}, {\"market\": \"0xa92a2efee98b18dd90df498db015067887f3517cadaf16229418f7fbe51f0daf\", \"asset_id\": \"57149864650023002170631233045014570570470633619872490728051346865158881828065\", \"timestamp\": \"1785928791701\", \"hash\": \"0c37eb91447b9d0744e2f6964d297bf0d1e26b7e\", \"bids\": [{\"price\": \"0.001\", \"size\": \"130.61\"}, {\"price\": \"0.002\", \"size\": \"2006.37\"}, {\"price\": \"0.004\", \"size\": \"18.82\"}, {\"price\": \"0.01\", \"size\": \"20\"}, {\"price\": \"0.011\", \"size\": \"7.95\"}, {\"price\": \"0.02\", \"size\": \"60\"}, {\"price\": \"0.023\", \"size\": \"30\"}, {\"price\": \"0.024\", \"size\": \"200\"}, {\"price\": \"0.03\", \"size\": \"10\"}, {\"price\": \"0.031\", \"size\": \"5.56\"}, {\"price\": \"0.04\", \"size\": \"100\"}, {\"price\": \"0.041\", \"size\": \"30\"}, {\"price\": \"0.05\", \"size\": \"10\"}, {\"price\": \"0.06\", \"size\": \"16.67\"}, {\"price\": \"0.061\", \"size\": \"5.78\"}, {\"price\": \"0.08\", \"size\": \"12.5\"}, {\"price\": \"0.1\", \"size\": \"10\"}, {\"price\": \"0.12\", \"size\": \"8.33\"}, {\"price\": \"0.14\", \"size\": \"7.14\"}, {\"price\": \"0.141\", \"size\": \"5.72\"}, {\"price\": \"0.15\", \"size\": \"5\"}, {\"price\": \"0.16\", \"size\": \"6.25\"}, {\"price\": \"0.18\", \"size\": \"5.56\"}, {\"price\": \"0.181\", \"size\": \"5.52\"}, {\"price\": \"0.3\", \"size\": \"10\"}, {\"price\": \"0.5\", \"size\": \"5\"}, {\"price\": \"0.7\", \"size\": \"5\"}, {\"price\": \"0.701\", \"size\": \"30\"}, {\"price\": \"0.71\", \"size\": \"5\"}, {\"price\": \"0.72\", \"size\": \"5\"}, {\"price\": \"0.73\", \"size\": \"5\"}, {\"price\": \"0.74\", \"size\": \"5\"}, {\"price\": \"0.75\", \"size\": \"5\"}, {\"price\": \"0.76\", \"size\": \"5\"}, {\"price\": \"0.77\", \"size\": \"5\"}, {\"price\": \"0.78\", \"size\": \"5\"}, {\"price\": \"0.79\", \"size\": \"5\"}, {\"price\": \"0.8\", \"size\": \"5\"}, {\"price\": \"0.81\", \"size\": \"5\"}, {\"price\": \"0.82\", \"size\": \"5\"}, {\"price\": \"0.83\", \"size\": \"5\"}, {\"price\": \"0.84\", \"size\": \"5\"}, {\"price\": \"0.85\", \"size\": \"5\"}, {\"price\": \"0.86\", \"size\": \"5\"}, {\"price\": \"0.87\", \"size\": \"5\"}, {\"price\": \"0.88\", \"size\": \"5\"}, {\"price\": \"0.89\", \"size\": \"5\"}, {\"price\": \"0.9\", \"size\": \"62\"}, {\"price\": \"0.901\", \"size\": \"20\"}, {\"price\": \"0.91\", \"size\": \"5\"}, {\"price\": \"0.92\", \"size\": \"5\"}, {\"price\": \"0.93\", \"size\": \"5\"}, {\"price\": \"0.94\", \"size\": \"5\"}, {\"price\": \"0.948\", \"size\": \"150\"}, {\"price\": \"0.95\", \"size\": \"5\"}, {\"price\": \"0.96\", \"size\": \"5\"}, {\"price\": \"0.962\", \"size\": \"30\"}, {\"price\": \"0.97\", \"size\": \"80\"}, {\"price\": \"0.978\", \"size\": \"82\"}, {\"price\": \"0.98\", \"size\": \"5\"}, {\"price\": \"0.981\", \"size\": \"10.19\"}, {\"price\": \"0.989\", \"size\": \"5\"}, {\"price\": \"0.99\", \"size\": \"75\"}, {\"price\": \"0.991\", \"size\": \"10\"}, {\"price\": \"0.992\", \"size\": \"10\"}, {\"price\": \"0.993\", \"size\": \"30\"}, {\"price\": \"0.994\", \"size\": \"80\"}, {\"price\": \"0.995\", \"size\": \"634\"}, {\"price\": \"0.996\", \"size\": \"2385\"}, {\"price\": \"0.997\", \"size\": \"2540\"}, {\"price\": \"0.998\", \"size\": \"7790\"}, {\"price\": \"0.999\", \"size\": \"13909.2\"}], \"asks\": [], \"tick_size\": \"0.001\", \"event_type\": \"book\", \"last_trade_price\": \"0.999\"}, {\"market\": \"0x5485a7970ab0bafa2e92a6af249cafafc9195bd8fd6fd54993e399cef1c96f05\", \"asset_id\": \"56068374358744535819487376174603560211630382761606580491592998652105187069116\", \"timestamp\": \"1785928768717\", \"hash\": \"66ed870536d138a6bbc8986b8284c39b46927087\", \"bids\": [{\"price\": \"0.001\", \"size\": \"1611.8\"}], \"asks\": [{\"price\": \"0.999\", \"size\": \"129.89\"}, {\"price\": \"0.998\", \"size\": \"49.21\"}, {\"price\": \"0.99\", \"size\": \"20\"}, {\"price\": \"0.989\", \"size\": \"13.6\"}, {\"price\": \"0.98\", \"size\": \"10\"}, {\"price\": \"0.979\", \"size\": \"804\"}, {\"price\": \"0.977\", \"size\": \"800\"}, {\"price\": \"0.976\", \"size\": \"30\"}, {\"price\": \"0.97\", \"size\": \"10\"}, {\"price\": \"0.969\", \"size\": \"5.52\"}, {\"price\": \"0.96\", \"size\": \"75\"}, {\"price\": \"0.95\", \"size\": \"30\"}, {\"price\": \"0.94\", \"size\": \"27\"}, {\"price\": \"0.939\", \"size\": \"12.13\"}, {\"price\": \"0.75\", \"size\": \"30\"}, {\"price\": \"0.749\", \"size\": \"5.68\"}, {\"price\": \"0.7\", \"size\": \"5\"}, {\"price\": \"0.65\", \"size\": \"10\"}, {\"price\": \"0.648\", \"size\": \"40\"}, {\"price\": \"0.647\", \"size\": \"100\"}, {\"price\": \"0.603\", \"size\": \"50\"}, {\"price\": \"0.601\", \"size\": \"30\"}, {\"price\": \"0.6\", \"size\": \"90\"}, {\"price\": \"0.599\", \"size\": \"30\"}, {\"price\": \"0.37\", \"size\": \"5\"}, {\"price\": \"0.17\", \"size\": \"7\"}, {\"price\": \"0.07\", \"size\": \"50\"}, {\"price\": \"0.047\", \"size\": \"5\"}, {\"price\": \"0.044\", \"size\": \"23\"}, {\"price\": \"0.03\", \"size\": \"49\"}, {\"price\": \"0.02\", \"size\": \"20\"}, {\"price\": \"0.019\", \"size\": \"50.98\"}, {\"price\": \"0.017\", \"size\": \"51.48\"}, {\"price\": \"0.016\", \"size\": \"50\"}, {\"price\": \"0.011\", \"size\": \"50\"}, {\"price\": \"0.01\", \"size\": \"42.72\"}, {\"price\": \"0.007\", \"size\": \"299.99\"}, {\"price\": \"0.006\", \"size\": \"6\"}, {\"price\": \"0.005\", \"size\": \"166.1\"}], \"tick_size\": \"0.001\", \"event_type\": \"book\", \"last_trade_price\": \"0.004\"}]", "trimmed": true}
{"recv_ts": 1785928837.7606068, "raw": "{\"market\":\"0x9564d81934c1550b627ff159cc139675d7d08916fa74cc4aaf8d416e4bedd807\",\"price_changes\":[{\"asset_id\":\"46123186009598106104671689617421295270790145953546842072887829618094075293472\",\"price\":\"0.42\",\"size\":\"13\",\"side\":\"BUY\",\"hash\":\"ab042302fb58bc68dd7dfbbabc6cda2cc0be3bd4\",\"best_bid\":\"0.48\",\"best_ask\":\"0.74\"},{\"asset_id\":\"33275922446271605474639218893344378139793083231796398469699104729778621445854\",\"price\":\"0.58\",\"size\":\"13\",\"side\":\"SELL\",\"hash\":\"4c804551e96db2adaca895a1a9ef2a0ed2387b1c\",\"best_bid\":\"0.26\",\"best_ask\":\"0.52\"}],\"timestamp\":\"1785928837614\",\"event_type\":\"price_change\"}"}
{"recv_ts": 1785928837.7606301, "raw": "{\"market\":\"0x31cc8cc9d1b3dbdc5219e0319a01ded09ad0c18296c8f27bc76b1f12364a4661\",\"price_changes\":[{\"asset_id\":\"51223233815348005431570032441325849255204346210650700628294623504463311020670\",\"price\":\"0.24\",\"size\":\"0\",\"side\":\"BUY\",\"hash\":\"3ab0c3a66f2cbb60137aeb0f8320d9bdf0294036\",\"best_bid\":\"0.21\",\"best_ask\":\"0.43\"},{\"asset_id\":\"36593914907192135817908362063800584939108275837285837232090830833195276003888\",\"price\":\"0.76\",\"size\":\"0\",\"side\":\"SELL\",\"hash\":\"172974be1d155a6b88f93903e3e7224379333949\",\"best_bid\":\"0.57\",\"best_ask\":\"0.79\"}],\"timestamp\":\"1785928837618\",\"event_type\":\"price_change\"}"}
{"recv_ts": 1785928837.7606442, "raw": "{\"market\":\"0x0393e451a7889f6472d5099a6de21d1fc6bea6ada01c2e227ea954a8ebce1771\",\"price_changes\":[{\"asset_id\":\"62439955870856164313493799301554574122664268361492077980110236255342893751283\",\"price\":\"0.369\",\"size\":\"50\",\"side\":\"BUY\",\"hash\":\"edf478b00e0622ca019f9222dc9f4c9064cb8d22\",\"best_bid\":\"0.914\",\"best_ask\":\"0.945\"},{\"asset_id\":\"19078179119846452574438096789570272099502061228398927027811652354916673625092\",\"price\":\"0.631\",\"size\":\"50\",\"side\":\"SELL\",\"hash\":\"3ea46a40161e9772d6c0b7d90afc521b80910f01\",\"best_bid\":\"0.055\",\"best_ask\":\"0.086\"}],\"timestamp\":\"1785928837622\",\"event_type\":\"price_change\"}"}
{"recv_ts": 1785928837.7606568, "raw": "{\"market\":\"0x0393e451a7889f6472d5099a6de21d1fc6bea6ada01c2e227ea954a8ebce1771\",\"price_changes\":[{\"asset_id\":\"62439955870856164313493799301554574122664268361492077980110236255342893751283\",\"price\":\"0.913\",\"size\":\"29\",\"side\":\"BUY\",\"hash\":\"4fa101ff0e270fe733cc766f87883ae8caf38746\",\"best_bid\":\"0.914\",\"best_ask\":\"0.945\"},{\"asset_id\":\"19078179119846452574438096789570272099502061228398927027811652354916673625092\",\"price\":\"0.087\",\"size\":\"29\",\"side\":\"SELL\",\"hash\":\"ec694fd9eaca37b3e2fa376d3f308d460466bcae\",\"best_bid\":\"0.055\",\"best_ask\":\"0.086\"}],\"timestamp\":\"1785928837623\",\"event_type\":\"price_change\"}"}
{"recv_ts": 1785928837.7606676, "raw": "{\"market\":\"0x9c68a1448a4cdb3993a297f1f0f759774383f2e514773621ceb04589399930bc\",\"price_changes\":[{\"asset_id\":\"33579711484128453880472647592907450388461194263236358989226504691017998237897\",\"price\":\"0.83\",\"size\":\"0\",\"side\":\"BUY\",\"hash\":\"16f403d981019feeebae3a1652e023996279c9df\",\"best_bid\":\"0.86\",\"best_ask\":\"0.91\"},{\"asset_id\":\"62791514040221235938370932209912323223995828701014253087241691765902207027191\",\"price\":\"0.17\",\"size\":\"0\",\"side\":\"SELL\",\"hash\":\"e741b5e49222d176c334a15ad09a6461d6384083\",\"best_bid\":\"0.09\",\"best_ask\":\"0.14\"}],\"timestamp\":\"1785928837629\",\"event_type\":\"price_change\"}"}
{"recv_ts": 1785928837.7606783, "raw": "{\"market\":\"0x31cc8cc9d1b3dbdc5219e0319a01ded09ad0c18296c8f27bc76b1f12364a4661\",\"price_changes\":[{\"asset_id\":\"51223233815348005431570032441325849255204346210650700628294623504463311020670\",\"price\":\"0.22\",\"size\":\"5\",\"side\":\"BUY\",\"hash\":\"acf2cbc283aab84d2e170f7a332d24ad8282eacb\",\"best_bid\":\"0.22\",\"best_ask\":\"0.43\"},{\"asset_id\":\"36593914907192135817908362063800584939108275837285837232090830833195276003888\",\"price\":\"0.78\",\"size\":\"5\",\"side\":\"SELL\",\"hash\":\"1d7b46ef6abeec56278e1553081bf5bf662e3bf8\",\"best_bid\":\"0.57\",\"best_ask\":\"0.78\"}],\"timestamp\":\"1785928837630\",\"event_type\":\"price_change\"}"}
{"recv_ts": 1785928837.7606885, "raw": "{\"market\":\"0x0334a689cdcaf81930d6d9940e13b5664320919528bb69d2c61f02d1bf8af1bc\",\"price_changes\":[{\"asset_id\":\"13192878898968946332084337129131084781833678983669578830145839502044493606147\",\"price\":\"0.651\",\"size\":\"7\",\"side\":\"BUY\",\"hash\":\"5c52e616e0ad1b633b68d72cea1a5a2b38fbc772\",\"best_bid\":\"0.651\",\"best_ask\":\"0.84\"},{\"asset_id\":\"10231543017839403478856563793210797939168689880219762361092559323833414965831\",\"price\":\"0.349\",\"size\":\"7\",\"side\":\"SELL\",\"hash\":\"3d9f915b86a27199303cdc967fdc53fad579841f\",\"best_bid\":\"0.16\",\"best_ask\":\"0.349\"}],\"timestamp\":\"1785928837630\",\"event_type\":\"price_change\"}"}
{"recv_ts": 1785928837.7606988, "raw": "{\"market\":\"0x30cefdde280d79ffcb7e9f25dbe99e6164d16651c9d8631f2b5bf402b6e697d5\",\"price_changes\":[{\"asset_id\":\"103247719666968457601315979306806361087685293523685277721928164828309367213844\",\"price\":\"0.14\",\"size\":\"57.14\",\"side\":\"BUY\",\"hash\":\"e55e238c08629d8df18226337c23722115749a7d\",\"best_bid\":\"0.85\",\"best_ask\":\"0.9\"},{\"asset_id\":\"78375158579295640490513288741441222289494383230318559761174600803653799947930\",\"price\":\"0.86\",\"size\":\"57.14\",\"side\":\"SELL\",\"hash\":\"025eae16c9aba86835f8f2dcba4eb6d19106e878\",\"best_bid\":\"0.1\",\"best_ask\":\"0.15\"}],\"timestamp\":\"1785928837632\",\"event_type\":\"price_change\"}"}
{"recv_ts": 1785928837.7607088, "raw": "{\"market\":\"0x0393e451a7889f6472d5099a6de21d1fc6bea6ada01c2e227ea954a8ebce1771\",\"price_changes\":[{\"asset_id\":\"62439955870856164313493799301554574122664268361492077980110236255342893751283\",\"price\":\"0.914\",\"size\":\"13.28\",\"side\":\"BUY\",\"hash\":\"fc969f1d3c32177ddc0eea04df374916431350bc\",\"best_bid\":\"0.914\",\"best_ask\":\"0.945\"},{\"asset_id\":\"19078179119846452574438096789570272099502061228398927027811652354916673625092\",\"price\":\"0.086\",\"size\":\"13.28\",\"side\":\"SELL\",\"hash\":\"677798ac27a4e2cf16f0a04671a8772788ba2fa0\",\"best_bid\":\"0.055\",\"best_ask\":\"0.086\"}],\"timestamp\":\"1785928837633\",\"event_type\":\"price_change\"}"}
{"recv_ts": 1785928837.7607195, "raw": "{\"market\":\"0x7fe6380a9bc9c18233ce9965eabc236e022aeb20dacca622cd0036a3d321f019\",\"price_changes\":[{\"asset_id\":\"32485726591125374810202571665824095992765312843753075204902424052664904200781\",\"price\":\"0.54\",\"size\":\"0\",\"side\":\"BUY\",\"hash\":\"2d48a8d1b75e9ad80f8cf371ec38bb730c8de7b4\",\"best_bid\":\"0.59\",\"best_ask\":\"0.69\"},{\"asset_id\":\"41349280673357814947384128085462517834719180689782897782246354279343930038911\",\"price\":\"0.46\",\"size\":\"0\",\"side\":\"SELL\",\"hash\":\"581b00179d3370eb0d15e6a6b4e7173662e43f3d\",\"best_bid\":\"0.31\",\"best_ask\":\"0.41\"}],\"timestamp\":\"1785928837645\",\"event_type\":\"price_change\"}"}
{"recv_ts": 1785928837.7607296, "raw": "{\"market\":\"0x7fe6380a9bc9c18233ce9965eabc236e022aeb20dacca622cd0036a3d321f019\",\"price_changes\":[{\"asset_id\":\"32485726591125374810202571665824095992765312843753075204902424052664904200781\",\"price\":\"0.53\",\"size\":\"36.4\",\"side\":\"BUY\",\"hash\":\"2d48a8d1b75e9ad80f8cf371ec38bb730c8de7b4\",\"best_bid\":\"0.59\",\"best_ask\":\"0.69\"},{\"asset_id\":\"41349280673357814947384128085462517834719180689782897782246354279343930038911\",\"price\":\"0.47\",\"size\":\"36.4\",\"side\":\"SELL\",\"hash\":\"581b00179d3370eb0d15e6a6b4e7173662e43f3d\",\"best_bid\":\"0.31\",\"best_ask\":\"0.41\"}],\"timestamp\":\"1785928837645\",\"event_type\":\"price_change\"}"}
{"recv_ts": 1785928837.7607393, "raw": "{\"market\":\"0xbf3934dfc014233beda6f87619371f394789219377ce438d38f74870f56c68ea\",\"price_changes\":[{\"asset_id\":\"29398731980061685892494196371571389220920495273593479516382999208418023734255\",\"price\":\"0.13\",\"size\":\"48.69\",\"side\":\"BUY\",\"hash\":\"ad391f191d5e00a3bb141db6167066fec3064889\",\"best_bid\":\"0.21\",\"best_ask\":\"0.25\"},{\"asset_id\":\"42024905581146846414507905961735200210462829982661029520878636315857683485217\",\"price\":\"0.87\",\"size\":\"48.69\",\"side\":\"SELL\",\"hash\":\"54d51463be31b61c05dca4b16afacb8ffd93283c\",\"best_bid\":\"0.75\",\"best_ask\":\"0.79\"}],\"timestamp\":\"1785928837645\",\"event_type\":\"price_change\"}"}
{"recv_ts": 1785928837.760772, "raw": "{\"market\":\"0xbf3934dfc014233beda6f87619371f394789219377ce438d38f74870f56c68ea\",\"price_changes\":[{\"asset_id\":\"29398731980061685892494196371571389220920495273593479516382999208418023734255\",\"price\":\"0.12\",\"size\":\"116.66\",\"side\":\"BUY\",\"hash\":\"ad391f191d5e00a3bb141db6167066fec3064889\",\"best_bid\":\"0.21\",\"best_ask\":\"0.25\"},{\"asset_id\":\"42024905581146846414507905961735200210462829982661029520878636315857683485217\",\"price\":\"0.88\",\"size\":\"116.66\",\"side\":\"SELL\",\"hash\":\"54d51463be31b61c05dca4b16afacb8ffd93283c\",\"best_bid\":\"0.75\",\"best_ask\":\"0.79\"}],\"timestamp\":\"1785928837645\",\"event_type\":\"price_change\"}"}
{"recv_ts": 1785928837.760783, "raw": "{\"market\":\"0x7fe6380a9bc9c18233ce9965eabc236e022aeb20dacca622cd0036a3d321f019\",\"price_changes\":[{\"asset_id\":\"32485726591125374810202571665824095992765312843753075204902424052664904200781\",\"price\":\"0.55\",\"size\":\"5\",\"side\":\"BUY\",\"hash\":\"6f434452bb663e2d05dfe8b471d6e9af2a7d1279\",\"best_bid\":\"0.59\",\"best_ask\":\"0.69\"},{\"asset_id\":\"41349280673357814947384128085462517834719180689782897782246354279343930038911\",\"price\":\"0.45\",\"size\":\"5\",\"side\":\"SELL\",\"hash\":\"20a89df4e67863377d12a905f60d43b2cc11a363\",\"best_bid\":\"0.31\",\"best_ask\":\"0.41\"}],\"timestamp\":\"1785928837647\",\"event_type\":\"price_change\"}"}
{"recv_ts": 1785928837.7607925, "raw": "{\"market\":\"0xbf3934dfc014233beda6f87619371f394789219377ce438d38f74870f56c68ea\",\"price_changes\":[{\"asset_id\":\"29398731980061685892494196371571389220920495273593479516382999208418023734255\",\"price\":\"0.13\",\"size\":\"53.69\",\"side\":\"BUY\",\"hash\":\"f85f5e8c6fdbdd907c571e1e73c185f4733e8912\",\"best_bid\":\"0.21\",\"best_ask\":\"0.25\"},{\"asset_id\":\"42024905581146846414507905961735200210462829982661029520878636315857683485217\",\"price\":\"0.87\",\"size\":\"53.69\",\"side\":\"SELL\",\"hash\":\"bed4ff1faa4ebd01cf7da043f9f8af0d41f7bf68\",\"best_bid\":\"0.75\",\"best_ask\":\"0.79\"}],\"timestamp\":\"1785928837648\",\"event_type\":\"price_change\"}"}
{"recv_ts": 1785928837.760802, "raw": "{\"market\":\"0xbf3934dfc014233beda6f87619371f394789219377ce438d38f74870f56c68ea\",\"price_changes\":[{\"asset_id\":\"29398731980061685892494196371571389220920495273593479516382999208418023734255\",\"price\":\"0.14\",\"size\":\"5\",\"side\":\"BUY\",\"hash\":\"f0243e4b549f85310fbfc597b12752aa55f022fc\",\"best_bid\":\"0.21\",\"best_ask\":\"0.25\"},{\"asset_id\":\"42024905581146846414507905961735200210462829982661029520878636315857683485217\",\"price\":\"0.86\",\"size\":\"5\",\"side\":\"SELL\",\"hash\":\"283d9f9042afa5c4ce40f6b41034a884a4c1fead\",\"best_bid\":\"0.75\",\"best_ask\":\"0.79\"}],\"timestamp\":\"1785928837648\",\"event_type\":\"price_change\"}"}
{"recv_ts": 1785928837.760811, "raw": "{\"market\":\"0x31cc8cc9d1b3dbdc5219e0319a01ded09ad0c18296c8f27bc76b1f12364a4661\",\"price_changes\":[{\"asset_id\":\"51223233815348005431570032441325849255204346210650700628294623504463311020670\",\"price\":\"0.25\",\"size\":\"5\",\"side\":\"BUY\",\"hash\":\"cff0012e943a57080cdb38b458d5804ea2b312d6\",\"best_bid\":\"0.25\",\"best_ask\":\"0.43\"},{\"asset_id\":\"36593914907192135817908362063800584939108275837285837232090830833195276003888\",\"price\":\"0.75\",\"size\":\"5\",\"side\":\"SELL\",\"hash\":\"0f0e7a588367926ca51b9cecf071119b903b816b\",\"best_bid\":\"0.57\",\"best_ask\":\"0.75\"}],\"timestamp\":\"1785928837648\",\"event_type\":\"price_change\"}"}
{"recv_ts": 1785928837.7608194, "raw": "{\"market\":\"0x7fe6380a9bc9c18233ce9965eabc236e022aeb20dacca622cd0036a3d321f019\",\"price_changes\":[{\"asset_id\":\"32485726591125374810202571665824095992765312843753075204902424052664904200781\",\"price\":\"0.56\",\"size\":\"38\",\"side\":\"BUY\",\"hash\":\"fce37dc7da235a4d03702a29025995f45739963d\",\"best_bid\":\"0.59\",\"best_ask\":\"0.69\"},{\"asset_id\":\"41349280673357814947384128085462517834719180689782897782246354279343930038911\",\"price\":\"0.44\",\"size\":\"38\",\"side\":\"SELL\",\"hash\":\"6dd27af5d10c4f12556d58bb57fced648e56ed1c\",\"best_bid\":\"0.31\",\"best_ask\":\"0.41\"}],\"timestamp\":\"1785928837649\",\"event_type\":\"price_change\"}"}
{"recv_ts": 1785928837.7608273, "raw": "{\"market\":\"0x0393e451a7889f6472d5099a6de21d1fc6bea6ada01c2e227ea954a8ebce1771\",\"price_changes\":[{\"asset_id\":\"19078179119846452574438096789570272099502061228398927027811652354916673625092\",\"price\":\"0.056\",\"size\":\"17.85\",\"side\":\"BUY\",\"hash\":\"d93807f2a16352a1c8254361a9bf0f55d295588b\",\"best_bid\":\"0.056\",\"best_ask\":\"0.086\"},{\"asset_id\":\"62439955870856164313493799301554574122664268361492077980110236255342893751283\",\"price\":\"0.944\",\"size\":\"17.85\",\"side\":\"SELL\",\"hash\":\"c7571920f13202cd69d219031576e81573147e4c\",\"best_bid\":\"0.914\",\"best_ask\":\"0.944\"}],\"timestamp\":\"1785928837650\",\"event_type\":\"price_change\"}"}
{"recv_ts": 1785928837.7608361, "raw": "{\"market\":\"0xbf3934dfc014233beda6f87619371f394789219377ce438d38f74870f56c68ea\",\"price_changes\":[{\"asset_id\":\"29398731980061685892494196371571389220920495273593479516382999208418023734255\",\"price\":\"0.11\",\"size\":\"16.5\",\"side\":\"BUY\",\"hash\":\"bd5fc34155e8d18ed8340bafd76d8f33fe5aa74c\",\"best_bid\":\"0.21\",\"best_ask\":\"0.25\"},{\"asset_id\":\"42024905581146846414507905961735200210462829982661029520878636315857683485217\",\"price\":\"0.89\",\"size\":\"16.5\",\"side\":\"SELL\",\"hash\":\"f985f159079b64ec9ea255742abfe2927fe08908\",\"best_bid\":\"0.75\",\"best_ask\":\"0.79\"}],\"timestamp\":\"1785928837652\",\"event_type\":\"price_change\"}"}
{"recv_ts": 1785928837.7608433, "raw": "{\"market\":\"0xbf3934dfc014233beda6f87619371f394789219377ce438d38f74870f56c68ea\",\"price_changes\":[{\"asset_id\":\"29398731980061685892494196371571389220920495273593479516382999208418023734255\",\"price\":\"0.1\",\"size\":\"0\",\"side\":\"BUY\",\"hash\":\"bd5fc34155e8d18ed8340bafd76d8f33fe5aa74c\",\"best_bid\":\"0.21\",\"best_ask\":\"0.25\"},{\"asset_id\":\"42024905581146846414507905961735200210462829982661029520878636315857683485217\",\"price\":\"0.9\",\"size\":\"0\",\"side\":\"SELL\",\"hash\":\"f985f159079b64ec9ea255742abfe2927fe08908\",\"best_bid\":\"0.75\",\"best_ask\":\"0.79\"}],\"timestamp\":\"1785928837652\",\"event_type\":\"price_change\"}"}
{"recv_ts": 1785928837.7608507, "raw": "{\"market\":\"0x7fe6380a9bc9c18233ce9965eabc236e022aeb20dacca622cd0036a3d321f019\",\"price_changes\":[{\"asset_id\":\"32485726591125374810202571665824095992765312843753075204902424052664904200781\",\"price\":\"0.52\",\"size\":\"0\",\"side\":\"BUY\",\"hash\":\"7ab67d07dd9ab08bb41d8574201c17eea222c29a\",\"best_bid\":\"0.59\",\"best_ask\":\"0.69\"},{\"asset_id\":\"41349280673357814947384128085462517834719180689782897782246354279343930038911\",\"price\":\"0.48\",\"size\":\"0\",\"side\":\"SELL\",\"hash\":\"f20a5db97b132f0690ce75b63b63c14701c9dea8\",\"best_bid\":\"0.31\",\"best_ask\":\"0.41\"}],\"timestamp\":\"1785928837652\",\"event_type\":\"price_change\"}"}
{"recv_ts": 1785928837.7608573, "raw": "{\"market\":\"0x7fe6380a9bc9c18233ce9965eabc236e022aeb20dacca622cd0036a3d321f019\",\"price_changes\":[{\"asset_id\":\"32485726591125374810202571665824095992765312843753075204902424052664904200781\",\"price\":\"0.51\",\"size\":\"0\",\"side\":\"BUY\",\"hash\":\"7ab67d07dd9ab08bb41d8574201c17eea222c29a\",\"best_bid\":\"0.59\",\"best_ask\":\"0.69\"},{\"asset_id\":\"41349280673357814947384128085462517834719180689782897782246354279343930038911\",\"price\":\"0.49\",\"size\":\"0\",\"side\":\"SELL\",\"hash\":\"f20a5db97b132f0690ce75b63b63c14701c9dea8\",\"best_bid\":\"0.31\",\"best_ask\":\"0.41\"}],\"timestamp\":\"1785928837652\",\"event_type\":\"price_change\"}"}
{"recv_ts": 1785928837.760864, "raw": "{\"market\":\"0x31cc8cc9d1b3dbdc5219e0319a01ded09ad0c18296c8f27bc76b1f12364a4661\",\"price_changes\":[{\"asset_id\":\"51223233815348005431570032441325849255204346210650700628294623504463311020670\",\"price\":\"0.22\",\"size\":\"12\",\"side\":\"BUY\",\"hash\":\"40196b74423c07e4cde49fa326574b3311522a85\",\"best_bid\":\"0.25\",\"best_ask\":\"0.43\"},{\"asset_id\":\"36593914907192135817908362063800584939108275837285837232090830833195276003888\",\"price\":\"0.78\",\"size\":\"12\",\"side\":\"SELL\",\"hash\":\"6e0742859e62da3581468c79b25be4a625714bb6\",\"best_bid\":\"0.57\",\"best_ask\":\"0.75\"}],\"timestamp\":\"1785928837653\",\"event_type\":\"price_change\"}"}
{"recv_ts": 1785928837.7608788, "raw": "{\"market\":\"0x9564d81934c1550b627ff159cc139675d7d08916fa74cc4aaf8d416e4bedd807\",\"price_changes\":[{\"asset_id\":\"46123186009598106104671689617421295270790145953546842072887829618094075293472\",\"price\":\"0.47\",\"size\":\"37.46\",\"side\":\"BUY\",\"hash\":\"3bd4b581663334e351f4f6d5488cd9a6977570d6\",\"best_bid\":\"0.48\",\"best_ask\":\"0.74\"},{\"asset_id\":\"33275922446271605474639218893344378139793083231796398469699104729778621445854\",\"price\":\"0.53\",\"size\":\"37.46\",\"side\":\"SELL\",\"hash\":\"386fc207160b96de4494ee8ce508689990a8d2b2\",\"best_bid\":\"0.26\",\"best_ask\":\"0.52\"}],\"timestamp\":\"1785928837654\",\"event_type\":\"price_change\"}"}
{"recv_ts": 1785928837.7608862, "raw": "{\"market\":\"0xbf3934dfc014233beda6f87619371f394789219377ce438d38f74870f56c68ea\",\"price_changes\":[{\"asset_id\":\"29398731980061685892494196371571389220920495273593479516382999208418023734255\",\"price\":\"0.11\",\"size\":\"21.5\",\"side\":\"BUY\",\"hash\":\"af1942a7d811f0bd3c3d9af7a9cb9b87ba8679a0\",\"best_bid\":\"0.21\",\"best_ask\":\"0.25\"},{\"asset_id\":\"42024905581146846414507905961735200210462829982661029520878636315857683485217\",\"price\":\"0.89\",\"size\":\"21.5\",\"side\":\"SELL\",\"hash\":\"6fcecb71fe971ded7cafd4c4931c964ffec115e6\",\"best_bid\":\"0.75\",\"best_ask\":\"0.79\"}],\"timestamp\":\"1785928837658\",\"event_type\":\"price_change\"}"}
{"recv_ts": 1785928837.760893, "raw": "{\"market\":\"0x0334a689cdcaf81930d6d9940e13b5664320919528bb69d2c61f02d1bf8af1bc\",\"price_changes\":[{\"asset_id\":\"10231543017839403478856563793210797939168689880219762361092559323833414965831\",\"price\":\"0.35\",\"size\":\"0\",\"side\":\"SELL\",\"hash\":\"f48e3d8a740052c5f406d4bd9597da5f668cef71\",\"best_bid\":\"0.16\",\"best_ask\":\"0.349\"},{\"asset_id\":\"13192878898968946332084337129131084781833678983669578830145839502044493606147\",\"price\":\"0.65\",\"size\":\"0\",\"side\":\"BUY\",\"hash\":\"354518f5921cc058561909705350d1bf1deac1c8\",\"best_bid\":\"0.651\",\"best_ask\":\"0.84\"}],\"timestamp\":\"1785928837658\",\"event_type\":\"price_change\"}"}
{"recv_ts": 1785928837.7609005, "raw": "{\"market\":\"0x7fe6380a9bc9c18233ce9965eabc236e022aeb20dacca622cd0036a3d321f019\",\"price_changes\":[{\"asset_id\":\"32485726591125374810202571665824095992765312843753075204902424052664904200781\",\"price\":\"0.54\",\"size\":\"5\",\"side\":\"BUY\",\"hash\":\"4aed7efa088191da0c862756d7b7a55147ed9f1c\",\"best_bid\":\"0.59\",\"best_ask\":\"0.69\"},{\"asset_id\":\"41349280673357814947384128085462517834719180689782897782246354279343930038911\",\"price\":\"0.46\",\"size\":\"5\",\"side\":\"SELL\",\"hash\":\"c2376236c72917a110b5d05af630ece70d901cca\",\"best_bid\":\"0.31\",\"best_ask\":\"0.41\"}],\"timestamp\":\"1785928837658\",\"event_type\":\"price_change\"}"}
{"recv_ts": 1785928837.7609072, "raw": "{\"market\":\"0xbf3934dfc014233beda6f87619371f394789219377ce438d38f74870f56c68ea\",\"price_changes\":[{\"asset_id\":\"29398731980061685892494196371571389220920495273593479516382999208418023734255\",\"price\":\"0.12\",\"size\":\"121.66\",\"side\":\"BUY\",\"hash\":\"f9836f4cbb11844d8c5687819d4a5607df8f1cc9\",\"best_bid\":\"0.21\",\"best_ask\":\"0.25\"},{\"asset_id\":\"42024905581146846414507905961735200210462829982661029520878636315857683485217\",\"price\":\"0.88\",\"size\":\"121.66\",\"side\":\"SELL\",\"hash\":\"2f7d3e4ba8513dffed17b1f34e27b309a281b127\",\"best_bid\":\"0.75\",\"best_ask\":\"0.79\"}],\"timestamp\":\"1785928837659\",\"event_type\":\"price_change\"}"}
{"recv_ts": 1785928837.760914, "raw": "{\"market\":\"0x9c68a1448a4cdb3993a297f1f0f759774383f2e514773621ceb04589399930bc\",\"price_changes\":[{\"asset_id\":\"33579711484128453880472647592907450388461194263236358989226504691017998237897\",\"price\":\"0.87\",\"size\":\"7\",\"side\":\"BUY\",\"hash\":\"589f721db0b9a258db1e455520fb7997b54170db\",\"best_bid\":\"0.87\",\"best_ask\":\"0.91\"},{\"asset_id\":\"62791514040221235938370932209912323223995828701014253087241691765902207027191\",\"price\":\"0.13\",\"size\":\"7\",\"side\":\"SELL\",\"hash\":\"19433cbd0ae591c03539ea96175642150cbe5506\",\"best_bid\":\"0.09\",\"best_ask\":\"0.13\"}],\"timestamp\":\"1785928837659\",\"event_type\":\"price_change\"}"}
{"recv_ts": 1785928837.760921, "raw": "{\"market\":\"0x7fe6380a9bc9c18233ce9965eabc236e022aeb20dacca622cd0036a3d321f019\",\"price_changes\":[{\"asset_id\":\"32485726591125374810202571665824095992765312843753075204902424052664904200781\",\"price\":\"0.53\",\"size\":\"41.4\",\"side\":\"BUY\",\"hash\":\"b6f904de57ae106520480781850714b86ac8f9cb\",\"best_bid\":\"0.59\",\"best_ask\":\"0.69\"},{\"asset_id\":\"41349280673357814947384128085462517834719180689782897782246354279343930038911\",\"price\":\"0.47\",\"size\":\"41.4\",\"side\":\"SELL\",\"hash\":\"d77eed9b2d0263a48c58422ceec082345f3a6dd0\",\"best_bid\":\"0.31\",\"best_ask\":\"0.41\"}],\"timestamp\":\"1785928837660\",\"event_type\":\"price_change\"}"}
{"recv_ts": 1785928837.760928, "raw": "{\"market\":\"0x30cefdde280d79ffcb7e9f25dbe99e6164d16651c9d8631f2b5bf402b6e697d5\",\"price_changes\":[{\"asset_id\":\"103247719666968457601315979306806361087685293523685277721928164828309367213844\",\"price\":\"0.14\",\"size\":\"7.14\",\"side\":\"BUY\",\"hash\":\"f7a2dc71e7a7866ee2852d252e9f87a1cf95bf7f\",\"best_bid\":\"0.85\",\"best_ask\":\"0.9\"},{\"asset_id\":\"78375158579295640490513288741441222289494383230318559761174600803653799947930\",\"price\":\"0.86\",\"size\":\"7.14\",\"side\":\"SELL\",\"hash\":\"3374ab7f1e338a7ee162b5e7db99bc5634449ef5\",\"best_bid\":\"0.1\",\"best_ask\":\"0.15\"}],\"timestamp\":\"1785928837661\",\"event_type\":\"price_change\"}"}
{"recv_ts": 1785928837.7609344, "raw": "{\"market\":\"0x9c68a1448a4cdb3993a297f1f0f759774383f2e514773621ceb04589399930bc\",\"price_changes\":[{\"asset_id\":\"33579711484128453880472647592907450388461194263236358989226504691017998237897\",\"price\":\"0.81\",\"size\":\"28\",\"side\":\"BUY\",\"hash\":\"9418854339ed999cb1d8396aac8668d26980f99c\",\"best_bid\":\"0.87\",\"best_ask\":\"0.91\"},{\"asset_id\":\"62791514040221235938370932209912323223995828701014253087241691765902207027191\",\"price\":\"0.19\",\"size\":\"28\",\"side\":\"SELL\",\"hash\":\"26ca2b902229f3331c5342e66f368eaa8195d038\",\"best_bid\":\"0.09\",\"best_ask\":\"0.13\"}],\"timestamp\":\"1785928837663\",\"event_type\":\"price_change\"}"}
{"recv_ts": 1785928837.760941, "raw": "{\"market\":\"0x31cc8cc9d1b3dbdc5219e0319a01ded09ad0c18296c8f27bc76b1f12364a4661\",\"price_changes\":[{\"asset_id\":\"51223233815348005431570032441325849255204346210650700628294623504463311020670\",\"price\":\"0.22\",\"size\":\"7\",\"side\":\"BUY\",\"hash\":\"e2968401b00e73fcbf93383d390674d632bf1eb1\",\"best_bid\":\"0.25\",\"best_ask\":\"0.43\"},{\"asset_id\":\"36593914907192135817908362063800584939108275837285837232090830833195276003888\",\"price\":\"0.78\",\"size\":\"7\",\"side\":\"SELL\",\"hash\":\"28b2a0dcc203d3b51f4aca3079f33da7ddfed874\",\"best_bid\":\"0.57\",\"best_ask\":\"0.75\"}],\"timestamp\":\"1785928837671\",\"event_type\":\"price_change\"}"}
{"recv_ts": 1785928837.7609477, "raw": "{\"market\":\"0xbf3934dfc014233beda6f87619371f394789219377ce438d38f74870f56c68ea\",\"price_changes\":[{\"asset_id\":\"42024905581146846414507905961735200210462829982661029520878636315857683485217\",\"price\":\"0.42\",\"size\":\"7.14\",\"side\":\"BUY\",\"hash\":\"507b6b2810fad2665e93633b876eda6662629a46\",\"best_bid\":\"0.75\",\"best_ask\":\"0.79\"},{\"asset_id\":\"29398731980061685892494196371571389220920495273593479516382999208418023734255\",\"price\":\"0.58\",\"size\":\"7.14\",\"side\":\"SELL\",\"hash\":\"4ca49a6609c4d4cf6b991fcd72be556909e7cad9\",\"best_bid\":\"0.21\",\"best_ask\":\"0.25\"}],\"timestamp\":\"1785928837673\",\"event_type\":\"price_change\"}"}
{"recv_ts": 1785928837.7609546, "raw": "{\"market\":\"0x31cc8cc9d1b3dbdc5219e0319a01ded09ad0c18296c8f27bc76b1f12364a4661\",\"price_changes\":[{\"asset_id\":\"51223233815348005431570032441325849255204346210650700628294623504463311020670\",\"price\":\"0.22\",\"size\":\"0\",\"side\":\"BUY\",\"hash\":\"ffaf7c288cd7ff5079516a3779902617eba87bad\",\"best_bid\":\"0.25\",\"best_ask\":\"0.43\"},{\"asset_id\":\"36593914907192135817908362063800584939108275837285837232090830833195276003888\",\"price\":\"0.78\",\"size\":\"0\",\"side\":\"SELL\",\"hash\":\"556843af59779a1fae4bf340def2c229e536b4e6\",\"best_bid\":\"0.57\",\"best_ask\":\"0.75\"}],\"timestamp\":\"1785928837675\",\"event_type\":\"price_change\"}"}
{"recv_ts": 1785928837.7609706, "raw": "{\"market\":\"0x0334a689cdcaf81930d6d9940e13b5664320919528bb69d2c61f02d1bf8af1bc\",\"price_changes\":[{\"asset_id\":\"13192878898968946332084337129131084781833678983669578830145839502044493606147\",\"price\":\"0.651\",\"size\":\"0\",\"side\":\"BUY\",\"hash\":\"f5587cffef25e572fedf7f7868ad47bedd15704b\",\"best_bid\":\"0.649\",\"best_ask\":\"0.84\"},{\"asset_id\":\"10231543017839403478856563793210797939168689880219762361092559323833414965831\",\"price\":\"0.349\",\"size\":\"0\",\"side\":\"SELL\",\"hash\":\"d67b5cd8d2ac4786c279a1742583f4f56812c99d\",\"best_bid\":\"0.16\",\"best_ask\":\"0.351\"}],\"timestamp\":\"1785928837676\",\"event_type\":\"price_change\"}"}
{"recv_ts": 1785928837.7609773, "raw": "{\"market\":\"0x4bb74368f18d620f5328a9129b1c57964dc3ac62038e760c88a28fc4504d435b\",\"price_changes\":[{\"asset_id\":\"5726763284153358781192672562149931567202591235121360539621518285640721325781\",\"price\":\"0.4\",\"size\":\"13\",\"side\":\"BUY\",\"hash\":\"c46b0af8f69e67500b5fcdfcf187996ec6ddc6c1\",\"best_bid\":\"0.4\",\"best_ask\":\"0.64\"},{\"asset_id\":\"13237157614996328413061105523849028414176042548317771436201040571517942065892\",\"price\":\"0.6\",\"size\":\"13\",\"side\":\"SELL\",\"hash\":\"5425d408046a8039b5b6e20935ae46c395ca740a\",\"best_bid\":\"0.36\",\"best_ask\":\"0.6\"}],\"timestamp\":\"1785928837679\",\"event_type\":\"price_change\"}"}
{"recv_ts": 1785928837.7609837, "raw": "{\"market\":\"0x30cefdde280d79ffcb7e9f25dbe99e6164d16651c9d8631f2b5bf402b6e697d5\",\"price_changes\":[{\"asset_id\":\"103247719666968457601315979306806361087685293523685277721928164828309367213844\",\"price\":\"0.16\",\"size\":\"56.25\",\"side\":\"BUY\",\"hash\":\"82e6e7e1057c34c497c7419060c7a975886b9acd\",\"best_bid\":\"0.85\",\"best_ask\":\"0.9\"},{\"asset_id\":\"78375158579295640490513288741441222289494383230318559761174600803653799947930\",\"price\":\"0.84\",\"size\":\"56.25\",\"side\":\"SELL\",\"hash\":\"b11e912614b57cc7301dbd3faf082c77e68f0422\",\"best_bid\":\"0.1\",\"best_ask\":\"0.15\"}],\"timestamp\":\"1785928837688\",\"event_type\":\"price_change\"}"}
{"recv_ts": 1785928837.7609904, "raw": "{\"market\":\"0x9564d81934c1550b627ff159cc139675d7d08916fa74cc4aaf8d416e4bedd807\",\"price_changes\":[{\"asset_id\":\"33275922446271605474639218893344378139793083231796398469699104729778621445854\",\"price\":\"0.53\",\"size\":\"25.4\",\"side\":\"SELL\",\"hash\":\"dd0e2f2585b315aef438bf9bdd3885d39ba6f164\",\"best_bid\":\"0.26\",\"best_ask\":\"0.52\"},{\"asset_id\":\"46123186009598106104671689617421295270790145953546842072887829618094075293472\",\"price\":\"0.47\",\"size\":\"25.4\",\"side\":\"BUY\",\"hash\":\"a3f18140298463d64a549392f69fc8cf98d7d1d8\",\"best_bid\":\"0.48\",\"best_ask\":\"0.74\"}],\"timestamp\":\"1785928837693\",\"event_type\":\"price_change\"}"}
{"recv_ts": 1785928837.760997, "raw": "{\"market\":\"0x393d7aef0363cf896d3842a946bbfe7f3e7348b7a70e0ecfbb38f475024201b7\",\"price_changes\":[{\"asset_id\":\"18071745397819074512816862124145081858065194935724818155665028803967642916272\",\"price\":\"0.439\",\"size\":\"0\",\"side\":\"SELL\",\"hash\":\"c90a3ea7b49412a4c49e37f807675cffbf8f553a\",\"best_bid\":\"0\",\"best_ask\":\"0.001\"},{\"asset_id\":\"86484217064415614588925980812806092027932396263156538383620686261406038304441\",\"price\":\"0.561\",\"size\":\"0\",\"side\":\"BUY\",\"hash\":\"7186c3100817ea83c0ed78262a9cc27ffbc31bed\",\"best_bid\":\"0.999\",\"best_ask\":\"1\"}],\"timestamp\":\"1785928837693\",\"event_type\":\"price_change\"}"}
{"recv_ts": 1785928837.7610037, "raw": "{\"market\":\"0xbf3934dfc014233beda6f87619371f394789219377ce438d38f74870f56c68ea\",\"price_changes\":[{\"asset_id\":\"42024905581146846414507905961735200210462829982661029520878636315857683485217\",\"price\":\"0.42\",\"size\":\"107.14\",\"side\":\"BUY\",\"hash\":\"9e43fd7b6480f4c82470eb2690008d01b294ecb0\",\"best_bid\":\"0.75\",\"best_ask\":\"0.79\"},{\"asset_id\":\"29398731980061685892494196371571389220920495273593479516382999208418023734255\",\"price\":\"0.58\",\"size\":\"107.14\",\"side\":\"SELL\",\"hash\":\"3450f8d6cf60ce63c6a4a7ea477f0799a19e7a2e\",\"best_bid\":\"0.21\",\"best_ask\":\"0.25\"}],\"timestamp\":\"1785928837700\",\"event_type\":\"price_change\"}"}
{"recv_ts": 1785928837.7610104, "raw": "{\"market\":\"0xc677dc4861ad64799759f9652e6ae0ff53c153057fd6db69af9e84a1ca2197ec\",\"price_changes\":[{\"asset_id\":\"77424084358345472197732445675309267934198319933946934156139630690411297600005\",\"price\":\"0.987\",\"size\":\"0\",\"side\":\"BUY\",\"hash\":\"d4e40f82497d03d68004ded3923d70fa52833a9b\",\"best_bid\":\"0.998\",\"best_ask\":\"0.999\"},{\"asset_id\":\"45534343227339732590622934884801860571492159958084925751306737519940828376450\",\"price\":\"0.013\",\"size\":\"0\",\"side\":\"SELL\",\"hash\":\"eb4a8d825510fb3e42b36b155d1933e846e77bf2\",\"best_bid\":\"0.001\",\"best_ask\":\"0.002\"}],\"timestamp\":\"1785928837703\",\"event_type\":\"price_change\"}"}
{"recv_ts": 1785928837.761017, "raw": "{\"market\":\"0x9c68a1448a4cdb3993a297f1f0f759774383f2e514773621ceb04589399930bc\",\"price_changes\":[{\"asset_id\":\"33579711484128453880472647592907450388461194263236358989226504691017998237897\",\"price\":\"0.86\",\"size\":\"0\",\"side\":\"BUY\",\"hash\":\"68a1bb6cc6b3d395cd11164e48d183d4e11de711\",\"best_bid\":\"0.87\",\"best_ask\":\"0.91\"},{\"asset_id\":\"62791514040221235938370932209912323223995828701014253087241691765902207027191\",\"price\":\"0.14\",\"size\":\"0\",\"side\":\"SELL\",\"hash\":\"3a196799c604aa865378e72962c0cc53e0900d1a\",\"best_bid\":\"0.09\",\"best_ask\":\"0.13\"}],\"timestamp\":\"1785928837705\",\"event_type\":\"price_change\"}"}
{"recv_ts": 1785928837.7610238, "raw": "{\"market\":\"0xbf3934dfc014233beda6f87619371f394789219377ce438d38f74870f56c68ea\",\"price_changes\":[{\"asset_id\":\"42024905581146846414507905961735200210462829982661029520878636315857683485217\",\"price\":\"0.72\",\"size\":\"0\",\"side\":\"BUY\",\"hash\":\"5cca5147b2d8971d5fec944711a70f1d63f12d96\",\"best_bid\":\"0.75\",\"best_ask\":\"0.79\"},{\"asset_id\":\"29398731980061685892494196371571389220920495273593479516382999208418023734255\",\"price\":\"0.28\",\"size\":\"0\",\"side\":\"SELL\",\"hash\":\"7b74b8f488e6cde3065f17d7ce23ffdbac34fef8\",\"best_bid\":\"0.21\",\"best_ask\":\"0.25\"}],\"timestamp\":\"1785928837708\",\"event_type\":\"price_change\"}"}
{"recv_ts": 1785928837.7610307, "raw": "{\"market\":\"0xc677dc4861ad64799759f9652e6ae0ff53c153057fd6db69af9e84a1ca2197ec\",\"price_changes\":[{\"asset_id\":\"77424084358345472197732445675309267934198319933946934156139630690411297600005\",\"price\":\"0.988\",\"size\":\"11.75\",\"side\":\"BUY\",\"hash\":\"0623ada0407340e041931c94c26a169d04376b74\",\"best_bid\":\"0.998\",\"best_ask\":\"0.999\"},{\"asset_id\":\"45534343227339732590622934884801860571492159958084925751306737519940828376450\",\"price\":\"0.012\",\"size\":\"11.75\",\"side\":\"SELL\",\"hash\":\"8ec0922dc396472238b20d3c082b973408489aa1\",\"best_bid\":\"0.001\",\"best_ask\":\"0.002\"}],\"timestamp\":\"1785928837707\",\"event_type\":\"price_change\"}"}
{"recv_ts": 1785928837.7610376, "raw": "{\"market\":\"0x0393e451a7889f6472d5099a6de21d1fc6bea6ada01c2e227ea954a8ebce1771\",\"price_changes\":[{\"asset_id\":\"62439955870856164313493799301554574122664268361492077980110236255342893751283\",\"price\":\"0.37\",\"size\":\"15\",\"side\":\"BUY\",\"hash\":\"13cf87945181364dfae9903119cf215e48ff317b\",\"best_bid\":\"0.914\",\"best_ask\":\"0.944\"},{\"asset_id\":\"19078179119846452574438096789570272099502061228398927027811652354916673625092\",\"price\":\"0.63\",\"size\":\"15\",\"side\":\"SELL\",\"hash\":\"ec84ae127f1cc6a76b148acee2385b441208b8d9\",\"best_bid\":\"0.056\",\"best_ask\":\"0.086\"}],\"timestamp\":\"1785928837710\",\"event_type\":\"price_change\"}"}
{"recv_ts": 1785928837.7610445, "raw": "{\"market\":\"0x0334a689cdcaf81930d6d9940e13b5664320919528bb69d2c61f02d1bf8af1bc\",\"price_changes\":[{\"asset_id\":\"10231543017839403478856563793210797939168689880219762361092559323833414965831\",\"price\":\"0.35\",\"size\":\"11.25\",\"side\":\"SELL\",\"hash\":\"64df08868d97579ae644de1f678a83a179a3ed7e\",\"best_bid\":\"0.16\",\"best_ask\":\"0.35\"},{\"asset_id\":\"13192878898968946332084337129131084781833678983669578830145839502044493606147\",\"price\":\"0.65\",\"size\":\"11.25\",\"side\":\"BUY\",\"hash\":\"362a9a3c80dc724822cdbf90618956523e1ba85e\",\"best_bid\":\"0.65\",\"best_ask\":\"0.84\"}],\"timestamp\":\"1785928837709\",\"event_type\":\"price_change\"}"}
{"recv_ts": 1785928837.7610621, "raw": "{\"market\":\"0xc677dc4861ad64799759f9652e6ae0ff53c153057fd6db69af9e84a1ca2197ec\",\"price_changes\":[{\"asset_id\":\"77424084358345472197732445675309267934198319933946934156139630690411297600005\",\"price\":\"0.989\",\"size\":\"9.12\",\"side\":\"BUY\",\"hash\":\"b734f3ccecdd89305e6e779cbbecae9b57043b9a\",\"best_bid\":\"0.998\",\"best_ask\":\"0.999\"},{\"asset_id\":\"45534343227339732590622934884801860571492159958084925751306737519940828376450\",\"price\":\"0.011\",\"size\":\"9.12\",\"side\":\"SELL\",\"hash\":\"92b392a090f165e0f52e004f0af76db25e848f46\",\"best_bid\":\"0.001\",\"best_ask\":\"0.002\"}],\"timestamp\":\"1785928837710\",\"event_type\":\"price_change\"}"}
{"recv_ts": 1785928837.7610722, "raw": "{\"market\":\"0xc677dc4861ad64799759f9652e6ae0ff53c153057fd6db69af9e84a1ca2197ec\",\"price_changes\":[{\"asset_id\":\"77424084358345472197732445675309267934198319933946934156139630690411297600005\",\"price\":\"0.986\",\"size\":\"0\",\"side\":\"BUY\",\"hash\":\"8903506e56e268fa64bf3d9361db908a5c6e102e\",\"best_bid\":\"0.998\",\"best_ask\":\"0.999\"},{\"asset_id\":\"45534343227339732590622934884801860571492159958084925751306737519940828376450\",\"price\":\"0.014\",\"size\":\"0\",\"side\":\"SELL\",\"hash\":\"26f0877b9e52f414d1547f22b20fcd5e14e11d44\",\"best_bid\":\"0.001\",\"best_ask\":\"0.002\"}],\"timestamp\":\"1785928837712\",\"event_type\":\"price_change\"}"}
{"recv_ts": 1785928837.7610807, "raw": "{\"market\":\"0x30cefdde280d79ffcb7e9f25dbe99e6164d16651c9d8631f2b5bf402b6e697d5\",\"price_changes\":[{\"asset_id\":\"103247719666968457601315979306806361087685293523685277721928164828309367213844\",\"price\":\"0.16\",\"size\":\"6.25\",\"side\":\"BUY\",\"hash\":\"90e54fb0f47d84ad10bc9cd5a7eb19f68227745b\",\"best_bid\":\"0.85\",\"best_ask\":\"0.9\"},{\"asset_id\":\"78375158579295640490513288741441222289494383230318559761174600803653799947930\",\"price\":\"0.84\",\"size\":\"6.25\",\"side\":\"SELL\",\"hash\":\"7d89611e5efc661d0815ba2dfa30f96be71ed69a\",\"best_bid\":\"0.1\",\"best_ask\":\"0.15\"}],\"timestamp\":\"1785928837713\",\"event_type\":\"price_change\"}"}
{"recv_ts": 1785928837.7610872, "raw": "{\"market\":\"0xcdf07db4679ef6e24d8a3e896bf652c59e34e32a85fd52c8674ffcb8feb1bd6b\",\"price_changes\":[{\"asset_id\":\"112281222984999372216196312058913012527283133455394337409744127099153489093767\",\"price\":\"0.32\",\"size\":\"20\",\"side\":\"BUY\",\"hash\":\"ef227cc85d5373b4ff99bb40547b4ddfae65daa0\",\"best_bid\":\"0.64\",\"best_ask\":\"0.71\"},{\"asset_id\":\"56851808432318955817653658644933948937489149977259469391695759113847085110251\",\"price\":\"0.68\",\"size\":\"20\",\"side\":\"SELL\",\"hash\":\"9d7bf672f67ad5db2f1f9eeec7d24637435afb9c\",\"best_bid\":\"0.29\",\"best_ask\":\"0.36\"}],\"timestamp\":\"1785928837715\",\"event_type\":\"price_change\"}"}
{"recv_ts": 1785928837.7610939, "raw": "{\"market\":\"0xbab083c8bb365a4076fbc0d24ba307a1c28d4f25c7f89ea1231bd9aad776f144\",\"price_changes\":[{\"asset_id\":\"103843050760108913906945141811136757046308978276759698197586312214650022815017\",\"price\":\"0.962\",\"size\":\"0\",\"side\":\"BUY\",\"hash\":\"d8a058c46aba408b6295fed4d2b52fd9612cb765\",\"best_bid\":\"0.996\",\"best_ask\":\"0.999\"},{\"asset_id\":\"6819349142499203276746921220091467839657969656169150924495502803133501838527\",\"price\":\"0.038\",\"size\":\"0\",\"side\":\"SELL\",\"hash\":\"22299a55ea3f3931705c4d966d2e1ac63efbfbef\",\"best_bid\":\"0.001\",\"best_ask\":\"0.004\"}],\"timestamp\":\"1785928837717\",\"event_type\":\"price_change\"}"}
{"recv_ts": 1785928837.7611005, "raw": "{\"market\":\"0xbab083c8bb365a4076fbc0d24ba307a1c28d4f25c7f89ea1231bd9aad776f144\",\"price_changes\":[{\"asset_id\":\"103843050760108913906945141811136757046308978276759698197586312214650022815017\",\"price\":\"0.96\",\"size\":\"0\",\"side\":\"BUY\",\"hash\":\"d8a058c46aba408b6295fed4d2b52fd9612cb765\",\"best_bid\":\"0.996\",\"best_ask\":\"0.999\"},{\"asset_id\":\"6819349142499203276746921220091467839657969656169150924495502803133501838527\",\"price\":\"0.04\",\"size\":\"0\",\"side\":\"SELL\",\"hash\":\"22299a55ea3f3931705c4d966d2e1ac63efbfbef\",\"best_bid\":\"0.001\",\"best_ask\":\"0.004\"}],\"timestamp\":\"1785928837717\",\"event_type\":\"price_change\"}"}
{"recv_ts": 1785928837.7611375, "raw": "{\"market\":\"0xa561e8bb41dc37e6c429290b86b99656cd970da7e88390610909e441b2723ac8\",\"price_changes\":[{\"asset_id\":\"105316834999130562959940001169510465111487012362923706009968664706973646526681\",\"price\":\"0.951\",\"size\":\"0\",\"side\":\"BUY\",\"hash\":\"f40baf56a63910e3653f972b22080d8ab8e82a52\",\"best_bid\":\"0.971\",\"best_ask\":\"0.988\"},{\"asset_id\":\"29825868751864646746310402216826737712044744388751470859717252715531890918100\",\"price\":\"0.049\",\"size\":\"0\",\"side\":\"SELL\",\"hash\":\"6e431294f12fd704c66961a341610a272e1f9e6c\",\"best_bid\":\"0.012\",\"best_ask\":\"0.029\"}],\"timestamp\":\"1785928837717\",\"event_type\":\"price_change\"}"}
{"recv_ts": 1785928837.761145, "raw": "{\"market\":\"0x75d23728059cad70d844df1c068e9262d8fa26ecb30f296c0d08b3c00fed01e0\",\"price_changes\":[{\"asset_id\":\"22712829542847599564052327157213856809105636169545956971844951739958318964908\",\"price\":\"0.962\",\"size\":\"0\",\"side\":\"BUY\",\"hash\":\"62510def029ece4c156421bd5486925ff3458df5\",\"best_bid\":\"0.996\",\"best_ask\":\"0.999\"},{\"asset_id\":\"92144408598950161315078212492027631334302853859174202522008056474158348296740\",\"price\":\"0.038\",\"size\":\"0\",\"side\":\"SELL\",\"hash\":\"f2adbd807c0b06433413fc58f55baf7f989ae308\",\"best_bid\":\"0.001\",\"best_ask\":\"0.004\"}],\"timestamp\":\"1785928837717\",\"event_type\":\"price_change\"}"}
{"recv_ts": 1785928837.7611516, "raw": "{\"market\":\"0xa561e8bb41dc37e6c429290b86b99656cd970da7e88390610909e441b2723ac8\",\"price_changes\":[{\"asset_id\":\"105316834999130562959940001169510465111487012362923706009968664706973646526681\",\"price\":\"0.949\",\"size\":\"100\",\"side\":\"BUY\",\"hash\":\"f40baf56a63910e3653f972b22080d8ab8e82a52\",\"best_bid\":\"0.971\",\"best_ask\":\"0.988\"},{\"asset_id\":\"29825868751864646746310402216826737712044744388751470859717252715531890918100\",\"price\":\"0.051\",\"size\":\"100\",\"side\":\"SELL\",\"hash\":\"6e431294f12fd704c66961a341610a272e1f9e6c\",\"best_bid\":\"0.012\",\"best_ask\":\"0.029\"}],\"timestamp\":\"1785928837717\",\"event_type\":\"price_change\"}"}
{"recv_ts": 1785928837.761158, "raw": "{\"market\":\"0x75d23728059cad70d844df1c068e9262d8fa26ecb30f296c0d08b3c00fed01e0\",\"price_changes\":[{\"asset_id\":\"22712829542847599564052327157213856809105636169545956971844951739958318964908\",\"price\":\"0.96\",\"size\":\"32\",\"side\":\"BUY\",\"hash\":\"62510def029ece4c156421bd5486925ff3458df5\",\"best_bid\":\"0.996\",\"best_ask\":\"0.999\"},{\"asset_id\":\"92144408598950161315078212492027631334302853859174202522008056474158348296740\",\"price\":\"0.04\",\"size\":\"32\",\"side\":\"SELL\",\"hash\":\"f2adbd807c0b06433413fc58f55baf7f989ae308\",\"best_bid\":\"0.001\",\"best_ask\":\"0.004\"}],\"timestamp\":\"1785928837717\",\"event_type\":\"price_change\"}"}
{"recv_ts": 1785928837.7611697, "raw": "{\"market\":\"0xeb1b02259692fde7a75131afde0c8c0382c7e72650ee029fa51a9a4d2b5a6772\",\"price_changes\":[{\"asset_id\":\"62662690220231139069175677931578761522631164090290295462996352611035070725067\",\"price\":\"0.956\",\"size\":\"0\",\"side\":\"BUY\",\"hash\":\"b6ee396663f66cd23fda7948b2c6c4f6ea644e6c\",\"best_bid\":\"0.976\",\"best_ask\":\"0.993\"},{\"asset_id\":\"111936281067666006196985095277433284360150604383695310403200564948321448684686\",\"price\":\"0.044\",\"size\":\"0\",\"side\":\"SELL\",\"hash\":\"fc9100c96b379768772ed29b9014a35bbb56a429\",\"best_bid\":\"0.007\",\"best_ask\":\"0.024\"}],\"timestamp\":\"1785928837717\",\"event_type\":\"price_change\"}"}
{"recv_ts": 1785928837.761176, "raw": "{\"market\":\"0xeb1b02259692fde7a75131afde0c8c0382c7e72650ee029fa51a9a4d2b5a6772\",\"price_changes\":[{\"asset_id\":\"62662690220231139069175677931578761522631164090290295462996352611035070725067\",\"price\":\"0.954\",\"size\":\"0\",\"side\":\"BUY\",\"hash\":\"b6ee396663f66cd23fda7948b2c6c4f6ea644e6c\",\"best_bid\":\"0.976\",\"best_ask\":\"0.993\"},{\"asset_id\":\"111936281067666006196985095277433284360150604383695310403200564948321448684686\",\"price\":\"0.046\",\"size\":\"0\",\"side\":\"SELL\",\"hash\":\"fc9100c96b379768772ed29b9014a35bbb56a429\",\"best_bid\":\"0.007\",\"best_ask\":\"0.024\"}],\"timestamp\":\"1785928837717\",\"event_type\":\"price_change\"}"}
{"recv_ts": 1785928837.7611918, "raw": "{\"market\":\"0xbab083c8bb365a4076fbc0d24ba307a1c28d4f25c7f89ea1231bd9aad776f144\",\"price_changes\":[{\"asset_id\":\"103843050760108913906945141811136757046308978276759698197586312214650022815017\",\"price\":\"0.963\",\"size\":\"5\",\"side\":\"BUY\",\"hash\":\"cd338970e4d8a989269437500f9ec4ef9ce27191\",\"best_bid\":\"0.996\",\"best_ask\":\"0.999\"},{\"asset_id\":\"6819349142499203276746921220091467839657969656169150924495502803133501838527\",\"price\":\"0.037\",\"size\":\"5\",\"side\":\"SELL\",\"hash\":\"47fccf74b38787bde063318de132ad16f280ee09\",\"best_bid\":\"0.001\",\"best_ask\":\"0.004\"}],\"timestamp\":\"1785928837719\",\"event_type\":\"price_change\"}"}
{"recv_ts": 1785928837.7611983, "raw": "{\"market\":\"0x31cc8cc9d1b3dbdc5219e0319a01ded09ad0c18296c8f27bc76b1f12364a4661\",\"price_changes\":[{\"asset_id\":\"51223233815348005431570032441325849255204346210650700628294623504463311020670\",\"price\":\"0.25\",\"size\":\"0\",\"side\":\"BUY\",\"hash\":\"1387231a017ae8c252648fe1249afba72662f943\",\"best_bid\":\"0.21\",\"best_ask\":\"0.43\"},{\"asset_id\":\"36593914907192135817908362063800584939108275837285837232090830833195276003888\",\"price\":\"0.75\",\"size\":\"0\",\"side\":\"SELL\",\"hash\":\"9ed977315532ace33ddab720d60dd9090e651123\",\"best_bid\":\"0.57\",\"best_ask\":\"0.79\"}],\"timestamp\":\"1785928837718\",\"event_type\":\"price_change\"}"}
{"recv_ts": 1785928837.761205, "raw": "{\"market\":\"0xeb1b02259692fde7a75131afde0c8c0382c7e72650ee029fa51a9a4d2b5a6772\",\"price_changes\":[{\"asset_id\":\"62662690220231139069175677931578761522631164090290295462996352611035070725067\",\"price\":\"0.957\",\"size\":\"5\",\"side\":\"BUY\",\"hash\":\"fcfb82d4c23a6fcfee97cdec7b6a3b201ec640bd\",\"best_bid\":\"0.976\",\"best_ask\":\"0.993\"},{\"asset_id\":\"111936281067666006196985095277433284360150604383695310403200564948321448684686\",\"price\":\"0.043\",\"size\":\"5\",\"side\":\"SELL\",\"hash\":\"645f6f99a8ed3f04f75a76359506407f4f28fea1\",\"best_bid\":\"0.007\",\"best_ask\":\"0.024\"}],\"timestamp\":\"1785928837720\",\"event_type\":\"price_change\"}"}
{"recv_ts": 1785928837.7612116, "raw": "{\"market\":\"0xeb1b02259692fde7a75131afde0c8c0382c7e72650ee029fa51a9a4d2b5a6772\",\"price_changes\":[{\"asset_id\":\"62662690220231139069175677931578761522631164090290295462996352611035070725067\",\"price\":\"0.959\",\"size\":\"5\",\"side\":\"BUY\",\"hash\":\"be8f8077c1562ba151dc5c95a3b365e192652a9c\",\"best_bid\":\"0.976\",\"best_ask\":\"0.993\"},{\"asset_id\":\"111936281067666006196985095277433284360150604383695310403200564948321448684686\",\"price\":\"0.041\",\"size\":\"5\",\"side\":\"SELL\",\"hash\":\"52dfdcf970b965e944b1779d970347c8a8c754bc\",\"best_bid\":\"0.007\",\"best_ask\":\"0.024\"}],\"timestamp\":\"1785928837721\",\"event_type\":\"price_change\"}"}
{"recv_ts": 1785928837.76123, "raw": "{\"market\":\"0x31cc8cc9d1b3dbdc5219e0319a01ded09ad0c18296c8f27bc76b1f12364a4661\",\"price_changes\":[{\"asset_id\":\"51223233815348005431570032441325849255204346210650700628294623504463311020670\",\"price\":\"0.22\",\"size\":\"5\",\"side\":\"BUY\",\"hash\":\"da2c11a4c9bb7a52d7afd992536ff5a26e1c06dd\",\"best_bid\":\"0.22\",\"best_ask\":\"0.43\"},{\"asset_id\":\"36593914907192135817908362063800584939108275837285837232090830833195276003888\",\"price\":\"0.78\",\"size\":\"5\",\"side\":\"SELL\",\"hash\":\"d112c911fba80fe0da979c58f322952fd88c9a8c\",\"best_bid\":\"0.57\",\"best_ask\":\"0.78\"}],\"timestamp\":\"1785928837721\",\"event_type\":\"price_change\"}"}
{"recv_ts": 1785928837.761237, "raw": "{\"market\":\"0xa561e8bb41dc37e6c429290b86b99656cd970da7e88390610909e441b2723ac8\",\"price_changes\":[{\"asset_id\":\"105316834999130562959940001169510465111487012362923706009968664706973646526681\",\"price\":\"0.954\",\"size\":\"5\",\"side\":\"BUY\",\"hash\":\"21cd0cc49c90fc2f2762ff056f5f5e93869a5cb9\",\"best_bid\":\"0.971\",\"best_ask\":\"0.988\"},{\"asset_id\":\"29825868751864646746310402216826737712044744388751470859717252715531890918100\",\"price\":\"0.046\",\"size\":\"5\",\"side\":\"SELL\",\"hash\":\"e1b030c5e7f911daafa828c9a2f916cb427b8b7e\",\"best_bid\":\"0.012\",\"best_ask\":\"0.029\"}],\"timestamp\":\"1785928837721\",\"event_type\":\"price_change\"}"}
{"recv_ts": 1785928837.7612438, "raw": "{\"market\":\"0xa561e8bb41dc37e6c429290b86b99656cd970da7e88390610909e441b2723ac8\",\"price_changes\":[{\"asset_id\":\"105316834999130562959940001169510465111487012362923706009968664706973646526681\",\"price\":\"0.952\",\"size\":\"5\",\"side\":\"BUY\",\"hash\":\"f1e1bf4ce260332a16ff074d15f3d2c25df76e86\",\"best_bid\":\"0.971\",\"best_ask\":\"0.988\"},{\"asset_id\":\"29825868751864646746310402216826737712044744388751470859717252715531890918100\",\"price\":\"0.048\",\"size\":\"5\",\"side\":\"SELL\",\"hash\":\"f45ede2869a411d7d08e41911b76984c7704b88d\",\"best_bid\":\"0.012\",\"best_ask\":\"0.029\"}],\"timestamp\":\"1785928837722\",\"event_type\":\"price_change\"}"}
{"recv_ts": 1785928837.7612505, "raw": "{\"market\":\"0x9c68a1448a4cdb3993a297f1f0f759774383f2e514773621ceb04589399930bc\",\"price_changes\":[{\"asset_id\":\"33579711484128453880472647592907450388461194263236358989226504691017998237897\",\"price\":\"0.87\",\"size\":\"0\",\"side\":\"BUY\",\"hash\":\"963ee78d7ac6b2ceea3ea6918532bbc931c71c80\",\"best_bid\":\"0.85\",\"best_ask\":\"0.91\"},{\"asset_id\":\"62791514040221235938370932209912323223995828701014253087241691765902207027191\",\"price\":\"0.13\",\"size\":\"0\",\"side\":\"SELL\",\"hash\":\"985052c66dbc0cc40503fd0ec20e6af7c986b1e5\",\"best_bid\":\"0.09\",\"best_ask\":\"0.15\"}],\"timestamp\":\"1785928837723\",\"event_type\":\"price_change\"}"}
{"recv_ts": 1785928837.761257, "raw": "{\"market\":\"0xbab083c8bb365a4076fbc0d24ba307a1c28d4f25c7f89ea1231bd9aad776f144\",\"price_changes\":[{\"asset_id\":\"103843050760108913906945141811136757046308978276759698197586312214650022815017\",\"price\":\"0.965\",\"size\":\"5\",\"side\":\"BUY\",\"hash\":\"1e85437196b557d6c775dfd8e4969b90f8370bbf\",\"best_bid\":\"0.996\",\"best_ask\":\"0.999\"},{\"asset_id\":\"6819349142499203276746921220091467839657969656169150924495502803133501838527\",\"price\":\"0.035\",\"size\":\"5\",\"side\":\"SELL\",\"hash\":\"f58918b68a4f28be9ca68baa84334e820358ada4\",\"best_bid\":\"0.001\",\"best_ask\":\"0.004\"}],\"timestamp\":\"1785928837723\",\"event_type\":\"price_change\"}"}
{"recv_ts": 1785928837.7612634, "raw": "{\"market\":\"0x9c68a1448a4cdb3993a297f1f0f759774383f2e514773621ceb04589399930bc\",\"price_changes\":[{\"asset_id\":\"33579711484128453880472647592907450388461194263236358989226504691017998237897\",\"price\":\"0.81\",\"size\":\"0\",\"side\":\"BUY\",\"hash\":\"11e1dc9ea0db81c7605e60fe23e3d0a3366aac61\",\"best_bid\":\"0.85\",\"best_ask\":\"0.91\"},{\"asset_id\":\"62791514040221235938370932209912323223995828701014253087241691765902207027191\",\"price\":\"0.19\",\"size\":\"0\",\"side\":\"SELL\",\"hash\":\"20580cc4cbb2d2ff6c0e17e246e79a50f3b0ca1f\",\"best_bid\":\"0.09\",\"best_ask\":\"0.15\"}],\"timestamp\":\"1785928837724\",\"event_type\":\"price_change\"}"}
{"recv_ts": 1785928837.7612698, "raw": "{\"market\":\"0x75d23728059cad70d844df1c068e9262d8fa26ecb30f296c0d08b3c00fed01e0\",\"price_changes\":[{\"asset_id\":\"22712829542847599564052327157213856809105636169545956971844951739958318964908\",\"price\":\"0.965\",\"size\":\"5\",\"side\":\"BUY\",\"hash\":\"551dcbf18365cc772294de4a33d79d7fdb407038\",\"best_bid\":\"0.996\",\"best_ask\":\"0.999\"},{\"asset_id\":\"92144408598950161315078212492027631334302853859174202522008056474158348296740\",\"price\":\"0.035\",\"size\":\"5\",\"side\":\"SELL\",\"hash\":\"daf1af919729a4968bb792c4b31bfad5cc3dbbfa\",\"best_bid\":\"0.001\",\"best_ask\":\"0.004\"}],\"timestamp\":\"1785928837724\",\"event_type\":\"price_change\"}"}
{"recv_ts": 1785928837.7612765, "raw": "{\"market\":\"0x75d23728059cad70d844df1c068e9262d8fa26ecb30f296c0d08b3c00fed01e0\",\"price_changes\":[{\"asset_id\":\"22712829542847599564052327157213856809105636169545956971844951739958318964908\",\"price\":\"0.963\",\"size\":\"5\",\"side\":\"BUY\",\"hash\":\"477f497dbc529ebd09324b899d6350940f7b8f23\",\"best_bid\":\"0.996\",\"best_ask\":\"0.999\"},{\"asset_id\":\"92144408598950161315078212492027631334302853859174202522008056474158348296740\",\"price\":\"0.037\",\"size\":\"5\",\"side\":\"SELL\",\"hash\":\"bbc9a7fdabae28323cbce9e70ee1d0552a5480b2\",\"best_bid\":\"0.001\",\"best_ask\":\"0.004\"}],\"timestamp\":\"1785928837725\",\"event_type\":\"price_change\"}"}
{"recv_ts": 1785928837.7612927, "raw": "{\"market\":\"0xbab083c8bb365a4076fbc0d24ba307a1c28d4f25c7f89ea1231bd9aad776f144\",\"price_changes\":[{\"asset_id\":\"103843050760108913906945141811136757046308978276759698197586312214650022815017\",\"price\":\"0.928\",\"size\":\"0\",\"side\":\"BUY\",\"hash\":\"be0b5a77379dcf81bc6d07ddac8c7e07c8589d39\",\"best_bid\":\"0.996\",\"best_ask\":\"0.999\"},{\"asset_id\":\"6819349142499203276746921220091467839657969656169150924495502803133501838527\",\"price\":\"0.072\",\"size\":\"0\",\"side\":\"SELL\",\"hash\":\"6633203fe811e9abbc7b6cf7d2e7dcf3f00de754\",\"best_bid\":\"0.001\",\"best_ask\":\"0.004\"}],\"timestamp\":\"1785928837727\",\"event_type\":\"price_change\"}"}
{"recv_ts": 1785928837.7612994, "raw": "{\"market\":\"0xbab083c8bb365a4076fbc0d24ba307a1c28d4f25c7f89ea1231bd9aad776f144\",\"price_changes\":[{\"asset_id\":\"103843050760108913906945141811136757046308978276759698197586312214650022815017\",\"price\":\"0.926\",\"size\":\"0\",\"side\":\"BUY\",\"hash\":\"be0b5a77379dcf81bc6d07ddac8c7e07c8589d39\",\"best_bid\":\"0.996\",\"best_ask\":\"0.999\"},{\"asset_id\":\"6819349142499203276746921220091467839657969656169150924495502803133501838527\",\"price\":\"0.074\",\"size\":\"0\",\"side\":\"SELL\",\"hash\":\"6633203fe811e9abbc7b6cf7d2e7dcf3f00de754\",\"best_bid\":\"0.001\",\"best_ask\":\"0.004\"}],\"timestamp\":\"1785928837727\",\"event_type\":\"price_change\"}"}
{"recv_ts": 1785928837.7613056, "raw": "{\"market\":\"0x75d23728059cad70d844df1c068e9262d8fa26ecb30f296c0d08b3c00fed01e0\",\"price_changes\":[{\"asset_id\":\"22712829542847599564052327157213856809105636169545956971844951739958318964908\",\"price\":\"0.928\",\"size\":\"0\",\"side\":\"BUY\",\"hash\":\"f525ec749ee384809178cf253a63db98bac517d5\",\"best_bid\":\"0.996\",\"best_ask\":\"0.999\"},{\"asset_id\":\"92144408598950161315078212492027631334302853859174202522008056474158348296740\",\"price\":\"0.072\",\"size\":\"0\",\"side\":\"SELL\",\"hash\":\"85ba20bacfeaa370e1b4a3453d01b95ce460a47a\",\"best_bid\":\"0.001\",\"best_ask\":\"0.004\"}],\"timestamp\":\"1785928837727\",\"event_type\":\"price_change\"}"}
{"recv_ts": 1785928837.761312, "raw": "{\"market\":\"0x75d23728059cad70d844df1c068e9262d8fa26ecb30f296c0d08b3c00fed01e0\",\"price_changes\":[{\"asset_id\":\"22712829542847599564052327157213856809105636169545956971844951739958318964908\",\"price\":\"0.926\",\"size\":\"0\",\"side\":\"BUY\",\"hash\":\"f525ec749ee384809178cf253a63db98bac517d5\",\"best_bid\":\"0.996\",\"best_ask\":\"0.999\"},{\"asset_id\":\"92144408598950161315078212492027631334302853859174202522008056474158348296740\",\"price\":\"0.074\",\"size\":\"0\",\"side\":\"SELL\",\"hash\":\"85ba20bacfeaa370e1b4a3453d01b95ce460a47a\",\"best_bid\":\"0.001\",\"best_ask\":\"0.004\"}],\"timestamp\":\"1785928837727\",\"event_type\":\"price_change\"}"}
{"recv_ts": 1785928837.7613187, "raw": "{\"market\":\"0xeb1b02259692fde7a75131afde0c8c0382c7e72650ee029fa51a9a4d2b5a6772\",\"price_changes\":[{\"asset_id\":\"62662690220231139069175677931578761522631164090290295462996352611035070725067\",\"price\":\"0.922\",\"size\":\"0\",\"side\":\"BUY\",\"hash\":\"5c4e4cb64123e220849e36d39bcd160248cf30cd\",\"best_bid\":\"0.976\",\"best_ask\":\"0.993\"},{\"asset_id\":\"111936281067666006196985095277433284360150604383695310403200564948321448684686\",\"price\":\"0.078\",\"size\":\"0\",\"side\":\"SELL\",\"hash\":\"a613987a8913d8ed65c70d5c3d97644632b2fc2e\",\"best_bid\":\"0.007\",\"best_ask\":\"0.024\"}],\"timestamp\":\"1785928837727\",\"event_type\":\"price_change\"}"}
{"recv_ts": 1785928837.7613256, "raw": "{\"market\":\"0xa561e8bb41dc37e6c429290b86b99656cd970da7e88390610909e441b2723ac8\",\"price_changes\":[{\"asset_id\":\"105316834999130562959940001169510465111487012362923706009968664706973646526681\",\"price\":\"0.918\",\"size\":\"0\",\"side\":\"BUY\",\"hash\":\"eff96d901b179da2b94266c540c7908d915d08b9\",\"best_bid\":\"0.971\",\"best_ask\":\"0.988\"},{\"asset_id\":\"29825868751864646746310402216826737712044744388751470859717252715531890918100\",\"price\":\"0.082\",\"size\":\"0\",\"side\":\"SELL\",\"hash\":\"34d77a2d767eceb7d622984aa607788b1a30dc47\",\"best_bid\":\"0.012\",\"best_ask\":\"0.029\"}],\"timestamp\":\"1785928837727\",\"event_type\":\"price_change\"}"}
{"recv_ts": 1785928837.761332, "raw": "{\"market\":\"0xa561e8bb41dc37e6c429290b86b99656cd970da7e88390610909e441b2723ac8\",\"price_changes\":[{\"asset_id\":\"105316834999130562959940001169510465111487012362923706009968664706973646526681\",\"price\":\"0.916\",\"size\":\"0\",\"side\":\"BUY\",\"hash\":\"eff96d901b179da2b94266c540c7908d915d08b9\",\"best_bid\":\"0.971\",\"best_ask\":\"0.988\"},{\"asset_id\":\"29825868751864646746310402216826737712044744388751470859717252715531890918100\",\"price\":\"0.084\",\"size\":\"0\",\"side\":\"SELL\",\"hash\":\"34d77a2d767eceb7d622984aa607788b1a30dc47\",\"best_bid\":\"0.012\",\"best_ask\":\"0.029\"}],\"timestamp\":\"1785928837727\",\"event_type\":\"price_change\"}"}
{"recv_ts": 1785928837.7613385, "raw": "{\"market\":\"0xeb1b02259692fde7a75131afde0c8c0382c7e72650ee029fa51a9a4d2b5a6772\",\"price_changes\":[{\"asset_id\":\"62662690220231139069175677931578761522631164090290295462996352611035070725067\",\"price\":\"0.92\",\"size\":\"23.91\",\"side\":\"BUY\",\"hash\":\"5c4e4cb64123e220849e36d39bcd160248cf30cd\",\"best_bid\":\"0.976\",\"best_ask\":\"0.993\"},{\"asset_id\":\"111936281067666006196985095277433284360150604383695310403200564948321448684686\",\"price\":\"0.08\",\"size\":\"23.91\",\"side\":\"SELL\",\"hash\":\"a613987a8913d8ed65c70d5c3d97644632b2fc2e\",\"best_bid\":\"0.007\",\"best_ask\":\"0.024\"}],\"timestamp\":\"1785928837727\",\"event_type\":\"price_change\"}"}
{"recv_ts": 1785928837.7613447, "raw": "{\"market\":\"0xdc0fee0756e3083da50c5fe387b680aa97cb49e4df2de0c56df51efa3fba6a02\",\"price_changes\":[{\"asset_id\":\"85218429274897603232771310322916442938026447509827864334452254142908802910802\",\"price\":\"0.74\",\"size\":\"0\",\"side\":\"BUY\",\"hash\":\"f1ef30770afee006b424061ee8360ccbfa515c53\",\"best_bid\":\"0.81\",\"best_ask\":\"0.82\"},{\"asset_id\":\"41544410164488289357175533349636873366413200567755614217325090865234847255944\",\"price\":\"0.26\",\"size\":\"0\",\"side\":\"SELL\",\"hash\":\"64cd9435c81812f5816b2cb67f2c0ade204343f3\",\"best_bid\":\"0.18\",\"best_ask\":\"0.19\"}],\"timestamp\":\"1785928837727\",\"event_type\":\"price_change\"}"}
{"recv_ts": 1785928837.7613509, "raw": "{\"market\":\"0xdc0fee0756e3083da50c5fe387b680aa97cb49e4df2de0c56df51efa3fba6a02\",\"price_changes\":[{\"asset_id\":\"85218429274897603232771310322916442938026447509827864334452254142908802910802\",\"price\":\"0.73\",\"size\":\"10\",\"side\":\"BUY\",\"hash\":\"f1ef30770afee006b424061ee8360ccbfa515c53\",\"best_bid\":\"0.81\",\"best_ask\":\"0.82\"},{\"asset_id\":\"41544410164488289357175533349636873366413200567755614217325090865234847255944\",\"price\":\"0.27\",\"size\":\"10\",\"side\":\"SELL\",\"hash\":\"64cd9435c81812f5816b2cb67f2c0ade204343f3\",\"best_bid\":\"0.18\",\"best_ask\":\"0.19\"}],\"timestamp\":\"1785928837727\",\"event_type\":\"price_change\"}"}
{"recv_ts": 1785928837.7613575, "raw": "{\"market\":\"0xbab083c8bb365a4076fbc0d24ba307a1c28d4f25c7f89ea1231bd9aad776f144\",\"price_changes\":[{\"asset_id\":\"103843050760108913906945141811136757046308978276759698197586312214650022815017\",\"price\":\"0.929\",\"size\":\"5\",\"side\":\"BUY\",\"hash\":\"2f11295ec5688b831fb3996341a5ad8d5a1a3ff0\",\"best_bid\":\"0.996\",\"best_ask\":\"0.999\"},{\"asset_id\":\"6819349142499203276746921220091467839657969656169150924495502803133501838527\",\"price\":\"0.071\",\"size\":\"5\",\"side\":\"SELL\",\"hash\":\"b3df13ef5fa1f44f886056a14987177ec614e664\",\"best_bid\":\"0.001\",\"best_ask\":\"0.004\"}],\"timestamp\":\"1785928837732\",\"event_type\":\"price_change\"}"}
{"recv_ts": 1785928837.761364, "raw": "{\"market\":\"0xa561e8bb41dc37e6c429290b86b99656cd970da7e88390610909e441b2723ac8\",\"price_changes\":[{\"asset_id\":\"105316834999130562959940001169510465111487012362923706009968664706973646526681\",\"price\":\"0.919\",\"size\":\"5\",\"side\":\"BUY\",\"hash\":\"6a2a764fd476dcdaac1a1cf1bf7f75e45737a1c4\",\"best_bid\":\"0.971\",\"best_ask\":\"0.988\"},{\"asset_id\":\"29825868751864646746310402216826737712044744388751470859717252715531890918100\",\"price\":\"0.081\",\"size\":\"5\",\"side\":\"SELL\",\"hash\":\"5a1c063faa15929f7d4a03ec521f82b54e355d82\",\"best_bid\":\"0.012\",\"best_ask\":\"0.029\"}],\"timestamp\":\"1785928837733\",\"event_type\":\"price_change\"}"}
{"recv_ts": 1785928837.7613776, "raw": "{\"market\":\"0xeb1b02259692fde7a75131afde0c8c0382c7e72650ee029fa51a9a4d2b5a6772\",\"price_changes\":[{\"asset_id\":\"62662690220231139069175677931578761522631164090290295462996352611035070725067\",\"price\":\"0.925\",\"size\":\"5\",\"side\":\"BUY\",\"hash\":\"fe74cb780f294943c96901d2691cf3ed8e334a0f\",\"best_bid\":\"0.976\",\"best_ask\":\"0.993\"},{\"asset_id\":\"111936281067666006196985095277433284360150604383695310403200564948321448684686\",\"price\":\"0.075\",\"size\":\"5\",\"side\":\"SELL\",\"hash\":\"0edc9de9b5de1fdd2b111e6ba02109b0f1693e17\",\"best_bid\":\"0.007\",\"best_ask\":\"0.024\"}],\"timestamp\":\"1785928837733\",\"event_type\":\"price_change\"}"}
{"recv_ts": 1785928837.7613842, "raw": "{\"market\":\"0x0393e451a7889f6472d5099a6de21d1fc6bea6ada01c2e227ea954a8ebce1771\",\"price_changes\":[{\"asset_id\":\"62439955870856164313493799301554574122664268361492077980110236255342893751283\",\"price\":\"0.369\",\"size\":\"0\",\"side\":\"BUY\",\"hash\":\"cec7e1cccc49e9fcaf3bd62507691a5717e2c28f\",\"best_bid\":\"0.914\",\"best_ask\":\"0.944\"},{\"asset_id\":\"19078179119846452574438096789570272099502061228398927027811652354916673625092\",\"price\":\"0.631\",\"size\":\"0\",\"side\":\"SELL\",\"hash\":\"ce637d31ee5208299b49f3ee1a07cf961c364e95\",\"best_bid\":\"0.056\",\"best_ask\":\"0.086\"}],\"timestamp\":\"1785928837735\",\"event_type\":\"price_change\"}"}
{"recv_ts": 1785928837.7613904, "raw": "{\"market\":\"0xa561e8bb41dc37e6c429290b86b99656cd970da7e88390610909e441b2723ac8\",\"price_changes\":[{\"asset_id\":\"105316834999130562959940001169510465111487012362923706009968664706973646526681\",\"price\":\"0.921\",\"size\":\"5\",\"side\":\"BUY\",\"hash\":\"725d1fde9c333b467d771a3f8538400b54151da9\",\"best_bid\":\"0.971\",\"best_ask\":\"0.988\"},{\"asset_id\":\"29825868751864646746310402216826737712044744388751470859717252715531890918100\",\"price\":\"0.079\",\"size\":\"5\",\"side\":\"SELL\",\"hash\":\"26b3f7c2eacc10661aab48028ae49ca9c6b53cbc\",\"best_bid\":\"0.012\",\"best_ask\":\"0.029\"}],\"timestamp\":\"1785928837734\",\"event_type\":\"price_change\"}"}
{"recv_ts": 1785928837.7614038, "raw": "{\"market\":\"0x0393e451a7889f6472d5099a6de21d1fc6bea6ada01c2e227ea954a8ebce1771\",\"price_changes\":[{\"asset_id\":\"19078179119846452574438096789570272099502061228398927027811652354916673625092\",\"price\":\"0.086\",\"size\":\"5\",\"side\":\"SELL\",\"hash\":\"fb0b7b2eb6b2a1aa13faca4e011d005e6f379926\",\"best_bid\":\"0.056\",\"best_ask\":\"0.086\"},{\"asset_id\":\"62439955870856164313493799301554574122664268361492077980110236255342893751283\",\"price\":\"0.914\",\"size\":\"5\",\"side\":\"BUY\",\"hash\":\"823bb93218cf8e826c0c8cbc92054645eea9e986\",\"best_bid\":\"0.914\",\"best_ask\":\"0.944\"}],\"timestamp\":\"1785928837735\",\"event_type\":\"price_change\"}"}
{"recv_ts": 1785928837.761412, "raw": "{\"market\":\"0xeb1b02259692fde7a75131afde0c8c0382c7e72650ee029fa51a9a4d2b5a6772\",\"price_changes\":[{\"asset_id\":\"62662690220231139069175677931578761522631164090290295462996352611035070725067\",\"price\":\"0.923\",\"size\":\"5\",\"side\":\"BUY\",\"hash\":\"505a8017f833a8444383bd245fbb95d1af1078f1\",\"best_bid\":\"0.976\",\"best_ask\":\"0.993\"},{\"asset_id\":\"111936281067666006196985095277433284360150604383695310403200564948321448684686\",\"price\":\"0.077\",\"size\":\"5\",\"side\":\"SELL\",\"hash\":\"5e04a2b3f8d160bd51c607604f660a1b70bdc39c\",\"best_bid\":\"0.007\",\"best_ask\":\"0.024\"}],\"timestamp\":\"1785928837735\",\"event_type\":\"price_change\"}"}
{"recv_ts": 1785928837.7614186, "raw": "{\"market\":\"0x75d23728059cad70d844df1c068e9262d8fa26ecb30f296c0d08b3c00fed01e0\",\"price_changes\":[{\"asset_id\":\"22712829542847599564052327157213856809105636169545956971844951739958318964908\",\"price\":\"0.931\",\"size\":\"5\",\"side\":\"BUY\",\"hash\":\"674c5184b2f0e7a379af5fd39558acd8c9dab68a\",\"best_bid\":\"0.996\",\"best_ask\":\"0.999\"},{\"asset_id\":\"92144408598950161315078212492027631334302853859174202522008056474158348296740\",\"price\":\"0.069\",\"size\":\"5\",\"side\":\"SELL\",\"hash\":\"f4fe2b614dc9f1918905677c919dd81d8ae88523\",\"best_bid\":\"0.001\",\"best_ask\":\"0.004\"}],\"timestamp\":\"1785928837736\",\"event_type\":\"price_change\"}"}
{"recv_ts": 1785928837.7614253, "raw": "{\"market\":\"0x75d23728059cad70d844df1c068e9262d8fa26ecb30f296c0d08b3c00fed01e0\",\"price_changes\":[{\"asset_id\":\"22712829542847599564052327157213856809105636169545956971844951739958318964908\",\"price\":\"0.929\",\"size\":\"5\",\"side\":\"BUY\",\"hash\":\"4ec83422c6e0eaf813c51f2baea23f54d8b4c94a\",\"best_bid\":\"0.996\",\"best_ask\":\"0.999\"},{\"asset_id\":\"92144408598950161315078212492027631334302853859174202522008056474158348296740\",\"price\":\"0.071\",\"size\":\"5\",\"side\":\"SELL\",\"hash\":\"c0a8ab23a1cef15afc4f5a37fdc812230583783c\",\"best_bid\":\"0.001\",\"best_ask\":\"0.004\"}],\"timestamp\":\"1785928837736\",\"event_type\":\"price_change\"}"}
{"recv_ts": 1785928837.7614315, "raw": "{\"market\":\"0xdc0fee0756e3083da50c5fe387b680aa97cb49e4df2de0c56df51efa3fba6a02\",\"price_changes\":[{\"asset_id\":\"85218429274897603232771310322916442938026447509827864334452254142908802910802\",\"price\":\"0.74\",\"size\":\"5\",\"side\":\"BUY\",\"hash\":\"afe57570d29ccb05caf3ae56780dc4eaa88767b3\",\"best_bid\":\"0.81\",\"best_ask\":\"0.82\"},{\"asset_id\":\"41544410164488289357175533349636873366413200567755614217325090865234847255944\",\"price\":\"0.26\",\"size\":\"5\",\"side\":\"SELL\",\"hash\":\"3014b30e0078366fd3ce36a44677059f4690d376\",\"best_bid\":\"0.18\",\"best_ask\":\"0.19\"}],\"timestamp\":\"1785928837737\",\"event_type\":\"price_change\"}"}
{"recv_ts": 1785928837.7790723, "raw": "{\"market\":\"0xdc0fee0756e3083da50c5fe387b680aa97cb49e4df2de0c56df51efa3fba6a02\",\"price_changes\":[{\"asset_id\":\"85218429274897603232771310322916442938026447509827864334452254142908802910802\",\"price\":\"0.75\",\"size\":\"5\",\"side\":\"BUY\",\"hash\":\"b73665c8b06a8665b5cf4ccc9f303f644edffff3\",\"best_bid\":\"0.81\",\"best_ask\":\"0.82\"},{\"asset_id\":\"41544410164488289357175533349636873366413200567755614217325090865234847255944\",\"price\":\"0.25\",\"size\":\"5\",\"side\":\"SELL\",\"hash\":\"457e119cf6f4da47ec239eac00892ac6c37a6a4c\",\"best_bid\":\"0.18\",\"best_ask\":\"0.19\"}],\"timestamp\":\"1785928837738\",\"event_type\":\"price_change\"}"}
{"recv_ts": 1785928837.779107, "raw": "{\"market\":\"0xbab083c8bb365a4076fbc0d24ba307a1c28d4f25c7f89ea1231bd9aad776f144\",\"price_changes\":[{\"asset_id\":\"103843050760108913906945141811136757046308978276759698197586312214650022815017\",\"price\":\"0.931\",\"size\":\"5\",\"side\":\"BUY\",\"hash\":\"993813c49fa8a3b6395755595406ac8c5135be21\",\"best_bid\":\"0.996\",\"best_ask\":\"0.999\"},{\"asset_id\":\"6819349142499203276746921220091467839657969656169150924495502803133501838527\",\"price\":\"0.069\",\"size\":\"5\",\"side\":\"SELL\",\"hash\":\"a681fa98350c73d6151ca7868507fe5ef2318bba\",\"best_bid\":\"0.001\",\"best_ask\":\"0.004\"}],\"timestamp\":\"1785928837739\",\"event_type\":\"price_change\"}"}
{"recv_ts": 1785928837.7791188, "raw": "{\"market\":\"0x9564d81934c1550b627ff159cc139675d7d08916fa74cc4aaf8d416e4bedd807\",\"price_changes\":[{\"asset_id\":\"46123186009598106104671689617421295270790145953546842072887829618094075293472\",\"price\":\"0.04\",\"size\":\"130\",\"side\":\"BUY\",\"hash\":\"99b0ec6ccbd26ec1152e4506647280e2129ad98b\",\"best_bid\":\"0.48\",\"best_ask\":\"0.74\"},{\"asset_id\":\"33275922446271605474639218893344378139793083231796398469699104729778621445854\",\"price\":\"0.96\",\"size\":\"130\",\"side\":\"SELL\",\"hash\":\"7460184098350859e798dbf604228df71e51d537\",\"best_bid\":\"0.26\",\"best_ask\":\"0.52\"}],\"timestamp\":\"1785928837739\",\"event_type\":\"price_change\"}"}
{"recv_ts": 1785928837.7791276, "raw": "{\"market\":\"0x31cc8cc9d1b3dbdc5219e0319a01ded09ad0c18296c8f27bc76b1f12364a4661\",\"price_changes\":[{\"asset_id\":\"51223233815348005431570032441325849255204346210650700628294623504463311020670\",\"price\":\"0.26\",\"size\":\"5\",\"side\":\"BUY\",\"hash\":\"d2d2dc8704dabd42a92d79178aeee4fed6bce177\",\"best_bid\":\"0.26\",\"best_ask\":\"0.43\"},{\"asset_id\":\"36593914907192135817908362063800584939108275837285837232090830833195276003888\",\"price\":\"0.74\",\"size\":\"5\",\"side\":\"SELL\",\"hash\":\"52c8aee3bf505afadd730b348416a623a1505251\",\"best_bid\":\"0.57\",\"best_ask\":\"0.74\"}],\"timestamp\":\"1785928837744\",\"event_type\":\"price_change\"}"}
{"recv_ts": 1785928837.77917, "raw": "{\"market\":\"0x30cefdde280d79ffcb7e9f25dbe99e6164d16651c9d8631f2b5bf402b6e697d5\",\"price_changes\":[{\"asset_id\":\"103247719666968457601315979306806361087685293523685277721928164828309367213844\",\"price\":\"0.14\",\"size\":\"57.14\",\"side\":\"BUY\",\"hash\":\"d40f5b0b52dd43048cb086eeb49c582ad483d630\",\"best_bid\":\"0.85\",\"best_ask\":\"0.9\"},{\"asset_id\":\"78375158579295640490513288741441222289494383230318559761174600803653799947930\",\"price\":\"0.86\",\"size\":\"57.14\",\"side\":\"SELL\",\"hash\":\"dd16edae9964587edf250a7f4f7e98695e645550\",\"best_bid\":\"0.1\",\"best_ask\":\"0.15\"}],\"timestamp\":\"1785928837748\",\"event_type\":\"price_change\"}"}
{"recv_ts": 1785928837.7791781, "raw": "{\"market\":\"0x9c68a1448a4cdb3993a297f1f0f759774383f2e514773621ceb04589399930bc\",\"price_changes\":[{\"asset_id\":\"33579711484128453880472647592907450388461194263236358989226504691017998237897\",\"price\":\"0.81\",\"size\":\"28\",\"side\":\"BUY\",\"hash\":\"95dc0cf85bb08fbb366290a7b240f053724b5868\",\"best_bid\":\"0.85\",\"best_ask\":\"0.91\"},{\"asset_id\":\"62791514040221235938370932209912323223995828701014253087241691765902207027191\",\"price\":\"0.19\",\"size\":\"28\",\"side\":\"SELL\",\"hash\":\"715772e4300edad64b92bf0a298dfe3e64a725b3\",\"best_bid\":\"0.09\",\"best_ask\":\"0.15\"}],\"timestamp\":\"1785928837750\",\"event_type\":\"price_change\"}"}
{"recv_ts": 1785928837.7791903, "raw": "{\"market\":\"0x32c0e87c7912c78baf8baba212fd71c9ae3b79668ef3704d9b5099c3c1951457\",\"price_changes\":[{\"asset_id\":\"113237755407869827254006429933575932602773153089417903336872655923687516944443\",\"price\":\"0.644\",\"size\":\"30\",\"side\":\"BUY\",\"hash\":\"7747421ddd101d4b89b0506fdcc8f7f9d7e46380\",\"best_bid\":\"0.991\",\"best_ask\":\"0.994\"},{\"asset_id\":\"16146461124066907595536869684932879822614798885626075746914948898944985760697\",\"price\":\"0.356\",\"size\":\"30\",\"side\":\"SELL\",\"hash\":\"9869fbac74cb272ed0282301c5344626816188f0\",\"best_bid\":\"0.006\",\"best_ask\":\"0.009\"}],\"timestamp\":\"1785928837707\",\"event_type\":\"price_change\"}"}
{"recv_ts": 1785928837.7791996, "raw": "{\"market\":\"0xf3c51342d4a09e9db404d5bda09dceba5eec36fee2e929187846271983165ee4\",\"price_changes\":[{\"asset_id\":\"35476438390607209914426669942782179640993045636238204239094516003106768962428\",\"price\":\"0.668\",\"size\":\"0\",\"side\":\"BUY\",\"hash\":\"4efe64459f96b32934414abf2a2b8b33c6a27ab1\",\"best_bid\":\"0.998\",\"best_ask\":\"0.999\"},{\"asset_id\":\"77467283570243320603724044925032832099734660394861873171045738755127945074264\",\"price\":\"0.332\",\"size\":\"0\",\"side\":\"SELL\",\"hash\":\"88d75ed94c0d0fbfdfe9211d37d36a0d3602eba0\",\"best_bid\":\"0.001\",\"best_ask\":\"0.002\"}],\"timestamp\":\"1785928837707\",\"event_type\":\"price_change\"}"}
{"recv_ts": 1785928837.7792068, "raw": "{\"market\":\"0xf357e65cdcf539ebec03cef60bd1d7b63c39dcbec7a776b287a9034105f109c3\",\"price_changes\":[{\"asset_id\":\"112334948398217246286204340737312251733067612940202013873286223663359589480504\",\"price\":\"0.45\",\"size\":\"472.34\",\"side\":\"BUY\",\"hash\":\"4ec2be260ede542f15b840ff97245db1d295f156\",\"best_bid\":\"0.47\",\"best_ask\":\"0.5\"},{\"asset_id\":\"109930676153389773259400824922429294067294153271064524805028562317130229163797\",\"price\":\"0.55\",\"size\":\"472.34\",\"side\":\"SELL\",\"hash\":\"e8028112c7cfd0b52947ba47dea797e1dd9f27c3\",\"best_bid\":\"0.5\",\"best_ask\":\"0.53\"}],\"timestamp\":\"1785928837714\",\"event_type\":\"price_change\"}"}
{"recv_ts": 1785928837.7801127, "raw": "{\"market\":\"0xf3c51342d4a09e9db404d5bda09dceba5eec36fee2e929187846271983165ee4\",\"price_changes\":[{\"asset_id\":\"35476438390607209914426669942782179640993045636238204239094516003106768962428\",\"price\":\"0.669\",\"size\":\"0\",\"side\":\"BUY\",\"hash\":\"58b7d55344afef582c46e4927fdcb6f31b1eebe6\",\"best_bid\":\"0.998\",\"best_ask\":\"0.999\"},{\"asset_id\":\"77467283570243320603724044925032832099734660394861873171045738755127945074264\",\"price\":\"0.331\",\"size\":\"0\",\"side\":\"SELL\",\"hash\":\"75412e5ae24b7dc0ced82c1259b60fc966c456b7\",\"best_bid\":\"0.001\",\"best_ask\":\"0.002\"}],\"timestamp\":\"1785928837730\",\"event_type\":\"price_change\"}"}
{"recv_ts": 1785928837.7801337, "raw": "{\"market\":\"0xf3c51342d4a09e9db404d5bda09dceba5eec36fee2e929187846271983165ee4\",\"price_changes\":[{\"asset_id\":\"35476438390607209914426669942782179640993045636238204239094516003106768962428\",\"price\":\"0.665\",\"size\":\"400\",\"side\":\"BUY\",\"hash\":\"9541d9f4b0db8865a991a4547b323fcd2f11deec\",\"best_bid\":\"0.998\",\"best_ask\":\"0.999\"},{\"asset_id\":\"77467283570243320603724044925032832099734660394861873171045738755127945074264\",\"price\":\"0.335\",\"size\":\"400\",\"side\":\"SELL\",\"hash\":\"122787bca02c24e934f74f71dc3fce37d9b15980\",\"best_bid\":\"0.001\",\"best_ask\":\"0.002\"}],\"timestamp\":\"1785928837754\",\"event_type\":\"price_change\"}"}
{"recv_ts": 1785928837.7838736, "raw": "[{\"market\": \"0x739c12d445e736c570ff5d3f671affbc72cf163cbb58f31e3fed14c56a344651\", \"asset_id\": \"65567611780474998480364308753633737558364465741326977960230894246870440411123\", \"timestamp\": \"1785928837557\", \"hash\": \"29d7d58bc244b760ff5d66938817a4a6d4f57793\", \"bids\": [{\"price\": \"0.001\", \"size\": \"535\"}, {\"price\": \"0.002\", \"size\": \"40\"}, {\"price\": \"0.003\", \"size\": \"60.98\"}, {\"price\": \"0.004\", \"size\": \"50\"}, {\"price\": \"0.005\", \"size\": \"50\"}, {\"price\": \"0.01\", \"size\": \"62.62\"}], \"asks\": [{\"price\": \"0.999\", \"size\": \"1199.01\"}, {\"price\": \"0.998\", \"size\": \"532.23\"}, {\"price\": \"0.997\", \"size\": \"1013.32\"}, {\"price\": \"0.996\", \"size\": \"17.4\"}, {\"price\": \"0.99\", \"size\": \"2120\"}, {\"price\": \"0.989\", \"size\": \"7.13\"}, {\"price\": \"0.98\", \"size\": \"2128\"}, {\"price\": \"0.979\", \"size\": \"6.04\"}, {\"price\": \"0.97\", \"size\": \"1010\"}, {\"price\": \"0.969\", \"size\": \"30\"}, {\"price\": \"0.96\", \"size\": \"1125\"}, {\"price\": \"0.959\", \"size\": \"6.69\"}, {\"price\": \"0.95\", \"size\": \"1010\"}, {\"price\": \"0.94\", \"size\": \"1045.33\"}, {\"price\": \"0.93\", \"size\": \"1000\"}, {\"price\": \"0.92\", \"size\": \"1025\"}, {\"price\": \"0.91\", \"size\": \"1000\"}, {\"price\": \"0.909\", \"size\": \"400\"}, {\"price\": \"0.9\", \"size\": \"1020\"}, {\"price\": \"0.899\", \"size\": \"413.02\"}, {\"price\": \"0.88\", \"size\": \"8.33\"}, {\"price\": \"0.86\", \"size\": \"7.14\"}, {\"price\": \"0.84\", \"size\": \"6.25\"}, {\"price\": \"0.82\", \"size\": \"5.56\"}, {\"price\": \"0.75\", \"size\": \"51\"}, {\"price\": \"0.749\", \"size\": \"5.2\"}, {\"price\": \"0.7\", \"size\": \"7\"}, {\"price\": \"0.65\", \"size\": \"35\"}, {\"price\": \"0.649\", \"size\": \"30\"}, {\"price\": \"0.6\", \"size\": \"10\"}, {\"price\": \"0.38\", \"size\": \"10\"}, {\"price\": \"0.379\", \"size\": \"1401\"}, {\"price\": \"0.378\", \"size\": \"560.4\"}, {\"price\": \"0.36\", \"size\": \"10\"}, {\"price\": \"0.35\", \"size\": \"5\"}, {\"price\": \"0.341\", \"size\": \"400\"}, {\"price\": \"0.34\", \"size\": \"30\"}, {\"price\": \"0.339\", \"size\": \"7.56\"}, {\"price\": \"0.2\", \"size\": \"41\"}, {\"price\": \"0.199\", \"size\": \"100\"}, {\"price\": \"0.186\", \"size\": \"10\"}, {\"price\": \"0.185\", \"size\": \"50\"}, {\"price\": \"0.152\", \"size\": \"26.53\"}, {\"price\": \"0.15\", \"size\": \"10\"}, {\"price\": \"0.146\", \"size\": \"50\"}, {\"price\": \"0.14\", \"size\": \"5\"}, {\"price\": \"0.139\", \"size\": \"45\"}, {\"price\": \"0.12\", \"size\": \"10\"}, {\"price\": \"0.112\", \"size\": \"7\"}, {\"price\": \"0.111\", \"size\": \"30\"}, {\"price\": \"0.09\", \"size\": \"20\"}, {\"price\": \"0.088\", \"size\": \"20\"}, {\"price\": \"0.087\", \"size\": \"10\"}, {\"price\": \"0.084\", \"size\": \"5\"}, {\"price\": \"0.082\", \"size\": \"5\"}, {\"price\": \"0.08\", \"size\": \"10\"}, {\"price\": \"0.07\", \"size\": \"42\"}, {\"price\": \"0.067\", \"size\": \"15\"}, {\"price\": \"0.06\", \"size\": \"7\"}, {\"price\": \"0.053\", \"size\": \"15\"}, {\"price\": \"0.052\", \"size\": \"3.13\"}, {\"price\": \"0.051\", \"size\": \"5\"}, {\"price\": \"0.05\", \"size\": \"7\"}, {\"price\": \"0.04\", \"size\": \"7\"}, {\"price\": \"0.03\", \"size\": \"50\"}, {\"price\": \"0.029\", \"size\": \"20\"}, {\"price\": \"0.02\", \"size\": \"7\"}, {\"price\": \"0.017\", \"size\": \"10\"}, {\"price\": \"0.016\", \"size\": \"6.24\"}], \"tick_size\": \"0.001\", \"event_type\": \"book\", \"last_trade_price\": \"0.990\"}, {\"market\": \"0xefab602ca573e099835e9027df85f9c28c78d452b24295893e90ee1459e76af0\", \"asset_id\": \"84665889288044879593021843799720148743474594992176520369203484047798320183589\", \"timestamp\": \"1785928831312\", \"hash\": \"b2d446c7e46eb16e4a151b410debfdad86953f36\", \"bids\": [{\"price\": \"0.01\", \"size\": \"84\"}, {\"price\": \"0.02\", \"size\": \"23.24\"}, {\"price\": \"0.03\", \"size\": \"156.43\"}, {\"price\": \"0.04\", \"size\": \"85.12\"}, {\"price\": \"0.05\", \"size\": \"30\"}, {\"price\": \"0.06\", \"size\": \"10\"}, {\"price\": \"0.07\", \"size\": \"217\"}, {\"price\": \"0.15\", \"size\": \"10\"}, {\"price\": \"0.16\", \"size\": \"20\"}, {\"price\": \"0.17\", \"size\": \"20\"}, {\"price\": \"0.18\", \"size\": \"20\"}, {\"price\": \"0.19\", \"size\": \"20\"}, {\"price\": \"0.2\", \"size\": \"1114\"}, {\"price\": \"0.21\", \"size\": \"445.6\"}, {\"price\": \"0.22\", \"size\": \"831\"}, {\"price\": \"0.23\", \"size\": \"352.4\"}, {\"price\": \"0.24\", \"size\": \"348\"}, {\"price\": \"0.25\", \"size\": \"139.19\"}, {\"price\": \"0.26\", \"size\": \"35\"}, {\"price\": \"0.27\", \"size\": \"30\"}, {\"price\": \"0.28\", \"size\": \"20\"}, {\"price\": \"0.3\", \"size\": \"10\"}, {\"price\": \"0.4\", \"size\": \"4.1\"}, {\"price\": \"0.41\", \"size\": \"40\"}, {\"price\": \"0.42\", \"size\": \"15\"}, {\"price\": \"0.44\", \"size\": \"25\"}, {\"price\": \"0.45\", \"size\": \"66\"}, {\"price\": \"0.46\", \"size\": \"56.36\"}], \"asks\": [{\"price\": \"0.99\", \"size\": \"156.88\"}, {\"price\": \"0.98\", \"size\": \"78\"}, {\"price\": \"0.97\", \"size\": \"15.48\"}, {\"price\": \"0.96\", \"size\": \"100\"}, {\"price\": \"0.95\", \"size\": \"12.12\"}, {\"price\": \"0.94\", \"size\": \"23.66\"}, {\"price\": \"0.93\", \"size\": \"20.28\"}, {\"price\": \"0.92\", \"size\": \"400\"}, {\"price\": \"0.76\", \"size\": \"1285\"}, {\"price\": \"0.75\", \"size\": \"524\"}, {\"price\": \"0.73\", \"size\": \"425.6\"}, {\"price\": \"0.72\", \"size\": \"1094\"}, {\"price\": \"0.7\", \"size\": \"10\"}, {\"price\": \"0.69\", \"size\": \"30\"}, {\"price\": \"0.68\", \"size\": \"233.2\"}, {\"price\": \"0.67\", \"size\": \"533\"}, {\"price\": \"0.66\", \"size\": \"100\"}, {\"price\": \"0.65\", \"size\": \"10\"}, {\"price\": \"0.63\", \"size\": \"80\"}, {\"price\": \"0.61\", \"size\": \"75\"}, {\"price\": \"0.6\", \"size\": \"120\"}, {\"price\": \"0.57\", \"size\": \"31.25\"}, {\"price\": \"0.52\", \"size\": \"414.9\"}, {\"price\": \"0.51\", \"size\": \"102\"}, {\"price\": \"0.5\", \"size\": \"45\"}], \"tick_size\": \"0.01\", \"event_type\": \"book\", \"last_trade_price\": \"0.540\"}, {\"market\": \"0x805dbc2f3cecf0c9076f87450e597e1e33de4165ad760e73ee75aceac3e374a4\", \"asset_id\": \"87428067364846555738908876299781999302772291007200346680160694213852120985627\", \"timestamp\": \"1785928813781\", \"hash\": \"d16a1d18af8c62a3acdf40fe65fb46b8a25c46bd\", \"bids\": [{\"price\": \"0.001\", \"size\": \"111.55\"}, {\"price\": \"0.002\", \"size\": \"154\"}], \"asks\": [{\"price\": \"0.999\", \"size\": \"157.52\"}, {\"price\": \"0.998\", \"size\": \"54\"}, {\"price\": \"0.997\", \"size\": \"25.47\"}, {\"price\": \"0.996\", \"size\": \"10.43\"}, {\"price\": \"0.99\", \"size\": \"20\"}, {\"price\": \"0.989\", \"size\": \"11.85\"}, {\"price\": \"0.98\", \"size\": \"10\"}, {\"price\": \"0.979\", \"size\": \"804\"}, {\"price\": \"0.977\", \"size\": \"800\"}, {\"price\": \"0.976\", \"size\": \"6.9\"}, {\"price\": \"0.97\", \"size\": \"10\"}, {\"price\": \"0.96\", \"size\": \"75\"}, {\"price\": \"0.959\", \"size\": \"6.63\"}, {\"price\": \"0.95\", \"size\": \"30\"}, {\"price\": \"0.94\", \"size\": \"7\"}, {\"price\": \"0.939\", \"size\": \"6.92\"}, {\"price\": \"0.9\", \"size\": \"10\"}, {\"price\": \"0.861\", \"size\": \"114\"}, {\"price\": \"0.86\", \"size\": \"19.57\"}, {\"price\": \"0.233\", \"size\": \"1237\"}, {\"price\": \"0.232\", \"size\": \"494.8\"}, {\"price\": \"0.23\", \"size\": \"160\"}, {\"price\": \"0.229\", \"size\": \"400\"}, {\"price\": \"0.225\", \"size\": \"25\"}, {\"price\": \"0.224\", \"size\": \"100\"}, {\"price\": \"0.1\", \"size\": \"107\"}, {\"price\": \"0.097\", \"size\": \"249.9\"}, {\"price\": \"0.09\", \"size\": \"50\"}, {\"price\": \"0.089\", \"size\": \"95\"}, {\"price\": \"0.08\", \"size\": \"50\"}, {\"price\": \"0.079\", \"size\": \"30\"}, {\"price\": \"0.07\", \"size\": \"75.63\"}, {\"price\": \"0.069\", \"size\": \"10\"}, {\"price\": \"0.06\", \"size\": \"50\"}, {\"price\": \"0.05\", \"size\": \"50\"}, {\"price\": \"0.04\", \"size\": \"150\"}, {\"price\": \"0.03\", \"size\": \"50\"}, {\"price\": \"0.02\", \"size\": \"305\"}, {\"price\": \"0.01\", \"size\": \"150\"}, {\"price\": \"0.009\", \"size\": \"50\"}, {\"price\": \"0.007\", \"size\": \"420\"}, {\"price\": \"0.005\", \"size\": \"223.28\"}], \"tick_size\": \"0.001\", \"event_type\": \"book\", \"last_trade_price\": \"0.001\"}, {\"market\": \"0x4b8b58f97c193f480e83d511c276d6131ca372ee5504cd4794c20967e2f4d2e0\", \"asset_id\": \"36044484968316107178921007507960096972223709741791131257962480235902699344131\", \"timestamp\": \"1785928837248\", \"hash\": \"20f5819806f3dd00b672f37d730911a89c55fddf\", \"bids\": [{\"price\": \"0.001\", \"size\": \"1318.3\"}, {\"price\": \"0.002\", \"size\": \"598.98\"}, {\"price\": \"0.003\", \"size\": \"1053.31\"}, {\"price\": \"0.004\", \"size\": \"36.99\"}, {\"price\": \"0.01\", \"size\": \"2120\"}, {\"price\": \"0.011\", \"size\": \"6.84\"}, {\"price\": \"0.02\", \"size\": \"2088\"}, {\"price\": \"0.021\", \"size\": \"5.85\"}, {\"price\": \"0.03\", \"size\": \"1010\"}, {\"price\": \"0.04\", \"size\": \"1105\"}, {\"price\": \"0.041\", \"size\": \"15.84\"}, {\"price\": \"0.05\", \"size\": \"1010\"}, {\"price\": \"0.06\", \"size\": \"1016.66\"}, {\"price\": \"0.07\", \"size\": \"1000\"}, {\"price\": \"0.08\", \"size\": \"1012.5\"}, {\"price\": \"0.09\", \"size\": \"1000\"}, {\"price\": \"0.091\", \"size\": \"30\"}, {\"price\": \"0.1\", \"size\": \"1010\"}, {\"price\": \"0.12\", \"size\": \"8.33\"}, {\"price\": \"0.14\", \"size\": \"7.14\"}, {\"price\": \"0.16\", \"size\": \"6.25\"}, {\"price\": \"0.18\", \"size\": \"5.55\"}, {\"price\": \"0.182\", \"size\": \"6003\"}, {\"price\": \"0.2\", \"size\": \"5\"}, {\"price\": \"0.22\", \"size\": \"9.09\"}, {\"price\": \"0.24\", \"size\": \"8.33\"}, {\"price\": \"0.25\", \"size\": \"51\"}, {\"price\": \"0.251\", \"size\": \"5.39\"}, {\"price\": \"0.26\", \"size\": \"7.69\"}, {\"price\": \"0.28\", \"size\": \"7.14\"}, {\"price\": \"0.3\", \"size\": \"16.66\"}, {\"price\": \"0.32\", \"size\": \"6.25\"}, {\"price\": \"0.34\", \"size\": \"5.88\"}, {\"price\": \"0.35\", \"size\": \"35\"}, {\"price\": \"0.36\", \"size\": \"5.55\"}, {\"price\": \"0.38\", \"size\": \"5.26\"}, {\"price\": \"0.4\", \"size\": \"15\"}, {\"price\": \"0.42\", \"size\": \"7.14\"}, {\"price\": \"0.44\", \"size\": \"6.81\"}, {\"price\": \"0.441\", \"size\": \"1975\"}, {\"price\": \"0.442\", \"size\": \"790\"}, {\"price\": \"0.46\", \"size\": \"6.52\"}, {\"price\": \"0.48\", \"size\": \"6.25\"}, {\"price\": \"0.484\", \"size\": \"617.2\"}, {\"price\": \"0.506\", \"size\": \"712.4\"}, {\"price\": \"0.507\", \"size\": \"1699\"}, {\"price\": \"0.508\", \"size\": \"30\"}, {\"price\": \"0.62\", \"size\": \"10\"}, {\"price\": \"0.63\", \"size\": \"20\"}, {\"price\": \"0.64\", \"size\": \"10\"}, {\"price\": \"0.641\", \"size\": \"400\"}, {\"price\": \"0.72\", \"size\": \"68.26\"}, {\"price\": \"0.721\", \"size\": \"150\"}, {\"price\": \"0.752\", \"size\": \"50\"}, {\"price\": \"0.8\", \"size\": \"120\"}, {\"price\": \"0.801\", \"size\": \"30\"}, {\"price\": \"0.802\", \"size\": \"45\"}, {\"price\": \"0.82\", \"size\": \"30.01\"}, {\"price\": \"0.83\", \"size\": \"19.99\"}, {\"price\": \"0.831\", \"size\": \"30\"}, {\"price\": \"0.843\", \"size\": \"10\"}, {\"price\": \"0.849\", \"size\": \"5\"}, {\"price\": \"0.85\", \"size\": \"39.12\"}, {\"price\": \"0.851\", \"size\": \"5\"}, {\"price\": \"0.852\", \"size\": \"10\"}, {\"price\": \"0.856\", \"size\": \"30\"}, {\"price\": \"0.86\", \"size\": \"32\"}, {\"price\": \"0.863\", \"size\": \"18.87\"}, {\"price\": \"0.865\", \"size\": \"10\"}, {\"price\": \"0.867\", \"size\": \"7\"}, {\"price\": \"0.87\", \"size\": \"10\"}, {\"price\": \"0.875\", \"size\": \"8.52\"}, {\"price\": \"0.88\", \"size\": \"5\"}, {\"price\": \"0.882\", \"size\": \"125\"}, {\"price\": \"0.883\", \"size\": \"78.22\"}, {\"price\": \"0.884\", \"size\": \"38\"}, {\"price\": \"0.885\", \"size\": \"10\"}, {\"price\": \"0.887\", \"size\": \"20\"}], \"asks\": [{\"price\": \"0.999\", \"size\": \"645\"}, {\"price\": \"0.998\", \"size\": \"188.67\"}, {\"price\": \"0.997\", \"size\": \"53.31\"}, {\"price\": \"0.995\", \"size\": \"1400\"}, {\"price\": \"0.994\", \"size\": \"560\"}, {\"price\": \"0.993\", \"size\": \"7.68\"}, {\"price\": \"0.992\", \"size\": \"15\"}, {\"price\": \"0.99\", \"size\": \"266.28\"}, {\"price\": \"0.98\", \"size\": \"25.5\"}, {\"price\": \"0.979\", \"size\": \"7\"}, {\"price\": \"0.97\", \"size\": \"5\"}, {\"price\": \"0.956\", \"size\": \"6\"}, {\"price\": \"0.95\", \"size\": \"70\"}, {\"price\": \"0.948\", \"size\": \"9\"}, {\"price\": \"0.945\", \"size\": \"100\"}, {\"price\": \"0.939\", \"size\": \"40\"}, {\"price\": \"0.936\", \"size\": \"811.2\"}, {\"price\": \"0.935\", \"size\": \"344.48\"}, {\"price\": \"0.93\", \"size\": \"80\"}, {\"price\": \"0.925\", \"size\": \"20\"}, {\"price\": \"0.92\", \"size\": \"500\"}, {\"price\": \"0.919\", \"size\": \"148\"}, {\"price\": \"0.918\", \"size\": \"182.3\"}, {\"price\": \"0.917\", \"size\": \"20\"}, {\"price\": \"0.915\", \"size\": \"15\"}, {\"price\": \"0.913\", \"size\": \"62.7\"}, {\"price\": \"0.911\", \"size\": \"30.29\"}, {\"price\": \"0.91\", \"size\": \"15\"}], \"tick_size\": \"0.001\", \"event_type\": \"book\", \"last_trade_price\": \"0.888\"}]", "trimmed": true}
{"recv_ts": 1785928837.7937706, "raw": "{\"market\":\"0x5f6237736dc11d27fba4fad4fb25f99efd989f317b526ea34e3389aed21e9989\",\"price_changes\":[{\"asset_id\":\"37621045142846649045567920410637528745565882107360712540945877385602345149225\",\"price\":\"0.033\",\"size\":\"0\",\"side\":\"BUY\",\"hash\":\"34e64db5816b8fbe4c50dc1fb342a6b5fac78d17\",\"best_bid\":\"0.034\",\"best_ask\":\"0.065\"},{\"asset_id\":\"43057741765998250782966918529553157356197931933657738370765235809855474471330\",\"price\":\"0.967\",\"size\":\"0\",\"side\":\"SELL\",\"hash\":\"3b541e11ef0eab574cbbc5149507c5c7898d10bc\",\"best_bid\":\"0.935\",\"best_ask\":\"0.966\"}],\"timestamp\":\"1785928837682\",\"event_type\":\"price_change\"}"}
{"recv_ts": 1785928837.7937949, "raw": "{\"market\":\"0xbb56f84320f6a322405d2a673ae1c09791696dfee009c8b4924a4d50ce02fdb2\",\"price_changes\":[{\"asset_id\":\"36752791203026604630773349263680321016807027579769857760609995963265445842019\",\"price\":\"0.877\",\"size\":\"10\",\"side\":\"BUY\",\"hash\":\"4851a988855fda099c24fa40d9efc64729223404\",\"best_bid\":\"0.95\",\"best_ask\":\"0.962\"},{\"asset_id\":\"3419269731159625127662380738887584521691084977785981284355622556812487764723\",\"price\":\"0.123\",\"size\":\"10\",\"side\":\"SELL\",\"hash\":\"d440041ed3f19d64f6dded1cc5d0f4ccd4e90686\",\"best_bid\":\"0.038\",\"best_ask\":\"0.05\"}],\"timestamp\":\"1785928837690\",\"event_type\":\"price_change\"}"}
{"recv_ts": 1785928837.7938063, "raw": "{\"market\":\"0xbb56f84320f6a322405d2a673ae1c09791696dfee009c8b4924a4d50ce02fdb2\",\"price_changes\":[{\"asset_id\":\"36752791203026604630773349263680321016807027579769857760609995963265445842019\",\"price\":\"0.921\",\"size\":\"10\",\"side\":\"BUY\",\"hash\":\"eddf97e327264237f2a26fc841bdb80c127ac903\",\"best_bid\":\"0.95\",\"best_ask\":\"0.962\"},{\"asset_id\":\"3419269731159625127662380738887584521691084977785981284355622556812487764723\",\"price\":\"0.079\",\"size\":\"10\",\"side\":\"SELL\",\"hash\":\"903d78df12872c966c86f0c78424626eacb56725\",\"best_bid\":\"0.038\",\"best_ask\":\"0.05\"}],\"timestamp\":\"1785928837691\",\"event_type\":\"price_change\"}"}
{"recv_ts": 1785928837.7938159, "raw": "{\"market\":\"0x4512b933a9db0969b4b59da732a7ff680b1d4e70fac45f88f3a1facc43f2523e\",\"price_changes\":[{\"asset_id\":\"98872378845946591857653676545426042456944570976171616154698795008512748360577\",\"price\":\"0.8\",\"size\":\"149.31\",\"side\":\"BUY\",\"hash\":\"2af568f09db18fe06679fd1011da16df78acd791\",\"best_bid\":\"0.8\",\"best_ask\":\"0.85\"},{\"asset_id\":\"31838063725681317376481701458052352932946613073431683458045098239850815645330\",\"price\":\"0.2\",\"size\":\"149.31\",\"side\":\"SELL\",\"hash\":\"cad81c2fff68c1ec81711109031c041d8b94d8e6\",\"best_bid\":\"0.15\",\"best_ask\":\"0.2\"}],\"timestamp\":\"1785928837695\",\"event_type\":\"price_change\"}"}
{"recv_ts": 1785928837.7938254, "raw": "{\"market\":\"0x4512b933a9db0969b4b59da732a7ff680b1d4e70fac45f88f3a1facc43f2523e\",\"price_changes\":[{\"asset_id\":\"98872378845946591857653676545426042456944570976171616154698795008512748360577\",\"price\":\"0.79\",\"size\":\"89\",\"side\":\"BUY\",\"hash\":\"061cd89e713a03046b811daed83caff6cf42abb3\",\"best_bid\":\"0.8\",\"best_ask\":\"0.85\"},{\"asset_id\":\"31838063725681317376481701458052352932946613073431683458045098239850815645330\",\"price\":\"0.21\",\"size\":\"89\",\"side\":\"SELL\",\"hash\":\"e9cbbcf05773547070c27fbf9a3f3bf5c14e86f3\",\"best_bid\":\"0.15\",\"best_ask\":\"0.2\"}],\"timestamp\":\"1785928837696\",\"event_type\":\"price_change\"}"}
{"recv_ts": 1785928837.7938337, "raw": "{\"market\":\"0x3d599811fafbd9ed7c781ff5c2084e4d32929c3df4d3cbd10f3a072853f1510a\",\"price_changes\":[{\"asset_id\":\"70223841871640107339851594952167293228967975377245249405718766178654823372458\",\"price\":\"0.08\",\"size\":\"1030\",\"side\":\"BUY\",\"hash\":\"6851f4b5622719f815b11935e2a3f708d72e361c\",\"best_bid\":\"0.33\",\"best_ask\":\"0.34\"},{\"asset_id\":\"39872822665422331722126808510093325993074587475855865128217288039882162116852\",\"price\":\"0.92\",\"size\":\"1030\",\"side\":\"SELL\",\"hash\":\"4c4c22422c30c4223f16e1a8a17fa61cec0753b5\",\"best_bid\":\"0.66\",\"best_ask\":\"0.67\"}],\"timestamp\":\"1785928837712\",\"event_type\":\"price_change\"}"}
{"recv_ts": 1785928837.7938418, "raw": "{\"market\":\"0xbb56f84320f6a322405d2a673ae1c09791696dfee009c8b4924a4d50ce02fdb2\",\"price_changes\":[{\"asset_id\":\"36752791203026604630773349263680321016807027579769857760609995963265445842019\",\"price\":\"0.918\",\"size\":\"15\",\"side\":\"BUY\",\"hash\":\"30e9996d939ac1ef568f10528386476d5a11181f\",\"best_bid\":\"0.95\",\"best_ask\":\"0.962\"},{\"asset_id\":\"3419269731159625127662380738887584521691084977785981284355622556812487764723\",\"price\":\"0.082\",\"size\":\"15\",\"side\":\"SELL\",\"hash\":\"3127eb1e5003ee16ed80d4b8598ab251494266a2\",\"best_bid\":\"0.038\",\"best_ask\":\"0.05\"}],\"timestamp\":\"1785928837717\",\"event_type\":\"price_change\"}"}
{"recv_ts": 1785928837.7938497, "raw": "{\"market\":\"0xbb56f84320f6a322405d2a673ae1c09791696dfee009c8b4924a4d50ce02fdb2\",\"price_changes\":[{\"asset_id\":\"36752791203026604630773349263680321016807027579769857760609995963265445842019\",\"price\":\"0.895\",\"size\":\"0\",\"side\":\"BUY\",\"hash\":\"30e9996d939ac1ef568f10528386476d5a11181f\",\"best_bid\":\"0.95\",\"best_ask\":\"0.962\"},{\"asset_id\":\"3419269731159625127662380738887584521691084977785981284355622556812487764723\",\"price\":\"0.105\",\"size\":\"0\",\"side\":\"SELL\",\"hash\":\"3127eb1e5003ee16ed80d4b8598ab251494266a2\",\"best_bid\":\"0.038\",\"best_ask\":\"0.05\"}],\"timestamp\":\"1785928837717\",\"event_type\":\"price_change\"}"}
{"recv_ts": 1785928837.7938576, "raw": "{\"market\":\"0x4b959bd9bc39d1321bc264d21815082d73fd8176e1218948651ead19001c2ff5\",\"price_changes\":[{\"asset_id\":\"23344010238883776795639253579533159249437038757669835327945706874615371790413\",\"price\":\"0.1\",\"size\":\"170\",\"side\":\"BUY\",\"hash\":\"f5eabedd5df888497b653c6ecc33772ed42253b5\",\"best_bid\":\"0.23\",\"best_ask\":\"0.24\"},{\"asset_id\":\"56671383017775735882085145016122187056132073409050311382574709367545431858326\",\"price\":\"0.9\",\"size\":\"170\",\"side\":\"SELL\",\"hash\":\"5b08330bb3bbfd574dcff12def86a571e935235f\",\"best_bid\":\"0.76\",\"best_ask\":\"0.77\"}],\"timestamp\":\"1785928837718\",\"event_type\":\"price_change\"}"}
{"recv_ts": 1785928837.793865, "raw": "{\"market\":\"0x3d599811fafbd9ed7c781ff5c2084e4d32929c3df4d3cbd10f3a072853f1510a\",\"price_changes\":[{\"asset_id\":\"70223841871640107339851594952167293228967975377245249405718766178654823372458\",\"price\":\"0.09\",\"size\":\"1036.36\",\"side\":\"BUY\",\"hash\":\"f9f2ccf13b3548e3c6efef89bee4d8706127ea63\",\"best_bid\":\"0.33\",\"best_ask\":\"0.34\"},{\"asset_id\":\"39872822665422331722126808510093325993074587475855865128217288039882162116852\",\"price\":\"0.91\",\"size\":\"1036.36\",\"side\":\"SELL\",\"hash\":\"d49278693932b5eeac0210e288f93b55257445e7\",\"best_bid\":\"0.66\",\"best_ask\":\"0.67\"}],\"timestamp\":\"1785928837719\",\"event_type\":\"price_change\"}"}
{"recv_ts": 1785928837.7938743, "raw": "{\"market\":\"0x5f6237736dc11d27fba4fad4fb25f99efd989f317b526ea34e3389aed21e9989\",\"price_changes\":[{\"asset_id\":\"37621045142846649045567920410637528745565882107360712540945877385602345149225\",\"price\":\"0.035\",\"size\":\"10\",\"side\":\"BUY\",\"hash\":\"fdb9289ae645333bcfecc154b252de38a6b24293\",\"best_bid\":\"0.035\",\"best_ask\":\"0.065\"},{\"asset_id\":\"43057741765998250782966918529553157356197931933657738370765235809855474471330\",\"price\":\"0.965\",\"size\":\"10\",\"side\":\"SELL\",\"hash\":\"0a6e6056f8813e310cad42f2466cb46d2e121909\",\"best_bid\":\"0.935\",\"best_ask\":\"0.965\"}],\"timestamp\":\"1785928837726\",\"event_type\":\"price_change\"}"}
{"recv_ts": 1785928837.7938845, "raw": "{\"market\":\"0xacfb1f9430d7822ad49df7f00b5d5ad30436a36e0ee4768509733803b86f6bde\",\"price_changes\":[{\"asset_id\":\"98813182023375644089780797211542701893611310921152077130269404348554395965484\",\"price\":\"0.655\",\"size\":\"0\",\"side\":\"BUY\",\"hash\":\"dead142ac8c2c8dbcd7a94e71bddc75c060ae4a2\",\"best_bid\":\"0.99\",\"best_ask\":\"0.996\"},{\"asset_id\":\"15319820116799641547006945015418076643372833899913092209131586892482243785946\",\"price\":\"0.345\",\"size\":\"0\",\"side\":\"SELL\",\"hash\":\"855d7852490f75d5d9935fe9fa2e5b0683ee5032\",\"best_bid\":\"0.004\",\"best_ask\":\"0.01\"}],\"timestamp\":\"1785928837751\",\"event_type\":\"price_change\"}"}
{"recv_ts": 1785928837.7939115, "raw": "{\"market\":\"0xbb56f84320f6a322405d2a673ae1c09791696dfee009c8b4924a4d50ce02fdb2\",\"price_changes\":[{\"asset_id\":\"36752791203026604630773349263680321016807027579769857760609995963265445842019\",\"price\":\"0.922\",\"size\":\"8\",\"side\":\"BUY\",\"hash\":\"3f90f2fb901b785bdbbe881c758e5d63203a4df7\",\"best_bid\":\"0.95\",\"best_ask\":\"0.962\"},{\"asset_id\":\"3419269731159625127662380738887584521691084977785981284355622556812487764723\",\"price\":\"0.078\",\"size\":\"8\",\"side\":\"SELL\",\"hash\":\"67925de1eb0d15b66534822d79b6a970eb33e66e\",\"best_bid\":\"0.038\",\"best_ask\":\"0.05\"}],\"timestamp\":\"1785928837754\",\"event_type\":\"price_change\"}"}
{"recv_ts": 1785928837.7939193, "raw": "{\"market\":\"0xbb56f84320f6a322405d2a673ae1c09791696dfee009c8b4924a4d50ce02fdb2\",\"price_changes\":[{\"asset_id\":\"36752791203026604630773349263680321016807027579769857760609995963265445842019\",\"price\":\"0.902\",\"size\":\"13\",\"side\":\"BUY\",\"hash\":\"edb98017daf1d63098c241fa210e6c71792f04b0\",\"best_bid\":\"0.95\",\"best_ask\":\"0.962\"},{\"asset_id\":\"3419269731159625127662380738887584521691084977785981284355622556812487764723\",\"price\":\"0.098\",\"size\":\"13\",\"side\":\"SELL\",\"hash\":\"a49dadd41766cc6e0101d5651c88faac2ad6c114\",\"best_bid\":\"0.038\",\"best_ask\":\"0.05\"}],\"timestamp\":\"1785928837754\",\"event_type\":\"price_change\"}"}
{"recv_ts": 1785928837.793926, "raw": "{\"market\":\"0xacfb1f9430d7822ad49df7f00b5d5ad30436a36e0ee4768509733803b86f6bde\",\"price_changes\":[{\"asset_id\":\"98813182023375644089780797211542701893611310921152077130269404348554395965484\",\"price\":\"0.658\",\"size\":\"400\",\"side\":\"BUY\",\"hash\":\"f670c6ba7de0be956819235c94716248896541d2\",\"best_bid\":\"0.99\",\"best_ask\":\"0.996\"},{\"asset_id\":\"15319820116799641547006945015418076643372833899913092209131586892482243785946\",\"price\":\"0.342\",\"size\":\"400\",\"side\":\"SELL\",\"hash\":\"32fbffdd8d0d7a11b8408d72025b73b9bdfabf26\",\"best_bid\":\"0.004\",\"best_ask\":\"0.01\"}],\"timestamp\":\"1785928837772\",\"event_type\":\"price_change\"}"}
{"recv_ts": 1785928837.7940824, "raw": "[{\"market\": \"0xcaeb64fab1b281ad2ebdb53b77166eed7a60b543db0dec7501f714d9d2cd144c\", \"asset_id\": \"109915262498339412306695336145369839628188647814984475353957247847278720214941\", \"timestamp\": \"1785928820810\", \"hash\": \"4fccfb3760ad72fd22674590ffbfa25a73acc67e\", \"bids\": [{\"price\": \"0.01\", \"size\": \"92.59\"}, {\"price\": \"0.02\", \"size\": \"17.27\"}, {\"price\": \"0.03\", \"size\": \"186\"}, {\"price\": \"0.04\", \"size\": \"160\"}, {\"price\": \"0.05\", \"size\": \"227\"}, {\"price\": \"0.06\", \"size\": \"90.8\"}, {\"price\": \"0.07\", \"size\": \"40\"}, {\"price\": \"0.15\", \"size\": \"30\"}, {\"price\": \"0.38\", \"size\": \"6.77\"}, {\"price\": \"0.43\", \"size\": \"64\"}, {\"price\": \"0.52\", \"size\": \"46.47\"}, {\"price\": \"0.53\", \"size\": \"5\"}, {\"price\": \"0.54\", \"size\": \"10\"}, {\"price\": \"0.55\", \"size\": \"133\"}, {\"price\": \"0.57\", \"size\": \"20\"}, {\"price\": \"0.59\", \"size\": \"25\"}, {\"price\": \"0.6\", \"size\": \"8\"}, {\"price\": \"0.61\", \"size\": \"7\"}], \"asks\": [{\"price\": \"0.99\", \"size\": \"197.4\"}, {\"price\": \"0.98\", \"size\": \"298.96\"}, {\"price\": \"0.97\", \"size\": \"28.97\"}, {\"price\": \"0.96\", \"size\": \"130\"}, {\"price\": \"0.95\", \"size\": \"162\"}, {\"price\": \"0.94\", \"size\": \"33.33\"}, {\"price\": \"0.93\", \"size\": \"5.68\"}, {\"price\": \"0.92\", \"size\": \"25\"}, {\"price\": \"0.9\", \"size\": \"20\"}, {\"price\": \"0.88\", \"size\": \"16.66\"}, {\"price\": \"0.87\", \"size\": \"30\"}, {\"price\": \"0.86\", \"size\": \"20.08\"}, {\"price\": \"0.84\", \"size\": \"12.5\"}, {\"price\": \"0.82\", \"size\": \"111.11\"}, {\"price\": \"0.81\", \"size\": \"20\"}, {\"price\": \"0.8\", \"size\": \"5\"}, {\"price\": \"0.78\", \"size\": \"9.09\"}, {\"price\": \"0.76\", \"size\": \"58.33\"}, {\"price\": \"0.75\", \"size\": \"75\"}, {\"price\": \"0.74\", \"size\": \"40\"}, {\"price\": \"0.73\", \"size\": \"15\"}, {\"price\": \"0.7\", \"size\": \"15\"}, {\"price\": \"0.69\", \"size\": \"8\"}, {\"price\": \"0.68\", \"size\": \"33\"}, {\"price\": \"0.67\", \"size\": \"8\"}], \"tick_size\": \"0.01\", \"event_type\": \"book\", \"last_trade_price\": \"0.310\"}, {\"market\": \"0xd1cf3f92fcea8667e2d295d927dad31c3676293f9253afd2c2460179fd1e19a6\", \"asset_id\": \"89050521382996286162473549073225482396447119787012619824763376176963890411797\", \"timestamp\": \"1785928830738\", \"hash\": \"18b5897aa7396539b52aaf34987f73ca75928d38\", \"bids\": [], \"asks\": [{\"price\": \"0.999\", \"size\": \"1124.17\"}, {\"price\": \"0.998\", \"size\": \"7.98\"}, {\"price\": \"0.997\", \"size\": \"1000\"}, {\"price\": \"0.996\", \"size\": \"9.71\"}, {\"price\": \"0.99\", \"size\": \"120\"}, {\"price\": \"0.989\", \"size\": \"6.13\"}, {\"price\": \"0.98\", \"size\": \"60\"}, {\"price\": \"0.979\", \"size\": \"824\"}, {\"price\": \"0.977\", \"size\": \"800\"}, {\"price\": \"0.976\", \"size\": \"30\"}, {\"price\": \"0.975\", \"size\": \"5.21\"}, {\"price\": \"0.97\", \"size\": \"10\"}, {\"price\": \"0.96\", \"size\": \"100\"}, {\"price\": \"0.95\", \"size\": \"10\"}, {\"price\": \"0.94\", \"size\": \"16.66\"}, {\"price\": \"0.939\", \"size\": \"5.65\"}, {\"price\": \"0.92\", \"size\": \"12.5\"}, {\"price\": \"0.9\", \"size\": \"10\"}, {\"price\": \"0.88\", \"size\": \"8.33\"}, {\"price\": \"0.86\", \"size\": \"7.14\"}, {\"price\": \"0.84\", \"size\": \"6.25\"}, {\"price\": \"0.82\", \"size\": \"5.55\"}, {\"price\": \"0.819\", \"size\": \"5.49\"}, {\"price\": \"0.8\", \"size\": \"5\"}, {\"price\": \"0.78\", \"size\": \"9.09\"}, {\"price\": \"0.76\", \"size\": \"8.33\"}, {\"price\": \"0.75\", \"size\": \"10\"}, {\"price\": \"0.74\", \"size\": \"157.68\"}, {\"price\": \"0.739\", \"size\": \"63.07\"}, {\"price\": \"0.72\", \"size\": \"7.14\"}, {\"price\": \"0.7\", \"size\": \"6.66\"}, {\"price\": \"0.68\", \"size\": \"6.25\"}, {\"price\": \"0.66\", \"size\": \"5.88\"}, {\"price\": \"0.658\", \"size\": \"30\"}, {\"price\": \"0.65\", \"size\": \"10\"}, {\"price\": \"0.649\", \"size\": \"100\"}, {\"price\": \"0.64\", \"size\": \"5.55\"}, {\"price\": \"0.639\", \"size\": \"20\"}, {\"price\": \"0.62\", \"size\": \"5.26\"}, {\"price\": \"0.6\", \"size\": \"5\"}, {\"price\": \"0.58\", \"size\": \"7.14\"}, {\"price\": \"0.56\", \"size\": \"6.81\"}, {\"price\": \"0.54\", \"size\": \"6.52\"}, {\"price\": \"0.52\", \"size\": \"6.25\"}, {\"price\": \"0.519\", \"size\": \"50\"}, {\"price\": \"0.18\", \"size\": \"10\"}, {\"price\": \"0.179\", \"size\": \"30\"}, {\"price\": \"0.1\", \"size\": \"57\"}, {\"price\": \"0.099\", \"size\": \"20\"}, {\"price\": \"0.07\", \"size\": \"10\"}, {\"price\": \"0.06\", \"size\": \"19.99\"}, {\"price\": \"0.05\", \"size\": \"32\"}, {\"price\": \"0.048\", \"size\": \"15\"}, {\"price\": \"0.02\", \"size\": \"30\"}, {\"price\": \"0.01\", \"size\": \"101\"}, {\"price\": \"0.009\", \"size\": \"99.99\"}, {\"price\": \"0.004\", \"size\": \"53.82\"}, {\"price\": \"0.002\", \"size\": \"310.73\"}, {\"price\": \"0.001\", \"size\": \"124.95\"}], \"tick_size\": \"0.001\", \"event_type\": \"book\", \"last_trade_price\": \"\"}, {\"market\": \"0x0f6cecfeb872037c95e2916bde80e549d27bb6ec1504beb245f1cbd2ff06669d\", \"asset_id\": \"60557715916542181216983386820096353369657838558233215685669780898477903523883\", \"timestamp\": \"1785928823219\", \"hash\": \"0d0869924f87c3333779db6e9063876d9b5659c9\", \"bids\": [], \"asks\": [{\"price\": \"0.999\", \"size\": \"130.17\"}, {\"price\": \"0.998\", \"size\": \"53.86\"}, {\"price\": \"0.99\", \"size\": \"2920\"}, {\"price\": \"0.989\", \"size\": \"1168\"}, {\"price\": \"0.988\", \"size\": \"6.07\"}, {\"price\": \"0.98\", \"size\": \"60\"}, {\"price\": \"0.979\", \"size\": \"830.53\"}, {\"price\": \"0.977\", \"size\": \"800\"}, {\"price\": \"0.976\", \"size\": \"30\"}, {\"price\": \"0.97\", \"size\": \"10\"}, {\"price\": \"0.96\", \"size\": \"100\"}, {\"price\": \"0.95\", \"size\": \"10\"}, {\"price\": \"0.94\", \"size\": \"16.67\"}, {\"price\": \"0.92\", \"size\": \"12.5\"}, {\"price\": \"0.9\", \"size\": \"10\"}, {\"price\": \"0.899\", \"size\": \"5.45\"}, {\"price\": \"0.89\", \"size\": \"263.63\"}, {\"price\": \"0.889\", \"size\": \"105.45\"}, {\"price\": \"0.88\", \"size\": \"8.33\"}, {\"price\": \"0.86\", \"size\": \"7.14\"}, {\"price\": \"0.84\", \"size\": \"6.25\"}, {\"price\": \"0.82\", \"size\": \"5.56\"}, {\"price\": \"0.79\", \"size\": \"138.09\"}, {\"price\": \"0.75\", \"size\": \"35\"}, {\"price\": \"0.749\", \"size\": \"5.67\"}, {\"price\": \"0.69\", \"size\": \"93.54\"}, {\"price\": \"0.65\", \"size\": \"35\"}, {\"price\": \"0.59\", \"size\": \"70.73\"}, {\"price\": \"0.49\", \"size\": \"56.86\"}, {\"price\": \"0.39\", \"size\": \"47.54\"}, {\"price\": \"0.29\", \"size\": \"40.84\"}, {\"price\": \"0.289\", \"size\": \"100\"}, {\"price\": \"0.2\", \"size\": \"36.25\"}, {\"price\": \"0.19\", \"size\": \"35.8\"}, {\"price\": \"0.18\", \"size\": \"35.36\"}, {\"price\": \"0.17\", \"size\": \"34.93\"}, {\"price\": \"0.16\", \"size\": \"34.52\"}, {\"price\": \"0.15\", \"size\": \"34.11\"}, {\"price\": \"0.149\", \"size\": \"50\"}, {\"price\": \"0.14\", \"size\": \"33.72\"}, {\"price\": \"0.139\", \"size\": \"20\"}, {\"price\": \"0.13\", \"size\": \"33.33\"}, {\"price\": \"0.129\", \"size\": \"30\"}, {\"price\": \"0.12\", \"size\": \"32.95\"}, {\"price\": \"0.11\", \"size\": \"32.58\"}, {\"price\": \"0.1\", \"size\": \"39.22\"}, {\"price\": \"0.09\", \"size\": \"61.86\"}, {\"price\": \"0.08\", \"size\": \"31.52\"}, {\"price\": \"0.07\", \"size\": \"31.18\"}, {\"price\": \"0.069\", \"size\": \"10\"}, {\"price\": \"0.06\", \"size\": \"60.85\"}, {\"price\": \"0.05\", \"size\": \"62.52\"}, {\"price\": \"0.04\", \"size\": \"30.2\"}, {\"price\": \"0.03\", \"size\": \"104.89\"}, {\"price\": \"0.025\", \"size\": \"34.74\"}, {\"price\": \"0.02\", \"size\": \"49.59\"}, {\"price\": \"0.015\", \"size\": \"29.44\"}, {\"price\": \"0.01\", \"size\": \"49.29\"}, {\"price\": \"0.007\", \"size\": \"420\"}, {\"price\": \"0.005\", \"size\": \"420\"}, {\"price\": \"0.004\", \"size\": \"50\"}, {\"price\": \"0.003\", \"size\": \"146.52\"}], \"tick_size\": \"0.001\", \"event_type\": \"book\", \"last_trade_price\": \"0.999\"}, {\"market\": \"0x3f3a671e3d1cef7655aecd0f166f850a17bd28fe7b72b90093490573a2994fd6\", \"asset_id\": \"7198044372093534297099777223469037893681954943362222765603378818037027165671\", \"timestamp\": \"1785928830281\", \"hash\": \"f661433ae338b013677a991b151dafe787653c0e\", \"bids\": [], \"asks\": [{\"price\": \"0.999\", \"size\": \"1130.51\"}, {\"price\": \"0.997\", \"size\": \"1008.23\"}, {\"price\": \"0.995\", \"size\": \"12.31\"}, {\"price\": \"0.99\", \"size\": \"50\"}, {\"price\": \"0.989\", \"size\": \"7.47\"}, {\"price\": \"0.98\", \"size\": \"50\"}, {\"price\": \"0.979\", \"size\": \"820\"}, {\"price\": \"0.977\", \"size\": \"800\"}, {\"price\": \"0.976\", \"size\": \"90\"}, {\"price\": \"0.975\", \"size\": \"6.48\"}, {\"price\": \"0.97\", \"size\": \"20\"}, {\"price\": \"0.96\", \"size\": \"80\"}, {\"price\": \"0.95\", \"size\": \"50\"}, {\"price\": \"0.949\", \"size\": \"7.33\"}, {\"price\": \"0.94\", \"size\": \"7\"}, {\"price\": \"0.939\", \"size\": \"6.93\"}, {\"price\": \"0.87\", \"size\": \"30\"}, {\"price\": \"0.85\", \"size\": \"5\"}, {\"price\": \"0.849\", \"size\": \"100\"}, {\"price\": \"0.75\", \"size\": \"80\"}, {\"price\": \"0.749\", \"size\": \"5.76\"}, {\"price\": \"0.7\", \"size\": \"20\"}, {\"price\": \"0.65\", \"size\": \"10\"}, {\"price\": \"0.648\", \"size\": \"50\"}, {\"price\": \"0.647\", \"size\": \"50\"}, {\"price\": \"0.5\", \"size\": \"5\"}, {\"price\": \"0.45\", \"size\": \"10\"}, {\"price\": \"0.449\", \"size\": \"30\"}, {\"price\": \"0.342\", \"size\": \"49.99\"}, {\"price\": \"0.3\", \"size\": \"5\"}, {\"price\": \"0.29\", \"size\": \"5\"}, {\"price\": \"0.28\", \"size\": \"5\"}, {\"price\": \"0.27\", \"size\": \"5\"}, {\"price\": \"0.26\", \"size\": \"5\"}, {\"price\": \"0.25\", \"size\": \"5\"}, {\"price\": \"0.24\", \"size\": \"5\"}, {\"price\": \"0.23\", \"size\": \"5\"}, {\"price\": \"0.22\", \"size\": \"5\"}, {\"price\": \"0.21\", \"size\": \"5\"}, {\"price\": \"0.2\", \"size\": \"5\"}, {\"price\": \"0.19\", \"size\": \"5\"}, {\"price\": \"0.18\", \"size\": \"5\"}, {\"price\": \"0.17\", \"size\": \"5\"}, {\"price\": \"0.16\", \"size\": \"5\"}, {\"price\": \"0.15\", \"size\": \"15\"}, {\"price\": \"0.14\", \"size\": \"25\"}, {\"price\": \"0.13\", \"size\": \"5\"}, {\"price\": \"0.12\", \"size\": \"5\"}, {\"price\": \"0.119\", \"size\": \"10\"}, {\"price\": \"0.11\", \"size\": \"12\"}, {\"price\": \"0.1\", \"size\": \"205\"}, {\"price\": \"0.09\", \"size\": \"5\"}, {\"price\": \"0.08\", \"size\": \"58.47\"}, {\"price\": \"0.07\", \"size\": \"5\"}, {\"price\": \"0.06\", \"size\": \"5\"}, {\"price\": \"0.052\", \"size\": \"50\"}, {\"price\": \"0.05\", \"size\": \"57\"}, {\"price\": \"0.047\", \"size\": \"15\"}, {\"price\": \"0.04\", \"size\": \"25\"}, {\"price\": \"0.039\", \"size\": \"10\"}, {\"price\": \"0.03\", \"size\": \"5\"}, {\"price\": \"0.022\", \"size\": \"37\"}, {\"price\": \"0.02\", \"size\": \"125\"}, {\"price\": \"0.018\", \"size\": \"11.03\"}, {\"price\": \"0.015\", \"size\": \"30\"}, {\"price\": \"0.013\", \"size\": \"36.24\"}, {\"price\": \"0.01\", \"size\": \"73\"}, {\"price\": \"0.009\", \"size\": \"16\"}, {\"price\": \"0.008\", \"size\": \"10\"}, {\"price\": \"0.007\", \"size\": \"10\"}, {\"price\": \"0.006\", \"size\": \"10\"}, {\"price\": \"0.005\", \"size\": \"394\"}, {\"price\": \"0.004\", \"size\": \"2484.99\"}, {\"price\": \"0.003\", \"size\": \"3103.31\"}, {\"price\": \"0.002\", \"size\": \"6939.22\"}, {\"price\": \"0.001\", \"size\": \"20699.21\"}], \"tick_size\": \"0.001\", \"event_type\": \"book\", \"last_trade_price\": \"0.001\"}]", "trimmed": true}
{"recv_ts": 1785928837.8018816, "raw": "{\"market\":\"0x8c6a64a8ffd1bfa3d7df81172f976764a2c52c87c1a093897f90b7217d6fea8d\",\"price_changes\":[{\"asset_id\":\"13409836330652892121423735936121472669640499078426321052185227972804816382422\",\"price\":\"0.93\",\"size\":\"0\",\"side\":\"SELL\",\"hash\":\"03d959e01b781c11f1d0e6ca6e8847a7729028d2\",\"best_bid\":\"0.908\",\"best_ask\":\"0.929\"},{\"asset_id\":\"83715211686534593705683144614374080403915454453849238224332560479040502634509\",\"price\":\"0.07\",\"size\":\"0\",\"side\":\"BUY\",\"hash\":\"fe2a042a5b8630e87557eba8d0ecde5a62893219\",\"best_bid\":\"0.071\",\"best_ask\":\"0.092\"}],\"timestamp\":\"1785928837618\",\"event_type\":\"price_change\"}"}
{"recv_ts": 1785928837.8018987, "raw": "{\"market\":\"0x89c7724f3b62e3ab90a09446ce9d227b12256ff8394964632d526f43a78b7335\",\"price_changes\":[{\"asset_id\":\"92983668663345506902995400696313739779072274038684129210212536869513542163808\",\"price\":\"0.58\",\"size\":\"15\",\"side\":\"BUY\",\"hash\":\"36b5f324c693120b331d1336cab9674971ee4fe7\",\"best_bid\":\"0.72\",\"best_ask\":\"0.74\"},{\"asset_id\":\"56159363116939983418834290083111492269169015762086846151246482515480802429423\",\"price\":\"0.42\",\"size\":\"15\",\"side\":\"SELL\",\"hash\":\"918a0cfd49b3f6f6edf0edb3b9aca7d63c4720c6\",\"best_bid\":\"0.26\",\"best_ask\":\"0.28\"}],\"timestamp\":\"1785928837630\",\"event_type\":\"price_change\"}"}
{"recv_ts": 1785928837.8019085, "raw": "{\"market\":\"0x8c6a64a8ffd1bfa3d7df81172f976764a2c52c87c1a093897f90b7217d6fea8d\",\"price_changes\":[{\"asset_id\":\"13409836330652892121423735936121472669640499078426321052185227972804816382422\",\"price\":\"0.928\",\"size\":\"10\",\"side\":\"SELL\",\"hash\":\"c6680ae212812e56e59f0d75d8dabc9358f7f89e\",\"best_bid\":\"0.908\",\"best_ask\":\"0.928\"},{\"asset_id\":\"83715211686534593705683144614374080403915454453849238224332560479040502634509\",\"price\":\"0.072\",\"size\":\"10\",\"side\":\"BUY\",\"hash\":\"f15fd1a2451c06586b825743d981d1d5c39c3a69\",\"best_bid\":\"0.072\",\"best_ask\":\"0.092\"}],\"timestamp\":\"1785928837666\",\"event_type\":\"price_change\"}"}
{"recv_ts": 1785928837.8019176, "raw": "{\"market\":\"0x8c6a64a8ffd1bfa3d7df81172f976764a2c52c87c1a093897f90b7217d6fea8d\",\"price_changes\":[{\"asset_id\":\"83715211686534593705683144614374080403915454453849238224332560479040502634509\",\"price\":\"0.061\",\"size\":\"5\",\"side\":\"BUY\",\"hash\":\"088bac2aad78cf78dfae81bbf5168f877c504582\",\"best_bid\":\"0.072\",\"best_ask\":\"0.092\"},{\"asset_id\":\"13409836330652892121423735936121472669640499078426321052185227972804816382422\",\"price\":\"0.939\",\"size\":\"5\",\"side\":\"SELL\",\"hash\":\"e705dfaaade915edfd6e45ce3dfc82a762f8dab5\",\"best_bid\":\"0.908\",\"best_ask\":\"0.928\"}],\"timestamp\":\"1785928837668\",\"event_type\":\"price_change\"}"}
{"recv_ts": 1785928837.801925, "raw": "{\"market\":\"0x8c6a64a8ffd1bfa3d7df81172f976764a2c52c87c1a093897f90b7217d6fea8d\",\"price_changes\":[{\"asset_id\":\"83715211686534593705683144614374080403915454453849238224332560479040502634509\",\"price\":\"0.071\",\"size\":\"0\",\"side\":\"BUY\",\"hash\":\"e92a2d1fad00ea464e0daaacdef65346c99a0ff3\",\"best_bid\":\"0.072\",\"best_ask\":\"0.092\"},{\"asset_id\":\"13409836330652892121423735936121472669640499078426321052185227972804816382422\",\"price\":\"0.929\",\"size\":\"0\",\"side\":\"SELL\",\"hash\":\"ee59b5e6570cf6b54832a7bc84a97af3a62c564e\",\"best_bid\":\"0.908\",\"best_ask\":\"0.928\"}],\"timestamp\":\"1785928837671\",\"event_type\":\"price_change\"}"}
{"recv_ts": 1785928837.8019316, "raw": "{\"market\":\"0x3b7a898c1f6aaaa06415dd21d9d34e74f709ef2f05cfa115b5f1b86cd52b0764\",\"price_changes\":[{\"asset_id\":\"42368303284040540916454038571075974455220000699401225104058654517066308897985\",\"price\":\"0.83\",\"size\":\"8\",\"side\":\"BUY\",\"hash\":\"77d18aa6f1af3f79be33b9f0ca40896fe00bb9ac\",\"best_bid\":\"0.83\",\"best_ask\":\"0.93\"},{\"asset_id\":\"36729596945295770718451012081770289585140761557194088365274916803472893285218\",\"price\":\"0.17\",\"size\":\"8\",\"side\":\"SELL\",\"hash\":\"e910bc5122357ed047b7345a4770ed891734d26c\",\"best_bid\":\"0.07\",\"best_ask\":\"0.17\"}],\"timestamp\":\"1785928837679\",\"event_type\":\"price_change\"}"}
{"recv_ts": 1785928837.8019388, "raw": "{\"market\":\"0x3b7a898c1f6aaaa06415dd21d9d34e74f709ef2f05cfa115b5f1b86cd52b0764\",\"price_changes\":[{\"asset_id\":\"42368303284040540916454038571075974455220000699401225104058654517066308897985\",\"price\":\"0.77\",\"size\":\"0\",\"side\":\"BUY\",\"hash\":\"05e489cb5ce7b8c136c8962179df3316173607dd\",\"best_bid\":\"0.83\",\"best_ask\":\"0.93\"},{\"asset_id\":\"36729596945295770718451012081770289585140761557194088365274916803472893285218\",\"price\":\"0.23\",\"size\":\"0\",\"side\":\"SELL\",\"hash\":\"96a360585e172e5b2d17d46ed08fec0b6e630643\",\"best_bid\":\"0.07\",\"best_ask\":\"0.17\"}],\"timestamp\":\"1785928837683\",\"event_type\":\"price_change\"}"}
{"recv_ts": 1785928837.801946, "raw": "{\"market\":\"0x3b7a898c1f6aaaa06415dd21d9d34e74f709ef2f05cfa115b5f1b86cd52b0764\",\"price_changes\":[{\"asset_id\":\"42368303284040540916454038571075974455220000699401225104058654517066308897985\",\"price\":\"0.74\",\"size\":\"30\",\"side\":\"BUY\",\"hash\":\"eaa0c5d70af13fff992ed3fdbfa717b526ee7c46\",\"best_bid\":\"0.83\",\"best_ask\":\"0.93\"},{\"asset_id\":\"36729596945295770718451012081770289585140761557194088365274916803472893285218\",\"price\":\"0.26\",\"size\":\"30\",\"side\":\"SELL\",\"hash\":\"fd1ee6eb8a53e4caaea574efb627f15930a2aec2\",\"best_bid\":\"0.07\",\"best_ask\":\"0.17\"}],\"timestamp\":\"1785928837689\",\"event_type\":\"price_change\"}"}
{"recv_ts": 1785928837.8019526, "raw": "{\"market\":\"0x8c6a64a8ffd1bfa3d7df81172f976764a2c52c87c1a093897f90b7217d6fea8d\",\"price_changes\":[{\"asset_id\":\"83715211686534593705683144614374080403915454453849238224332560479040502634509\",\"price\":\"0.06\",\"size\":\"5\",\"side\":\"BUY\",\"hash\":\"715b65a36defff15c140db6c54852bdb04cd992a\",\"best_bid\":\"0.072\",\"best_ask\":\"0.092\"},{\"asset_id\":\"13409836330652892121423735936121472669640499078426321052185227972804816382422\",\"price\":\"0.94\",\"size\":\"5\",\"side\":\"SELL\",\"hash\":\"bf280a5e15b91e484d847be562bd0917512a19a6\",\"best_bid\":\"0.908\",\"best_ask\":\"0.928\"}],\"timestamp\":\"1785928837695\",\"event_type\":\"price_change\"}"}
{"recv_ts": 1785928837.8019593, "raw": "{\"market\":\"0x3b7a898c1f6aaaa06415dd21d9d34e74f709ef2f05cfa115b5f1b86cd52b0764\",\"price_changes\":[{\"asset_id\":\"42368303284040540916454038571075974455220000699401225104058654517066308897985\",\"price\":\"0.79\",\"size\":\"7\",\"side\":\"BUY\",\"hash\":\"8ff2165aa844d228f400f8adc81206a4324b6879\",\"best_bid\":\"0.83\",\"best_ask\":\"0.93\"},{\"asset_id\":\"36729596945295770718451012081770289585140761557194088365274916803472893285218\",\"price\":\"0.21\",\"size\":\"7\",\"side\":\"SELL\",\"hash\":\"4d5ce2e246a80bf2541f0b0ee399b8a52e445f16\",\"best_bid\":\"0.07\",\"best_ask\":\"0.17\"}],\"timestamp\":\"1785928837702\",\"event_type\":\"price_change\"}"}
{"recv_ts": 1785928837.8019662, "raw": "{\"market\":\"0x8c6a64a8ffd1bfa3d7df81172f976764a2c52c87c1a093897f90b7217d6fea8d\",\"price_changes\":[{\"asset_id\":\"83715211686534593705683144614374080403915454453849238224332560479040502634509\",\"price\":\"0.061\",\"size\":\"0\",\"side\":\"BUY\",\"hash\":\"3d677d5488d7e8f90c052ae63e7d4243b8088030\",\"best_bid\":\"0.072\",\"best_ask\":\"0.092\"},{\"asset_id\":\"13409836330652892121423735936121472669640499078426321052185227972804816382422\",\"price\":\"0.939\",\"size\":\"0\",\"side\":\"SELL\",\"hash\":\"2db0078f4e2b39e6c290bf9d782aa2a48a4fd371\",\"best_bid\":\"0.908\",\"best_ask\":\"0.928\"}],\"timestamp\":\"1785928837718\",\"event_type\":\"price_change\"}"}
{"recv_ts": 1785928837.8019726, "raw": "{\"market\":\"0x8c6a64a8ffd1bfa3d7df81172f976764a2c52c87c1a093897f90b7217d6fea8d\",\"price_changes\":[{\"asset_id\":\"83715211686534593705683144614374080403915454453849238224332560479040502634509\",\"price\":\"0.073\",\"size\":\"5\",\"side\":\"BUY\",\"hash\":\"f03f3a9ce266476497afda1124972b18ecc5bb5f\",\"best_bid\":\"0.073\",\"best_ask\":\"0.092\"},{\"asset_id\":\"13409836330652892121423735936121472669640499078426321052185227972804816382422\",\"price\":\"0.927\",\"size\":\"5\",\"side\":\"SELL\",\"hash\":\"06ad666d06911afc91048a9054fa936f3034ba79\",\"best_bid\":\"0.908\",\"best_ask\":\"0.927\"}],\"timestamp\":\"1785928837721\",\"event_type\":\"price_change\"}"}
{"recv_ts": 1785928837.8019955, "raw": "{\"market\":\"0x8c6a64a8ffd1bfa3d7df81172f976764a2c52c87c1a093897f90b7217d6fea8d\",\"price_changes\":[{\"asset_id\":\"83715211686534593705683144614374080403915454453849238224332560479040502634509\",\"price\":\"0.062\",\"size\":\"8\",\"side\":\"BUY\",\"hash\":\"072da492a33e61467ddaebf16744444618aeefe2\",\"best_bid\":\"0.073\",\"best_ask\":\"0.092\"},{\"asset_id\":\"13409836330652892121423735936121472669640499078426321052185227972804816382422\",\"price\":\"0.938\",\"size\":\"8\",\"side\":\"SELL\",\"hash\":\"fde0e982feb2671165c8f8df94e6a4e7c5d81237\",\"best_bid\":\"0.908\",\"best_ask\":\"0.927\"}],\"timestamp\":\"1785928837731\",\"event_type\":\"price_change\"}"}
{"recv_ts": 1785928837.8020024, "raw": "{\"market\":\"0xaabacb4e1b93000a623bf2628d5515b4d37a5fdf1f11de2de24f57901931a745\",\"price_changes\":[{\"asset_id\":\"6559205747794158754228276868872274737030873517974100520323235488983261897392\",\"price\":\"0.999\",\"size\":\"195.69\",\"side\":\"SELL\",\"hash\":\"4068aba58bd26a577af1499ee8d9fb44a1e89080\",\"best_bid\":\"0\",\"best_ask\":\"0.001\"},{\"asset_id\":\"60626789939718658216738957499549134757941715527072567030777579976072072995386\",\"price\":\"0.001\",\"size\":\"195.69\",\"side\":\"BUY\",\"hash\":\"de416dbc3c4f549f15fcaa64e1efd1293b05efef\",\"best_bid\":\"0.999\",\"best_ask\":\"1\"}],\"timestamp\":\"1785928837764\",\"event_type\":\"price_change\"}"}
{"recv_ts": 1785928837.802009, "raw": "{\"market\":\"0x8c6a64a8ffd1bfa3d7df81172f976764a2c52c87c1a093897f90b7217d6fea8d\",\"price_changes\":[{\"asset_id\":\"83715211686534593705683144614374080403915454453849238224332560479040502634509\",\"price\":\"0.062\",\"size\":\"0\",\"side\":\"BUY\",\"hash\":\"2f67f09a8bd26ea5cc96522277a7bb2d130de75d\",\"best_bid\":\"0.073\",\"best_ask\":\"0.092\"},{\"asset_id\":\"13409836330652892121423735936121472669640499078426321052185227972804816382422\",\"price\":\"0.938\",\"size\":\"0\",\"side\":\"SELL\",\"hash\":\"b78907e00f3a618f0be0cba2cdef6436b2ab6737\",\"best_bid\":\"0.908\",\"best_ask\":\"0.927\"}],\"timestamp\":\"1785928837766\",\"event_type\":\"price_change\"}"}
{"recv_ts": 1785928837.802026, "raw": "{\"market\":\"0x0393e451a7889f6472d5099a6de21d1fc6bea6ada01c2e227ea954a8ebce1771\",\"price_changes\":[{\"asset_id\":\"62439955870856164313493799301554574122664268361492077980110236255342893751283\",\"price\":\"0.37\",\"size\":\"65\",\"side\":\"BUY\",\"hash\":\"43806628a536589fa84d957ee9b5618410587152\",\"best_bid\":\"0.914\",\"best_ask\":\"0.944\"},{\"asset_id\":\"19078179119846452574438096789570272099502061228398927027811652354916673625092\",\"price\":\"0.63\",\"size\":\"65\",\"side\":\"SELL\",\"hash\":\"c8b649cc9817eb846ae7e667cf857259ec34da41\",\"best_bid\":\"0.056\",\"best_ask\":\"0.086\"}],\"timestamp\":\"1785928837763\",\"event_type\":\"price_change\"}"}
{"recv_ts": 1785928837.8020344, "raw": "{\"market\":\"0xbf3934dfc014233beda6f87619371f394789219377ce438d38f74870f56c68ea\",\"price_changes\":[{\"asset_id\":\"42024905581146846414507905961735200210462829982661029520878636315857683485217\",\"price\":\"0.73\",\"size\":\"0\",\"side\":\"BUY\",\"hash\":\"f7c416e61e30da08b5ad2cec317d3020c55d13c3\",\"best_bid\":\"0.75\",\"best_ask\":\"0.79\"},{\"asset_id\":\"29398731980061685892494196371571389220920495273593479516382999208418023734255\",\"price\":\"0.27\",\"size\":\"0\",\"side\":\"SELL\",\"hash\":\"56b5829ef61cd1858b248b71bc953c6288c64315\",\"best_bid\":\"0.21\",\"best_ask\":\"0.25\"}],\"timestamp\":\"1785928837767\",\"event_type\":\"price_change\"}"}
{"recv_ts": 1785928837.8020413, "raw": "{\"market\":\"0xc677dc4861ad64799759f9652e6ae0ff53c153057fd6db69af9e84a1ca2197ec\",\"price_changes\":[{\"asset_id\":\"77424084358345472197732445675309267934198319933946934156139630690411297600005\",\"price\":\"0.989\",\"size\":\"0\",\"side\":\"BUY\",\"hash\":\"5af5282976a792d0b70ce59b752e09dbe8aa122d\",\"best_bid\":\"0.998\",\"best_ask\":\"0.999\"},{\"asset_id\":\"45534343227339732590622934884801860571492159958084925751306737519940828376450\",\"price\":\"0.011\",\"size\":\"0\",\"side\":\"SELL\",\"hash\":\"0b9a8f98e1d7114a720c26ff5f978678bc2ff128\",\"best_bid\":\"0.001\",\"best_ask\":\"0.002\"}],\"timestamp\":\"1785928837769\",\"event_type\":\"price_change\"}"}
{"recv_ts": 1785928837.802048, "raw": "{\"market\":\"0x31cc8cc9d1b3dbdc5219e0319a01ded09ad0c18296c8f27bc76b1f12364a4661\",\"price_changes\":[{\"asset_id\":\"51223233815348005431570032441325849255204346210650700628294623504463311020670\",\"price\":\"0.22\",\"size\":\"0\",\"side\":\"BUY\",\"hash\":\"26e1ab80a331b64bee1746b0007024535259dfcf\",\"best_bid\":\"0.26\",\"best_ask\":\"0.43\"},{\"asset_id\":\"36593914907192135817908362063800584939108275837285837232090830833195276003888\",\"price\":\"0.78\",\"size\":\"0\",\"side\":\"SELL\",\"hash\":\"85bcf14ded3c167b71fd51d2a44a7c0b62d04e68\",\"best_bid\":\"0.57\",\"best_ask\":\"0.74\"}],\"timestamp\":\"1785928837770\",\"event_type\":\"price_change\"}"}
{"recv_ts": 1785928837.8020544, "raw": "{\"market\":\"0x9564d81934c1550b627ff159cc139675d7d08916fa74cc4aaf8d416e4bedd807\",\"price_changes\":[{\"asset_id\":\"46123186009598106104671689617421295270790145953546842072887829618094075293472\",\"price\":\"0.05\",\"size\":\"90\",\"side\":\"BUY\",\"hash\":\"eb949fa7758ba1231d1b846d941778b8175abcc7\",\"best_bid\":\"0.48\",\"best_ask\":\"0.74\"},{\"asset_id\":\"33275922446271605474639218893344378139793083231796398469699104729778621445854\",\"price\":\"0.95\",\"size\":\"90\",\"side\":\"SELL\",\"hash\":\"e7716ef24cd566abda75b294e024a88a46203db6\",\"best_bid\":\"0.26\",\"best_ask\":\"0.52\"}],\"timestamp\":\"1785928837770\",\"event_type\":\"price_change\"}"}
{"recv_ts": 1785928837.8020608, "raw": "{\"market\":\"0x0393e451a7889f6472d5099a6de21d1fc6bea6ada01c2e227ea954a8ebce1771\",\"price_changes\":[{\"asset_id\":\"62439955870856164313493799301554574122664268361492077980110236255342893751283\",\"price\":\"0.914\",\"size\":\"0\",\"side\":\"BUY\",\"hash\":\"9d134d4cf12eaff6250255a2d104c77576f5ce03\",\"best_bid\":\"0.913\",\"best_ask\":\"0.944\"},{\"asset_id\":\"19078179119846452574438096789570272099502061228398927027811652354916673625092\",\"price\":\"0.086\",\"size\":\"0\",\"side\":\"SELL\",\"hash\":\"9d27510b0a17c617c75ce309188f96ed5af29eb7\",\"best_bid\":\"0.056\",\"best_ask\":\"0.087\"}],\"timestamp\":\"1785928837771\",\"event_type\":\"price_change\"}"}
{"recv_ts": 1785928837.8449686, "raw": "{\"market\":\"0x4512b933a9db0969b4b59da732a7ff680b1d4e70fac45f88f3a1facc43f2523e\",\"price_changes\":[{\"asset_id\":\"98872378845946591857653676545426042456944570976171616154698795008512748360577\",\"price\":\"0.79\",\"size\":\"79\",\"side\":\"BUY\",\"hash\":\"244b5235185ece5741c6462ab603155cd6736804\",\"best_bid\":\"0.8\",\"best_ask\":\"0.85\"},{\"asset_id\":\"31838063725681317376481701458052352932946613073431683458045098239850815645330\",\"price\":\"0.21\",\"size\":\"79\",\"side\":\"SELL\",\"hash\":\"59a5ffef8dd47ade1e46817cd8b38df1aecbd5dc\",\"best_bid\":\"0.15\",\"best_ask\":\"0.2\"}],\"timestamp\":\"1785928837774\",\"event_type\":\"price_change\"}"}
{"recv_ts": 1785928837.8450074, "raw": "{\"market\":\"0x4512b933a9db0969b4b59da732a7ff680b1d4e70fac45f88f3a1facc43f2523e\",\"price_changes\":[{\"asset_id\":\"98872378845946591857653676545426042456944570976171616154698795008512748360577\",\"price\":\"0.8\",\"size\":\"159.31\",\"side\":\"BUY\",\"hash\":\"de5b27d594395dd9623bc3a06f4c27875f218a3b\",\"best_bid\":\"0.8\",\"best_ask\":\"0.85\"},{\"asset_id\":\"31838063725681317376481701458052352932946613073431683458045098239850815645330\",\"price\":\"0.2\",\"size\":\"159.31\",\"side\":\"SELL\",\"hash\":\"78f9574a2fb445e756359460660a0d263035b80e\",\"best_bid\":\"0.15\",\"best_ask\":\"0.2\"}],\"timestamp\":\"1785928837775\",\"event_type\":\"price_change\"}"}
{"recv_ts": 1785928837.845019, "raw": "{\"market\":\"0x49e0bc2d92fd5118263bb3968c679cb8e236c6912d899b48b3925f26ed9ee209\",\"price_changes\":[{\"asset_id\":\"80051321337559111951453828109935186137789769064013919737026204361460144693479\",\"price\":\"0.57\",\"size\":\"95\",\"side\":\"SELL\",\"hash\":\"057a75f9979c2593556426279eb62ea765f2262a\",\"best_bid\":\"0.3\",\"best_ask\":\"0.38\"},{\"asset_id\":\"9622500641191387664431955870185399485936790493585104294220539600837039752975\",\"price\":\"0.43\",\"size\":\"95\",\"side\":\"BUY\",\"hash\":\"9b4c8d053e08817ec4ef1c2c183b2648a6798c04\",\"best_bid\":\"0.62\",\"best_ask\":\"0.7\"}],\"timestamp\":\"1785928837784\",\"event_type\":\"price_change\"}"}
{"recv_ts": 1785928837.845156, "raw": "[{\"market\": \"0xf5b32e83670ba5f5d56bc824a13565c3ebe9f902ab73889015d21183f8865cac\", \"asset_id\": \"57375031225458836170444756570483233559181332527798489809451042323852124651411\", \"timestamp\": \"1785928811403\", \"hash\": \"4f8faea06d7acd5570d13dbede1bc1821b640e69\", \"bids\": [{\"price\": \"0.01\", \"size\": \"2884.75\"}, {\"price\": \"0.02\", \"size\": \"2078\"}, {\"price\": \"0.03\", \"size\": \"1016.96\"}, {\"price\": \"0.04\", \"size\": \"1100\"}, {\"price\": \"0.05\", \"size\": \"1010\"}, {\"price\": \"0.06\", \"size\": \"1022.28\"}, {\"price\": \"0.07\", \"size\": \"1000\"}, {\"price\": \"0.08\", \"size\": \"1012.5\"}, {\"price\": \"0.09\", \"size\": \"1000\"}, {\"price\": \"0.1\", \"size\": \"1010\"}, {\"price\": \"0.11\", \"size\": \"30\"}, {\"price\": \"0.12\", \"size\": \"18\"}, {\"price\": \"0.13\", \"size\": \"12.58\"}, {\"price\": \"0.3\", \"size\": \"5\"}, {\"price\": \"0.54\", \"size\": \"30\"}, {\"price\": \"0.55\", \"size\": \"818\"}, {\"price\": \"0.56\", \"size\": \"60\"}, {\"price\": \"0.57\", \"size\": \"20\"}, {\"price\": \"0.8\", \"size\": \"13\"}, {\"price\": \"0.83\", \"size\": \"36.14\"}, {\"price\": \"0.84\", \"size\": \"10\"}, {\"price\": \"0.85\", \"size\": \"229.78\"}, {\"price\": \"0.92\", \"size\": \"20\"}, {\"price\": \"0.93\", \"size\": \"28.1\"}, {\"price\": \"0.94\", \"size\": \"143.3\"}, {\"price\": \"0.95\", \"size\": \"90.93\"}], \"asks\": [{\"price\": \"0.99\", \"size\": \"109\"}, {\"price\": \"0.98\", \"size\": \"33.9\"}], \"tick_size\": \"0.01\", \"event_type\": \"book\", \"last_trade_price\": \"0.030\"}, {\"market\": \"0x30ce7e8123b2c4709f88fefd901df80257bc2348831fc14bd88038865ca7ddbb\", \"asset_id\": \"105742938130799294058845080285704500745178972627407814717155516176492037979832\", \"timestamp\": \"1785928816288\", \"hash\": \"2ec8faaaf250f94cbbc09dccf30d6a471782c07f\", \"bids\": [{\"price\": \"0.001\", \"size\": \"411.93\"}], \"asks\": [{\"price\": \"0.999\", \"size\": \"128.85\"}, {\"price\": \"0.998\", \"size\": \"46.39\"}, {\"price\": \"0.99\", \"size\": \"2620\"}, {\"price\": \"0.989\", \"size\": \"12.64\"}, {\"price\": \"0.98\", \"size\": \"60\"}, {\"price\": \"0.97\", \"size\": \"10\"}, {\"price\": \"0.969\", \"size\": \"8.06\"}, {\"price\": \"0.96\", \"size\": \"100\"}, {\"price\": \"0.958\", \"size\": \"5\"}, {\"price\": \"0.95\", \"size\": \"10\"}, {\"price\": \"0.94\", \"size\": \"16.67\"}, {\"price\": \"0.92\", \"size\": \"12.5\"}, {\"price\": \"0.919\", \"size\": \"5.77\"}, {\"price\": \"0.9\", \"size\": \"10\"}, {\"price\": \"0.89\", \"size\": \"236.36\"}, {\"price\": \"0.88\", \"size\": \"8.33\"}, {\"price\": \"0.86\", \"size\": \"7.14\"}, {\"price\": \"0.84\", \"size\": \"6.25\"}, {\"price\": \"0.82\", \"size\": \"5.56\"}, {\"price\": \"0.79\", \"size\": \"123.8\"}, {\"price\": \"0.789\", \"size\": \"90\"}, {\"price\": \"0.788\", \"size\": \"6.77\"}, {\"price\": \"0.69\", \"size\": \"83.87\"}, {\"price\": \"0.59\", \"size\": \"63.41\"}, {\"price\": \"0.49\", \"size\": \"50.98\"}, {\"price\": \"0.489\", \"size\": \"25\"}, {\"price\": \"0.39\", \"size\": \"42.62\"}, {\"price\": \"0.35\", \"size\": \"5\"}, {\"price\": \"0.29\", \"size\": \"36.61\"}, {\"price\": \"0.287\", \"size\": \"2027\"}, {\"price\": \"0.2\", \"size\": \"95.5\"}, {\"price\": \"0.19\", \"size\": \"32.09\"}, {\"price\": \"0.18\", \"size\": \"31.7\"}, {\"price\": \"0.17\", \"size\": \"31.32\"}, {\"price\": \"0.16\", \"size\": \"30.95\"}, {\"price\": \"0.15\", \"size\": \"30.58\"}, {\"price\": \"0.14\", \"size\": \"80.23\"}, {\"price\": \"0.13\", \"size\": \"29.88\"}, {\"price\": \"0.12\", \"size\": \"29.54\"}, {\"price\": \"0.11\", \"size\": \"29.21\"}, {\"price\": \"0.1\", \"size\": \"35.88\"}, {\"price\": \"0.09\", \"size\": \"328.57\"}, {\"price\": \"0.08\", \"size\": \"128.26\"}, {\"price\": \"0.07\", \"size\": \"377.95\"}, {\"price\": \"0.06\", \"size\": \"38.65\"}, {\"price\": \"0.05\", \"size\": \"348.41\"}, {\"price\": \"0.041\", \"size\": \"34\"}, {\"price\": \"0.04\", \"size\": \"327.08\"}, {\"price\": \"0.038\", \"size\": \"40\"}, {\"price\": \"0.03\", \"size\": \"361.8\"}, {\"price\": \"0.025\", \"size\": \"82.66\"}, {\"price\": \"0.02\", \"size\": \"613.53\"}, {\"price\": \"0.015\", \"size\": \"26.39\"}, {\"price\": \"0.01\", \"size\": \"766.26\"}, {\"price\": \"0.005\", \"size\": \"320\"}], \"tick_size\": \"0.001\", \"event_type\": \"book\", \"last_trade_price\": \"0.001\"}, {\"market\": \"0x7d73d1dc43df4cf26aac8daaef25ee1a8033d17a081b6b41125d27d9b89b44e2\", \"asset_id\": \"114357758424583362559308425314250053810759577591009937119820382024224812776024\", \"timestamp\": \"1785928747326\", \"hash\": \"dcae98fdcce701bb2536a531aec1394ffd674d6e\", \"bids\": [{\"price\": \"0.01\", \"size\": \"136.12\"}, {\"price\": \"0.02\", \"size\": \"3.91\"}], \"asks\": [{\"price\": \"0.99\", \"size\": \"2638.1\"}, {\"price\": \"0.98\", \"size\": \"2135.62\"}, {\"price\": \"0.97\", \"size\": \"1018.05\"}, {\"price\": \"0.96\", \"size\": \"1125\"}, {\"price\": \"0.95\", \"size\": \"1115.66\"}, {\"price\": \"0.94\", \"size\": \"1039.33\"}, {\"price\": \"0.93\", \"size\": \"1000\"}, {\"price\": \"0.92\", \"size\": \"1031.26\"}, {\"price\": \"0.91\", \"size\": \"1000\"}, {\"price\": \"0.9\", \"size\": \"1020\"}, {\"price\": \"0.89\", \"size\": \"30\"}, {\"price\": \"0.88\", \"size\": \"16.66\"}, {\"price\": \"0.87\", \"size\": \"9\"}, {\"price\": \"0.86\", \"size\": \"14.28\"}, {\"price\": \"0.85\", \"size\": \"5.47\"}, {\"price\": \"0.84\", \"size\": \"12.5\"}, {\"price\": \"0.82\", \"size\": \"11.11\"}, {\"price\": \"0.8\", \"size\": \"5\"}, {\"price\": \"0.78\", \"size\": \"9.09\"}, {\"price\": \"0.76\", \"size\": \"8.33\"}, {\"price\": \"0.74\", \"size\": \"7.69\"}, {\"price\": \"0.72\", \"size\": \"7.14\"}, {\"price\": \"0.7\", \"size\": \"11.66\"}, {\"price\": \"0.69\", \"size\": \"5.54\"}, {\"price\": \"0.68\", \"size\": \"6.25\"}, {\"price\": \"0.66\", \"size\": \"5.88\"}, {\"price\": \"0.64\", \"size\": \"5.55\"}, {\"price\": \"0.62\", \"size\": \"5.26\"}, {\"price\": \"0.6\", \"size\": \"5\"}, {\"price\": \"0.58\", \"size\": \"7.14\"}, {\"price\": \"0.56\", \"size\": \"6.81\"}, {\"price\": \"0.54\", \"size\": \"6.52\"}, {\"price\": \"0.52\", \"size\": \"6.25\"}, {\"price\": \"0.45\", \"size\": \"278\"}, {\"price\": \"0.44\", \"size\": \"30\"}, {\"price\": \"0.2\", \"size\": \"13\"}, {\"price\": \"0.14\", \"size\": \"10\"}, {\"price\": \"0.13\", \"size\": \"16\"}, {\"price\": \"0.11\", \"size\": \"47\"}, {\"price\": \"0.09\", \"size\": \"10\"}, {\"price\": \"0.08\", \"size\": \"10\"}, {\"price\": \"0.07\", \"size\": \"46\"}, {\"price\": \"0.06\", \"size\": \"7\"}, {\"price\": \"0.05\", \"size\": \"17\"}, {\"price\": \"0.04\", \"size\": \"17.5\"}, {\"price\": \"0.03\", \"size\": \"7.21\"}], \"tick_size\": \"0.01\", \"event_type\": \"book\", \"last_trade_price\": \"0.020\"}, {\"market\": \"0xb4fc6b6ae04594ede2c7ac8567a2cdbaadf35ea66a46f50588b6ee8cfc5d1023\", \"asset_id\": \"99775668599101736297555864227694223594476889309478796777537873720546874254148\", \"timestamp\": \"1785928836619\", \"hash\": \"8b7ef83891cf098a6341f4276074f790c17f12f8\", \"bids\": [{\"price\": \"0.001\", \"size\": \"200.06\"}], \"asks\": [{\"price\": \"0.999\", \"size\": \"3545\"}, {\"price\": \"0.998\", \"size\": \"500\"}, {\"price\": \"0.997\", \"size\": \"1000\"}, {\"price\": \"0.99\", \"size\": \"2130.57\"}, {\"price\": \"0.98\", \"size\": \"2122.29\"}, {\"price\": \"0.979\", \"size\": \"30\"}, {\"price\": \"0.97\", \"size\": \"1010\"}, {\"price\": \"0.96\", \"size\": \"1100\"}, {\"price\": \"0.95\", \"size\": \"1017.28\"}, {\"price\": \"0.94\", \"size\": \"1016.66\"}, {\"price\": \"0.93\", \"size\": \"1000\"}, {\"price\": \"0.92\", \"size\": \"1012.5\"}, {\"price\": \"0.91\", \"size\": \"1000\"}, {\"price\": \"0.9\", \"size\": \"1000\"}, {\"price\": \"0.89\", \"size\": \"30\"}, {\"price\": \"0.88\", \"size\": \"5.28\"}, {\"price\": \"0.87\", \"size\": \"8\"}, {\"price\": \"0.86\", \"size\": \"7.49\"}, {\"price\": \"0.8\", \"size\": \"30\"}, {\"price\": \"0.75\", \"size\": \"30\"}, {\"price\": \"0.7\", \"size\": \"35\"}, {\"price\": \"0.65\", \"size\": \"30\"}, {\"price\": \"0.6\", \"size\": \"30\"}, {\"price\": \"0.55\", \"size\": \"30\"}, {\"price\": \"0.5\", \"size\": \"20\"}, {\"price\": \"0.46\", \"size\": \"30\"}, {\"price\": \"0.35\", \"size\": \"5\"}, {\"price\": \"0.215\", \"size\": \"1100\"}, {\"price\": \"0.214\", \"size\": \"30\"}, {\"price\": \"0.2\", \"size\": \"173\"}, {\"price\": \"0.17\", \"size\": \"36.14\"}, {\"price\": \"0.16\", \"size\": \"25\"}, {\"price\": \"0.1\", \"size\": \"7\"}, {\"price\": \"0.067\", \"size\": \"10\"}, {\"price\": \"0.06\", \"size\": \"25.09\"}, {\"price\": \"0.03\", \"size\": \"75\"}, {\"price\": \"0.02\", \"size\": \"76.81\"}, {\"price\": \"0.01\", \"size\": \"704\"}], \"tick_size\": \"0.001\", \"event_type\": \"book\", \"last_trade_price\": \"0.001\"}]", "trimmed": true}
{"recv_ts": 1785928837.8513477, "raw": "{\"market\":\"0xf54ae434dd707eb46704d2a73a173e1abb8f79a6c73490d4724a7179b495e0b7\",\"price_changes\":[{\"asset_id\":\"78315646603106684031343800789850431783405075770039481340741625933426744732240\",\"price\":\"0.86\",\"size\":\"10\",\"side\":\"BUY\",\"hash\":\"989dabb930981bc21630c184baf296f955c97895\",\"best_bid\":\"0.88\",\"best_ask\":\"0.98\"},{\"asset_id\":\"77857731064896872653582592932137102425749502805329271503389620183534450460402\",\"price\":\"0.14\",\"size\":\"10\",\"side\":\"SELL\",\"hash\":\"62221edb98e418ec67308572939c2a5137eafd28\",\"best_bid\":\"0.02\",\"best_ask\":\"0.12\"}],\"timestamp\":\"1785928837678\",\"event_type\":\"price_change\"}"}
{"recv_ts": 1785928837.8513644, "raw": "{\"market\":\"0x9f537b77607956b1faf8da0325b2589b62c806609536a5468e5c1b464fde8b96\",\"price_changes\":[{\"asset_id\":\"102148549866655967368398111509878487750191342607434149673857758361783061358186\",\"price\":\"0.51\",\"size\":\"54\",\"side\":\"BUY\",\"hash\":\"20d4ce561002b10121f1128e51f8773f3cfdcf0c\",\"best_bid\":\"0.53\",\"best_ask\":\"0.55\"},{\"asset_id\":\"97902541796413115805218649188004823840306839129356943909533075740261995315836\",\"price\":\"0.49\",\"size\":\"54\",\"side\":\"SELL\",\"hash\":\"7bb20b70f3399ccd1ebdf1986f16de363acb400a\",\"best_bid\":\"0.45\",\"best_ask\":\"0.47\"}],\"timestamp\":\"1785928837679\",\"event_type\":\"price_change\"}"}
{"recv_ts": 1785928837.8513746, "raw": "{\"market\":\"0x9f537b77607956b1faf8da0325b2589b62c806609536a5468e5c1b464fde8b96\",\"price_changes\":[{\"asset_id\":\"102148549866655967368398111509878487750191342607434149673857758361783061358186\",\"price\":\"0.52\",\"size\":\"253.3\",\"side\":\"BUY\",\"hash\":\"15532956243299d861d4e31c3d45117a39f5a95e\",\"best_bid\":\"0.53\",\"best_ask\":\"0.55\"},{\"asset_id\":\"97902541796413115805218649188004823840306839129356943909533075740261995315836\",\"price\":\"0.48\",\"size\":\"253.3\",\"side\":\"SELL\",\"hash\":\"d284ca6e8444b0f687875e81eea665c2789e9c90\",\"best_bid\":\"0.45\",\"best_ask\":\"0.47\"}],\"timestamp\":\"1785928837679\",\"event_type\":\"price_change\"}"}
{"recv_ts": 1785928837.851383, "raw": "{\"market\":\"0x0494a1dfe4863aa2f45f659f5033506685d2c8413ba2b9bb264729f1da071505\",\"price_changes\":[{\"asset_id\":\"78735342823757821535544739336339152563646452099906843064768149875057285267358\",\"price\":\"0.6\",\"size\":\"10\",\"side\":\"BUY\",\"hash\":\"4ee91d8ade0817e997d4213734ace3b0fbe7429b\",\"best_bid\":\"0.72\",\"best_ask\":\"0.79\"},{\"asset_id\":\"75523088102358771282999080233254659675006226439931966721716367940084175099074\",\"price\":\"0.4\",\"size\":\"10\",\"side\":\"SELL\",\"hash\":\"e2741ea5c654b3b5c52faffcae24d4bf94208891\",\"best_bid\":\"0.21\",\"best_ask\":\"0.28\"}],\"timestamp\":\"1785928837680\",\"event_type\":\"price_change\"}"}
{"recv_ts": 1785928837.8513925, "raw": "{\"market\":\"0x0494a1dfe4863aa2f45f659f5033506685d2c8413ba2b9bb264729f1da071505\",\"price_changes\":[{\"asset_id\":\"78735342823757821535544739336339152563646452099906843064768149875057285267358\",\"price\":\"0.72\",\"size\":\"85\",\"side\":\"BUY\",\"hash\":\"0220e58ddf1e4692d4c0d5c4f02d453c3f8287d7\",\"best_bid\":\"0.72\",\"best_ask\":\"0.79\"},{\"asset_id\":\"75523088102358771282999080233254659675006226439931966721716367940084175099074\",\"price\":\"0.28\",\"size\":\"85\",\"side\":\"SELL\",\"hash\":\"7c7d69d09f2b9ad2ae7ef9457f8b0bacf44dc5d5\",\"best_bid\":\"0.21\",\"best_ask\":\"0.28\"}],\"timestamp\":\"1785928837680\",\"event_type\":\"price_change\"}"}
{"recv_ts": 1785928837.8514016, "raw": "{\"market\":\"0xf54ae434dd707eb46704d2a73a173e1abb8f79a6c73490d4724a7179b495e0b7\",\"price_changes\":[{\"asset_id\":\"78315646603106684031343800789850431783405075770039481340741625933426744732240\",\"price\":\"0.88\",\"size\":\"0\",\"side\":\"BUY\",\"hash\":\"0e2b460d3f7faa50cb7c6212e22349a6e26d764e\",\"best_bid\":\"0.86\",\"best_ask\":\"0.98\"},{\"asset_id\":\"77857731064896872653582592932137102425749502805329271503389620183534450460402\",\"price\":\"0.12\",\"size\":\"0\",\"side\":\"SELL\",\"hash\":\"e0c9a39b926a34a5088697f313feab5fa680dc43\",\"best_bid\":\"0.02\",\"best_ask\":\"0.14\"}],\"timestamp\":\"1785928837686\",\"event_type\":\"price_change\"}"}
{"recv_ts": 1785928837.851409, "raw": "{\"market\":\"0xf54ae434dd707eb46704d2a73a173e1abb8f79a6c73490d4724a7179b495e0b7\",\"price_changes\":[{\"asset_id\":\"78315646603106684031343800789850431783405075770039481340741625933426744732240\",\"price\":\"0.87\",\"size\":\"20\",\"side\":\"BUY\",\"hash\":\"80bd022244d8a6745c12a60448eda06383ade5ef\",\"best_bid\":\"0.87\",\"best_ask\":\"0.98\"},{\"asset_id\":\"77857731064896872653582592932137102425749502805329271503389620183534450460402\",\"price\":\"0.13\",\"size\":\"20\",\"side\":\"SELL\",\"hash\":\"0df038b52b581ad5e019c3cc5a5fe4d31d08e725\",\"best_bid\":\"0.02\",\"best_ask\":\"0.13\"}],\"timestamp\":\"1785928837720\",\"event_type\":\"price_change\"}"}
{"recv_ts": 1785928837.8514166, "raw": "{\"market\":\"0x838c8b1374b74742b25ef4a15c8f99969fdf346f1922741a352f4bc10ada0a3f\",\"price_changes\":[{\"asset_id\":\"5375457723065783779279424542147357853818386446602787308158710973888670874335\",\"price\":\"0.8\",\"size\":\"25\",\"side\":\"BUY\",\"hash\":\"d92c3875de414e2941adb1c15dbe6be1df0eb1e1\",\"best_bid\":\"0.81\",\"best_ask\":\"0.97\"},{\"asset_id\":\"110953710557391685151254163016419793353576076714107360351886720169266932594443\",\"price\":\"0.2\",\"size\":\"25\",\"side\":\"SELL\",\"hash\":\"f2cbaae09d7b4cd21c39153c6d84d49636715a18\",\"best_bid\":\"0.03\",\"best_ask\":\"0.19\"}],\"timestamp\":\"1785928837720\",\"event_type\":\"price_change\"}"}
{"recv_ts": 1785928837.8514247, "raw": "{\"market\":\"0x0494a1dfe4863aa2f45f659f5033506685d2c8413ba2b9bb264729f1da071505\",\"price_changes\":[{\"asset_id\":\"78735342823757821535544739336339152563646452099906843064768149875057285267358\",\"price\":\"0.72\",\"size\":\"95\",\"side\":\"BUY\",\"hash\":\"bd9a23ef9caad1676885b16086834afc242b2a59\",\"best_bid\":\"0.72\",\"best_ask\":\"0.79\"},{\"asset_id\":\"75523088102358771282999080233254659675006226439931966721716367940084175099074\",\"price\":\"0.28\",\"size\":\"95\",\"side\":\"SELL\",\"hash\":\"ac313c47879e0684f30f63280894024e03e5582d\",\"best_bid\":\"0.21\",\"best_ask\":\"0.28\"}],\"timestamp\":\"1785928837754\",\"event_type\":\"price_change\"}"}
{"recv_ts": 1785928837.8514326, "raw": "{\"market\":\"0x0494a1dfe4863aa2f45f659f5033506685d2c8413ba2b9bb264729f1da071505\",\"price_changes\":[{\"asset_id\":\"78735342823757821535544739336339152563646452099906843064768149875057285267358\",\"price\":\"0.6\",\"size\":\"0\",\"side\":\"BUY\",\"hash\":\"86c54cacb4272da3fb79b7b727a29b48732a2983\",\"best_bid\":\"0.72\",\"best_ask\":\"0.79\"},{\"asset_id\":\"75523088102358771282999080233254659675006226439931966721716367940084175099074\",\"price\":\"0.4\",\"size\":\"0\",\"side\":\"SELL\",\"hash\":\"0b084a00a5b612500e7423004326346d8cfc6bc8\",\"best_bid\":\"0.21\",\"best_ask\":\"0.28\"}],\"timestamp\":\"1785928837760\",\"event_type\":\"price_change\"}"}
{"recv_ts": 1785928837.85144, "raw": "{\"market\":\"0xf54ae434dd707eb46704d2a73a173e1abb8f79a6c73490d4724a7179b495e0b7\",\"price_changes\":[{\"asset_id\":\"78315646603106684031343800789850431783405075770039481340741625933426744732240\",\"price\":\"0.86\",\"size\":\"0\",\"side\":\"BUY\",\"hash\":\"2a41fe08cb1b3810160359dd33079b0ee5a2232c\",\"best_bid\":\"0.87\",\"best_ask\":\"0.98\"},{\"asset_id\":\"77857731064896872653582592932137102425749502805329271503389620183534450460402\",\"price\":\"0.14\",\"size\":\"0\",\"side\":\"SELL\",\"hash\":\"bcd46c7783b0b5dbd810d8c3d0f70dc9131f84f0\",\"best_bid\":\"0.02\",\"best_ask\":\"0.13\"}],\"timestamp\":\"1785928837774\",\"event_type\":\"price_change\"}"}
{"recv_ts": 1785928837.8514478, "raw": "{\"market\":\"0x9f537b77607956b1faf8da0325b2589b62c806609536a5468e5c1b464fde8b96\",\"price_changes\":[{\"asset_id\":\"102148549866655967368398111509878487750191342607434149673857758361783061358186\",\"price\":\"0.52\",\"size\":\"263.3\",\"side\":\"BUY\",\"hash\":\"e516be07bc7ba6e9529c3ee15f2895a0220b94db\",\"best_bid\":\"0.53\",\"best_ask\":\"0.55\"},{\"asset_id\":\"97902541796413115805218649188004823840306839129356943909533075740261995315836\",\"price\":\"0.48\",\"size\":\"263.3\",\"side\":\"SELL\",\"hash\":\"e13dd6698e2a02850441ca21418d31aa805c5104\",\"best_bid\":\"0.45\",\"best_ask\":\"0.47\"}],\"timestamp\":\"1785928837776\",\"event_type\":\"price_change\"}"}
{"recv_ts": 1785928837.8514714, "raw": "{\"market\":\"0xf54ae434dd707eb46704d2a73a173e1abb8f79a6c73490d4724a7179b495e0b7\",\"price_changes\":[{\"asset_id\":\"78315646603106684031343800789850431783405075770039481340741625933426744732240\",\"price\":\"0.88\",\"size\":\"10\",\"side\":\"BUY\",\"hash\":\"943dd67b2af37ea53d92d32913f4755f69058665\",\"best_bid\":\"0.88\",\"best_ask\":\"0.98\"},{\"asset_id\":\"77857731064896872653582592932137102425749502805329271503389620183534450460402\",\"price\":\"0.12\",\"size\":\"10\",\"side\":\"SELL\",\"hash\":\"c3b8a27d670780598370f96892f7c52bb86c0504\",\"best_bid\":\"0.02\",\"best_ask\":\"0.12\"}],\"timestamp\":\"1785928837782\",\"event_type\":\"price_change\"}"}
{"recv_ts": 1785928837.8514795, "raw": "{\"market\":\"0x9f537b77607956b1faf8da0325b2589b62c806609536a5468e5c1b464fde8b96\",\"price_changes\":[{\"asset_id\":\"102148549866655967368398111509878487750191342607434149673857758361783061358186\",\"price\":\"0.51\",\"size\":\"44\",\"side\":\"BUY\",\"hash\":\"07fe41f2a77fe8d6ec27923340586e4cecff5682\",\"best_bid\":\"0.53\",\"best_ask\":\"0.55\"},{\"asset_id\":\"97902541796413115805218649188004823840306839129356943909533075740261995315836\",\"price\":\"0.49\",\"size\":\"44\",\"side\":\"SELL\",\"hash\":\"49b3a23541379aede11af237ed9dce9372229439\",\"best_bid\":\"0.45\",\"best_ask\":\"0.47\"}],\"timestamp\":\"1785928837783\",\"event_type\":\"price_change\"}"}
{"recv_ts": 1785928837.8518925, "raw": "[{\"market\": \"0x2921b8ffc742a106c597791563ff0b0015fc774a17ad452ae236cdf9ae1229e3\", \"asset_id\": \"31270549316975946989407157571956344458444172840941241301071789360728506669797\", \"timestamp\": \"1785928832848\", \"hash\": \"c86629198312edfe09e7d72249f34f72c0768d86\", \"bids\": [{\"price\": \"0.001\", \"size\": \"1724\"}, {\"price\": \"0.002\", \"size\": \"40\"}, {\"price\": \"0.004\", \"size\": \"25\"}, {\"price\": \"0.008\", \"size\": \"270.99\"}, {\"price\": \"0.009\", \"size\": \"246.22\"}], \"asks\": [{\"price\": \"0.999\", \"size\": \"1092.47\"}, {\"price\": \"0.998\", \"size\": \"529.71\"}, {\"price\": \"0.997\", \"size\": \"1019.08\"}, {\"price\": \"0.996\", \"size\": \"27.25\"}, {\"price\": \"0.99\", \"size\": \"2120\"}, {\"price\": \"0.989\", \"size\": \"11.16\"}, {\"price\": \"0.98\", \"size\": \"2078\"}, {\"price\": \"0.979\", \"size\": \"8.91\"}, {\"price\": \"0.97\", \"size\": \"1010\"}, {\"price\": \"0.96\", \"size\": \"1100\"}, {\"price\": \"0.959\", \"size\": \"7.72\"}, {\"price\": \"0.95\", \"size\": \"1010\"}, {\"price\": \"0.94\", \"size\": \"1026.66\"}, {\"price\": \"0.93\", \"size\": \"1000\"}, {\"price\": \"0.92\", \"size\": \"1012.5\"}, {\"price\": \"0.919\", \"size\": \"6.17\"}, {\"price\": \"0.91\", \"size\": \"1000\"}, {\"price\": \"0.9\", \"size\": \"1020\"}, {\"price\": \"0.88\", \"size\": \"8.33\"}, {\"price\": \"0.86\", \"size\": \"7.14\"}, {\"price\": \"0.84\", \"size\": \"6.25\"}, {\"price\": \"0.839\", \"size\": \"5.34\"}, {\"price\": \"0.82\", \"size\": \"5.55\"}, {\"price\": \"0.819\", \"size\": \"1309.2\"}, {\"price\": \"0.8\", \"size\": \"5\"}, {\"price\": \"0.78\", \"size\": \"9.09\"}, {\"price\": \"0.76\", \"size\": \"8.33\"}, {\"price\": \"0.75\", \"size\": \"51\"}, {\"price\": \"0.74\", \"size\": \"7.69\"}, {\"price\": \"0.72\", \"size\": \"7.14\"}, {\"price\": \"0.7\", \"size\": \"16.66\"}, {\"price\": \"0.68\", \"size\": \"6.25\"}, {\"price\": \"0.66\", \"size\": \"5.88\"}, {\"price\": \"0.659\", \"size\": \"5.12\"}, {\"price\": \"0.65\", \"size\": \"35\"}, {\"price\": \"0.64\", \"size\": \"5.55\"}, {\"price\": \"0.62\", \"size\": \"5.26\"}, {\"price\": \"0.6\", \"size\": \"15\"}, {\"price\": \"0.58\", \"size\": \"7.14\"}, {\"price\": \"0.56\", \"size\": \"6.81\"}, {\"price\": \"0.54\", \"size\": \"6.52\"}, {\"price\": \"0.52\", \"size\": \"6.25\"}, {\"price\": \"0.519\", \"size\": \"2073\"}, {\"price\": \"0.518\", \"size\": \"829.2\"}, {\"price\": \"0.516\", \"size\": \"621.2\"}, {\"price\": \"0.515\", \"size\": \"2919\"}, {\"price\": \"0.415\", \"size\": \"30\"}, {\"price\": \"0.37\", \"size\": \"11\"}, {\"price\": \"0.204\", \"size\": \"28.26\"}, {\"price\": \"0.2\", \"size\": \"5\"}, {\"price\": \"0.199\", \"size\": \"400\"}, {\"price\": \"0.15\", \"size\": \"31\"}, {\"price\": \"0.14\", \"size\": \"6\"}, {\"price\": \"0.117\", \"size\": \"7\"}, {\"price\": \"0.112\", \"size\": \"30\"}, {\"price\": \"0.111\", \"size\": \"100\"}, {\"price\": \"0.109\", \"size\": \"10\"}, {\"price\": \"0.09\", \"size\": \"25.98\"}, {\"price\": \"0.089\", \"size\": \"25\"}, {\"price\": \"0.088\", \"size\": \"50\"}, {\"price\": \"0.064\", \"size\": \"25\"}, {\"price\": \"0.063\", \"size\": \"70\"}, {\"price\": \"0.06\", \"size\": \"15\"}, {\"price\": \"0.057\", \"size\": \"5\"}, {\"price\": \"0.056\", \"size\": \"45\"}, {\"price\": \"0.05\", \"size\": \"32\"}, {\"price\": \"0.049\", \"size\": \"20\"}, {\"price\": \"0.048\", \"size\": \"30\"}, {\"price\": \"0.047\", \"size\": \"44.07\"}, {\"price\": \"0.042\", \"size\": \"10.66\"}, {\"price\": \"0.036\", \"size\": \"80\"}, {\"price\": \"0.035\", \"size\": \"27.3\"}, {\"price\": \"0.033\", \"size\": \"33.07\"}, {\"price\": \"0.032\", \"size\": \"29\"}, {\"price\": \"0.031\", \"size\": \"10.07\"}, {\"price\": \"0.03\", \"size\": \"65\"}], \"tick_size\": \"0.001\", \"event_type\": \"book\", \"last_trade_price\": \"0.010\"}, {\"market\": \"0x75aac7bd8ded639b2d06e8a67aeff566a3aabab6fedc805d08a185f2c592ca70\", \"asset_id\": \"4226739125608094976558916446933754037101169876411369437964171032217295920949\", \"timestamp\": \"1785928803930\", \"hash\": \"65ca4eb74a72a692a362172cfa0bb3e2c811ab6b\", \"bids\": [{\"price\": \"0.01\", \"size\": \"2660.33\"}, {\"price\": \"0.02\", \"size\": \"3164.92\"}, {\"price\": \"0.03\", \"size\": \"843.54\"}, {\"price\": \"0.04\", \"size\": \"106.19\"}, {\"price\": \"0.05\", \"size\": \"30\"}, {\"price\": \"0.06\", \"size\": \"16.67\"}, {\"price\": \"0.07\", \"size\": \"5.34\"}, {\"price\": \"0.08\", \"size\": \"37.5\"}, {\"price\": \"0.1\", \"size\": \"50\"}, {\"price\": \"0.12\", \"size\": \"14.48\"}, {\"price\": \"0.14\", \"size\": \"7.14\"}, {\"price\": \"0.16\", \"size\": \"6.25\"}, {\"price\": \"0.17\", \"size\": \"100\"}, {\"price\": \"0.18\", \"size\": \"35.56\"}, {\"price\": \"0.2\", \"size\": \"20\"}, {\"price\": \"0.21\", \"size\": \"100\"}, {\"price\": \"0.22\", \"size\": \"10\"}, {\"price\": \"0.23\", \"size\": \"180\"}, {\"price\": \"0.24\", \"size\": \"755\"}, {\"price\": \"0.25\", \"size\": \"1156\"}, {\"price\": \"0.26\", \"size\": \"290.18\"}], \"asks\": [{\"price\": \"0.99\", \"size\": \"91.74\"}, {\"price\": \"0.98\", \"size\": \"7.27\"}, {\"price\": \"0.97\", \"size\": \"1013.9\"}, {\"price\": \"0.96\", \"size\": \"175\"}, {\"price\": \"0.85\", \"size\": \"31.95\"}, {\"price\": \"0.8\", \"size\": \"10\"}, {\"price\": \"0.75\", \"size\": \"30.66\"}, {\"price\": \"0.6\", \"size\": \"5\"}, {\"price\": \"0.36\", \"size\": \"178.32\"}, {\"price\": \"0.34\", \"size\": \"7\"}, {\"price\": \"0.33\", \"size\": \"8\"}, {\"price\": \"0.3\", \"size\": \"444\"}, {\"price\": \"0.29\", \"size\": \"3575.6\"}, {\"price\": \"0.28\", \"size\": \"1173\"}, {\"price\": \"0.27\", \"size\": \"5\"}], \"tick_size\": \"0.01\", \"event_type\": \"book\", \"last_trade_price\": \"0.730\"}, {\"market\": \"0x26bd111f3a15a95e2aa728b24aa5026761bd7c2afe20783296a510bce8e24a73\", \"asset_id\": \"30236945419509563031097605873156145722546232855924447936397863746263235127154\", \"timestamp\": \"1785928836925\", \"hash\": \"eb27ea12c1f89c4b2a844fe776d94c5a04052827\", \"bids\": [{\"price\": \"0.001\", \"size\": \"497\"}, {\"price\": \"0.002\", \"size\": \"126.45\"}], \"asks\": [{\"price\": \"0.999\", \"size\": \"106.04\"}, {\"price\": \"0.998\", \"size\": \"60.68\"}, {\"price\": \"0.997\", \"size\": \"26.22\"}, {\"price\": \"0.996\", \"size\": \"12.35\"}, {\"price\": \"0.99\", \"size\": \"1670\"}, {\"price\": \"0.989\", \"size\": \"668\"}, {\"price\": \"0.988\", \"size\": \"20.13\"}, {\"price\": \"0.98\", \"size\": \"70\"}, {\"price\": \"0.979\", \"size\": \"828\"}, {\"price\": \"0.977\", \"size\": \"800\"}, {\"price\": \"0.97\", \"size\": \"10\"}, {\"price\": \"0.969\", \"size\": \"6.81\"}, {\"price\": \"0.96\", \"size\": \"75\"}, {\"price\": \"0.95\", \"size\": \"10\"}, {\"price\": \"0.949\", \"size\": \"6.45\"}, {\"price\": \"0.89\", \"size\": \"150\"}, {\"price\": \"0.889\", \"size\": \"5.48\"}, {\"price\": \"0.79\", \"size\": \"78.57\"}, {\"price\": \"0.789\", \"size\": \"30\"}, {\"price\": \"0.75\", \"size\": \"16\"}, {\"price\": \"0.69\", \"size\": \"53.22\"}, {\"price\": \"0.689\", \"size\": \"7.41\"}, {\"price\": \"0.6\", \"size\": \"10\"}, {\"price\": \"0.59\", \"size\": \"40.24\"}, {\"price\": \"0.49\", \"size\": \"32.35\"}, {\"price\": \"0.39\", \"size\": \"27.04\"}, {\"price\": \"0.37\", \"size\": \"6\"}, {\"price\": \"0.35\", \"size\": \"5\"}, {\"price\": \"0.29\", \"size\": \"23.23\"}, {\"price\": \"0.289\", \"size\": \"1382\"}, {\"price\": \"0.288\", \"size\": \"552.79\"}, {\"price\": \"0.28\", \"size\": \"160\"}, {\"price\": \"0.279\", \"size\": \"400\"}, {\"price\": \"0.2\", \"size\": \"53.62\"}, {\"price\": \"0.19\", \"size\": \"20.37\"}, {\"price\": \"0.18\", \"size\": \"20.12\"}, {\"price\": \"0.17\", \"size\": \"19.87\"}, {\"price\": \"0.16\", \"size\": \"19.64\"}, {\"price\": \"0.15\", \"size\": \"19.41\"}, {\"price\": \"0.149\", \"size\": \"100\"}, {\"price\": \"0.14\", \"size\": \"29.18\"}, {\"price\": \"0.13\", \"size\": \"18.96\"}, {\"price\": \"0.12\", \"size\": \"18.75\"}, {\"price\": \"0.119\", \"size\": \"50\"}, {\"price\": \"0.118\", \"size\": \"60\"}, {\"price\": \"0.11\", \"size\": \"68.53\"}, {\"price\": \"0.104\", \"size\": \"25\"}, {\"price\": \"0.1\", \"size\": \"25.33\"}, {\"price\": \"0.097\", \"size\": \"88.66\"}, {\"price\": \"0.09\", \"size\": \"218.13\"}, {\"price\": \"0.089\", \"size\": \"45\"}, {\"price\": \"0.08\", \"size\": \"17.93\"}, {\"price\": \"0.078\", \"size\": \"30\"}, {\"price\": \"0.07\", \"size\": \"217.74\"}, {\"price\": \"0.067\", \"size\": \"45\"}, {\"price\": \"0.06\", \"size\": \"17.55\"}, {\"price\": \"0.059\", \"size\": \"30\"}, {\"price\": \"0.05\", \"size\": \"324.36\"}, {\"price\": \"0.047\", \"size\": \"43.19\"}, {\"price\": \"0.045\", \"size\": \"5\"}, {\"price\": \"0.04\", \"size\": \"17.18\"}, {\"price\": \"0.034\", \"size\": \"10\"}, {\"price\": \"0.03\", \"size\": \"17.01\"}, {\"price\": \"0.029\", \"size\": \"28.19\"}, {\"price\": \"0.025\", \"size\": \"16.92\"}, {\"price\": \"0.02\", \"size\": \"80.58\"}, {\"price\": \"0.015\", \"size\": \"16.75\"}, {\"price\": \"0.014\", \"size\": \"100\"}, {\"price\": \"0.01\", \"size\": \"21.66\"}, {\"price\": \"0.009\", \"size\": \"20\"}, {\"price\": \"0.008\", \"size\": \"25\"}], \"tick_size\": \"0.001\", \"event_type\": \"book\", \"last_trade_price\": \"0.998\"}, {\"market\": \"0x8bbd682dca632553a8e18d4df9c441f9f2a47b8daa3f7a7f3324d0612fb1612a\", \"asset_id\": \"13701261934309571100639349688014241007997669047899594832141485633442085702852\", \"timestamp\": \"1785928837402\", \"hash\": \"0658bf50a428745a98b47cea90625b24e008b6d9\", \"bids\": [{\"price\": \"0.01\", \"size\": \"259.44\"}, {\"price\": \"0.02\", \"size\": \"35.5\"}, {\"price\": \"0.03\", \"size\": \"233\"}, {\"price\": \"0.04\", \"size\": \"105\"}, {\"price\": \"0.05\", \"size\": \"2004.8\"}, {\"price\": \"0.06\", \"size\": \"1101.92\"}, {\"price\": \"0.07\", \"size\": \"30\"}, {\"price\": \"0.08\", \"size\": \"200\"}, {\"price\": \"0.1\", \"size\": \"1744\"}, {\"price\": \"0.12\", \"size\": \"55\"}, {\"price\": \"0.13\", \"size\": \"501.6\"}, {\"price\": \"0.14\", \"size\": \"100\"}, {\"price\": \"0.15\", \"size\": \"5\"}, {\"price\": \"0.17\", \"size\": \"139.99\"}, {\"price\": \"0.19\", \"size\": \"44\"}, {\"price\": \"0.2\", \"size\": \"50\"}, {\"price\": \"0.21\", \"size\": \"20\"}, {\"price\": \"0.22\", \"size\": \"58.13\"}, {\"price\": \"0.23\", \"size\": \"290\"}, {\"price\": \"0.24\", \"size\": \"306.25\"}, {\"price\": \"0.25\", \"size\": \"111.53\"}, {\"price\": \"0.26\", \"size\": \"194.43\"}], \"asks\": [{\"price\": \"0.99\", \"size\": \"2654.78\"}, {\"price\": \"0.98\", \"size\": \"2143.4\"}, {\"price\": \"0.97\", \"size\": \"1210.41\"}, {\"price\": \"0.96\", \"size\": \"1130\"}, {\"price\": \"0.95\", \"size\": \"1007.94\"}, {\"price\": \"0.94\", \"size\": \"1063.33\"}, {\"price\": \"0.93\", \"size\": \"1000\"}, {\"price\": \"0.92\", \"size\": \"1025\"}, {\"price\": \"0.91\", \"size\": \"1005.27\"}, {\"price\": \"0.9\", \"size\": \"1020\"}, {\"price\": \"0.88\", \"size\": \"16.66\"}, {\"price\": \"0.86\", \"size\": \"14.28\"}, {\"price\": \"0.85\", \"size\": \"5.88\"}, {\"price\": \"0.84\", \"size\": \"12.5\"}, {\"price\": \"0.82\", \"size\": \"11.11\"}, {\"price\": \"0.8\", \"size\": \"5\"}, {\"price\": \"0.78\", \"size\": \"18.09\"}, {\"price\": \"0.76\", \"size\": \"8.33\"}, {\"price\": \"0.75\", \"size\": \"35\"}, {\"price\": \"0.74\", \"size\": \"7.69\"}, {\"price\": \"0.72\", \"size\": \"7.14\"}, {\"price\": \"0.71\", \"size\": \"5.6\"}, {\"price\": \"0.7\", \"size\": \"26.66\"}, {\"price\": \"0.68\", \"size\": \"6.25\"}, {\"price\": \"0.66\", \"size\": \"5.88\"}, {\"price\": \"0.65\", \"size\": \"35\"}, {\"price\": \"0.64\", \"size\": \"5.55\"}, {\"price\": \"0.63\", \"size\": \"1997\"}, {\"price\": \"0.62\", \"size\": \"707.76\"}, {\"price\": \"0.6\", \"size\": \"687.8\"}, {\"price\": \"0.59\", \"size\": \"1953\"}, {\"price\": \"0.58\", \"size\": \"7.14\"}, {\"price\": \"0.56\", \"size\": \"6.81\"}, {\"price\": \"0.54\", \"size\": \"36.52\"}, {\"price\": \"0.52\", \"size\": \"6.25\"}, {\"price\": \"0.5\", \"size\": \"5\"}, {\"price\": \"0.49\", \"size\": \"400\"}, {\"price\": \"0.48\", \"size\": \"185\"}, {\"price\": \"0.47\", \"size\": \"100\"}, {\"price\": \"0.39\", \"size\": \"16\"}, {\"price\": \"0.38\", \"size\": \"110\"}, {\"price\": \"0.37\", \"size\": \"356.99\"}, {\"price\": \"0.36\", \"size\": \"52.04\"}, {\"price\": \"0.35\", \"size\": \"157.96\"}, {\"price\": \"0.34\", \"size\": \"78\"}, {\"price\": \"0.31\", \"size\": \"10\"}, {\"price\": \"0.3\", \"size\": \"128\"}, {\"price\": \"0.29\", \"size\": \"288.08\"}, {\"price\": \"0.28\", \"size\": \"320\"}, {\"price\": \"0.27\", \"size\": \"25\"}], \"tick_size\": \"0.01\", \"event_type\": \"book\", \"last_trade_price\": \"0.260\"}]", "trimmed": true}
{"recv_ts": 1785928837.8597653, "raw": "{\"market\":\"0xa0cd65c4616a968f38371769f17db6cb75343d62094ebb441a28425fc4a721ea\",\"price_changes\":[{\"asset_id\":\"56335734587631653319889109795616921022625399433806353677000920962734256162036\",\"price\":\"0.21\",\"size\":\"6.65\",\"side\":\"BUY\",\"hash\":\"f1c10a37f78a9e94764044b929f70e6414534436\",\"best_bid\":\"0.74\",\"best_ask\":\"0.75\"},{\"asset_id\":\"91017247517023340034250603494125657928888399377307761618326705159666572053929\",\"price\":\"0.79\",\"size\":\"6.65\",\"side\":\"SELL\",\"hash\":\"959d4df735429500585f24ce52feb14191b9320a\",\"best_bid\":\"0.25\",\"best_ask\":\"0.26\"}],\"timestamp\":\"1785928837627\",\"event_type\":\"price_change\"}"}
{"recv_ts": 1785928837.859786, "raw": "{\"market\":\"0xcf18321c185b673ea8e5426a486849e16d36b2777fcb1134a8ba51d23d11aead\",\"price_changes\":[{\"asset_id\":\"57911042823594460326253813782992561454714043491621725108026096118831610547271\",\"price\":\"0.02\",\"size\":\"3246.82\",\"side\":\"BUY\",\"hash\":\"6a1f756dee6efafc45b4788caa7620cc3dabbbd4\",\"best_bid\":\"0.41\",\"best_ask\":\"0.43\"},{\"asset_id\":\"96163751862238549401627600570500013034958098321412017219926486577283607443513\",\"price\":\"0.98\",\"size\":\"3246.82\",\"side\":\"SELL\",\"hash\":\"d95489f1ad317965bd389ba21c456ae96c16f915\",\"best_bid\":\"0.57\",\"best_ask\":\"0.59\"}],\"timestamp\":\"1785928837759\",\"event_type\":\"price_change\"}"}
