{"recv_ts": 1785928837.909885, "raw": "[{\"market\": \"0x0d3570a7e75dae8f1bda69335348bec7ca53a638567a8fe8d5410438f240832a\", \"asset_id\": \"52263117979879369313182656253764556345185194277285145853651547598850322208939\", \"timestamp\": \"1785928820804\", \"hash\": \"4ea3526489ca88cd9769b08989e605b6e92a6902\", \"bids\": [{\"price\": \"0.001\", \"size\": \"88\"}], \"asks\": [{\"price\": \"0.999\", \"size\": \"169.41\"}, {\"price\": \"0.998\", \"size\": \"57.92\"}, {\"price\": \"0.99\", \"size\": \"2970\"}, {\"price\": \"0.989\", \"size\": \"20.31\"}, {\"price\": \"0.98\", \"size\": \"60\"}, {\"price\": \"0.97\", \"size\": \"10\"}, {\"price\": \"0.969\", \"size\": \"5.65\"}, {\"price\": \"0.96\", \"size\": \"75\"}, {\"price\": \"0.955\", \"size\": \"15\"}, {\"price\": \"0.95\", \"size\": \"10\"}, {\"price\": \"0.949\", \"size\": \"9.82\"}, {\"price\": \"0.89\", \"size\": \"268.18\"}, {\"price\": \"0.889\", \"size\": \"9.09\"}, {\"price\": \"0.888\", \"size\": \"25\"}, {\"price\": \"0.79\", \"size\": \"140.47\"}, {\"price\": \"0.69\", \"size\": \"95.16\"}, {\"price\": \"0.689\", \"size\": \"5.85\"}, {\"price\": \"0.59\", \"size\": \"71.95\"}, {\"price\": \"0.589\", \"size\": \"30\"}, {\"price\": \"0.49\", \"size\": \"57.84\"}, {\"price\": \"0.46\", \"size\": \"30\"}, {\"price\": \"0.39\", \"size\": \"48.36\"}, {\"price\": \"0.35\", \"size\": \"5\"}, {\"price\": \"0.29\", \"size\": \"41.54\"}, {\"price\": \"0.277\", \"size\": \"2203\"}, {\"price\": \"0.276\", \"size\": \"30\"}, {\"price\": \"0.2\", \"size\": \"99.87\"}, {\"price\": \"0.19\", \"size\": \"36.41\"}, {\"price\": \"0.18\", \"size\": \"35.97\"}, {\"price\": \"0.17\", \"size\": \"35.54\"}, {\"price\": \"0.16\", \"size\": \"35.11\"}, {\"price\": \"0.15\", \"size\": \"34.7\"}, {\"price\": \"0.14\", \"size\": \"34.3\"}, {\"price\": \"0.139\", \"size\": \"30\"}, {\"price\": \"0.13\", \"size\": \"33.9\"}, {\"price\": \"0.12\", \"size\": \"33.52\"}, {\"price\": \"0.11\", \"size\": \"33.14\"}, {\"price\": \"0.1\", \"size\": \"39.77\"}, {\"price\": \"0.09\", \"size\": \"432.41\"}, {\"price\": \"0.08\", \"size\": \"132.06\"}, {\"price\": \"0.07\", \"size\": \"481.72\"}, {\"price\": \"0.069\", \"size\": \"10\"}, {\"price\": \"0.06\", \"size\": \"31.38\"}, {\"price\": \"0.05\", \"size\": \"581.05\"}, {\"price\": \"0.04\", \"size\": \"430.72\"}, {\"price\": \"0.03\", \"size\": \"430.41\"}, {\"price\": \"0.025\", \"size\": \"30.25\"}, {\"price\": \"0.02\", \"size\": \"796.1\"}, {\"price\": \"0.015\", \"size\": \"429.94\"}, {\"price\": \"0.012\", \"size\": \"156\"}, {\"price\": \"0.011\", \"size\": \"15\"}, {\"price\": \"0.01\", \"size\": \"629.79\"}, {\"price\": \"0.006\", \"size\": \"460\"}, {\"price\": \"0.005\", \"size\": \"320\"}, {\"price\": \"0.004\", \"size\": \"10\"}], \"tick_size\": \"0.001\", \"event_type\": \"book\", \"last_trade_price\": \"0.001\"}, {\"market\": \"0x0034bb4aa88cd4d79f7d456f9a62a4f26003ce8c6b65a98809e6f9b69140cfd8\", \"asset_id\": \"27137402620521194109917426900964954761473821089877746487547948950312113107348\", \"timestamp\": \"1785928821257\", \"hash\": \"7248c3b316be1a3df3e206dfc2a57ea4004c6b43\", \"bids\": [{\"price\": \"0.001\", \"size\": \"128.85\"}, {\"price\": \"0.002\", \"size\": \"45.96\"}, {\"price\": \"0.01\", \"size\": \"2270\"}, {\"price\": \"0.011\", \"size\": \"12.66\"}, {\"price\": \"0.02\", \"size\": \"110\"}, {\"price\": \"0.03\", \"size\": \"10\"}, {\"price\": \"0.031\", \"size\": \"8.07\"}, {\"price\": \"0.04\", \"size\": \"100\"}, {\"price\": \"0.041\", \"size\": \"60\"}, {\"price\": \"0.06\", \"size\": \"16.66\"}, {\"price\": \"0.08\", \"size\": \"12.5\"}, {\"price\": \"0.081\", \"size\": \"6.91\"}, {\"price\": \"0.1\", \"size\": \"10\"}, {\"price\": \"0.11\", \"size\": \"195.45\"}, {\"price\": \"0.12\", \"size\": \"8.33\"}, {\"price\": \"0.14\", \"size\": \"7.14\"}, {\"price\": \"0.16\", \"size\": \"6.25\"}, {\"price\": \"0.18\", \"size\": \"5.55\"}, {\"price\": \"0.2\", \"size\": \"125\"}, {\"price\": \"0.21\", \"size\": \"102.38\"}, {\"price\": \"0.22\", \"size\": \"9.09\"}, {\"price\": \"0.24\", \"size\": \"8.33\"}, {\"price\": \"0.241\", \"size\": \"5.57\"}, {\"price\": \"0.25\", \"size\": \"120\"}, {\"price\": \"0.26\", \"size\": \"7.69\"}, {\"price\": \"0.28\", \"size\": \"7.14\"}, {\"price\": \"0.3\", \"size\": \"126.66\"}, {\"price\": \"0.31\", \"size\": \"69.35\"}, {\"price\": \"0.32\", \"size\": \"6.25\"}, {\"price\": \"0.34\", \"size\": \"5.88\"}, {\"price\": \"0.35\", \"size\": \"120\"}, {\"price\": \"0.351\", \"size\": \"30\"}, {\"price\": \"0.36\", \"size\": \"5.55\"}, {\"price\": \"0.38\", \"size\": \"5.26\"}, {\"price\": \"0.4\", \"size\": \"125\"}, {\"price\": \"0.41\", \"size\": \"52.43\"}, {\"price\": \"0.42\", \"size\": \"7.14\"}, {\"price\": \"0.44\", \"size\": \"6.81\"}, {\"price\": \"0.45\", \"size\": \"120\"}, {\"price\": \"0.46\", \"size\": \"6.52\"}, {\"price\": \"0.48\", \"size\": \"6.25\"}, {\"price\": \"0.5\", \"size\": \"120\"}, {\"price\": \"0.51\", \"size\": \"42.15\"}, {\"price\": \"0.55\", \"size\": \"120\"}, {\"price\": \"0.6\", \"size\": \"120\"}, {\"price\": \"0.61\", \"size\": \"35.24\"}, {\"price\": \"0.63\", \"size\": \"10\"}, {\"price\": \"0.65\", \"size\": \"125\"}, {\"price\": \"0.71\", \"size\": \"30.28\"}, {\"price\": \"0.75\", \"size\": \"20\"}, {\"price\": \"0.783\", \"size\": \"1608\"}, {\"price\": \"0.784\", \"size\": \"30\"}, {\"price\": \"0.8\", \"size\": \"69.87\"}, {\"price\": \"0.81\", \"size\": \"26.54\"}, {\"price\": \"0.82\", \"size\": \"26.21\"}, {\"price\": \"0.821\", \"size\": \"25\"}, {\"price\": \"0.83\", \"size\": \"25.9\"}, {\"price\": \"0.84\", \"size\": \"25.59\"}, {\"price\": \"0.85\", \"size\": \"25.29\"}, {\"price\": \"0.86\", \"size\": \"25\"}, {\"price\": \"0.87\", \"size\": \"24.71\"}, {\"price\": \"0.88\", \"size\": \"24.43\"}, {\"price\": \"0.89\", \"size\": \"24.15\"}, {\"price\": \"0.894\", \"size\": \"26\"}, {\"price\": \"0.9\", \"size\": \"50.88\"}, {\"price\": \"0.903\", \"size\": \"38.37\"}, {\"price\": \"0.91\", \"size\": \"323.62\"}, {\"price\": \"0.92\", \"size\": \"123.36\"}, {\"price\": \"0.93\", \"size\": \"323.11\"}, {\"price\": \"0.94\", \"size\": \"22.87\"}, {\"price\": \"0.95\", \"size\": \"343.68\"}, {\"price\": \"0.951\", \"size\": \"20\"}, {\"price\": \"0.96\", \"size\": \"322.39\"}, {\"price\": \"0.97\", \"size\": \"322.16\"}, {\"price\": \"0.971\", \"size\": \"20\"}, {\"price\": \"0.975\", \"size\": \"22.05\"}, {\"price\": \"0.98\", \"size\": \"341.93\"}, {\"price\": \"0.981\", \"size\": \"20\"}, {\"price\": \"0.985\", \"size\": \"21.82\"}, {\"price\": \"0.988\", \"size\": \"156\"}, {\"price\": \"0.99\", \"size\": \"21.71\"}, {\"price\": \"0.991\", \"size\": \"430\"}, {\"price\": \"0.992\", \"size\": \"10\"}], \"asks\": [], \"tick_size\": \"0.001\", \"event_type\": \"book\", \"last_trade_price\": \"0.001\"}, {\"market\": \"0x9c9e9444a73b681f22947f89b55f3f493999e39cc85082b0bf18f8b0c74d2ba7\", \"asset_id\": \"29257173929830527323486715101405272662682012889236191150815829135168468819823\", \"timestamp\": \"1785928833058\", \"hash\": \"a847699ff3003883d4eae056a5c051e05f9222fc\", \"bids\": [{\"price\": \"0.01\", \"size\": \"2129.88\"}, {\"price\": \"0.02\", \"size\": \"34.92\"}, {\"price\": \"0.03\", \"size\": \"10\"}, {\"price\": \"0.04\", \"size\": \"81.34\"}, {\"price\": \"0.06\", \"size\": \"7\"}, {\"price\": \"0.07\", \"size\": \"400\"}, {\"price\": \"0.08\", \"size\": \"23.86\"}, {\"price\": \"0.3\", \"size\": \"10\"}, {\"price\": \"0.32\", \"size\": \"338\"}, {\"price\": \"0.33\", \"size\": \"1167\"}, {\"price\": \"0.47\", \"size\": \"137.04\"}, {\"price\": \"0.49\", \"size\": \"60\"}, {\"price\": \"0.5\", \"size\": \"100\"}, {\"price\": \"0.63\", \"size\": \"5\"}, {\"price\": \"0.67\", \"size\": \"25\"}, {\"price\": \"0.68\", \"size\": \"135\"}, {\"price\": \"0.76\", \"size\": \"10\"}, {\"price\": \"0.79\", \"size\": \"31\"}, {\"price\": \"0.8\", \"size\": \"101\"}], \"asks\": [{\"price\": \"0.99\", \"size\": \"158\"}, {\"price\": \"0.98\", \"size\": \"1123\"}, {\"price\": \"0.97\", \"size\": \"375.27\"}, {\"price\": \"0.93\", \"size\": \"114.28\"}, {\"price\": \"0.92\", \"size\": \"100\"}, {\"price\": \"0.9\", \"size\": \"80\"}, {\"price\": \"0.89\", \"size\": \"20\"}, {\"price\": \"0.86\", \"size\": \"14\"}, {\"price\": \"0.85\", \"size\": \"33.33\"}, {\"price\": \"0.83\", \"size\": \"71.13\"}, {\"price\": \"0.82\", \"size\": \"53.35\"}], \"tick_size\": \"0.01\", \"event_type\": \"book\", \"last_trade_price\": \"0.190\"}, {\"market\": \"0xa83c65d37ad166bcfce9d1cdf2181f72f58d6b51382fb65645c4956254f0f949\", \"asset_id\": \"61933778115426955592678677738429011343338730335199239805290264845566888335568\", \"timestamp\": \"1785928832662\", \"hash\": \"3de0221f61774e1f4cf99a44059275478e12c537\", \"bids\": [{\"price\": \"0.01\", \"size\": \"112.45\"}], \"asks\": [{\"price\": \"0.99\", \"size\": \"2141.96\"}, {\"price\": \"0.98\", \"size\": \"60\"}, {\"price\": \"0.97\", \"size\": \"18.92\"}, {\"price\": \"0.96\", \"size\": \"100\"}, {\"price\": \"0.95\", \"size\": \"30\"}, {\"price\": \"0.94\", \"size\": \"23.66\"}, {\"price\": \"0.93\", \"size\": \"5.14\"}, {\"price\": \"0.9\", \"size\": \"240\"}, {\"price\": \"0.85\", \"size\": \"10.35\"}, {\"price\": \"0.84\", \"size\": \"400\"}, {\"price\": \"0.83\", \"size\": \"30\"}, {\"price\": \"0.7\", \"size\": \"10\"}, {\"price\": \"0.69\", \"size\": \"888\"}, {\"price\": \"0.67\", \"size\": \"30\"}, {\"price\": \"0.37\", \"size\": \"5\"}, {\"price\": \"0.36\", \"size\": \"150\"}, {\"price\": \"0.14\", \"size\": \"99.06\"}, {\"price\": \"0.11\", \"size\": \"22.47\"}, {\"price\": \"0.1\", \"size\": \"100.6\"}, {\"price\": \"0.09\", \"size\": \"10.9\"}], \"tick_size\": \"0.01\", \"event_type\": \"book\", \"last_trade_price\": \"0.010\"}]", "trimmed": true}
{"recv_ts": 1785928837.922398, "raw": "{\"market\":\"0xf357e65cdcf539ebec03cef60bd1d7b63c39dcbec7a776b287a9034105f109c3\",\"price_changes\":[{\"asset_id\":\"112334948398217246286204340737312251733067612940202013873286223663359589480504\",\"price\":\"0.47\",\"size\":\"759.56\",\"side\":\"BUY\",\"hash\":\"73b01cef63589cef77fa28c43c4c4b45d0e3029d\",\"best_bid\":\"0.47\",\"best_ask\":\"0.5\"},{\"asset_id\":\"109930676153389773259400824922429294067294153271064524805028562317130229163797\",\"price\":\"0.53\",\"size\":\"759.56\",\"side\":\"SELL\",\"hash\":\"81fd6e079eb37029f1bb4ff80a28387bad290742\",\"best_bid\":\"0.5\",\"best_ask\":\"0.53\"}],\"timestamp\":\"1785928837776\",\"event_type\":\"price_change\"}"}
{"recv_ts": 1785928837.922428, "raw": "{\"market\":\"0x0393e451a7889f6472d5099a6de21d1fc6bea6ada01c2e227ea954a8ebce1771\",\"price_changes\":[{\"asset_id\":\"62439955870856164313493799301554574122664268361492077980110236255342893751283\",\"price\":\"0.913\",\"size\":\"34\",\"side\":\"BUY\",\"hash\":\"49e0e5789b92ab39925f26f36dd8dfe22ee1eb15\",\"best_bid\":\"0.913\",\"best_ask\":\"0.944\"},{\"asset_id\":\"19078179119846452574438096789570272099502061228398927027811652354916673625092\",\"price\":\"0.087\",\"size\":\"34\",\"side\":\"SELL\",\"hash\":\"e877a9151d4b57902670ba7022d23828721e6a9e\",\"best_bid\":\"0.056\",\"best_ask\":\"0.087\"}],\"timestamp\":\"1785928837777\",\"event_type\":\"price_change\"}"}
{"recv_ts": 1785928837.9224443, "raw": "{\"market\":\"0x0393e451a7889f6472d5099a6de21d1fc6bea6ada01c2e227ea954a8ebce1771\",\"price_changes\":[{\"asset_id\":\"19078179119846452574438096789570272099502061228398927027811652354916673625092\",\"price\":\"0.085\",\"size\":\"8.28\",\"side\":\"SELL\",\"hash\":\"d82e19fe2daee76767c0453651f554b357a5b68e\",\"best_bid\":\"0.056\",\"best_ask\":\"0.085\"},{\"asset_id\":\"62439955870856164313493799301554574122664268361492077980110236255342893751283\",\"price\":\"0.915\",\"size\":\"8.28\",\"side\":\"BUY\",\"hash\":\"e5beedb5c470a30736960b61efacad0c05d065ef\",\"best_bid\":\"0.915\",\"best_ask\":\"0.944\"}],\"timestamp\":\"1785928837795\",\"event_type\":\"price_change\"}"}
{"recv_ts": 1785928837.9224555, "raw": "{\"market\":\"0x146c69bf19e21cae019688465c88fe8eb07c5ae2d425279282c25ea0a98fefdd\",\"price_changes\":[{\"asset_id\":\"93420494003970262759738978991276062947766020271594954442771098529243724757758\",\"price\":\"0.74\",\"size\":\"13\",\"side\":\"BUY\",\"hash\":\"1d5f4636ec128f2432a3dfc764cfaa47ddfe1f95\",\"best_bid\":\"0.76\",\"best_ask\":\"0.82\"},{\"asset_id\":\"8632296884659248304814402612007718477557593230755667506055691146213920031545\",\"price\":\"0.26\",\"size\":\"13\",\"side\":\"SELL\",\"hash\":\"cd169ee5bde7d05166133470c9d5cb3c4b05ead9\",\"best_bid\":\"0.18\",\"best_ask\":\"0.24\"}],\"timestamp\":\"1785928837799\",\"event_type\":\"price_change\"}"}
{"recv_ts": 1785928837.922464, "raw": "{\"market\":\"0xc677dc4861ad64799759f9652e6ae0ff53c153057fd6db69af9e84a1ca2197ec\",\"price_changes\":[{\"asset_id\":\"77424084358345472197732445675309267934198319933946934156139630690411297600005\",\"price\":\"0.987\",\"size\":\"11.75\",\"side\":\"BUY\",\"hash\":\"1cc31e688074f03c907cf4e64b13756fb481f900\",\"best_bid\":\"0.998\",\"best_ask\":\"0.999\"},{\"asset_id\":\"45534343227339732590622934884801860571492159958084925751306737519940828376450\",\"price\":\"0.013\",\"size\":\"11.75\",\"side\":\"SELL\",\"hash\":\"3608c34c83ab8c4784e47a7f46ce1afed038b6e4\",\"best_bid\":\"0.001\",\"best_ask\":\"0.002\"}],\"timestamp\":\"1785928837799\",\"event_type\":\"price_change\"}"}
{"recv_ts": 1785928837.9224715, "raw": "{\"market\":\"0x9c68a1448a4cdb3993a297f1f0f759774383f2e514773621ceb04589399930bc\",\"price_changes\":[{\"asset_id\":\"33579711484128453880472647592907450388461194263236358989226504691017998237897\",\"price\":\"0.82\",\"size\":\"15\",\"side\":\"BUY\",\"hash\":\"6d8d191bde600460292bad20978d3c228d4359db\",\"best_bid\":\"0.85\",\"best_ask\":\"0.91\"},{\"asset_id\":\"62791514040221235938370932209912323223995828701014253087241691765902207027191\",\"price\":\"0.18\",\"size\":\"15\",\"side\":\"SELL\",\"hash\":\"c056df2ee4e0657fe01f7b7d1395f7384a22427a\",\"best_bid\":\"0.09\",\"best_ask\":\"0.15\"}],\"timestamp\":\"1785928837805\",\"event_type\":\"price_change\"}"}
{"recv_ts": 1785928837.9224777, "raw": "{\"market\":\"0x0393e451a7889f6472d5099a6de21d1fc6bea6ada01c2e227ea954a8ebce1771\",\"price_changes\":[{\"asset_id\":\"62439955870856164313493799301554574122664268361492077980110236255342893751283\",\"price\":\"0.943\",\"size\":\"10\",\"side\":\"SELL\",\"hash\":\"fa956787ada1eba6d7a76d08dec15bd4b0643048\",\"best_bid\":\"0.915\",\"best_ask\":\"0.943\"},{\"asset_id\":\"19078179119846452574438096789570272099502061228398927027811652354916673625092\",\"price\":\"0.057\",\"size\":\"10\",\"side\":\"BUY\",\"hash\":\"beff00bbfc69e5b6b253180a5f07b99554ca9651\",\"best_bid\":\"0.057\",\"best_ask\":\"0.085\"}],\"timestamp\":\"1785928837813\",\"event_type\":\"price_change\"}"}
{"recv_ts": 1785928837.9224842, "raw": "{\"market\":\"0xbf3934dfc014233beda6f87619371f394789219377ce438d38f74870f56c68ea\",\"price_changes\":[{\"asset_id\":\"42024905581146846414507905961735200210462829982661029520878636315857683485217\",\"price\":\"0.72\",\"size\":\"15\",\"side\":\"BUY\",\"hash\":\"291ba81ac70cd3736398896ae7705199d0b37595\",\"best_bid\":\"0.75\",\"best_ask\":\"0.79\"},{\"asset_id\":\"29398731980061685892494196371571389220920495273593479516382999208418023734255\",\"price\":\"0.28\",\"size\":\"15\",\"side\":\"SELL\",\"hash\":\"9765e62e70bb407e3fe968d3d772c73236395245\",\"best_bid\":\"0.21\",\"best_ask\":\"0.25\"}],\"timestamp\":\"1785928837816\",\"event_type\":\"price_change\"}"}
{"recv_ts": 1785928837.9224916, "raw": "{\"market\":\"0x31cc8cc9d1b3dbdc5219e0319a01ded09ad0c18296c8f27bc76b1f12364a4661\",\"price_changes\":[{\"asset_id\":\"51223233815348005431570032441325849255204346210650700628294623504463311020670\",\"price\":\"0.22\",\"size\":\"5\",\"side\":\"BUY\",\"hash\":\"69afe2d3ecdbb1e401780d2a4752c739ca08d9b7\",\"best_bid\":\"0.26\",\"best_ask\":\"0.43\"},{\"asset_id\":\"36593914907192135817908362063800584939108275837285837232090830833195276003888\",\"price\":\"0.78\",\"size\":\"5\",\"side\":\"SELL\",\"hash\":\"cc17a84ca0229e44e07015e1fbe05483b8f19e01\",\"best_bid\":\"0.57\",\"best_ask\":\"0.74\"}],\"timestamp\":\"1785928837821\",\"event_type\":\"price_change\"}"}
{"recv_ts": 1785928837.9224985, "raw": "{\"market\":\"0x31cc8cc9d1b3dbdc5219e0319a01ded09ad0c18296c8f27bc76b1f12364a4661\",\"price_changes\":[{\"asset_id\":\"51223233815348005431570032441325849255204346210650700628294623504463311020670\",\"price\":\"0.26\",\"size\":\"0\",\"side\":\"BUY\",\"hash\":\"f602a1a06ff9ff8b2243cb50a10def58d72318de\",\"best_bid\":\"0.22\",\"best_ask\":\"0.43\"},{\"asset_id\":\"36593914907192135817908362063800584939108275837285837232090830833195276003888\",\"price\":\"0.74\",\"size\":\"0\",\"side\":\"SELL\",\"hash\":\"8a79cc84ed7e7f4a4b482948289825ddaa114c39\",\"best_bid\":\"0.57\",\"best_ask\":\"0.78\"}],\"timestamp\":\"1785928837821\",\"event_type\":\"price_change\"}"}
{"recv_ts": 1785928837.9225187, "raw": "{\"market\":\"0xcdf07db4679ef6e24d8a3e896bf652c59e34e32a85fd52c8674ffcb8feb1bd6b\",\"price_changes\":[{\"asset_id\":\"112281222984999372216196312058913012527283133455394337409744127099153489093767\",\"price\":\"0.31\",\"size\":\"0\",\"side\":\"BUY\",\"hash\":\"f3138dc2ad703446effe9f3347c60ff9f429f2dc\",\"best_bid\":\"0.64\",\"best_ask\":\"0.71\"},{\"asset_id\":\"56851808432318955817653658644933948937489149977259469391695759113847085110251\",\"price\":\"0.69\",\"size\":\"0\",\"side\":\"SELL\",\"hash\":\"0e2dab1ec8a874ed8ea3c3904f5964f8fbf97b0b\",\"best_bid\":\"0.29\",\"best_ask\":\"0.36\"}],\"timestamp\":\"1785928837829\",\"event_type\":\"price_change\"}"}
{"recv_ts": 1785928837.922529, "raw": "{\"market\":\"0x0393e451a7889f6472d5099a6de21d1fc6bea6ada01c2e227ea954a8ebce1771\",\"price_changes\":[{\"asset_id\":\"62439955870856164313493799301554574122664268361492077980110236255342893751283\",\"price\":\"0.913\",\"size\":\"29\",\"side\":\"BUY\",\"hash\":\"6a4e78c5ec8f85e3a5c1b1bfb1dcd11e3e328460\",\"best_bid\":\"0.915\",\"best_ask\":\"0.943\"},{\"asset_id\":\"19078179119846452574438096789570272099502061228398927027811652354916673625092\",\"price\":\"0.087\",\"size\":\"29\",\"side\":\"SELL\",\"hash\":\"d7396aade37d70f888676f7357adfe0509f1e046\",\"best_bid\":\"0.057\",\"best_ask\":\"0.085\"}],\"timestamp\":\"1785928837835\",\"event_type\":\"price_change\"}"}
{"recv_ts": 1785928837.9225633, "raw": "{\"market\":\"0x0393e451a7889f6472d5099a6de21d1fc6bea6ada01c2e227ea954a8ebce1771\",\"price_changes\":[{\"asset_id\":\"62439955870856164313493799301554574122664268361492077980110236255342893751283\",\"price\":\"0.915\",\"size\":\"13.28\",\"side\":\"BUY\",\"hash\":\"1431dd47a329617126cef9bce05f5000a64c15d3\",\"best_bid\":\"0.915\",\"best_ask\":\"0.943\"},{\"asset_id\":\"19078179119846452574438096789570272099502061228398927027811652354916673625092\",\"price\":\"0.085\",\"size\":\"13.28\",\"side\":\"SELL\",\"hash\":\"de5c4b52ce8c728025a57a02806b2813382be7e5\",\"best_bid\":\"0.057\",\"best_ask\":\"0.085\"}],\"timestamp\":\"1785928837837\",\"event_type\":\"price_change\"}"}
{"recv_ts": 1785928837.9225733, "raw": "{\"market\":\"0x0393e451a7889f6472d5099a6de21d1fc6bea6ada01c2e227ea954a8ebce1771\",\"price_changes\":[{\"asset_id\":\"19078179119846452574438096789570272099502061228398927027811652354916673625092\",\"price\":\"0.085\",\"size\":\"5\",\"side\":\"SELL\",\"hash\":\"01f8e21d2bdad2831a3dc7c0bd4baa9d1916161e\",\"best_bid\":\"0.057\",\"best_ask\":\"0.085\"},{\"asset_id\":\"62439955870856164313493799301554574122664268361492077980110236255342893751283\",\"price\":\"0.915\",\"size\":\"5\",\"side\":\"BUY\",\"hash\":\"9fb77b1a39417f3e002d9a93d60e8fd5f918411d\",\"best_bid\":\"0.915\",\"best_ask\":\"0.943\"}],\"timestamp\":\"1785928837846\",\"event_type\":\"price_change\"}"}
{"recv_ts": 1785928837.9225829, "raw": "{\"market\":\"0x9564d81934c1550b627ff159cc139675d7d08916fa74cc4aaf8d416e4bedd807\",\"price_changes\":[{\"asset_id\":\"46123186009598106104671689617421295270790145953546842072887829618094075293472\",\"price\":\"0.48\",\"size\":\"23\",\"side\":\"BUY\",\"hash\":\"9bb1adcbdd1d722e8b696c7bf8d871e6f1e49c37\",\"best_bid\":\"0.48\",\"best_ask\":\"0.74\"},{\"asset_id\":\"33275922446271605474639218893344378139793083231796398469699104729778621445854\",\"price\":\"0.52\",\"size\":\"23\",\"side\":\"SELL\",\"hash\":\"bf4ac269484beb68be359c1514bf531ca4a80843\",\"best_bid\":\"0.26\",\"best_ask\":\"0.52\"}],\"timestamp\":\"1785928837847\",\"event_type\":\"price_change\"}"}
{"recv_ts": 1785928837.9225988, "raw": "{\"market\":\"0x6c715ecfdbbaabd6a35c62fc98bcc87b3dcdd1b6416dcbab283ca1efb45d3a66\",\"price_changes\":[{\"asset_id\":\"69030387516002355950473361761810554018090177194157601139681746081629683036016\",\"price\":\"0.973\",\"size\":\"0\",\"side\":\"BUY\",\"hash\":\"4241a09433fdbacd0bec961e58b48c08137a2853\",\"best_bid\":\"0.999\",\"best_ask\":\"1\"},{\"asset_id\":\"58978412978313199193375200360490879960373966471802907932573964849694973717406\",\"price\":\"0.027\",\"size\":\"0\",\"side\":\"SELL\",\"hash\":\"604183a57d40813cd1d1cdf53e1256b043a3bbed\",\"best_bid\":\"0\",\"best_ask\":\"0.001\"}],\"timestamp\":\"1785928837789\",\"event_type\":\"price_change\"}"}
{"recv_ts": 1785928837.9226096, "raw": "{\"market\":\"0x6c715ecfdbbaabd6a35c62fc98bcc87b3dcdd1b6416dcbab283ca1efb45d3a66\",\"price_changes\":[{\"asset_id\":\"58978412978313199193375200360490879960373966471802907932573964849694973717406\",\"price\":\"0.025\",\"size\":\"35.52\",\"side\":\"SELL\",\"hash\":\"26169562d91724fedf509a581c25d0ac699fd2d3\",\"best_bid\":\"0\",\"best_ask\":\"0.001\"},{\"asset_id\":\"69030387516002355950473361761810554018090177194157601139681746081629683036016\",\"price\":\"0.975\",\"size\":\"35.52\",\"side\":\"BUY\",\"hash\":\"8f8a5e67e5267fb54fc4f241ee8a2b7bedebcd43\",\"best_bid\":\"0.999\",\"best_ask\":\"1\"}],\"timestamp\":\"1785928837794\",\"event_type\":\"price_change\"}"}
{"recv_ts": 1785928837.9226196, "raw": "{\"market\":\"0x0fc2f6268feaef436c823c1824f62706c6eb2715397751e5da5fbd61e7d71025\",\"price_changes\":[{\"asset_id\":\"43558042711663224323089716504686480613254622318408013281716785638216020017932\",\"price\":\"0.74\",\"size\":\"0\",\"side\":\"BUY\",\"hash\":\"9c44f4c01d0df2cc373186acc0c99d8f57a8001a\",\"best_bid\":\"0.95\",\"best_ask\":\"0.96\"},{\"asset_id\":\"98193888735084412499188018668234638776987362559885132138120992642932186443125\",\"price\":\"0.26\",\"size\":\"0\",\"side\":\"SELL\",\"hash\":\"724333d313bdfba0cf4f8ebed753d8ce12bccbc1\",\"best_bid\":\"0.04\",\"best_ask\":\"0.05\"}],\"timestamp\":\"1785928837802\",\"event_type\":\"price_change\"}"}
{"recv_ts": 1785928837.9226303, "raw": "{\"market\":\"0x0fc2f6268feaef436c823c1824f62706c6eb2715397751e5da5fbd61e7d71025\",\"price_changes\":[{\"asset_id\":\"43558042711663224323089716504686480613254622318408013281716785638216020017932\",\"price\":\"0.73\",\"size\":\"0\",\"side\":\"BUY\",\"hash\":\"9c44f4c01d0df2cc373186acc0c99d8f57a8001a\",\"best_bid\":\"0.95\",\"best_ask\":\"0.96\"},{\"asset_id\":\"98193888735084412499188018668234638776987362559885132138120992642932186443125\",\"price\":\"0.27\",\"size\":\"0\",\"side\":\"SELL\",\"hash\":\"724333d313bdfba0cf4f8ebed753d8ce12bccbc1\",\"best_bid\":\"0.04\",\"best_ask\":\"0.05\"}],\"timestamp\":\"1785928837802\",\"event_type\":\"price_change\"}"}
{"recv_ts": 1785928837.9226403, "raw": "{\"market\":\"0x60dd5cb0ee09c2bfa3aebf6c0f467dad995cd569e2d02d6ef16a8e1574f3391a\",\"price_changes\":[{\"asset_id\":\"105587291707338677319901854004669096039802388717388366602161653820194749804003\",\"price\":\"0.787\",\"size\":\"0\",\"side\":\"BUY\",\"hash\":\"51414d6ddf6fb620619d04184e94a71a16ba9194\",\"best_bid\":\"0.991\",\"best_ask\":\"0.998\"},{\"asset_id\":\"112985164027628227488878312680394089251082925438802203342764659476692996732786\",\"price\":\"0.213\",\"size\":\"0\",\"side\":\"SELL\",\"hash\":\"395770040cfeb69caf31ed95d8dd5bd041fc4f06\",\"best_bid\":\"0.002\",\"best_ask\":\"0.009\"}],\"timestamp\":\"1785928837802\",\"event_type\":\"price_change\"}"}
{"recv_ts": 1785928837.92265, "raw": "{\"market\":\"0x29f7aaffe748d1d89ddcbd42ae23c99de64f96bea474165deca0eab1bb81af5c\",\"price_changes\":[{\"asset_id\":\"36511505070289859222068333212120928179759941913669314725077996651101613068646\",\"price\":\"0.776\",\"size\":\"0\",\"side\":\"BUY\",\"hash\":\"165331ca6b3086da9c7815cbf5fb1e210f5b043e\",\"best_bid\":\"0.977\",\"best_ask\":\"0.987\"},{\"asset_id\":\"79052648470198021026660909312029738928593559509249411995852902181835680645124\",\"price\":\"0.224\",\"size\":\"0\",\"side\":\"SELL\",\"hash\":\"f2c1c9e1d48d37f2a0dc8cd3b672df30ff55cfbf\",\"best_bid\":\"0.013\",\"best_ask\":\"0.023\"}],\"timestamp\":\"1785928837802\",\"event_type\":\"price_change\"}"}
{"recv_ts": 1785928837.9226599, "raw": "{\"market\":\"0x60dd5cb0ee09c2bfa3aebf6c0f467dad995cd569e2d02d6ef16a8e1574f3391a\",\"price_changes\":[{\"asset_id\":\"105587291707338677319901854004669096039802388717388366602161653820194749804003\",\"price\":\"0.785\",\"size\":\"0\",\"side\":\"BUY\",\"hash\":\"51414d6ddf6fb620619d04184e94a71a16ba9194\",\"best_bid\":\"0.991\",\"best_ask\":\"0.998\"},{\"asset_id\":\"112985164027628227488878312680394089251082925438802203342764659476692996732786\",\"price\":\"0.215\",\"size\":\"0\",\"side\":\"SELL\",\"hash\":\"395770040cfeb69caf31ed95d8dd5bd041fc4f06\",\"best_bid\":\"0.002\",\"best_ask\":\"0.009\"}],\"timestamp\":\"1785928837802\",\"event_type\":\"price_change\"}"}
{"recv_ts": 1785928837.92267, "raw": "{\"market\":\"0x29f7aaffe748d1d89ddcbd42ae23c99de64f96bea474165deca0eab1bb81af5c\",\"price_changes\":[{\"asset_id\":\"36511505070289859222068333212120928179759941913669314725077996651101613068646\",\"price\":\"0.774\",\"size\":\"0\",\"side\":\"BUY\",\"hash\":\"165331ca6b3086da9c7815cbf5fb1e210f5b043e\",\"best_bid\":\"0.977\",\"best_ask\":\"0.987\"},{\"asset_id\":\"79052648470198021026660909312029738928593559509249411995852902181835680645124\",\"price\":\"0.226\",\"size\":\"0\",\"side\":\"SELL\",\"hash\":\"f2c1c9e1d48d37f2a0dc8cd3b672df30ff55cfbf\",\"best_bid\":\"0.013\",\"best_ask\":\"0.023\"}],\"timestamp\":\"1785928837802\",\"event_type\":\"price_change\"}"}
{"recv_ts": 1785928837.922679, "raw": "{\"market\":\"0xc63b77f3ee336da37a4d56dbe4e0208b75a82a0328c1c0dae20892cc10dd3639\",\"price_changes\":[{\"asset_id\":\"47134398181755193148939338651935697535629466899703647579961809235723208653564\",\"price\":\"0.45\",\"size\":\"5\",\"side\":\"BUY\",\"hash\":\"1b6e8a35ee457d1061deef689034616b871bfd17\",\"best_bid\":\"0.49\",\"best_ask\":\"0.64\"},{\"asset_id\":\"47013553420493540294331062983804345798310691246036862411615126739061671840454\",\"price\":\"0.55\",\"size\":\"5\",\"side\":\"SELL\",\"hash\":\"1d7134faaf56c4621e6f5817054b76358e66f782\",\"best_bid\":\"0.36\",\"best_ask\":\"0.51\"}],\"timestamp\":\"1785928837802\",\"event_type\":\"price_change\"}"}
{"recv_ts": 1785928837.922701, "raw": "{\"market\":\"0xcd4ac3a6578a23356aecba357b64f76d27674234c3d4754a08efd16bad3a975e\",\"price_changes\":[{\"asset_id\":\"27487852275060665491616972753944499454119120273037155333415153328314444194648\",\"price\":\"0.788\",\"size\":\"0\",\"side\":\"BUY\",\"hash\":\"d0b7710d9ff851f796c2ff5821411ec365bf6994\",\"best_bid\":\"0.993\",\"best_ask\":\"0.999\"},{\"asset_id\":\"111209535652472112432522517641793708239144293646362321025603254860473020607660\",\"price\":\"0.212\",\"size\":\"0\",\"side\":\"SELL\",\"hash\":\"6ce3910ba9bae846f68187e013ad325af78761f1\",\"best_bid\":\"0.001\",\"best_ask\":\"0.007\"}],\"timestamp\":\"1785928837802\",\"event_type\":\"price_change\"}"}
{"recv_ts": 1785928837.9227111, "raw": "{\"market\":\"0xcd4ac3a6578a23356aecba357b64f76d27674234c3d4754a08efd16bad3a975e\",\"price_changes\":[{\"asset_id\":\"27487852275060665491616972753944499454119120273037155333415153328314444194648\",\"price\":\"0.786\",\"size\":\"0\",\"side\":\"BUY\",\"hash\":\"d0b7710d9ff851f796c2ff5821411ec365bf6994\",\"best_bid\":\"0.993\",\"best_ask\":\"0.999\"},{\"asset_id\":\"111209535652472112432522517641793708239144293646362321025603254860473020607660\",\"price\":\"0.214\",\"size\":\"0\",\"side\":\"SELL\",\"hash\":\"6ce3910ba9bae846f68187e013ad325af78761f1\",\"best_bid\":\"0.001\",\"best_ask\":\"0.007\"}],\"timestamp\":\"1785928837802\",\"event_type\":\"price_change\"}"}
{"recv_ts": 1785928837.9227214, "raw": "{\"market\":\"0x8c6a64a8ffd1bfa3d7df81172f976764a2c52c87c1a093897f90b7217d6fea8d\",\"price_changes\":[{\"asset_id\":\"13409836330652892121423735936121472669640499078426321052185227972804816382422\",\"price\":\"0.725\",\"size\":\"0\",\"side\":\"BUY\",\"hash\":\"209d942566fe3cee2d1ef52e9d5ee176c0aaa2ea\",\"best_bid\":\"0.908\",\"best_ask\":\"0.927\"},{\"asset_id\":\"83715211686534593705683144614374080403915454453849238224332560479040502634509\",\"price\":\"0.275\",\"size\":\"0\",\"side\":\"SELL\",\"hash\":\"80a8fe2496246883e726bb7d39a39b6d2c2b936b\",\"best_bid\":\"0.073\",\"best_ask\":\"0.092\"}],\"timestamp\":\"1785928837802\",\"event_type\":\"price_change\"}"}
{"recv_ts": 1785928837.922731, "raw": "{\"market\":\"0x8c6a64a8ffd1bfa3d7df81172f976764a2c52c87c1a093897f90b7217d6fea8d\",\"price_changes\":[{\"asset_id\":\"13409836330652892121423735936121472669640499078426321052185227972804816382422\",\"price\":\"0.723\",\"size\":\"0\",\"side\":\"BUY\",\"hash\":\"209d942566fe3cee2d1ef52e9d5ee176c0aaa2ea\",\"best_bid\":\"0.908\",\"best_ask\":\"0.927\"},{\"asset_id\":\"83715211686534593705683144614374080403915454453849238224332560479040502634509\",\"price\":\"0.277\",\"size\":\"0\",\"side\":\"SELL\",\"hash\":\"80a8fe2496246883e726bb7d39a39b6d2c2b936b\",\"best_bid\":\"0.073\",\"best_ask\":\"0.092\"}],\"timestamp\":\"1785928837802\",\"event_type\":\"price_change\"}"}
{"recv_ts": 1785928837.92274, "raw": "{\"market\":\"0xc63b77f3ee336da37a4d56dbe4e0208b75a82a0328c1c0dae20892cc10dd3639\",\"price_changes\":[{\"asset_id\":\"47134398181755193148939338651935697535629466899703647579961809235723208653564\",\"price\":\"0.44\",\"size\":\"0\",\"side\":\"BUY\",\"hash\":\"818f0ed5ffc7e96e71ac10a08b7613d2b9f8bba2\",\"best_bid\":\"0.49\",\"best_ask\":\"0.64\"},{\"asset_id\":\"47013553420493540294331062983804345798310691246036862411615126739061671840454\",\"price\":\"0.56\",\"size\":\"0\",\"side\":\"SELL\",\"hash\":\"123de689af8d90699c97e1f7a3b8a31e6716440c\",\"best_bid\":\"0.36\",\"best_ask\":\"0.51\"}],\"timestamp\":\"1785928837802\",\"event_type\":\"price_change\"}"}
{"recv_ts": 1785928837.9227495, "raw": "{\"market\":\"0xc63b77f3ee336da37a4d56dbe4e0208b75a82a0328c1c0dae20892cc10dd3639\",\"price_changes\":[{\"asset_id\":\"47134398181755193148939338651935697535629466899703647579961809235723208653564\",\"price\":\"0.43\",\"size\":\"0\",\"side\":\"BUY\",\"hash\":\"818f0ed5ffc7e96e71ac10a08b7613d2b9f8bba2\",\"best_bid\":\"0.49\",\"best_ask\":\"0.64\"},{\"asset_id\":\"47013553420493540294331062983804345798310691246036862411615126739061671840454\",\"price\":\"0.57\",\"size\":\"0\",\"side\":\"SELL\",\"hash\":\"123de689af8d90699c97e1f7a3b8a31e6716440c\",\"best_bid\":\"0.36\",\"best_ask\":\"0.51\"}],\"timestamp\":\"1785928837802\",\"event_type\":\"price_change\"}"}
{"recv_ts": 1785928837.9227579, "raw": "{\"market\":\"0xc63b77f3ee336da37a4d56dbe4e0208b75a82a0328c1c0dae20892cc10dd3639\",\"price_changes\":[{\"asset_id\":\"47134398181755193148939338651935697535629466899703647579961809235723208653564\",\"price\":\"0.46\",\"size\":\"5\",\"side\":\"BUY\",\"hash\":\"695de371a126e6edcdb3c05a04a0ce3f0fd1c588\",\"best_bid\":\"0.49\",\"best_ask\":\"0.64\"},{\"asset_id\":\"47013553420493540294331062983804345798310691246036862411615126739061671840454\",\"price\":\"0.54\",\"size\":\"5\",\"side\":\"SELL\",\"hash\":\"6288d0a0f573949ec4fd67334155167a3bdc3e16\",\"best_bid\":\"0.36\",\"best_ask\":\"0.51\"}],\"timestamp\":\"1785928837802\",\"event_type\":\"price_change\"}"}
{"recv_ts": 1785928837.9227648, "raw": "{\"market\":\"0xcd4ac3a6578a23356aecba357b64f76d27674234c3d4754a08efd16bad3a975e\",\"price_changes\":[{\"asset_id\":\"27487852275060665491616972753944499454119120273037155333415153328314444194648\",\"price\":\"0.814\",\"size\":\"5\",\"side\":\"BUY\",\"hash\":\"ca7307d1f7a28595c627a0b338c258b9a2a03612\",\"best_bid\":\"0.993\",\"best_ask\":\"0.999\"},{\"asset_id\":\"111209535652472112432522517641793708239144293646362321025603254860473020607660\",\"price\":\"0.186\",\"size\":\"5\",\"side\":\"SELL\",\"hash\":\"6ead9efca9d9e1c2691d256a4e656109f9a62777\",\"best_bid\":\"0.001\",\"best_ask\":\"0.007\"}],\"timestamp\":\"1785928837803\",\"event_type\":\"price_change\"}"}
{"recv_ts": 1785928837.9227715, "raw": "{\"market\":\"0x8c6a64a8ffd1bfa3d7df81172f976764a2c52c87c1a093897f90b7217d6fea8d\",\"price_changes\":[{\"asset_id\":\"13409836330652892121423735936121472669640499078426321052185227972804816382422\",\"price\":\"0.745\",\"size\":\"5\",\"side\":\"BUY\",\"hash\":\"747cc39a74a492a406b03916b4b8a4beb9ab630f\",\"best_bid\":\"0.908\",\"best_ask\":\"0.927\"},{\"asset_id\":\"83715211686534593705683144614374080403915454453849238224332560479040502634509\",\"price\":\"0.255\",\"size\":\"5\",\"side\":\"SELL\",\"hash\":\"e9e57b163591d9db0d521dc77ee852a12d48823a\",\"best_bid\":\"0.073\",\"best_ask\":\"0.092\"}],\"timestamp\":\"1785928837804\",\"event_type\":\"price_change\"}"}
{"recv_ts": 1785928837.9227781, "raw": "{\"market\":\"0x29f7aaffe748d1d89ddcbd42ae23c99de64f96bea474165deca0eab1bb81af5c\",\"price_changes\":[{\"asset_id\":\"36511505070289859222068333212120928179759941913669314725077996651101613068646\",\"price\":\"0.802\",\"size\":\"5\",\"side\":\"BUY\",\"hash\":\"c5fb8e6de697491b274dcb49507b6e580cc971ee\",\"best_bid\":\"0.977\",\"best_ask\":\"0.987\"},{\"asset_id\":\"79052648470198021026660909312029738928593559509249411995852902181835680645124\",\"price\":\"0.198\",\"size\":\"5\",\"side\":\"SELL\",\"hash\":\"e7dc0173d3dad5875109c81e9353eb28963ae9ca\",\"best_bid\":\"0.013\",\"best_ask\":\"0.023\"}],\"timestamp\":\"1785928837805\",\"event_type\":\"price_change\"}"}
{"recv_ts": 1785928837.9227848, "raw": "{\"market\":\"0x0fc2f6268feaef436c823c1824f62706c6eb2715397751e5da5fbd61e7d71025\",\"price_changes\":[{\"asset_id\":\"43558042711663224323089716504686480613254622318408013281716785638216020017932\",\"price\":\"0.76\",\"size\":\"25\",\"side\":\"BUY\",\"hash\":\"8a27d8b0c1e584827faf71a7b4f04269127cfe3e\",\"best_bid\":\"0.95\",\"best_ask\":\"0.96\"},{\"asset_id\":\"98193888735084412499188018668234638776987362559885132138120992642932186443125\",\"price\":\"0.24\",\"size\":\"25\",\"side\":\"SELL\",\"hash\":\"6af1d92f30ac90f14dbe95478e879a14097cbf10\",\"best_bid\":\"0.04\",\"best_ask\":\"0.05\"}],\"timestamp\":\"1785928837805\",\"event_type\":\"price_change\"}"}
{"recv_ts": 1785928837.9227915, "raw": "{\"market\":\"0x0fc2f6268feaef436c823c1824f62706c6eb2715397751e5da5fbd61e7d71025\",\"price_changes\":[{\"asset_id\":\"43558042711663224323089716504686480613254622318408013281716785638216020017932\",\"price\":\"0.75\",\"size\":\"5\",\"side\":\"BUY\",\"hash\":\"2e957e834d30fc70d8925f807e5bb2106e02f30d\",\"best_bid\":\"0.95\",\"best_ask\":\"0.96\"},{\"asset_id\":\"98193888735084412499188018668234638776987362559885132138120992642932186443125\",\"price\":\"0.25\",\"size\":\"5\",\"side\":\"SELL\",\"hash\":\"ec7dd5a7602b0d9aeb1b7017dc62cc2bef15594b\",\"best_bid\":\"0.04\",\"best_ask\":\"0.05\"}],\"timestamp\":\"1785928837806\",\"event_type\":\"price_change\"}"}
{"recv_ts": 1785928837.9228067, "raw": "{\"market\":\"0x8c6a64a8ffd1bfa3d7df81172f976764a2c52c87c1a093897f90b7217d6fea8d\",\"price_changes\":[{\"asset_id\":\"83715211686534593705683144614374080403915454453849238224332560479040502634509\",\"price\":\"0.06\",\"size\":\"13\",\"side\":\"BUY\",\"hash\":\"eaa76c10d251f90d97f1e4c31b84eb3a3b238cc5\",\"best_bid\":\"0.073\",\"best_ask\":\"0.092\"},{\"asset_id\":\"13409836330652892121423735936121472669640499078426321052185227972804816382422\",\"price\":\"0.94\",\"size\":\"13\",\"side\":\"SELL\",\"hash\":\"722fe1d760019d743afc92ddcc9de20664ad6215\",\"best_bid\":\"0.908\",\"best_ask\":\"0.927\"}],\"timestamp\":\"1785928837806\",\"event_type\":\"price_change\"}"}
{"recv_ts": 1785928837.9228132, "raw": "{\"market\":\"0x60dd5cb0ee09c2bfa3aebf6c0f467dad995cd569e2d02d6ef16a8e1574f3391a\",\"price_changes\":[{\"asset_id\":\"105587291707338677319901854004669096039802388717388366602161653820194749804003\",\"price\":\"0.815\",\"size\":\"5\",\"side\":\"BUY\",\"hash\":\"d6a09944cce4c2209b4beb485493bcab867baf43\",\"best_bid\":\"0.991\",\"best_ask\":\"0.998\"},{\"asset_id\":\"112985164027628227488878312680394089251082925438802203342764659476692996732786\",\"price\":\"0.185\",\"size\":\"5\",\"side\":\"SELL\",\"hash\":\"cd5730089061ef74e443b588e09f83020f685063\",\"best_bid\":\"0.002\",\"best_ask\":\"0.009\"}],\"timestamp\":\"1785928837807\",\"event_type\":\"price_change\"}"}
{"recv_ts": 1785928837.9228199, "raw": "{\"market\":\"0xcd4ac3a6578a23356aecba357b64f76d27674234c3d4754a08efd16bad3a975e\",\"price_changes\":[{\"asset_id\":\"27487852275060665491616972753944499454119120273037155333415153328314444194648\",\"price\":\"0.76\",\"size\":\"0\",\"side\":\"BUY\",\"hash\":\"8ef08ebad3ca7a13f6732b250ed9a6aa1ce020f2\",\"best_bid\":\"0.993\",\"best_ask\":\"0.999\"},{\"asset_id\":\"111209535652472112432522517641793708239144293646362321025603254860473020607660\",\"price\":\"0.24\",\"size\":\"0\",\"side\":\"SELL\",\"hash\":\"52e938d89a1c8b9d6cd73b45fa4a82ad634363fe\",\"best_bid\":\"0.001\",\"best_ask\":\"0.007\"}],\"timestamp\":\"1785928837807\",\"event_type\":\"price_change\"}"}
{"recv_ts": 1785928837.9228275, "raw": "{\"market\":\"0x0fc2f6268feaef436c823c1824f62706c6eb2715397751e5da5fbd61e7d71025\",\"price_changes\":[{\"asset_id\":\"43558042711663224323089716504686480613254622318408013281716785638216020017932\",\"price\":\"0.71\",\"size\":\"10\",\"side\":\"BUY\",\"hash\":\"739d168fd8f7bf40ee197bf9a25dfb2021e784c1\",\"best_bid\":\"0.95\",\"best_ask\":\"0.96\"},{\"asset_id\":\"98193888735084412499188018668234638776987362559885132138120992642932186443125\",\"price\":\"0.29\",\"size\":\"10\",\"side\":\"SELL\",\"hash\":\"193aa5bb69688f2a523ca816d88f105c9f4e067f\",\"best_bid\":\"0.04\",\"best_ask\":\"0.05\"}],\"timestamp\":\"1785928837807\",\"event_type\":\"price_change\"}"}
{"recv_ts": 1785928837.9228346, "raw": "{\"market\":\"0x0db126ce7967f05290fe3c447fda7aadea75806e63d721b841181d37d361acff\",\"price_changes\":[{\"asset_id\":\"35835929224780790364362553368163009989775826083159639636027464056564214856030\",\"price\":\"0.43\",\"size\":\"30\",\"side\":\"BUY\",\"hash\":\"db8eafadae3d40704e117c6565af9e0a5d4b3e3f\",\"best_bid\":\"0.55\",\"best_ask\":\"0.65\"},{\"asset_id\":\"4788836516371088395388338986004317529952940613144895514047283950263185675387\",\"price\":\"0.57\",\"size\":\"30\",\"side\":\"SELL\",\"hash\":\"a2b77e171ae8a153d207576fe3d77bb36ffc1303\",\"best_bid\":\"0.35\",\"best_ask\":\"0.45\"}],\"timestamp\":\"1785928837807\",\"event_type\":\"price_change\"}"}
{"recv_ts": 1785928837.9228415, "raw": "{\"market\":\"0x0fc2f6268feaef436c823c1824f62706c6eb2715397751e5da5fbd61e7d71025\",\"price_changes\":[{\"asset_id\":\"43558042711663224323089716504686480613254622318408013281716785638216020017932\",\"price\":\"0.7\",\"size\":\"153.74\",\"side\":\"BUY\",\"hash\":\"739d168fd8f7bf40ee197bf9a25dfb2021e784c1\",\"best_bid\":\"0.95\",\"best_ask\":\"0.96\"},{\"asset_id\":\"98193888735084412499188018668234638776987362559885132138120992642932186443125\",\"price\":\"0.3\",\"size\":\"153.74\",\"side\":\"SELL\",\"hash\":\"193aa5bb69688f2a523ca816d88f105c9f4e067f\",\"best_bid\":\"0.04\",\"best_ask\":\"0.05\"}],\"timestamp\":\"1785928837807\",\"event_type\":\"price_change\"}"}
{"recv_ts": 1785928837.922848, "raw": "{\"market\":\"0xcd4ac3a6578a23356aecba357b64f76d27674234c3d4754a08efd16bad3a975e\",\"price_changes\":[{\"asset_id\":\"27487852275060665491616972753944499454119120273037155333415153328314444194648\",\"price\":\"0.758\",\"size\":\"0\",\"side\":\"BUY\",\"hash\":\"8ef08ebad3ca7a13f6732b250ed9a6aa1ce020f2\",\"best_bid\":\"0.993\",\"best_ask\":\"0.999\"},{\"asset_id\":\"111209535652472112432522517641793708239144293646362321025603254860473020607660\",\"price\":\"0.242\",\"size\":\"0\",\"side\":\"SELL\",\"hash\":\"52e938d89a1c8b9d6cd73b45fa4a82ad634363fe\",\"best_bid\":\"0.001\",\"best_ask\":\"0.007\"}],\"timestamp\":\"1785928837807\",\"event_type\":\"price_change\"}"}
{"recv_ts": 1785928837.9228554, "raw": "{\"market\":\"0x60dd5cb0ee09c2bfa3aebf6c0f467dad995cd569e2d02d6ef16a8e1574f3391a\",\"price_changes\":[{\"asset_id\":\"105587291707338677319901854004669096039802388717388366602161653820194749804003\",\"price\":\"0.759\",\"size\":\"0\",\"side\":\"BUY\",\"hash\":\"eb7f5d66c53ff5a2d3017c67f285fd605f88ffec\",\"best_bid\":\"0.991\",\"best_ask\":\"0.998\"},{\"asset_id\":\"112985164027628227488878312680394089251082925438802203342764659476692996732786\",\"price\":\"0.241\",\"size\":\"0\",\"side\":\"SELL\",\"hash\":\"bec8334732373d2e5873672eadcf31cd5986c592\",\"best_bid\":\"0.002\",\"best_ask\":\"0.009\"}],\"timestamp\":\"1785928837808\",\"event_type\":\"price_change\"}"}
{"recv_ts": 1785928837.9228628, "raw": "{\"market\":\"0x8c6a64a8ffd1bfa3d7df81172f976764a2c52c87c1a093897f90b7217d6fea8d\",\"price_changes\":[{\"asset_id\":\"13409836330652892121423735936121472669640499078426321052185227972804816382422\",\"price\":\"0.7\",\"size\":\"7.21\",\"side\":\"BUY\",\"hash\":\"97e49c104e471be3af5ca763526c8e12e86b3194\",\"best_bid\":\"0.908\",\"best_ask\":\"0.927\"},{\"asset_id\":\"83715211686534593705683144614374080403915454453849238224332560479040502634509\",\"price\":\"0.3\",\"size\":\"7.21\",\"side\":\"SELL\",\"hash\":\"a62e9441a84f73ed8861957cd5bb4325b9a608be\",\"best_bid\":\"0.073\",\"best_ask\":\"0.092\"}],\"timestamp\":\"1785928837807\",\"event_type\":\"price_change\"}"}
{"recv_ts": 1785928837.92287, "raw": "{\"market\":\"0x60dd5cb0ee09c2bfa3aebf6c0f467dad995cd569e2d02d6ef16a8e1574f3391a\",\"price_changes\":[{\"asset_id\":\"105587291707338677319901854004669096039802388717388366602161653820194749804003\",\"price\":\"0.757\",\"size\":\"0\",\"side\":\"BUY\",\"hash\":\"eb7f5d66c53ff5a2d3017c67f285fd605f88ffec\",\"best_bid\":\"0.991\",\"best_ask\":\"0.998\"},{\"asset_id\":\"112985164027628227488878312680394089251082925438802203342764659476692996732786\",\"price\":\"0.243\",\"size\":\"0\",\"side\":\"SELL\",\"hash\":\"bec8334732373d2e5873672eadcf31cd5986c592\",\"best_bid\":\"0.002\",\"best_ask\":\"0.009\"}],\"timestamp\":\"1785928837808\",\"event_type\":\"price_change\"}"}
{"recv_ts": 1785928837.922877, "raw": "{\"market\":\"0x8c6a64a8ffd1bfa3d7df81172f976764a2c52c87c1a093897f90b7217d6fea8d\",\"price_changes\":[{\"asset_id\":\"13409836330652892121423735936121472669640499078426321052185227972804816382422\",\"price\":\"0.698\",\"size\":\"0\",\"side\":\"BUY\",\"hash\":\"97e49c104e471be3af5ca763526c8e12e86b3194\",\"best_bid\":\"0.908\",\"best_ask\":\"0.927\"},{\"asset_id\":\"83715211686534593705683144614374080403915454453849238224332560479040502634509\",\"price\":\"0.302\",\"size\":\"0\",\"side\":\"SELL\",\"hash\":\"a62e9441a84f73ed8861957cd5bb4325b9a608be\",\"best_bid\":\"0.073\",\"best_ask\":\"0.092\"}],\"timestamp\":\"1785928837807\",\"event_type\":\"price_change\"}"}
{"recv_ts": 1785928837.9228837, "raw": "{\"market\":\"0x0db126ce7967f05290fe3c447fda7aadea75806e63d721b841181d37d361acff\",\"price_changes\":[{\"asset_id\":\"35835929224780790364362553368163009989775826083159639636027464056564214856030\",\"price\":\"0.42\",\"size\":\"0\",\"side\":\"BUY\",\"hash\":\"db8eafadae3d40704e117c6565af9e0a5d4b3e3f\",\"best_bid\":\"0.55\",\"best_ask\":\"0.65\"},{\"asset_id\":\"4788836516371088395388338986004317529952940613144895514047283950263185675387\",\"price\":\"0.58\",\"size\":\"0\",\"side\":\"SELL\",\"hash\":\"a2b77e171ae8a153d207576fe3d77bb36ffc1303\",\"best_bid\":\"0.35\",\"best_ask\":\"0.45\"}],\"timestamp\":\"1785928837807\",\"event_type\":\"price_change\"}"}
{"recv_ts": 1785928837.9228973, "raw": "{\"market\":\"0xc63b77f3ee336da37a4d56dbe4e0208b75a82a0328c1c0dae20892cc10dd3639\",\"price_changes\":[{\"asset_id\":\"47134398181755193148939338651935697535629466899703647579961809235723208653564\",\"price\":\"0.42\",\"size\":\"20\",\"side\":\"BUY\",\"hash\":\"1abad45d2a831be441e9d033b5e26f153cb83c9b\",\"best_bid\":\"0.49\",\"best_ask\":\"0.64\"},{\"asset_id\":\"47013553420493540294331062983804345798310691246036862411615126739061671840454\",\"price\":\"0.58\",\"size\":\"20\",\"side\":\"SELL\",\"hash\":\"1e58712eb7db6b4ae04dd7a8114909fb5f12dac7\",\"best_bid\":\"0.36\",\"best_ask\":\"0.51\"}],\"timestamp\":\"1785928837807\",\"event_type\":\"price_change\"}"}
{"recv_ts": 1785928837.922904, "raw": "{\"market\":\"0x29f7aaffe748d1d89ddcbd42ae23c99de64f96bea474165deca0eab1bb81af5c\",\"price_changes\":[{\"asset_id\":\"36511505070289859222068333212120928179759941913669314725077996651101613068646\",\"price\":\"0.748\",\"size\":\"0\",\"side\":\"BUY\",\"hash\":\"56d97e8caf7fb918b39de299f0872744b48744a5\",\"best_bid\":\"0.977\",\"best_ask\":\"0.987\"},{\"asset_id\":\"79052648470198021026660909312029738928593559509249411995852902181835680645124\",\"price\":\"0.252\",\"size\":\"0\",\"side\":\"SELL\",\"hash\":\"1fadf6e446c7c8b2da394d5f55dcd40e8bc58fca\",\"best_bid\":\"0.013\",\"best_ask\":\"0.023\"}],\"timestamp\":\"1785928837807\",\"event_type\":\"price_change\"}"}
{"recv_ts": 1785928837.9229105, "raw": "{\"market\":\"0xc63b77f3ee336da37a4d56dbe4e0208b75a82a0328c1c0dae20892cc10dd3639\",\"price_changes\":[{\"asset_id\":\"47134398181755193148939338651935697535629466899703647579961809235723208653564\",\"price\":\"0.41\",\"size\":\"10\",\"side\":\"BUY\",\"hash\":\"1abad45d2a831be441e9d033b5e26f153cb83c9b\",\"best_bid\":\"0.49\",\"best_ask\":\"0.64\"},{\"asset_id\":\"47013553420493540294331062983804345798310691246036862411615126739061671840454\",\"price\":\"0.59\",\"size\":\"10\",\"side\":\"SELL\",\"hash\":\"1e58712eb7db6b4ae04dd7a8114909fb5f12dac7\",\"best_bid\":\"0.36\",\"best_ask\":\"0.51\"}],\"timestamp\":\"1785928837807\",\"event_type\":\"price_change\"}"}
{"recv_ts": 1785928837.9229174, "raw": "{\"market\":\"0x29f7aaffe748d1d89ddcbd42ae23c99de64f96bea474165deca0eab1bb81af5c\",\"price_changes\":[{\"asset_id\":\"36511505070289859222068333212120928179759941913669314725077996651101613068646\",\"price\":\"0.746\",\"size\":\"0\",\"side\":\"BUY\",\"hash\":\"56d97e8caf7fb918b39de299f0872744b48744a5\",\"best_bid\":\"0.977\",\"best_ask\":\"0.987\"},{\"asset_id\":\"79052648470198021026660909312029738928593559509249411995852902181835680645124\",\"price\":\"0.254\",\"size\":\"0\",\"side\":\"SELL\",\"hash\":\"1fadf6e446c7c8b2da394d5f55dcd40e8bc58fca\",\"best_bid\":\"0.013\",\"best_ask\":\"0.023\"}],\"timestamp\":\"1785928837807\",\"event_type\":\"price_change\"}"}
{"recv_ts": 1785928837.9229243, "raw": "{\"market\":\"0x29f7aaffe748d1d89ddcbd42ae23c99de64f96bea474165deca0eab1bb81af5c\",\"price_changes\":[{\"asset_id\":\"36511505070289859222068333212120928179759941913669314725077996651101613068646\",\"price\":\"0.804\",\"size\":\"5\",\"side\":\"BUY\",\"hash\":\"fd54372aee990d8c46a161449ad82184cac7cf29\",\"best_bid\":\"0.977\",\"best_ask\":\"0.987\"},{\"asset_id\":\"79052648470198021026660909312029738928593559509249411995852902181835680645124\",\"price\":\"0.196\",\"size\":\"5\",\"side\":\"SELL\",\"hash\":\"8df8f0b38e32e73ce62460218593de240d5bb046\",\"best_bid\":\"0.013\",\"best_ask\":\"0.023\"}],\"timestamp\":\"1785928837808\",\"event_type\":\"price_change\"}"}
{"recv_ts": 1785928837.9229307, "raw": "{\"market\":\"0xcd4ac3a6578a23356aecba357b64f76d27674234c3d4754a08efd16bad3a975e\",\"price_changes\":[{\"asset_id\":\"27487852275060665491616972753944499454119120273037155333415153328314444194648\",\"price\":\"0.816\",\"size\":\"5\",\"side\":\"BUY\",\"hash\":\"1cd055f9274ae1799c715cec628c6758679c0722\",\"best_bid\":\"0.993\",\"best_ask\":\"0.999\"},{\"asset_id\":\"111209535652472112432522517641793708239144293646362321025603254860473020607660\",\"price\":\"0.184\",\"size\":\"5\",\"side\":\"SELL\",\"hash\":\"a1a055a8ff18faa2383961bf89e5a2a5ba9f0d80\",\"best_bid\":\"0.001\",\"best_ask\":\"0.007\"}],\"timestamp\":\"1785928837809\",\"event_type\":\"price_change\"}"}
{"recv_ts": 1785928837.9229372, "raw": "{\"market\":\"0x60dd5cb0ee09c2bfa3aebf6c0f467dad995cd569e2d02d6ef16a8e1574f3391a\",\"price_changes\":[{\"asset_id\":\"105587291707338677319901854004669096039802388717388366602161653820194749804003\",\"price\":\"0.813\",\"size\":\"5\",\"side\":\"BUY\",\"hash\":\"63ff01490e60198785234f75cc3bd6cbe87bd6aa\",\"best_bid\":\"0.991\",\"best_ask\":\"0.998\"},{\"asset_id\":\"112985164027628227488878312680394089251082925438802203342764659476692996732786\",\"price\":\"0.187\",\"size\":\"5\",\"side\":\"SELL\",\"hash\":\"94188641c73e5a7388aa5ba060e3b9334ab55544\",\"best_bid\":\"0.002\",\"best_ask\":\"0.009\"}],\"timestamp\":\"1785928837809\",\"event_type\":\"price_change\"}"}
{"recv_ts": 1785928837.9229443, "raw": "{\"market\":\"0xcd4ac3a6578a23356aecba357b64f76d27674234c3d4754a08efd16bad3a975e\",\"price_changes\":[{\"asset_id\":\"27487852275060665491616972753944499454119120273037155333415153328314444194648\",\"price\":\"0.785\",\"size\":\"5\",\"side\":\"BUY\",\"hash\":\"5b39db5a11661067372dad6ed68350ee660751bd\",\"best_bid\":\"0.993\",\"best_ask\":\"0.999\"},{\"asset_id\":\"111209535652472112432522517641793708239144293646362321025603254860473020607660\",\"price\":\"0.215\",\"size\":\"5\",\"side\":\"SELL\",\"hash\":\"8b595da02693fef6f51f31cc3275a393d60a5455\",\"best_bid\":\"0.001\",\"best_ask\":\"0.007\"}],\"timestamp\":\"1785928837809\",\"event_type\":\"price_change\"}"}
{"recv_ts": 1785928837.922952, "raw": "{\"market\":\"0x8c6a64a8ffd1bfa3d7df81172f976764a2c52c87c1a093897f90b7217d6fea8d\",\"price_changes\":[{\"asset_id\":\"13409836330652892121423735936121472669640499078426321052185227972804816382422\",\"price\":\"0.743\",\"size\":\"5\",\"side\":\"BUY\",\"hash\":\"2796f03d3707c951597de14336a1e2e91af5803f\",\"best_bid\":\"0.908\",\"best_ask\":\"0.927\"},{\"asset_id\":\"83715211686534593705683144614374080403915454453849238224332560479040502634509\",\"price\":\"0.257\",\"size\":\"5\",\"side\":\"SELL\",\"hash\":\"69654dc27d90a03d06a0040570a43d833c657b83\",\"best_bid\":\"0.073\",\"best_ask\":\"0.092\"}],\"timestamp\":\"1785928837810\",\"event_type\":\"price_change\"}"}
{"recv_ts": 1785928837.9229596, "raw": "{\"market\":\"0x8c6a64a8ffd1bfa3d7df81172f976764a2c52c87c1a093897f90b7217d6fea8d\",\"price_changes\":[{\"asset_id\":\"13409836330652892121423735936121472669640499078426321052185227972804816382422\",\"price\":\"0.717\",\"size\":\"5\",\"side\":\"BUY\",\"hash\":\"35889257601f26bda202f69d7003f76135e96a6d\",\"best_bid\":\"0.908\",\"best_ask\":\"0.927\"},{\"asset_id\":\"83715211686534593705683144614374080403915454453849238224332560479040502634509\",\"price\":\"0.283\",\"size\":\"5\",\"side\":\"SELL\",\"hash\":\"d1de7556912acfab10c512a77ce09d3a7f0a330b\",\"best_bid\":\"0.073\",\"best_ask\":\"0.092\"}],\"timestamp\":\"1785928837811\",\"event_type\":\"price_change\"}"}
{"recv_ts": 1785928837.9229665, "raw": "{\"market\":\"0xcd4ac3a6578a23356aecba357b64f76d27674234c3d4754a08efd16bad3a975e\",\"price_changes\":[{\"asset_id\":\"27487852275060665491616972753944499454119120273037155333415153328314444194648\",\"price\":\"0.787\",\"size\":\"5\",\"side\":\"BUY\",\"hash\":\"db16bc66094fd3f1991c29ea564c338efb72593d\",\"best_bid\":\"0.993\",\"best_ask\":\"0.999\"},{\"asset_id\":\"111209535652472112432522517641793708239144293646362321025603254860473020607660\",\"price\":\"0.213\",\"size\":\"5\",\"side\":\"SELL\",\"hash\":\"f0ee475944bfa904ad80fdcca57db54d3ae30d7c\",\"best_bid\":\"0.001\",\"best_ask\":\"0.007\"}],\"timestamp\":\"1785928837812\",\"event_type\":\"price_change\"}"}
{"recv_ts": 1785928837.9229734, "raw": "{\"market\":\"0xc63b77f3ee336da37a4d56dbe4e0208b75a82a0328c1c0dae20892cc10dd3639\",\"price_changes\":[{\"asset_id\":\"47134398181755193148939338651935697535629466899703647579961809235723208653564\",\"price\":\"0.45\",\"size\":\"10\",\"side\":\"BUY\",\"hash\":\"e5fe24253e930ab04b2f1356b7607acd4c1a5b0f\",\"best_bid\":\"0.49\",\"best_ask\":\"0.64\"},{\"asset_id\":\"47013553420493540294331062983804345798310691246036862411615126739061671840454\",\"price\":\"0.55\",\"size\":\"10\",\"side\":\"SELL\",\"hash\":\"76002c059e53a8d567362c36d56a0735bb101987\",\"best_bid\":\"0.36\",\"best_ask\":\"0.51\"}],\"timestamp\":\"1785928837813\",\"event_type\":\"price_change\"}"}
{"recv_ts": 1785928837.9229875, "raw": "{\"market\":\"0x29f7aaffe748d1d89ddcbd42ae23c99de64f96bea474165deca0eab1bb81af5c\",\"price_changes\":[{\"asset_id\":\"36511505070289859222068333212120928179759941913669314725077996651101613068646\",\"price\":\"0.773\",\"size\":\"5\",\"side\":\"BUY\",\"hash\":\"88e0828a2e4506e6c5414a1a1cf99c004386b705\",\"best_bid\":\"0.977\",\"best_ask\":\"0.987\"},{\"asset_id\":\"79052648470198021026660909312029738928593559509249411995852902181835680645124\",\"price\":\"0.227\",\"size\":\"5\",\"side\":\"SELL\",\"hash\":\"2c7702082613275079dc98d401f6accf2aeab16f\",\"best_bid\":\"0.013\",\"best_ask\":\"0.023\"}],\"timestamp\":\"1785928837813\",\"event_type\":\"price_change\"}"}
{"recv_ts": 1785928837.922994, "raw": "{\"market\":\"0x60dd5cb0ee09c2bfa3aebf6c0f467dad995cd569e2d02d6ef16a8e1574f3391a\",\"price_changes\":[{\"asset_id\":\"105587291707338677319901854004669096039802388717388366602161653820194749804003\",\"price\":\"0.786\",\"size\":\"5\",\"side\":\"BUY\",\"hash\":\"9a49ed410df7c9d27ec9492c32fc3b7e73b3cef7\",\"best_bid\":\"0.991\",\"best_ask\":\"0.998\"},{\"asset_id\":\"112985164027628227488878312680394089251082925438802203342764659476692996732786\",\"price\":\"0.214\",\"size\":\"5\",\"side\":\"SELL\",\"hash\":\"0c8be7e461a49f8ed053fd5afa75fc166eb7b3a9\",\"best_bid\":\"0.002\",\"best_ask\":\"0.009\"}],\"timestamp\":\"1785928837814\",\"event_type\":\"price_change\"}"}
{"recv_ts": 1785928837.9230006, "raw": "{\"market\":\"0x0db126ce7967f05290fe3c447fda7aadea75806e63d721b841181d37d361acff\",\"price_changes\":[{\"asset_id\":\"35835929224780790364362553368163009989775826083159639636027464056564214856030\",\"price\":\"0.43\",\"size\":\"35\",\"side\":\"BUY\",\"hash\":\"4f446aa9a26ab2b19744b284003711faece9e986\",\"best_bid\":\"0.55\",\"best_ask\":\"0.65\"},{\"asset_id\":\"4788836516371088395388338986004317529952940613144895514047283950263185675387\",\"price\":\"0.57\",\"size\":\"35\",\"side\":\"SELL\",\"hash\":\"52ecf66842331683c8534d56aa845e2e8f77844a\",\"best_bid\":\"0.35\",\"best_ask\":\"0.45\"}],\"timestamp\":\"1785928837815\",\"event_type\":\"price_change\"}"}
{"recv_ts": 1785928837.9230082, "raw": "{\"market\":\"0x0fc2f6268feaef436c823c1824f62706c6eb2715397751e5da5fbd61e7d71025\",\"price_changes\":[{\"asset_id\":\"43558042711663224323089716504686480613254622318408013281716785638216020017932\",\"price\":\"0.74\",\"size\":\"5\",\"side\":\"BUY\",\"hash\":\"03e9e480a0b085947c507a092c87a9f7d7e13965\",\"best_bid\":\"0.95\",\"best_ask\":\"0.96\"},{\"asset_id\":\"98193888735084412499188018668234638776987362559885132138120992642932186443125\",\"price\":\"0.26\",\"size\":\"5\",\"side\":\"SELL\",\"hash\":\"a66c3aa726b355ec52c7d04a8f0defb33cb017f2\",\"best_bid\":\"0.04\",\"best_ask\":\"0.05\"}],\"timestamp\":\"1785928837816\",\"event_type\":\"price_change\"}"}
{"recv_ts": 1785928837.9230154, "raw": "{\"market\":\"0x0db126ce7967f05290fe3c447fda7aadea75806e63d721b841181d37d361acff\",\"price_changes\":[{\"asset_id\":\"35835929224780790364362553368163009989775826083159639636027464056564214856030\",\"price\":\"0.44\",\"size\":\"80.73\",\"side\":\"BUY\",\"hash\":\"d0c31de77b24f10acd8a9d3af18fa04d8918ca8f\",\"best_bid\":\"0.55\",\"best_ask\":\"0.65\"},{\"asset_id\":\"4788836516371088395388338986004317529952940613144895514047283950263185675387\",\"price\":\"0.56\",\"size\":\"80.73\",\"side\":\"SELL\",\"hash\":\"2de362172d11bcf5182e143eb919995145992b19\",\"best_bid\":\"0.35\",\"best_ask\":\"0.45\"}],\"timestamp\":\"1785928837817\",\"event_type\":\"price_change\"}"}
{"recv_ts": 1785928837.923022, "raw": "{\"market\":\"0xb00ea2f63c9e34ab13d477e1fdd1817fe9e1884dcd4a31003d53e764e3ede49c\",\"price_changes\":[{\"asset_id\":\"103863072680508819456799466047880311398774458712012103097990130731304502610158\",\"price\":\"0.39\",\"size\":\"40\",\"side\":\"BUY\",\"hash\":\"60ab1508a4d1ae4699871b6abedbf14ca2367780\",\"best_bid\":\"0.58\",\"best_ask\":\"0.59\"},{\"asset_id\":\"105183690526418859772129322051491946056033828239291818040036511065016553030234\",\"price\":\"0.61\",\"size\":\"40\",\"side\":\"SELL\",\"hash\":\"737d97b1d59306f6f9c26a4cfc7749dadeedbb67\",\"best_bid\":\"0.41\",\"best_ask\":\"0.42\"}],\"timestamp\":\"1785928837817\",\"event_type\":\"price_change\"}"}
{"recv_ts": 1785928837.9230285, "raw": "{\"market\":\"0xc63b77f3ee336da37a4d56dbe4e0208b75a82a0328c1c0dae20892cc10dd3639\",\"price_changes\":[{\"asset_id\":\"47134398181755193148939338651935697535629466899703647579961809235723208653564\",\"price\":\"0.44\",\"size\":\"5\",\"side\":\"BUY\",\"hash\":\"0e88056eb27f509571b14cb97ab908dc883f0e99\",\"best_bid\":\"0.49\",\"best_ask\":\"0.64\"},{\"asset_id\":\"47013553420493540294331062983804345798310691246036862411615126739061671840454\",\"price\":\"0.56\",\"size\":\"5\",\"side\":\"SELL\",\"hash\":\"914eabc832c5b91b23816a5f9edcc74f23f000a5\",\"best_bid\":\"0.36\",\"best_ask\":\"0.51\"}],\"timestamp\":\"1785928837818\",\"event_type\":\"price_change\"}"}
{"recv_ts": 1785928837.923041, "raw": "{\"market\":\"0x60dd5cb0ee09c2bfa3aebf6c0f467dad995cd569e2d02d6ef16a8e1574f3391a\",\"price_changes\":[{\"asset_id\":\"105587291707338677319901854004669096039802388717388366602161653820194749804003\",\"price\":\"0.784\",\"size\":\"5\",\"side\":\"BUY\",\"hash\":\"f626db647850cd36f1b1bbf64678cc9d6e151d5e\",\"best_bid\":\"0.991\",\"best_ask\":\"0.998\"},{\"asset_id\":\"112985164027628227488878312680394089251082925438802203342764659476692996732786\",\"price\":\"0.216\",\"size\":\"5\",\"side\":\"SELL\",\"hash\":\"65118401eee5a2e3b01f6530affb544f6a74e380\",\"best_bid\":\"0.002\",\"best_ask\":\"0.009\"}],\"timestamp\":\"1785928837818\",\"event_type\":\"price_change\"}"}
{"recv_ts": 1785928837.9230492, "raw": "{\"market\":\"0x8c6a64a8ffd1bfa3d7df81172f976764a2c52c87c1a093897f90b7217d6fea8d\",\"price_changes\":[{\"asset_id\":\"13409836330652892121423735936121472669640499078426321052185227972804816382422\",\"price\":\"0.719\",\"size\":\"5\",\"side\":\"BUY\",\"hash\":\"9d73f6b86f6e65b9b887c21c9c7dd3a3ff695345\",\"best_bid\":\"0.908\",\"best_ask\":\"0.927\"},{\"asset_id\":\"83715211686534593705683144614374080403915454453849238224332560479040502634509\",\"price\":\"0.281\",\"size\":\"5\",\"side\":\"SELL\",\"hash\":\"479c554b36fdc7148428da8ea71d0beac3265873\",\"best_bid\":\"0.073\",\"best_ask\":\"0.092\"}],\"timestamp\":\"1785928837819\",\"event_type\":\"price_change\"}"}
{"recv_ts": 1785928837.9230592, "raw": "{\"market\":\"0x0fc2f6268feaef436c823c1824f62706c6eb2715397751e5da5fbd61e7d71025\",\"price_changes\":[{\"asset_id\":\"43558042711663224323089716504686480613254622318408013281716785638216020017932\",\"price\":\"0.73\",\"size\":\"5\",\"side\":\"BUY\",\"hash\":\"1792b9f19bbca61d7b37a7562081168a77b09c9e\",\"best_bid\":\"0.95\",\"best_ask\":\"0.96\"},{\"asset_id\":\"98193888735084412499188018668234638776987362559885132138120992642932186443125\",\"price\":\"0.27\",\"size\":\"5\",\"side\":\"SELL\",\"hash\":\"e9131a3691caa034b98ef8e433994ffad96e22ed\",\"best_bid\":\"0.04\",\"best_ask\":\"0.05\"}],\"timestamp\":\"1785928837820\",\"event_type\":\"price_change\"}"}
{"recv_ts": 1785928837.92307, "raw": "{\"market\":\"0x29f7aaffe748d1d89ddcbd42ae23c99de64f96bea474165deca0eab1bb81af5c\",\"price_changes\":[{\"asset_id\":\"36511505070289859222068333212120928179759941913669314725077996651101613068646\",\"price\":\"0.775\",\"size\":\"5\",\"side\":\"BUY\",\"hash\":\"461472bb10991d55a6ab9605dce13fb6627076ca\",\"best_bid\":\"0.977\",\"best_ask\":\"0.987\"},{\"asset_id\":\"79052648470198021026660909312029738928593559509249411995852902181835680645124\",\"price\":\"0.225\",\"size\":\"5\",\"side\":\"SELL\",\"hash\":\"c7cff7de0c158f3131cfe66363a94fc1f41b3921\",\"best_bid\":\"0.013\",\"best_ask\":\"0.023\"}],\"timestamp\":\"1785928837821\",\"event_type\":\"price_change\"}"}
{"recv_ts": 1785928837.9230797, "raw": "{\"market\":\"0x642cbdc82c82a4fbdbe2a4d2d9e736437c4964d01a380495031d60a9ef7db584\",\"price_changes\":[{\"asset_id\":\"70656373024994622637329737055820446980309053018940023843531019037164331264231\",\"price\":\"0.481\",\"size\":\"0\",\"side\":\"BUY\",\"hash\":\"516b03437daeb61de6f290b708c385b2e40a2666\",\"best_bid\":\"0.991\",\"best_ask\":\"0.998\"},{\"asset_id\":\"58169314657178736174419656073174039884719438889707165411208205980340573542844\",\"price\":\"0.519\",\"size\":\"0\",\"side\":\"SELL\",\"hash\":\"781e34dbdd1e46f26dde517918af9a34c9973524\",\"best_bid\":\"0.002\",\"best_ask\":\"0.009\"}],\"timestamp\":\"1785928837842\",\"event_type\":\"price_change\"}"}
{"recv_ts": 1785928837.9421976, "raw": "{\"market\":\"0x838c8b1374b74742b25ef4a15c8f99969fdf346f1922741a352f4bc10ada0a3f\",\"price_changes\":[{\"asset_id\":\"5375457723065783779279424542147357853818386446602787308158710973888670874335\",\"price\":\"0.82\",\"size\":\"5\",\"side\":\"BUY\",\"hash\":\"7b08fd50bfd1f405e789e3e1e61d13af11198579\",\"best_bid\":\"0.82\",\"best_ask\":\"0.97\"},{\"asset_id\":\"110953710557391685151254163016419793353576076714107360351886720169266932594443\",\"price\":\"0.18\",\"size\":\"5\",\"side\":\"SELL\",\"hash\":\"612716d26cc65157f4a5172a1b519c6a80920dc5\",\"best_bid\":\"0.03\",\"best_ask\":\"0.18\"}],\"timestamp\":\"1785928837798\",\"event_type\":\"price_change\"}"}
{"recv_ts": 1785928837.9422495, "raw": "{\"market\":\"0xf54ae434dd707eb46704d2a73a173e1abb8f79a6c73490d4724a7179b495e0b7\",\"price_changes\":[{\"asset_id\":\"78315646603106684031343800789850431783405075770039481340741625933426744732240\",\"price\":\"0.87\",\"size\":\"0\",\"side\":\"BUY\",\"hash\":\"4887ffea29388bc78b5dbc9b3b87d164ec262409\",\"best_bid\":\"0.88\",\"best_ask\":\"0.98\"},{\"asset_id\":\"77857731064896872653582592932137102425749502805329271503389620183534450460402\",\"price\":\"0.13\",\"size\":\"0\",\"side\":\"SELL\",\"hash\":\"ae4d07c37627ee373f7c1ef6e80826ca1b68152e\",\"best_bid\":\"0.02\",\"best_ask\":\"0.12\"}],\"timestamp\":\"1785928837806\",\"event_type\":\"price_change\"}"}
{"recv_ts": 1785928837.942261, "raw": "{\"market\":\"0x838c8b1374b74742b25ef4a15c8f99969fdf346f1922741a352f4bc10ada0a3f\",\"price_changes\":[{\"asset_id\":\"5375457723065783779279424542147357853818386446602787308158710973888670874335\",\"price\":\"0.83\",\"size\":\"10\",\"side\":\"BUY\",\"hash\":\"d1a7dcc55b5d93e2fc54d4e166d1e9f196fcc6c8\",\"best_bid\":\"0.83\",\"best_ask\":\"0.97\"},{\"asset_id\":\"110953710557391685151254163016419793353576076714107360351886720169266932594443\",\"price\":\"0.17\",\"size\":\"10\",\"side\":\"SELL\",\"hash\":\"3303a3470e13084f7b4660de85d5c7c3aa3a73f2\",\"best_bid\":\"0.03\",\"best_ask\":\"0.17\"}],\"timestamp\":\"1785928837861\",\"event_type\":\"price_change\"}"}
{"recv_ts": 1785928837.9422703, "raw": "{\"market\":\"0x376b671a61a557a4c380c43b9ca3e40f8d355e6409b98fb5508d1d2ddd879fbe\",\"price_changes\":[{\"asset_id\":\"40859689113347339367411969530768845110751313937978733104418509283357180472010\",\"price\":\"0.012\",\"size\":\"0\",\"side\":\"BUY\",\"hash\":\"b06afb8b5dac30098c82c2003e78b5082a92c79c\",\"best_bid\":\"0.992\",\"best_ask\":\"0.999\"},{\"asset_id\":\"62162395672554756590822376368235710306364782506546574945936887484665928986278\",\"price\":\"0.988\",\"size\":\"0\",\"side\":\"SELL\",\"hash\":\"3b0e22955e2e521f77e67c16c9e00246bd1d6257\",\"best_bid\":\"0.001\",\"best_ask\":\"0.008\"}],\"timestamp\":\"1785928837877\",\"event_type\":\"price_change\"}"}
{"recv_ts": 1785928837.9422796, "raw": "{\"market\":\"0x838c8b1374b74742b25ef4a15c8f99969fdf346f1922741a352f4bc10ada0a3f\",\"price_changes\":[{\"asset_id\":\"5375457723065783779279424542147357853818386446602787308158710973888670874335\",\"price\":\"0.8\",\"size\":\"0\",\"side\":\"BUY\",\"hash\":\"bc6d524e9769cb07a3bf9f65d693e4579b4b308f\",\"best_bid\":\"0.83\",\"best_ask\":\"0.97\"},{\"asset_id\":\"110953710557391685151254163016419793353576076714107360351886720169266932594443\",\"price\":\"0.2\",\"size\":\"0\",\"side\":\"SELL\",\"hash\":\"0f04de2c470793560b46881dcba59b264c682bf7\",\"best_bid\":\"0.03\",\"best_ask\":\"0.17\"}],\"timestamp\":\"1785928837902\",\"event_type\":\"price_change\"}"}
{"recv_ts": 1785928837.9422925, "raw": "{\"market\":\"0x04fe7337f376f8931cd3068461cec68037535ce97abcf13c042152baf13befde\",\"price_changes\":[{\"asset_id\":\"50740292274847780209507644462307574612676149355535035139336442040374589113775\",\"price\":\"0.38\",\"size\":\"480\",\"side\":\"BUY\",\"hash\":\"16dfa765a8aabd35b61cc8a79e2dfeb6bd6aeaad\",\"best_bid\":\"0.39\",\"best_ask\":\"0.4\"},{\"asset_id\":\"53770307109125981002170328887835960390908711352346661961390902843874235145088\",\"price\":\"0.62\",\"size\":\"480\",\"side\":\"SELL\",\"hash\":\"f42747d3c77ca0ae84d0979481ceac84135fceba\",\"best_bid\":\"0.6\",\"best_ask\":\"0.61\"}],\"timestamp\":\"1785928837795\",\"event_type\":\"price_change\"}"}
{"recv_ts": 1785928837.9423006, "raw": "{\"market\":\"0x5f6237736dc11d27fba4fad4fb25f99efd989f317b526ea34e3389aed21e9989\",\"price_changes\":[{\"asset_id\":\"37621045142846649045567920410637528745565882107360712540945877385602345149225\",\"price\":\"0.034\",\"size\":\"0\",\"side\":\"BUY\",\"hash\":\"bf5c3f5327eaf40d0875e1a4037b48d20caf23f0\",\"best_bid\":\"0.035\",\"best_ask\":\"0.065\"},{\"asset_id\":\"43057741765998250782966918529553157356197931933657738370765235809855474471330\",\"price\":\"0.966\",\"size\":\"0\",\"side\":\"SELL\",\"hash\":\"23cda5ea059dcf4ddae6e119d3114116fe620eb0\",\"best_bid\":\"0.935\",\"best_ask\":\"0.965\"}],\"timestamp\":\"1785928837800\",\"event_type\":\"price_change\"}"}
{"recv_ts": 1785928837.942308, "raw": "{\"market\":\"0xbb56f84320f6a322405d2a673ae1c09791696dfee009c8b4924a4d50ce02fdb2\",\"price_changes\":[{\"asset_id\":\"36752791203026604630773349263680321016807027579769857760609995963265445842019\",\"price\":\"0.918\",\"size\":\"0\",\"side\":\"BUY\",\"hash\":\"d4eae35a58aff1c35fcbb9d9d0f6d203a7bbfe17\",\"best_bid\":\"0.95\",\"best_ask\":\"0.962\"},{\"asset_id\":\"3419269731159625127662380738887584521691084977785981284355622556812487764723\",\"price\":\"0.082\",\"size\":\"0\",\"side\":\"SELL\",\"hash\":\"98845c8387e34a8898ebf7fbf1d8c5714e7ac843\",\"best_bid\":\"0.038\",\"best_ask\":\"0.05\"}],\"timestamp\":\"1785928837803\",\"event_type\":\"price_change\"}"}
{"recv_ts": 1785928837.942316, "raw": "{\"market\":\"0x49e0bc2d92fd5118263bb3968c679cb8e236c6912d899b48b3925f26ed9ee209\",\"price_changes\":[{\"asset_id\":\"80051321337559111951453828109935186137789769064013919737026204361460144693479\",\"price\":\"0.57\",\"size\":\"0\",\"side\":\"SELL\",\"hash\":\"aa756a0176b00697319fcde56b17b851cde17973\",\"best_bid\":\"0.3\",\"best_ask\":\"0.38\"},{\"asset_id\":\"9622500641191387664431955870185399485936790493585104294220539600837039752975\",\"price\":\"0.43\",\"size\":\"0\",\"side\":\"BUY\",\"hash\":\"563b1df0c67f616eef267690192c41f5f942910f\",\"best_bid\":\"0.62\",\"best_ask\":\"0.7\"}],\"timestamp\":\"1785928837803\",\"event_type\":\"price_change\"}"}
{"recv_ts": 1785928837.942324, "raw": "{\"market\":\"0xb486739040088c936e729d74081f0e81fc48fce7151e5e41243d9d219453e2fe\",\"price_changes\":[{\"asset_id\":\"31140992653083956068389050095744741836184250715525331976510476908962593127814\",\"price\":\"0.56\",\"size\":\"221.88\",\"side\":\"BUY\",\"hash\":\"3fe6300b529711939b61819bbd935885719a4011\",\"best_bid\":\"0.98\",\"best_ask\":\"0.99\"},{\"asset_id\":\"2695957428619450078473712547501643526076503784897710224766392221435772884261\",\"price\":\"0.44\",\"size\":\"221.88\",\"side\":\"SELL\",\"hash\":\"f450b1bf1330ed76dd5797a3547614847bad3e6d\",\"best_bid\":\"0.01\",\"best_ask\":\"0.02\"}],\"timestamp\":\"1785928837804\",\"event_type\":\"price_change\"}"}
{"recv_ts": 1785928837.9423316, "raw": "{\"market\":\"0x130cc223b8cf2d0aa833c1cd308d9bc9ae541a0603813493d86db8e6ceeaf367\",\"price_changes\":[{\"asset_id\":\"84797559581459129894146686397592394213402216446504178493974835270512414528595\",\"price\":\"0.38\",\"size\":\"5.26\",\"side\":\"BUY\",\"hash\":\"36341914e311108e4d484f40a46bbf292a196200\",\"best_bid\":\"0.65\",\"best_ask\":\"0.78\"},{\"asset_id\":\"50417249107122530467347355639451540409667050551215201803480978137821249864431\",\"price\":\"0.62\",\"size\":\"5.26\",\"side\":\"SELL\",\"hash\":\"2bf20735b0ad24ca7ce850087c172f26fca4cd65\",\"best_bid\":\"0.22\",\"best_ask\":\"0.35\"}],\"timestamp\":\"1785928837819\",\"event_type\":\"price_change\"}"}
{"recv_ts": 1785928837.9423385, "raw": "{\"market\":\"0x9d59ce284519e9f2f0369add65ec0dea4e30478960f285abc70af2d1b76beec2\",\"price_changes\":[{\"asset_id\":\"8503403807554825835825187516742241065300919332765839374024863929306661721210\",\"price\":\"0.318\",\"size\":\"0\",\"side\":\"BUY\",\"hash\":\"93cfb2736cc0f7569d0c87978924eafb47937496\",\"best_bid\":\"0.998\",\"best_ask\":\"0.999\"},{\"asset_id\":\"30223512369396895064014083752486018049203540341317193220024366876194287102529\",\"price\":\"0.682\",\"size\":\"0\",\"side\":\"SELL\",\"hash\":\"9a3922089e10a5a638ca24e4d8ff97927095b390\",\"best_bid\":\"0.001\",\"best_ask\":\"0.002\"}],\"timestamp\":\"1785928837824\",\"event_type\":\"price_change\"}"}
{"recv_ts": 1785928837.94238, "raw": "{\"market\":\"0xec806996a4a5f6acd2d6a18f51b15c3aa1c51ab9742183e0e6878d58cce5a0d0\",\"price_changes\":[{\"asset_id\":\"17118616214138798454321086756896158972659063265161382365722741404449969675213\",\"price\":\"0.63\",\"size\":\"10\",\"side\":\"BUY\",\"hash\":\"5e3b77fa81ed7896ccd36e2266083c3dfdbc1447\",\"best_bid\":\"0.89\",\"best_ask\":\"0.98\"},{\"asset_id\":\"66442850127194305408378836595684234249962298005014821789027805328236573201788\",\"price\":\"0.37\",\"size\":\"10\",\"side\":\"SELL\",\"hash\":\"f0641d93a23852c80d39133eb8e9bafb6006a2dc\",\"best_bid\":\"0.02\",\"best_ask\":\"0.11\"}],\"timestamp\":\"1785928837824\",\"event_type\":\"price_change\"}"}
{"recv_ts": 1785928837.942387, "raw": "{\"market\":\"0x130cc223b8cf2d0aa833c1cd308d9bc9ae541a0603813493d86db8e6ceeaf367\",\"price_changes\":[{\"asset_id\":\"84797559581459129894146686397592394213402216446504178493974835270512414528595\",\"price\":\"0.45\",\"size\":\"0\",\"side\":\"BUY\",\"hash\":\"44f1c6f99ad644779e398758084db07774ef0d6a\",\"best_bid\":\"0.65\",\"best_ask\":\"0.78\"},{\"asset_id\":\"50417249107122530467347355639451540409667050551215201803480978137821249864431\",\"price\":\"0.55\",\"size\":\"0\",\"side\":\"SELL\",\"hash\":\"08d13e8d23e18d66971c8dd0e5ea4d40679a1e62\",\"best_bid\":\"0.22\",\"best_ask\":\"0.35\"}],\"timestamp\":\"1785928837824\",\"event_type\":\"price_change\"}"}
{"recv_ts": 1785928837.9423938, "raw": "{\"market\":\"0x130cc223b8cf2d0aa833c1cd308d9bc9ae541a0603813493d86db8e6ceeaf367\",\"price_changes\":[{\"asset_id\":\"84797559581459129894146686397592394213402216446504178493974835270512414528595\",\"price\":\"0.34\",\"size\":\"5.88\",\"side\":\"BUY\",\"hash\":\"44f1c6f99ad644779e398758084db07774ef0d6a\",\"best_bid\":\"0.65\",\"best_ask\":\"0.78\"},{\"asset_id\":\"50417249107122530467347355639451540409667050551215201803480978137821249864431\",\"price\":\"0.66\",\"size\":\"5.88\",\"side\":\"SELL\",\"hash\":\"08d13e8d23e18d66971c8dd0e5ea4d40679a1e62\",\"best_bid\":\"0.22\",\"best_ask\":\"0.35\"}],\"timestamp\":\"1785928837824\",\"event_type\":\"price_change\"}"}
{"recv_ts": 1785928837.9424007, "raw": "{\"market\":\"0xb6edcec0d720dbec04c1ccad106f8cae4168791c17ef7981ba5dd999af079865\",\"price_changes\":[{\"asset_id\":\"18116214702249440028416672680904535920938539838669208127252902741898575306507\",\"price\":\"0.641\",\"size\":\"0\",\"side\":\"BUY\",\"hash\":\"d312ca5fa79ad396d02805053bca501597005ed5\",\"best_bid\":\"0.998\",\"best_ask\":\"1\"},{\"asset_id\":\"111500185607543632995147702414312573517975210173310244515899623973650146423799\",\"price\":\"0.359\",\"size\":\"0\",\"side\":\"SELL\",\"hash\":\"45d65eac3cdd73ae9549380e985ac9de233326a4\",\"best_bid\":\"0\",\"best_ask\":\"0.002\"}],\"timestamp\":\"1785928837824\",\"event_type\":\"price_change\"}"}
{"recv_ts": 1785928837.9424074, "raw": "{\"market\":\"0xec806996a4a5f6acd2d6a18f51b15c3aa1c51ab9742183e0e6878d58cce5a0d0\",\"price_changes\":[{\"asset_id\":\"17118616214138798454321086756896158972659063265161382365722741404449969675213\",\"price\":\"0.31\",\"size\":\"0\",\"side\":\"BUY\",\"hash\":\"5e3b77fa81ed7896ccd36e2266083c3dfdbc1447\",\"best_bid\":\"0.89\",\"best_ask\":\"0.98\"},{\"asset_id\":\"66442850127194305408378836595684234249962298005014821789027805328236573201788\",\"price\":\"0.69\",\"size\":\"0\",\"side\":\"SELL\",\"hash\":\"f0641d93a23852c80d39133eb8e9bafb6006a2dc\",\"best_bid\":\"0.02\",\"best_ask\":\"0.11\"}],\"timestamp\":\"1785928837824\",\"event_type\":\"price_change\"}"}
{"recv_ts": 1785928837.942414, "raw": "{\"market\":\"0xb486739040088c936e729d74081f0e81fc48fce7151e5e41243d9d219453e2fe\",\"price_changes\":[{\"asset_id\":\"31140992653083956068389050095744741836184250715525331976510476908962593127814\",\"price\":\"0.64\",\"size\":\"40\",\"side\":\"BUY\",\"hash\":\"faf9a35e6a89f0046d2af7c00dfd5b482c88b4f5\",\"best_bid\":\"0.98\",\"best_ask\":\"0.99\"},{\"asset_id\":\"2695957428619450078473712547501643526076503784897710224766392221435772884261\",\"price\":\"0.36\",\"size\":\"40\",\"side\":\"SELL\",\"hash\":\"6f067d45933b6556c02957aa1a16fd3b5f79304f\",\"best_bid\":\"0.01\",\"best_ask\":\"0.02\"}],\"timestamp\":\"1785928837824\",\"event_type\":\"price_change\"}"}
{"recv_ts": 1785928837.9424205, "raw": "{\"market\":\"0xab566cdbff91073332a0e2ed9ff5a067c91f4295b45e7f419b811f7cc57b8edb\",\"price_changes\":[{\"asset_id\":\"858224069165336107309887139101186345264990943433876453050435444819500042777\",\"price\":\"0.641\",\"size\":\"0\",\"side\":\"BUY\",\"hash\":\"7e34a6ae23f15fe4cbbe1acb74fdb8c710a2bd47\",\"best_bid\":\"0.998\",\"best_ask\":\"1\"},{\"asset_id\":\"78339664986092019828629644767444699887634765118583590448691028633408082863680\",\"price\":\"0.359\",\"size\":\"0\",\"side\":\"SELL\",\"hash\":\"e67e13e3efa223cd321a4189590875eb541d8910\",\"best_bid\":\"0\",\"best_ask\":\"0.002\"}],\"timestamp\":\"1785928837824\",\"event_type\":\"price_change\"}"}
{"recv_ts": 1785928837.9424272, "raw": "{\"market\":\"0x130cc223b8cf2d0aa833c1cd308d9bc9ae541a0603813493d86db8e6ceeaf367\",\"price_changes\":[{\"asset_id\":\"84797559581459129894146686397592394213402216446504178493974835270512414528595\",\"price\":\"0.22\",\"size\":\"9.09\",\"side\":\"BUY\",\"hash\":\"44f1c6f99ad644779e398758084db07774ef0d6a\",\"best_bid\":\"0.65\",\"best_ask\":\"0.78\"},{\"asset_id\":\"50417249107122530467347355639451540409667050551215201803480978137821249864431\",\"price\":\"0.78\",\"size\":\"9.09\",\"side\":\"SELL\",\"hash\":\"08d13e8d23e18d66971c8dd0e5ea4d40679a1e62\",\"best_bid\":\"0.22\",\"best_ask\":\"0.35\"}],\"timestamp\":\"1785928837824\",\"event_type\":\"price_change\"}"}
{"recv_ts": 1785928837.9424338, "raw": "{\"market\":\"0xe9b4e8a317c00cc347c95c9a36720492f7929f8e4cb4c1aa6c49410742ca3247\",\"price_changes\":[{\"asset_id\":\"49725804003683168820158044063139299301568536146474955034537761285736915106189\",\"price\":\"0.65\",\"size\":\"45\",\"side\":\"BUY\",\"hash\":\"d784a32a1ce3bb2d42c0fb4b3b5ba0f6aff0c6f4\",\"best_bid\":\"0.998\",\"best_ask\":\"0.999\"},{\"asset_id\":\"69779375789382878827509646477200695767063770808156104602588660330492573155019\",\"price\":\"0.35\",\"size\":\"45\",\"side\":\"SELL\",\"hash\":\"c0f1e6a98a64ded314f6c6d8d1231b64ab4425e2\",\"best_bid\":\"0.001\",\"best_ask\":\"0.002\"}],\"timestamp\":\"1785928837825\",\"event_type\":\"price_change\"}"}
{"recv_ts": 1785928837.9424407, "raw": "{\"market\":\"0xab566cdbff91073332a0e2ed9ff5a067c91f4295b45e7f419b811f7cc57b8edb\",\"price_changes\":[{\"asset_id\":\"858224069165336107309887139101186345264990943433876453050435444819500042777\",\"price\":\"0.319\",\"size\":\"0\",\"side\":\"BUY\",\"hash\":\"7e34a6ae23f15fe4cbbe1acb74fdb8c710a2bd47\",\"best_bid\":\"0.998\",\"best_ask\":\"1\"},{\"asset_id\":\"78339664986092019828629644767444699887634765118583590448691028633408082863680\",\"price\":\"0.681\",\"size\":\"0\",\"side\":\"SELL\",\"hash\":\"e67e13e3efa223cd321a4189590875eb541d8910\",\"best_bid\":\"0\",\"best_ask\":\"0.002\"}],\"timestamp\":\"1785928837824\",\"event_type\":\"price_change\"}"}
{"recv_ts": 1785928837.942448, "raw": "{\"market\":\"0xb0888f1ce675a9aa0922477fe51dee0301f8151c6c654fdca0b6686b3d950d72\",\"price_changes\":[{\"asset_id\":\"23899216176849972464746004559512101061428203436614711958419582587808176252521\",\"price\":\"0.641\",\"size\":\"45\",\"side\":\"BUY\",\"hash\":\"7d39dfe512da8d53fe49182be6c9eadff90beda4\",\"best_bid\":\"0.999\",\"best_ask\":\"1\"},{\"asset_id\":\"36643957373341611960904326441294750591185870967999269666742322817156798741738\",\"price\":\"0.359\",\"size\":\"45\",\"side\":\"SELL\",\"hash\":\"406c31d17a701ec6caad49620dc353de9910c3e2\",\"best_bid\":\"0\",\"best_ask\":\"0.001\"}],\"timestamp\":\"1785928837825\",\"event_type\":\"price_change\"}"}
{"recv_ts": 1785928837.9424546, "raw": "{\"market\":\"0x78d1b99c143f4c883bfac454ecb754a378e813f055e26635bd8bb1104c01e10c\",\"price_changes\":[{\"asset_id\":\"102412742158857590017747491811105003733183085810881951151838275182949174179725\",\"price\":\"0.641\",\"size\":\"25\",\"side\":\"BUY\",\"hash\":\"4366122354b4bc8a8c699c7daa823575cfe45621\",\"best_bid\":\"0.998\",\"best_ask\":\"0.999\"},{\"asset_id\":\"77458919270710097190554502750946983185517527342052889935998991292909755594834\",\"price\":\"0.359\",\"size\":\"25\",\"side\":\"SELL\",\"hash\":\"0065d448f94ce5fecfd07d0199c64891bcadd70f\",\"best_bid\":\"0.001\",\"best_ask\":\"0.002\"}],\"timestamp\":\"1785928837825\",\"event_type\":\"price_change\"}"}
{"recv_ts": 1785928837.942469, "raw": "{\"market\":\"0x04fe7337f376f8931cd3068461cec68037535ce97abcf13c042152baf13befde\",\"price_changes\":[{\"asset_id\":\"50740292274847780209507644462307574612676149355535035139336442040374589113775\",\"price\":\"0.38\",\"size\":\"384\",\"side\":\"BUY\",\"hash\":\"5b60a0a7989d4bfc82b937c3b66098493860da95\",\"best_bid\":\"0.39\",\"best_ask\":\"0.4\"},{\"asset_id\":\"53770307109125981002170328887835960390908711352346661961390902843874235145088\",\"price\":\"0.62\",\"size\":\"384\",\"side\":\"SELL\",\"hash\":\"7a858db39c12895d1e6b0fb03a8c084b5afaef0d\",\"best_bid\":\"0.6\",\"best_ask\":\"0.61\"}],\"timestamp\":\"1785928837825\",\"event_type\":\"price_change\"}"}
{"recv_ts": 1785928837.9424758, "raw": "{\"market\":\"0xb486739040088c936e729d74081f0e81fc48fce7151e5e41243d9d219453e2fe\",\"price_changes\":[{\"asset_id\":\"31140992653083956068389050095744741836184250715525331976510476908962593127814\",\"price\":\"0.43\",\"size\":\"100\",\"side\":\"BUY\",\"hash\":\"ee729dc17f953e87b59b85c5f4092166500895b2\",\"best_bid\":\"0.98\",\"best_ask\":\"0.99\"},{\"asset_id\":\"2695957428619450078473712547501643526076503784897710224766392221435772884261\",\"price\":\"0.57\",\"size\":\"100\",\"side\":\"SELL\",\"hash\":\"8d5b1c09f60fe1209bc6ad1d68b086a711a55e5a\",\"best_bid\":\"0.01\",\"best_ask\":\"0.02\"}],\"timestamp\":\"1785928837836\",\"event_type\":\"price_change\"}"}
{"recv_ts": 1785928837.9424827, "raw": "{\"market\":\"0x49e0bc2d92fd5118263bb3968c679cb8e236c6912d899b48b3925f26ed9ee209\",\"price_changes\":[{\"asset_id\":\"80051321337559111951453828109935186137789769064013919737026204361460144693479\",\"price\":\"0.56\",\"size\":\"13\",\"side\":\"SELL\",\"hash\":\"b59d39245429a956fcca37a74f4ef6071c420407\",\"best_bid\":\"0.3\",\"best_ask\":\"0.38\"},{\"asset_id\":\"9622500641191387664431955870185399485936790493585104294220539600837039752975\",\"price\":\"0.44\",\"size\":\"13\",\"side\":\"BUY\",\"hash\":\"7ff1c026c9bd6eb272b86b439bec890050faf089\",\"best_bid\":\"0.62\",\"best_ask\":\"0.7\"}],\"timestamp\":\"1785928837837\",\"event_type\":\"price_change\"}"}
{"recv_ts": 1785928837.9424896, "raw": "{\"market\":\"0xb486739040088c936e729d74081f0e81fc48fce7151e5e41243d9d219453e2fe\",\"price_changes\":[{\"asset_id\":\"31140992653083956068389050095744741836184250715525331976510476908962593127814\",\"price\":\"0.65\",\"size\":\"0\",\"side\":\"BUY\",\"hash\":\"a38d51f888881f7323572256f58759db68e4e56f\",\"best_bid\":\"0.98\",\"best_ask\":\"0.99\"},{\"asset_id\":\"2695957428619450078473712547501643526076503784897710224766392221435772884261\",\"price\":\"0.35\",\"size\":\"0\",\"side\":\"SELL\",\"hash\":\"3e5e648b5533443fa8ab6efb448f72065a5ffeec\",\"best_bid\":\"0.01\",\"best_ask\":\"0.02\"}],\"timestamp\":\"1785928837844\",\"event_type\":\"price_change\"}"}
{"recv_ts": 1785928837.9424963, "raw": "{\"market\":\"0x130cc223b8cf2d0aa833c1cd308d9bc9ae541a0603813493d86db8e6ceeaf367\",\"price_changes\":[{\"asset_id\":\"84797559581459129894146686397592394213402216446504178493974835270512414528595\",\"price\":\"0.35\",\"size\":\"60\",\"side\":\"BUY\",\"hash\":\"f8c6cd030c780df6c1980a960d9a6614b6f6c135\",\"best_bid\":\"0.65\",\"best_ask\":\"0.78\"},{\"asset_id\":\"50417249107122530467347355639451540409667050551215201803480978137821249864431\",\"price\":\"0.65\",\"size\":\"60\",\"side\":\"SELL\",\"hash\":\"9229f81c59b22a1e0f651ac96ccedae89c6ad106\",\"best_bid\":\"0.22\",\"best_ask\":\"0.35\"}],\"timestamp\":\"1785928837846\",\"event_type\":\"price_change\"}"}
{"recv_ts": 1785928837.9425123, "raw": "{\"market\":\"0x49e0bc2d92fd5118263bb3968c679cb8e236c6912d899b48b3925f26ed9ee209\",\"price_changes\":[{\"asset_id\":\"80051321337559111951453828109935186137789769064013919737026204361460144693479\",\"price\":\"0.59\",\"size\":\"107\",\"side\":\"SELL\",\"hash\":\"bc39f17e55aa8996c9d2d0dfab7d093d5c0fbfa6\",\"best_bid\":\"0.3\",\"best_ask\":\"0.38\"},{\"asset_id\":\"9622500641191387664431955870185399485936790493585104294220539600837039752975\",\"price\":\"0.41\",\"size\":\"107\",\"side\":\"BUY\",\"hash\":\"3373d7ec7f3c04793e5d45eeba2347312754bc44\",\"best_bid\":\"0.62\",\"best_ask\":\"0.7\"}],\"timestamp\":\"1785928837848\",\"event_type\":\"price_change\"}"}
{"recv_ts": 1785928837.9425223, "raw": "{\"market\":\"0xec806996a4a5f6acd2d6a18f51b15c3aa1c51ab9742183e0e6878d58cce5a0d0\",\"price_changes\":[{\"asset_id\":\"17118616214138798454321086756896158972659063265161382365722741404449969675213\",\"price\":\"0.82\",\"size\":\"10\",\"side\":\"BUY\",\"hash\":\"10fe822bf364d6a7e8d18aaf6edbbd859e77992a\",\"best_bid\":\"0.89\",\"best_ask\":\"0.98\"},{\"asset_id\":\"66442850127194305408378836595684234249962298005014821789027805328236573201788\",\"price\":\"0.18\",\"size\":\"10\",\"side\":\"SELL\",\"hash\":\"3d9cbacc5148be4d83c5319b71d4ad1f0dcadeb4\",\"best_bid\":\"0.02\",\"best_ask\":\"0.11\"}],\"timestamp\":\"1785928837848\",\"event_type\":\"price_change\"}"}
{"recv_ts": 1785928837.942532, "raw": "{\"market\":\"0xcf8d63fe5155c088784dcb2db8a6eeac4dc6a7ecbb3069a2cc852d89b2c9e5b8\",\"price_changes\":[{\"asset_id\":\"17439010682602639337342247993625278076350026240815133925416550994933294690127\",\"price\":\"0.44\",\"size\":\"193.6\",\"side\":\"BUY\",\"hash\":\"987be9d634364567850976647a18f27b804095c1\",\"best_bid\":\"0.65\",\"best_ask\":\"0.66\"},{\"asset_id\":\"88256678245767764053063285347705910948379761834566212031431077364006401584344\",\"price\":\"0.56\",\"size\":\"193.6\",\"side\":\"SELL\",\"hash\":\"80f4bce3d345dd6e34458fc763e13f5f020db1aa\",\"best_bid\":\"0.34\",\"best_ask\":\"0.35\"}],\"timestamp\":\"1785928837854\",\"event_type\":\"price_change\"}"}
{"recv_ts": 1785928837.9425411, "raw": "{\"market\":\"0xec806996a4a5f6acd2d6a18f51b15c3aa1c51ab9742183e0e6878d58cce5a0d0\",\"price_changes\":[{\"asset_id\":\"17118616214138798454321086756896158972659063265161382365722741404449969675213\",\"price\":\"0.55\",\"size\":\"0\",\"side\":\"BUY\",\"hash\":\"c3e707234f15b49c3b1806e14e283de81593e3bc\",\"best_bid\":\"0.89\",\"best_ask\":\"0.98\"},{\"asset_id\":\"66442850127194305408378836595684234249962298005014821789027805328236573201788\",\"price\":\"0.45\",\"size\":\"0\",\"side\":\"SELL\",\"hash\":\"d900fa7ea7e4fd116e0a2ee748cb7b985e207d14\",\"best_bid\":\"0.02\",\"best_ask\":\"0.11\"}],\"timestamp\":\"1785928837854\",\"event_type\":\"price_change\"}"}
{"recv_ts": 1785928837.94255, "raw": "{\"market\":\"0xec806996a4a5f6acd2d6a18f51b15c3aa1c51ab9742183e0e6878d58cce5a0d0\",\"price_changes\":[{\"asset_id\":\"17118616214138798454321086756896158972659063265161382365722741404449969675213\",\"price\":\"0.82\",\"size\":\"0\",\"side\":\"BUY\",\"hash\":\"0a573f2c0244e5be1dae5e09ef6f4b4fb643e9d7\",\"best_bid\":\"0.89\",\"best_ask\":\"0.98\"},{\"asset_id\":\"66442850127194305408378836595684234249962298005014821789027805328236573201788\",\"price\":\"0.18\",\"size\":\"0\",\"side\":\"SELL\",\"hash\":\"383232b1e3881d4932115895715f5f929781ea12\",\"best_bid\":\"0.02\",\"best_ask\":\"0.11\"}],\"timestamp\":\"1785928837867\",\"event_type\":\"price_change\"}"}
{"recv_ts": 1785928837.942559, "raw": "{\"market\":\"0xec806996a4a5f6acd2d6a18f51b15c3aa1c51ab9742183e0e6878d58cce5a0d0\",\"price_changes\":[{\"asset_id\":\"17118616214138798454321086756896158972659063265161382365722741404449969675213\",\"price\":\"0.79\",\"size\":\"0\",\"side\":\"BUY\",\"hash\":\"0a573f2c0244e5be1dae5e09ef6f4b4fb643e9d7\",\"best_bid\":\"0.89\",\"best_ask\":\"0.98\"},{\"asset_id\":\"66442850127194305408378836595684234249962298005014821789027805328236573201788\",\"price\":\"0.21\",\"size\":\"0\",\"side\":\"SELL\",\"hash\":\"383232b1e3881d4932115895715f5f929781ea12\",\"best_bid\":\"0.02\",\"best_ask\":\"0.11\"}],\"timestamp\":\"1785928837867\",\"event_type\":\"price_change\"}"}
{"recv_ts": 1785928837.9425683, "raw": "{\"market\":\"0xb486739040088c936e729d74081f0e81fc48fce7151e5e41243d9d219453e2fe\",\"price_changes\":[{\"asset_id\":\"31140992653083956068389050095744741836184250715525331976510476908962593127814\",\"price\":\"0.65\",\"size\":\"45\",\"side\":\"BUY\",\"hash\":\"e1c64c9bbe73292fad0745aa651353678f6c3121\",\"best_bid\":\"0.98\",\"best_ask\":\"0.99\"},{\"asset_id\":\"2695957428619450078473712547501643526076503784897710224766392221435772884261\",\"price\":\"0.35\",\"size\":\"45\",\"side\":\"SELL\",\"hash\":\"a7e66d187f02d051d39834706715e2143958c95a\",\"best_bid\":\"0.01\",\"best_ask\":\"0.02\"}],\"timestamp\":\"1785928837869\",\"event_type\":\"price_change\"}"}
{"recv_ts": 1785928837.9425914, "raw": "{\"market\":\"0xec806996a4a5f6acd2d6a18f51b15c3aa1c51ab9742183e0e6878d58cce5a0d0\",\"price_changes\":[{\"asset_id\":\"17118616214138798454321086756896158972659063265161382365722741404449969675213\",\"price\":\"0.54\",\"size\":\"303\",\"side\":\"BUY\",\"hash\":\"c1f2db5f3707b4b2858e53f3b636b3240f926d61\",\"best_bid\":\"0.89\",\"best_ask\":\"0.98\"},{\"asset_id\":\"66442850127194305408378836595684234249962298005014821789027805328236573201788\",\"price\":\"0.46\",\"size\":\"303\",\"side\":\"SELL\",\"hash\":\"7294c101e76243de8aaa04d239e438bcb7522fb6\",\"best_bid\":\"0.02\",\"best_ask\":\"0.11\"}],\"timestamp\":\"1785928837870\",\"event_type\":\"price_change\"}"}
{"recv_ts": 1785928837.9426014, "raw": "{\"market\":\"0x130cc223b8cf2d0aa833c1cd308d9bc9ae541a0603813493d86db8e6ceeaf367\",\"price_changes\":[{\"asset_id\":\"84797559581459129894146686397592394213402216446504178493974835270512414528595\",\"price\":\"0.35\",\"size\":\"10\",\"side\":\"BUY\",\"hash\":\"abeb9fb7c2b9bbf8ef83af4975eb2910280f082a\",\"best_bid\":\"0.65\",\"best_ask\":\"0.78\"},{\"asset_id\":\"50417249107122530467347355639451540409667050551215201803480978137821249864431\",\"price\":\"0.65\",\"size\":\"10\",\"side\":\"SELL\",\"hash\":\"3addc295b2762eba6610de3bde6a9b1860d47263\",\"best_bid\":\"0.22\",\"best_ask\":\"0.35\"}],\"timestamp\":\"1785928837873\",\"event_type\":\"price_change\"}"}
{"recv_ts": 1785928837.942611, "raw": "{\"market\":\"0xb486739040088c936e729d74081f0e81fc48fce7151e5e41243d9d219453e2fe\",\"price_changes\":[{\"asset_id\":\"31140992653083956068389050095744741836184250715525331976510476908962593127814\",\"price\":\"0.42\",\"size\":\"0\",\"side\":\"BUY\",\"hash\":\"75947f5ae40452a25375457ffd3e77c3ff320525\",\"best_bid\":\"0.98\",\"best_ask\":\"0.99\"},{\"asset_id\":\"2695957428619450078473712547501643526076503784897710224766392221435772884261\",\"price\":\"0.58\",\"size\":\"0\",\"side\":\"SELL\",\"hash\":\"6a709ea2874d0d02e552b9bf5e2861c8104121cc\",\"best_bid\":\"0.01\",\"best_ask\":\"0.02\"}],\"timestamp\":\"1785928837873\",\"event_type\":\"price_change\"}"}
{"recv_ts": 1785928837.9426203, "raw": "{\"market\":\"0xec806996a4a5f6acd2d6a18f51b15c3aa1c51ab9742183e0e6878d58cce5a0d0\",\"price_changes\":[{\"asset_id\":\"17118616214138798454321086756896158972659063265161382365722741404449969675213\",\"price\":\"0.58\",\"size\":\"50\",\"side\":\"BUY\",\"hash\":\"13e52825f3db37e8b68598277654c036660eac65\",\"best_bid\":\"0.89\",\"best_ask\":\"0.98\"},{\"asset_id\":\"66442850127194305408378836595684234249962298005014821789027805328236573201788\",\"price\":\"0.42\",\"size\":\"50\",\"side\":\"SELL\",\"hash\":\"95fd2c33ad6f18d367a53e025e08ad1f6fe413d6\",\"best_bid\":\"0.02\",\"best_ask\":\"0.11\"}],\"timestamp\":\"1785928837877\",\"event_type\":\"price_change\"}"}
{"recv_ts": 1785928837.942629, "raw": "{\"market\":\"0xec806996a4a5f6acd2d6a18f51b15c3aa1c51ab9742183e0e6878d58cce5a0d0\",\"price_changes\":[{\"asset_id\":\"17118616214138798454321086756896158972659063265161382365722741404449969675213\",\"price\":\"0.82\",\"size\":\"77\",\"side\":\"BUY\",\"hash\":\"502d73a002d5fcdda2ad5fadab62c3ab94a56fcb\",\"best_bid\":\"0.89\",\"best_ask\":\"0.98\"},{\"asset_id\":\"66442850127194305408378836595684234249962298005014821789027805328236573201788\",\"price\":\"0.18\",\"size\":\"77\",\"side\":\"SELL\",\"hash\":\"cb4212f024db01350f4e96fde1de705566c82c31\",\"best_bid\":\"0.02\",\"best_ask\":\"0.11\"}],\"timestamp\":\"1785928837878\",\"event_type\":\"price_change\"}"}
{"recv_ts": 1785928837.9426382, "raw": "{\"market\":\"0x9d59ce284519e9f2f0369add65ec0dea4e30478960f285abc70af2d1b76beec2\",\"price_changes\":[{\"asset_id\":\"8503403807554825835825187516742241065300919332765839374024863929306661721210\",\"price\":\"0.311\",\"size\":\"400\",\"side\":\"BUY\",\"hash\":\"af535ec2a79130f5220ef997fb80432b630e96da\",\"best_bid\":\"0.998\",\"best_ask\":\"0.999\"},{\"asset_id\":\"30223512369396895064014083752486018049203540341317193220024366876194287102529\",\"price\":\"0.689\",\"size\":\"400\",\"side\":\"SELL\",\"hash\":\"7368ff200b76c3dfc1dfc3fd8c71b2d2490bdb2d\",\"best_bid\":\"0.001\",\"best_ask\":\"0.002\"}],\"timestamp\":\"1785928837878\",\"event_type\":\"price_change\"}"}
{"recv_ts": 1785928837.9426472, "raw": "{\"market\":\"0xab566cdbff91073332a0e2ed9ff5a067c91f4295b45e7f419b811f7cc57b8edb\",\"price_changes\":[{\"asset_id\":\"858224069165336107309887139101186345264990943433876453050435444819500042777\",\"price\":\"0.631\",\"size\":\"50\",\"side\":\"BUY\",\"hash\":\"7b304a09ccee86af8fdbd77b444c83f30066cb0d\",\"best_bid\":\"0.998\",\"best_ask\":\"1\"},{\"asset_id\":\"78339664986092019828629644767444699887634765118583590448691028633408082863680\",\"price\":\"0.369\",\"size\":\"50\",\"side\":\"SELL\",\"hash\":\"d27dc406b5bd89e125abcd83b1571085d27cbbb3\",\"best_bid\":\"0\",\"best_ask\":\"0.002\"}],\"timestamp\":\"1785928837878\",\"event_type\":\"price_change\"}"}
{"recv_ts": 1785928837.9426563, "raw": "{\"market\":\"0x130cc223b8cf2d0aa833c1cd308d9bc9ae541a0603813493d86db8e6ceeaf367\",\"price_changes\":[{\"asset_id\":\"84797559581459129894146686397592394213402216446504178493974835270512414528595\",\"price\":\"0.32\",\"size\":\"106.25\",\"side\":\"BUY\",\"hash\":\"9ce18b58995566d4b3d3dfbd38ce81cdb569f82f\",\"best_bid\":\"0.65\",\"best_ask\":\"0.78\"},{\"asset_id\":\"50417249107122530467347355639451540409667050551215201803480978137821249864431\",\"price\":\"0.68\",\"size\":\"106.25\",\"side\":\"SELL\",\"hash\":\"23ec9d379348d814251b905a1f9bc1cdbb10cb15\",\"best_bid\":\"0.22\",\"best_ask\":\"0.35\"}],\"timestamp\":\"1785928837879\",\"event_type\":\"price_change\"}"}
{"recv_ts": 1785928837.942666, "raw": "{\"market\":\"0xe9b4e8a317c00cc347c95c9a36720492f7929f8e4cb4c1aa6c49410742ca3247\",\"price_changes\":[{\"asset_id\":\"49725804003683168820158044063139299301568536146474955034537761285736915106189\",\"price\":\"0.631\",\"size\":\"50\",\"side\":\"BUY\",\"hash\":\"ac3fd485465523a1c0049884bfe8ee1cf6c44eec\",\"best_bid\":\"0.998\",\"best_ask\":\"0.999\"},{\"asset_id\":\"69779375789382878827509646477200695767063770808156104602588660330492573155019\",\"price\":\"0.369\",\"size\":\"50\",\"side\":\"SELL\",\"hash\":\"d7ee333e005ac5afb1a5927aa0ea970ba021bb11\",\"best_bid\":\"0.001\",\"best_ask\":\"0.002\"}],\"timestamp\":\"1785928837880\",\"event_type\":\"price_change\"}"}
{"recv_ts": 1785928837.942675, "raw": "{\"market\":\"0x78d1b99c143f4c883bfac454ecb754a378e813f055e26635bd8bb1104c01e10c\",\"price_changes\":[{\"asset_id\":\"102412742158857590017747491811105003733183085810881951151838275182949174179725\",\"price\":\"0.631\",\"size\":\"50\",\"side\":\"BUY\",\"hash\":\"2e1b6093603509f7e1fe2acaa6a35c1c9d32527d\",\"best_bid\":\"0.998\",\"best_ask\":\"0.999\"},{\"asset_id\":\"77458919270710097190554502750946983185517527342052889935998991292909755594834\",\"price\":\"0.369\",\"size\":\"50\",\"side\":\"SELL\",\"hash\":\"dc0e198532e33d161960aafc9523bed1bfbb0808\",\"best_bid\":\"0.001\",\"best_ask\":\"0.002\"}],\"timestamp\":\"1785928837881\",\"event_type\":\"price_change\"}"}
{"recv_ts": 1785928837.9426847, "raw": "{\"market\":\"0xb6edcec0d720dbec04c1ccad106f8cae4168791c17ef7981ba5dd999af079865\",\"price_changes\":[{\"asset_id\":\"18116214702249440028416672680904535920938539838669208127252902741898575306507\",\"price\":\"0.631\",\"size\":\"50\",\"side\":\"BUY\",\"hash\":\"a51d2bb0e79fdcb1bd91e10d0e71dda7b0ab7231\",\"best_bid\":\"0.998\",\"best_ask\":\"1\"},{\"asset_id\":\"111500185607543632995147702414312573517975210173310244515899623973650146423799\",\"price\":\"0.369\",\"size\":\"50\",\"side\":\"SELL\",\"hash\":\"1d0018124a378105910fd103a3a2ee67def82883\",\"best_bid\":\"0\",\"best_ask\":\"0.002\"}],\"timestamp\":\"1785928837881\",\"event_type\":\"price_change\"}"}
{"recv_ts": 1785928837.942694, "raw": "{\"market\":\"0x130cc223b8cf2d0aa833c1cd308d9bc9ae541a0603813493d86db8e6ceeaf367\",\"price_changes\":[{\"asset_id\":\"84797559581459129894146686397592394213402216446504178493974835270512414528595\",\"price\":\"0.43\",\"size\":\"75\",\"side\":\"BUY\",\"hash\":\"8c1a9f068f82aad5f513e0e64cf31f45ef845d90\",\"best_bid\":\"0.65\",\"best_ask\":\"0.78\"},{\"asset_id\":\"50417249107122530467347355639451540409667050551215201803480978137821249864431\",\"price\":\"0.57\",\"size\":\"75\",\"side\":\"SELL\",\"hash\":\"c8f9f7348fd2ae12ce24bd5a63a1abcbcf63e0ad\",\"best_bid\":\"0.22\",\"best_ask\":\"0.35\"}],\"timestamp\":\"1785928837882\",\"event_type\":\"price_change\"}"}
{"recv_ts": 1785928837.9427178, "raw": "{\"market\":\"0xec806996a4a5f6acd2d6a18f51b15c3aa1c51ab9742183e0e6878d58cce5a0d0\",\"price_changes\":[{\"asset_id\":\"17118616214138798454321086756896158972659063265161382365722741404449969675213\",\"price\":\"0.3\",\"size\":\"520\",\"side\":\"BUY\",\"hash\":\"57be85566a80b15317974721e3773c9932f46b6c\",\"best_bid\":\"0.89\",\"best_ask\":\"0.98\"},{\"asset_id\":\"66442850127194305408378836595684234249962298005014821789027805328236573201788\",\"price\":\"0.7\",\"size\":\"520\",\"side\":\"SELL\",\"hash\":\"75c4002a59ce48ff0d1832c6d7543192f82d3e4a\",\"best_bid\":\"0.02\",\"best_ask\":\"0.11\"}],\"timestamp\":\"1785928837883\",\"event_type\":\"price_change\"}"}
{"recv_ts": 1785928837.942727, "raw": "{\"market\":\"0xb486739040088c936e729d74081f0e81fc48fce7151e5e41243d9d219453e2fe\",\"price_changes\":[{\"asset_id\":\"31140992653083956068389050095744741836184250715525331976510476908962593127814\",\"price\":\"0.62\",\"size\":\"60\",\"side\":\"BUY\",\"hash\":\"e8c250ba00016a34e6b5ae621440ad5b801d5470\",\"best_bid\":\"0.98\",\"best_ask\":\"0.99\"},{\"asset_id\":\"2695957428619450078473712547501643526076503784897710224766392221435772884261\",\"price\":\"0.38\",\"size\":\"60\",\"side\":\"SELL\",\"hash\":\"715cd50bbcd449c0a5059fcf1560d8f407499027\",\"best_bid\":\"0.01\",\"best_ask\":\"0.02\"}],\"timestamp\":\"1785928837883\",\"event_type\":\"price_change\"}"}
{"recv_ts": 1785928837.9427361, "raw": "{\"market\":\"0xab566cdbff91073332a0e2ed9ff5a067c91f4295b45e7f419b811f7cc57b8edb\",\"price_changes\":[{\"asset_id\":\"858224069165336107309887139101186345264990943433876453050435444819500042777\",\"price\":\"0.315\",\"size\":\"400\",\"side\":\"BUY\",\"hash\":\"aae974cc4b54bc4d0a5a68f9db97c826413eccec\",\"best_bid\":\"0.998\",\"best_ask\":\"1\"},{\"asset_id\":\"78339664986092019828629644767444699887634765118583590448691028633408082863680\",\"price\":\"0.685\",\"size\":\"400\",\"side\":\"SELL\",\"hash\":\"f7be725d5f09d26627ddb16e77af72a642d4c810\",\"best_bid\":\"0\",\"best_ask\":\"0.002\"}],\"timestamp\":\"1785928837884\",\"event_type\":\"price_change\"}"}
{"recv_ts": 1785928837.9427454, "raw": "{\"market\":\"0xb0888f1ce675a9aa0922477fe51dee0301f8151c6c654fdca0b6686b3d950d72\",\"price_changes\":[{\"asset_id\":\"23899216176849972464746004559512101061428203436614711958419582587808176252521\",\"price\":\"0.631\",\"size\":\"50\",\"side\":\"BUY\",\"hash\":\"0f16a41400b23eb051b2a66ccc5fca80acd0ddb4\",\"best_bid\":\"0.999\",\"best_ask\":\"1\"},{\"asset_id\":\"36643957373341611960904326441294750591185870967999269666742322817156798741738\",\"price\":\"0.369\",\"size\":\"50\",\"side\":\"SELL\",\"hash\":\"2b522580065d71b69cc30f5cf2fabc7edc7a1597\",\"best_bid\":\"0\",\"best_ask\":\"0.001\"}],\"timestamp\":\"1785928837885\",\"event_type\":\"price_change\"}"}
{"recv_ts": 1785928837.9427545, "raw": "{\"market\":\"0x130cc223b8cf2d0aa833c1cd308d9bc9ae541a0603813493d86db8e6ceeaf367\",\"price_changes\":[{\"asset_id\":\"84797559581459129894146686397592394213402216446504178493974835270512414528595\",\"price\":\"0.21\",\"size\":\"400\",\"side\":\"BUY\",\"hash\":\"8013c88678b8ef4837604387caab3ca67d05d206\",\"best_bid\":\"0.65\",\"best_ask\":\"0.78\"},{\"asset_id\":\"50417249107122530467347355639451540409667050551215201803480978137821249864431\",\"price\":\"0.79\",\"size\":\"400\",\"side\":\"SELL\",\"hash\":\"b3a98a8783a1f826cfff193a8abb7088283be7ca\",\"best_bid\":\"0.22\",\"best_ask\":\"0.35\"}],\"timestamp\":\"1785928837886\",\"event_type\":\"price_change\"}"}
{"recv_ts": 1785928837.942764, "raw": "{\"market\":\"0xcf8d63fe5155c088784dcb2db8a6eeac4dc6a7ecbb3069a2cc852d89b2c9e5b8\",\"price_changes\":[{\"asset_id\":\"17439010682602639337342247993625278076350026240815133925416550994933294690127\",\"price\":\"0.43\",\"size\":\"460\",\"side\":\"BUY\",\"hash\":\"34f96ba35377e6051183c8bfe1587d19c680a4c0\",\"best_bid\":\"0.65\",\"best_ask\":\"0.66\"},{\"asset_id\":\"88256678245767764053063285347705910948379761834566212031431077364006401584344\",\"price\":\"0.57\",\"size\":\"460\",\"side\":\"SELL\",\"hash\":\"916da3381159dd03ace0ba8c268ab573b6a39b2d\",\"best_bid\":\"0.34\",\"best_ask\":\"0.35\"}],\"timestamp\":\"1785928837889\",\"event_type\":\"price_change\"}"}
{"recv_ts": 1785928837.9427738, "raw": "{\"market\":\"0xec806996a4a5f6acd2d6a18f51b15c3aa1c51ab9742183e0e6878d58cce5a0d0\",\"price_changes\":[{\"asset_id\":\"17118616214138798454321086756896158972659063265161382365722741404449969675213\",\"price\":\"0.74\",\"size\":\"75\",\"side\":\"BUY\",\"hash\":\"22be6a22acbc375bd95ef6447399f59f8f4f0612\",\"best_bid\":\"0.89\",\"best_ask\":\"0.98\"},{\"asset_id\":\"66442850127194305408378836595684234249962298005014821789027805328236573201788\",\"price\":\"0.26\",\"size\":\"75\",\"side\":\"SELL\",\"hash\":\"f8c21ccccc74cd04e41e02f82621a296596916db\",\"best_bid\":\"0.02\",\"best_ask\":\"0.11\"}],\"timestamp\":\"1785928837890\",\"event_type\":\"price_change\"}"}
{"recv_ts": 1785928837.9427829, "raw": "{\"market\":\"0xec806996a4a5f6acd2d6a18f51b15c3aa1c51ab9742183e0e6878d58cce5a0d0\",\"price_changes\":[{\"asset_id\":\"17118616214138798454321086756896158972659063265161382365722741404449969675213\",\"price\":\"0.74\",\"size\":\"85\",\"side\":\"BUY\",\"hash\":\"46ddec5895cfdfe36cf600b3481b814f11450f34\",\"best_bid\":\"0.89\",\"best_ask\":\"0.98\"},{\"asset_id\":\"66442850127194305408378836595684234249962298005014821789027805328236573201788\",\"price\":\"0.26\",\"size\":\"85\",\"side\":\"SELL\",\"hash\":\"19eaceb5a93561a43886b334578bc1fd382b9417\",\"best_bid\":\"0.02\",\"best_ask\":\"0.11\"}],\"timestamp\":\"1785928837891\",\"event_type\":\"price_change\"}"}
{"recv_ts": 1785928837.942792, "raw": "{\"market\":\"0xf70b1e7e21cbcf0bf2f718e89e5a35433f0b23b25a637ab9e03e59ec88067c88\",\"price_changes\":[{\"asset_id\":\"51136076050933303814845579746011726280350225608825544637207593585011721290322\",\"price\":\"0.611\",\"size\":\"0\",\"side\":\"BUY\",\"hash\":\"19bb6c230112db06fea46b7a89842e19e712fed3\",\"best_bid\":\"0.999\",\"best_ask\":\"1\"},{\"asset_id\":\"60355106290311882722789017119331532709385060114501109427963183552374323506695\",\"price\":\"0.389\",\"size\":\"0\",\"side\":\"SELL\",\"hash\":\"f65985914da71ba615b50c43e8900759925f84a9\",\"best_bid\":\"0\",\"best_ask\":\"0.001\"}],\"timestamp\":\"1785928837902\",\"event_type\":\"price_change\"}"}
{"recv_ts": 1785928837.9428005, "raw": "{\"market\":\"0x130cc223b8cf2d0aa833c1cd308d9bc9ae541a0603813493d86db8e6ceeaf367\",\"price_changes\":[{\"asset_id\":\"84797559581459129894146686397592394213402216446504178493974835270512414528595\",\"price\":\"0.43\",\"size\":\"50\",\"side\":\"BUY\",\"hash\":\"5f2bf890837f3e52beefe1948e6b5b95306b23ed\",\"best_bid\":\"0.65\",\"best_ask\":\"0.78\"},{\"asset_id\":\"50417249107122530467347355639451540409667050551215201803480978137821249864431\",\"price\":\"0.57\",\"size\":\"50\",\"side\":\"SELL\",\"hash\":\"e5751cca4ed6c03aa96823b1e272dae76ec31058\",\"best_bid\":\"0.22\",\"best_ask\":\"0.35\"}],\"timestamp\":\"1785928837902\",\"event_type\":\"price_change\"}"}
{"recv_ts": 1785928837.9428096, "raw": "{\"market\":\"0x4b8b58f97c193f480e83d511c276d6131ca372ee5504cd4794c20967e2f4d2e0\",\"price_changes\":[{\"asset_id\":\"36044484968316107178921007507960096972223709741791131257962480235902699344131\",\"price\":\"0.8\",\"size\":\"95\",\"side\":\"BUY\",\"hash\":\"33c4587addb49d53dba10e151c96067843fcd12f\",\"best_bid\":\"0.887\",\"best_ask\":\"0.91\"},{\"asset_id\":\"22395479087762588606691197614629615906167809250098702092639291066698521984331\",\"price\":\"0.2\",\"size\":\"95\",\"side\":\"SELL\",\"hash\":\"a4865d4aacc26f5553f5011c5c45080d36e68de3\",\"best_bid\":\"0.09\",\"best_ask\":\"0.113\"}],\"timestamp\":\"1785928837902\",\"event_type\":\"price_change\"}"}
{"recv_ts": 1785928837.9428186, "raw": "{\"market\":\"0x9d59ce284519e9f2f0369add65ec0dea4e30478960f285abc70af2d1b76beec2\",\"price_changes\":[{\"asset_id\":\"8503403807554825835825187516742241065300919332765839374024863929306661721210\",\"price\":\"0.611\",\"size\":\"0\",\"side\":\"BUY\",\"hash\":\"b59a992c39217411619cc37ebc08123a477fba2d\",\"best_bid\":\"0.998\",\"best_ask\":\"0.999\"},{\"asset_id\":\"30223512369396895064014083752486018049203540341317193220024366876194287102529\",\"price\":\"0.389\",\"size\":\"0\",\"side\":\"SELL\",\"hash\":\"1beec90d744cbbef85e40648ab394369be4be874\",\"best_bid\":\"0.001\",\"best_ask\":\"0.002\"}],\"timestamp\":\"1785928837902\",\"event_type\":\"price_change\"}"}
{"recv_ts": 1785928837.9428406, "raw": "{\"market\":\"0x78d1b99c143f4c883bfac454ecb754a378e813f055e26635bd8bb1104c01e10c\",\"price_changes\":[{\"asset_id\":\"102412742158857590017747491811105003733183085810881951151838275182949174179725\",\"price\":\"0.641\",\"size\":\"0\",\"side\":\"BUY\",\"hash\":\"07ddfd89bb7cff9ff40a88fac80d3386e0ccf456\",\"best_bid\":\"0.998\",\"best_ask\":\"0.999\"},{\"asset_id\":\"77458919270710097190554502750946983185517527342052889935998991292909755594834\",\"price\":\"0.359\",\"size\":\"0\",\"side\":\"SELL\",\"hash\":\"dc78a36f8ec1bee5ec85e66890fe0b572e6fc042\",\"best_bid\":\"0.001\",\"best_ask\":\"0.002\"}],\"timestamp\":\"1785928837902\",\"event_type\":\"price_change\"}"}
{"recv_ts": 1785928837.9428484, "raw": "{\"market\":\"0x5f6237736dc11d27fba4fad4fb25f99efd989f317b526ea34e3389aed21e9989\",\"price_changes\":[{\"asset_id\":\"37621045142846649045567920410637528745565882107360712540945877385602345149225\",\"price\":\"0.032\",\"size\":\"15\",\"side\":\"BUY\",\"hash\":\"cb3393deeb6dab491bdcc211d9ef09db154191f9\",\"best_bid\":\"0.035\",\"best_ask\":\"0.065\"},{\"asset_id\":\"43057741765998250782966918529553157356197931933657738370765235809855474471330\",\"price\":\"0.968\",\"size\":\"15\",\"side\":\"SELL\",\"hash\":\"d520fe7ebfc606e19ff488d1f1b638c11f3048e0\",\"best_bid\":\"0.935\",\"best_ask\":\"0.965\"}],\"timestamp\":\"1785928837903\",\"event_type\":\"price_change\"}"}
{"recv_ts": 1785928837.942855, "raw": "{\"market\":\"0x130cc223b8cf2d0aa833c1cd308d9bc9ae541a0603813493d86db8e6ceeaf367\",\"price_changes\":[{\"asset_id\":\"84797559581459129894146686397592394213402216446504178493974835270512414528595\",\"price\":\"0.38\",\"size\":\"55.26\",\"side\":\"BUY\",\"hash\":\"e6343e8279a9609c48dffa4f36250ddc3b20ec91\",\"best_bid\":\"0.65\",\"best_ask\":\"0.78\"},{\"asset_id\":\"50417249107122530467347355639451540409667050551215201803480978137821249864431\",\"price\":\"0.62\",\"size\":\"55.26\",\"side\":\"SELL\",\"hash\":\"ecfe66e457cb5fafe60a2ecc3e59c08f6f319b86\",\"best_bid\":\"0.22\",\"best_ask\":\"0.35\"}],\"timestamp\":\"1785928837905\",\"event_type\":\"price_change\"}"}
{"recv_ts": 1785928837.9428616, "raw": "{\"market\":\"0xbb56f84320f6a322405d2a673ae1c09791696dfee009c8b4924a4d50ce02fdb2\",\"price_changes\":[{\"asset_id\":\"36752791203026604630773349263680321016807027579769857760609995963265445842019\",\"price\":\"0.923\",\"size\":\"15\",\"side\":\"BUY\",\"hash\":\"3d17b10681f6def37a441eae7c82982fb82c5b17\",\"best_bid\":\"0.95\",\"best_ask\":\"0.962\"},{\"asset_id\":\"3419269731159625127662380738887584521691084977785981284355622556812487764723\",\"price\":\"0.077\",\"size\":\"15\",\"side\":\"SELL\",\"hash\":\"8f1c265e1cae9e443af8fd505f4a7a65fa08572c\",\"best_bid\":\"0.038\",\"best_ask\":\"0.05\"}],\"timestamp\":\"1785928837905\",\"event_type\":\"price_change\"}"}
{"recv_ts": 1785928837.9428682, "raw": "{\"market\":\"0xb486739040088c936e729d74081f0e81fc48fce7151e5e41243d9d219453e2fe\",\"price_changes\":[{\"asset_id\":\"31140992653083956068389050095744741836184250715525331976510476908962593127814\",\"price\":\"0.43\",\"size\":\"150\",\"side\":\"BUY\",\"hash\":\"eba533888f6912dc044f33fa95f8919fb09bd0b7\",\"best_bid\":\"0.98\",\"best_ask\":\"0.99\"},{\"asset_id\":\"2695957428619450078473712547501643526076503784897710224766392221435772884261\",\"price\":\"0.57\",\"size\":\"150\",\"side\":\"SELL\",\"hash\":\"bcc5436bf21ee461a65904fda725b82bd0c8352e\",\"best_bid\":\"0.01\",\"best_ask\":\"0.02\"}],\"timestamp\":\"1785928837906\",\"event_type\":\"price_change\"}"}
{"recv_ts": 1785928837.943635, "raw": "{\"market\":\"0x0393e451a7889f6472d5099a6de21d1fc6bea6ada01c2e227ea954a8ebce1771\",\"price_changes\":[{\"asset_id\":\"19078179119846452574438096789570272099502061228398927027811652354916673625092\",\"price\":\"0.056\",\"size\":\"0\",\"side\":\"BUY\",\"hash\":\"496623006938a41803ea6773be716cae89b561c3\",\"best_bid\":\"0.057\",\"best_ask\":\"0.085\"},{\"asset_id\":\"62439955870856164313493799301554574122664268361492077980110236255342893751283\",\"price\":\"0.944\",\"size\":\"0\",\"side\":\"SELL\",\"hash\":\"24443e349fa6e146739230b451b51026d565f733\",\"best_bid\":\"0.915\",\"best_ask\":\"0.943\"}],\"timestamp\":\"1785928837854\",\"event_type\":\"price_change\"}"}
{"recv_ts": 1785928837.943656, "raw": "{\"market\":\"0x0393e451a7889f6472d5099a6de21d1fc6bea6ada01c2e227ea954a8ebce1771\",\"price_changes\":[{\"asset_id\":\"19078179119846452574438096789570272099502061228398927027811652354916673625092\",\"price\":\"0.055\",\"size\":\"0\",\"side\":\"BUY\",\"hash\":\"560c55bdab5df388d304ac45af1cd14d5bfba230\",\"best_bid\":\"0.057\",\"best_ask\":\"0.085\"},{\"asset_id\":\"62439955870856164313493799301554574122664268361492077980110236255342893751283\",\"price\":\"0.945\",\"size\":\"0\",\"side\":\"SELL\",\"hash\":\"a29e9288fd8821930b35e50d46e7478b72b01300\",\"best_bid\":\"0.915\",\"best_ask\":\"0.943\"}],\"timestamp\":\"1785928837864\",\"event_type\":\"price_change\"}"}
{"recv_ts": 1785928837.9436677, "raw": "{\"market\":\"0x9564d81934c1550b627ff159cc139675d7d08916fa74cc4aaf8d416e4bedd807\",\"price_changes\":[{\"asset_id\":\"46123186009598106104671689617421295270790145953546842072887829618094075293472\",\"price\":\"0.49\",\"size\":\"7\",\"side\":\"BUY\",\"hash\":\"049d0843f159da36caf1a68078c7313948a16818\",\"best_bid\":\"0.49\",\"best_ask\":\"0.74\"},{\"asset_id\":\"33275922446271605474639218893344378139793083231796398469699104729778621445854\",\"price\":\"0.51\",\"size\":\"7\",\"side\":\"SELL\",\"hash\":\"cbf87655630747af25e82195a258492713014d9e\",\"best_bid\":\"0.26\",\"best_ask\":\"0.51\"}],\"timestamp\":\"1785928837870\",\"event_type\":\"price_change\"}"}
{"recv_ts": 1785928837.9436774, "raw": "{\"market\":\"0x0393e451a7889f6472d5099a6de21d1fc6bea6ada01c2e227ea954a8ebce1771\",\"price_changes\":[{\"asset_id\":\"62439955870856164313493799301554574122664268361492077980110236255342893751283\",\"price\":\"0.915\",\"size\":\"0\",\"side\":\"BUY\",\"hash\":\"4d04a6d8a44fcb0a73d6a11799d0f6e366bb5954\",\"best_bid\":\"0.913\",\"best_ask\":\"0.943\"},{\"asset_id\":\"19078179119846452574438096789570272099502061228398927027811652354916673625092\",\"price\":\"0.085\",\"size\":\"0\",\"side\":\"SELL\",\"hash\":\"f5bdaaf8be6cab5ae04a04c023f23311f9298826\",\"best_bid\":\"0.057\",\"best_ask\":\"0.087\"}],\"timestamp\":\"1785928837887\",\"event_type\":\"price_change\"}"}
{"recv_ts": 1785928837.943687, "raw": "{\"market\":\"0x0393e451a7889f6472d5099a6de21d1fc6bea6ada01c2e227ea954a8ebce1771\",\"price_changes\":[{\"asset_id\":\"62439955870856164313493799301554574122664268361492077980110236255342893751283\",\"price\":\"0.913\",\"size\":\"34\",\"side\":\"BUY\",\"hash\":\"e61d0470a957a74fd711c119158bfa88f4404995\",\"best_bid\":\"0.913\",\"best_ask\":\"0.943\"},{\"asset_id\":\"19078179119846452574438096789570272099502061228398927027811652354916673625092\",\"price\":\"0.087\",\"size\":\"34\",\"side\":\"SELL\",\"hash\":\"033d1e145706e17bccc677f6fdc916180c5a2623\",\"best_bid\":\"0.057\",\"best_ask\":\"0.087\"}],\"timestamp\":\"1785928837889\",\"event_type\":\"price_change\"}"}
{"recv_ts": 1785928837.943696, "raw": "{\"market\":\"0x31cc8cc9d1b3dbdc5219e0319a01ded09ad0c18296c8f27bc76b1f12364a4661\",\"price_changes\":[{\"asset_id\":\"51223233815348005431570032441325849255204346210650700628294623504463311020670\",\"price\":\"0.22\",\"size\":\"13\",\"side\":\"BUY\",\"hash\":\"e6158f26af3675a134e2300920b300190468d2b3\",\"best_bid\":\"0.22\",\"best_ask\":\"0.43\"},{\"asset_id\":\"36593914907192135817908362063800584939108275837285837232090830833195276003888\",\"price\":\"0.78\",\"size\":\"13\",\"side\":\"SELL\",\"hash\":\"7e60a261e4f0b823e13281d185bc48052decfd33\",\"best_bid\":\"0.57\",\"best_ask\":\"0.78\"}],\"timestamp\":\"1785928837893\",\"event_type\":\"price_change\"}"}
{"recv_ts": 1785928837.9437053, "raw": "{\"market\":\"0x0393e451a7889f6472d5099a6de21d1fc6bea6ada01c2e227ea954a8ebce1771\",\"price_changes\":[{\"asset_id\":\"19078179119846452574438096789570272099502061228398927027811652354916673625092\",\"price\":\"0.058\",\"size\":\"17.24\",\"side\":\"BUY\",\"hash\":\"7cff03c24524c1fbc5332af8c8bdb5cc80510eee\",\"best_bid\":\"0.058\",\"best_ask\":\"0.087\"},{\"asset_id\":\"62439955870856164313493799301554574122664268361492077980110236255342893751283\",\"price\":\"0.942\",\"size\":\"17.24\",\"side\":\"SELL\",\"hash\":\"79b2cb00d77053a15e5a0b08986ac38f7f65ea7a\",\"best_bid\":\"0.913\",\"best_ask\":\"0.942\"}],\"timestamp\":\"1785928837893\",\"event_type\":\"price_change\"}"}
{"recv_ts": 1785928837.9437356, "raw": "{\"market\":\"0x9564d81934c1550b627ff159cc139675d7d08916fa74cc4aaf8d416e4bedd807\",\"price_changes\":[{\"asset_id\":\"33275922446271605474639218893344378139793083231796398469699104729778621445854\",\"price\":\"0.52\",\"size\":\"35.06\",\"side\":\"SELL\",\"hash\":\"1c6151c3f843fec7bfd4d1b3ae9e6748868a94c7\",\"best_bid\":\"0.26\",\"best_ask\":\"0.51\"},{\"asset_id\":\"46123186009598106104671689617421295270790145953546842072887829618094075293472\",\"price\":\"0.48\",\"size\":\"35.06\",\"side\":\"BUY\",\"hash\":\"f1c510442aad03a395801d0c024765d74eee9cad\",\"best_bid\":\"0.49\",\"best_ask\":\"0.74\"}],\"timestamp\":\"1785928837894\",\"event_type\":\"price_change\"}"}
{"recv_ts": 1785928837.9437451, "raw": "{\"market\":\"0x9564d81934c1550b627ff159cc139675d7d08916fa74cc4aaf8d416e4bedd807\",\"price_changes\":[{\"asset_id\":\"46123186009598106104671689617421295270790145953546842072887829618094075293472\",\"price\":\"0.48\",\"size\":\"27.06\",\"side\":\"BUY\",\"hash\":\"719518eca1f0ec37c14445543e87d054c6d58fe0\",\"best_bid\":\"0.49\",\"best_ask\":\"0.74\"},{\"asset_id\":\"33275922446271605474639218893344378139793083231796398469699104729778621445854\",\"price\":\"0.52\",\"size\":\"27.06\",\"side\":\"SELL\",\"hash\":\"6fa7f76a23610064178e693f79901cd5515e3852\",\"best_bid\":\"0.26\",\"best_ask\":\"0.51\"}],\"timestamp\":\"1785928837894\",\"event_type\":\"price_change\"}"}
{"recv_ts": 1785928837.943754, "raw": "{\"market\":\"0x9564d81934c1550b627ff159cc139675d7d08916fa74cc4aaf8d416e4bedd807\",\"price_changes\":[{\"asset_id\":\"46123186009598106104671689617421295270790145953546842072887829618094075293472\",\"price\":\"0.42\",\"size\":\"0\",\"side\":\"BUY\",\"hash\":\"719518eca1f0ec37c14445543e87d054c6d58fe0\",\"best_bid\":\"0.49\",\"best_ask\":\"0.74\"},{\"asset_id\":\"33275922446271605474639218893344378139793083231796398469699104729778621445854\",\"price\":\"0.58\",\"size\":\"0\",\"side\":\"SELL\",\"hash\":\"6fa7f76a23610064178e693f79901cd5515e3852\",\"best_bid\":\"0.26\",\"best_ask\":\"0.51\"}],\"timestamp\":\"1785928837894\",\"event_type\":\"price_change\"}"}
{"recv_ts": 1785928837.943763, "raw": "{\"market\":\"0x0393e451a7889f6472d5099a6de21d1fc6bea6ada01c2e227ea954a8ebce1771\",\"price_changes\":[{\"asset_id\":\"19078179119846452574438096789570272099502061228398927027811652354916673625092\",\"price\":\"0.084\",\"size\":\"8.28\",\"side\":\"SELL\",\"hash\":\"36a9df150cb7ba952f38eedba8df45473aa8cf28\",\"best_bid\":\"0.058\",\"best_ask\":\"0.084\"},{\"asset_id\":\"62439955870856164313493799301554574122664268361492077980110236255342893751283\",\"price\":\"0.916\",\"size\":\"8.28\",\"side\":\"BUY\",\"hash\":\"71ab3b0e0477d267e183fe0bbb5d8d0a873bfaea\",\"best_bid\":\"0.916\",\"best_ask\":\"0.942\"}],\"timestamp\":\"1785928837899\",\"event_type\":\"price_change\"}"}
{"recv_ts": 1785928837.9437718, "raw": "{\"market\":\"0x9564d81934c1550b627ff159cc139675d7d08916fa74cc4aaf8d416e4bedd807\",\"price_changes\":[{\"asset_id\":\"46123186009598106104671689617421295270790145953546842072887829618094075293472\",\"price\":\"0.48\",\"size\":\"12.06\",\"side\":\"BUY\",\"hash\":\"517b31e0ac1614c9349ca35ae59ad71839968e7e\",\"best_bid\":\"0.49\",\"best_ask\":\"0.74\"},{\"asset_id\":\"33275922446271605474639218893344378139793083231796398469699104729778621445854\",\"price\":\"0.52\",\"size\":\"12.06\",\"side\":\"SELL\",\"hash\":\"9f878c8fe620fa90df54a6b579c66fa4528da161\",\"best_bid\":\"0.26\",\"best_ask\":\"0.51\"}],\"timestamp\":\"1785928837912\",\"event_type\":\"price_change\"}"}
{"recv_ts": 1785928837.9437807, "raw": "{\"market\":\"0x9564d81934c1550b627ff159cc139675d7d08916fa74cc4aaf8d416e4bedd807\",\"price_changes\":[{\"asset_id\":\"46123186009598106104671689617421295270790145953546842072887829618094075293472\",\"price\":\"0.48\",\"size\":\"25.06\",\"side\":\"BUY\",\"hash\":\"af8104b7991daf581e16a9637b80bdff9a0fc97a\",\"best_bid\":\"0.49\",\"best_ask\":\"0.74\"},{\"asset_id\":\"33275922446271605474639218893344378139793083231796398469699104729778621445854\",\"price\":\"0.52\",\"size\":\"25.06\",\"side\":\"SELL\",\"hash\":\"3d63d99b84c65bb51adf5cefdcbf04ac4aff4d2a\",\"best_bid\":\"0.26\",\"best_ask\":\"0.51\"}],\"timestamp\":\"1785928837931\",\"event_type\":\"price_change\"}"}
{"recv_ts": 1785928837.9437892, "raw": "{\"market\":\"0x0393e451a7889f6472d5099a6de21d1fc6bea6ada01c2e227ea954a8ebce1771\",\"price_changes\":[{\"asset_id\":\"62439955870856164313493799301554574122664268361492077980110236255342893751283\",\"price\":\"0.913\",\"size\":\"29\",\"side\":\"BUY\",\"hash\":\"cd635a7e5732caf48969a6b4d1c7891f9b78b62f\",\"best_bid\":\"0.916\",\"best_ask\":\"0.942\"},{\"asset_id\":\"19078179119846452574438096789570272099502061228398927027811652354916673625092\",\"price\":\"0.087\",\"size\":\"29\",\"side\":\"SELL\",\"hash\":\"fba846d10c272ec79068e8730d9d821a90188244\",\"best_bid\":\"0.058\",\"best_ask\":\"0.084\"}],\"timestamp\":\"1785928837932\",\"event_type\":\"price_change\"}"}
